Workbook

Sheet Readme
A1: 字段 / field | B1: 内容 / value
A2: 任务 | B2: 宁德时代2025年经营现金与信用分析
A3: 版本 | B3: catl-2025-example-v1
A4: 信息截止 | B4: 2026-03-10
A5: 范围 | B5: consolidated
A6: 准则 | B6: CAS
A7: 单位 | B7: Facts D=原始值，E=倍数，F=基础单位。Calculations D=基础单位，E=展示值。
A8: 复算 | B8: 数值公式可编辑；修改主体、期间、币种、规则或资料后须重跑 export.py 复核口径。
A9: 缺口 | B9: 空值不是零。未执行程序、假设与已披露数据分别标识。
A10: 限制 | B10: 本例为选定公开资料的专业研究示范，不是整本年报全部披露的完整审计。
A11: 限制 | B11: 未取得银行/授信合同、按法人可调度现金、逐月预算、保修明细及资产组原始预测，不出具正式信用等级或审计鉴证。
A12: 限制 | B12: 事实以2026年3月10日已公开的2025年报为界；假设与实际披露分列。

Sheet Facts
A1: ID | B1: 原始科目 | C1: 证据 | D1: 原始数值 | E1: 倍数 | F1: 基础单位数值 | G1: 量纲 | H1: 币种 | I1: 实体 | J1: 范围 | K1: 开始 | L1: 结束 | M1: 统计类型 | N1: 状态 | O1: 准则 | P1: 说明 | Q1: 概念 | R1: 实物单位
A2: revenue | B2: 营业收入 | C2: E_PL | D2: 423701834 | E2: 1000 | F2: =IF(COUNT(D2,E2)=2,D2*E2,NA()) -> 423701834000 | G2: money | H2: CNY | I2: 宁德时代集团 | J2: consolidated | K2: 2025-01-01 | L2: 2025-12-31 | M2: flow | N2: reported | O2: CAS | Q2: revenue
A3: revenue_prior | B3: 营业收入 上期 | C3: E_PL | D3: 362012554 | E3: 1000 | F3: =IF(COUNT(D3,E3)=2,D3*E3,NA()) -> 362012554000 | G3: money | H3: CNY | I3: 宁德时代集团 | J3: consolidated | K3: 2024-01-01 | L3: 2024-12-31 | M3: flow | N3: reported | O3: CAS | Q3: revenue
A4: cost | B4: 营业成本 | C4: E_PL | D4: 312383297 | E4: 1000 | F4: =IF(COUNT(D4,E4)=2,D4*E4,NA()) -> 312383297000 | G4: money | H4: CNY | I4: 宁德时代集团 | J4: consolidated | K4: 2025-01-01 | L4: 2025-12-31 | M4: flow | N4: reported | O4: CAS | Q4: cost
A5: cost_prior | B5: 营业成本 上期 | C5: E_PL | D5: 273518959 | E5: 1000 | F5: =IF(COUNT(D5,E5)=2,D5*E5,NA()) -> 273518959000 | G5: money | H5: CNY | I5: 宁德时代集团 | J5: consolidated | K5: 2024-01-01 | L5: 2024-12-31 | M5: flow | N5: reported | O5: CAS | Q5: cost
A6: ni | B6: 合并净利润 | C6: E_BRIDGE | D6: 76786309 | E6: 1000 | F6: =IF(COUNT(D6,E6)=2,D6*E6,NA()) -> 76786309000 | G6: money | H6: CNY | I6: 宁德时代集团 | J6: consolidated | K6: 2025-01-01 | L6: 2025-12-31 | M6: flow | N6: reported | O6: CAS | Q6: ni
A7: ni_prior | B7: 合并净利润 上期 | C7: E_BRIDGE | D7: 54006794 | E7: 1000 | F7: =IF(COUNT(D7,E7)=2,D7*E7,NA()) -> 54006794000 | G7: money | H7: CNY | I7: 宁德时代集团 | J7: consolidated | K7: 2024-01-01 | L7: 2024-12-31 | M7: flow | N7: reported | O7: CAS | Q7: ni
A8: cfo | B8: 经营活动现金净额 | C8: E_CF | D8: 133219982 | E8: 1000 | F8: =IF(COUNT(D8,E8)=2,D8*E8,NA()) -> 133219982000 | G8: money | H8: CNY | I8: 宁德时代集团 | J8: consolidated | K8: 2025-01-01 | L8: 2025-12-31 | M8: flow | N8: reported | O8: CAS | Q8: cfo
A9: cfo_prior | B9: 经营活动现金净额 上期 | C9: E_CF | D9: 96990345 | E9: 1000 | F9: =IF(COUNT(D9,E9)=2,D9*E9,NA()) -> 96990345000 | G9: money | H9: CNY | I9: 宁德时代集团 | J9: consolidated | K9: 2024-01-01 | L9: 2024-12-31 | M9: flow | N9: reported | O9: CAS | Q9: cfo
A10: cash | B10: 现金及现金等价物 | C10: E_CASH | D10: 299929741 | E10: 1000 | F10: =IF(COUNT(D10,E10)=2,D10*E10,NA()) -> 299929741000 | G10: money | H10: CNY | I10: 宁德时代集团 | J10: consolidated | L10: 2025-12-31 | M10: instant | N10: reported | O10: CAS | Q10: cash
A11: cash_prior | B11: 现金及现金等价物 上期 | C11: E_CASH | D11: 270159734 | E11: 1000 | F11: =IF(COUNT(D11,E11)=2,D11*E11,NA()) -> 270159734000 | G11: money | H11: CNY | I11: 宁德时代集团 | J11: consolidated | L11: 2024-12-31 | M11: instant | N11: reported | O11: CAS | Q11: cash
A12: assets | B12: 资产总额 | C12: E_BS | D12: 974827544 | E12: 1000 | F12: =IF(COUNT(D12,E12)=2,D12*E12,NA()) -> 974827544000 | G12: money | H12: CNY | I12: 宁德时代集团 | J12: consolidated | L12: 2025-12-31 | M12: instant | N12: reported | O12: CAS | Q12: assets
A13: assets_prior | B13: 资产总额 上期 | C13: E_BS | D13: 786658123 | E13: 1000 | F13: =IF(COUNT(D13,E13)=2,D13*E13,NA()) -> 786658123000 | G13: money | H13: CNY | I13: 宁德时代集团 | J13: consolidated | L13: 2024-12-31 | M13: instant | N13: reported | O13: CAS | Q13: assets
A14: equity | B14: 所有者权益总额 | C14: E_BS | D14: 371026324 | E14: 1000 | F14: =IF(COUNT(D14,E14)=2,D14*E14,NA()) -> 371026324000 | G14: money | H14: CNY | I14: 宁德时代集团 | J14: consolidated | L14: 2025-12-31 | M14: instant | N14: reported | O14: CAS | Q14: equity
A15: equity_prior | B15: 所有者权益总额 上期 | C15: E_BS | D15: 273456174 | E15: 1000 | F15: =IF(COUNT(D15,E15)=2,D15*E15,NA()) -> 273456174000 | G15: money | H15: CNY | I15: 宁德时代集团 | J15: consolidated | L15: 2024-12-31 | M15: instant | N15: reported | O15: CAS | Q15: equity
A16: parent_equity | B16: 归母权益 | C16: E_BS | D16: 337107747 | E16: 1000 | F16: =IF(COUNT(D16,E16)=2,D16*E16,NA()) -> 337107747000 | G16: money | H16: CNY | I16: 宁德时代集团 | J16: consolidated | L16: 2025-12-31 | M16: instant | N16: reported | O16: CAS | Q16: parent_equity
A17: parent_equity_prior | B17: 归母权益 上期 | C17: E_BS | D17: 246930033 | E17: 1000 | F17: =IF(COUNT(D17,E17)=2,D17*E17,NA()) -> 246930033000 | G17: money | H17: CNY | I17: 宁德时代集团 | J17: consolidated | L17: 2024-12-31 | M17: instant | N17: reported | O17: CAS | Q17: parent_equity
A18: inventory | B18: 存货账面值 | C18: E_BS | D18: 94526239 | E18: 1000 | F18: =IF(COUNT(D18,E18)=2,D18*E18,NA()) -> 94526239000 | G18: money | H18: CNY | I18: 宁德时代集团 | J18: consolidated | L18: 2025-12-31 | M18: instant | N18: reported | O18: CAS | Q18: inventory
A19: inventory_prior | B19: 存货账面值 上期 | C19: E_BS | D19: 59835533 | E19: 1000 | F19: =IF(COUNT(D19,E19)=2,D19*E19,NA()) -> 59835533000 | G19: money | H19: CNY | I19: 宁德时代集团 | J19: consolidated | L19: 2024-12-31 | M19: instant | N19: reported | O19: CAS | Q19: inventory
A20: ar | B20: 应收账款账面值 | C20: E_BS | D20: 76403264 | E20: 1000 | F20: =IF(COUNT(D20,E20)=2,D20*E20,NA()) -> 76403264000 | G20: money | H20: CNY | I20: 宁德时代集团 | J20: consolidated | L20: 2025-12-31 | M20: instant | N20: reported | O20: CAS | Q20: ar
A21: ar_prior | B21: 应收账款账面值 上期 | C21: E_BS | D21: 64135510 | E21: 1000 | F21: =IF(COUNT(D21,E21)=2,D21*E21,NA()) -> 64135510000 | G21: money | H21: CNY | I21: 宁德时代集团 | J21: consolidated | L21: 2024-12-31 | M21: instant | N21: reported | O21: CAS | Q21: ar
... A31: debt_prior | B31: 筹资负债表借款债券及租赁合计 上期 | C31: E_DEBT | D31: 136346553 | E31: 1000 | F31: =IF(COUNT(D31,E31)=2,D31*E31,NA()) -> 136346553000 | G31: money | H31: CNY | I31: 宁德时代集团 | J31: consolidated | L31: 2024-12-31 | M31: instant | N31: reported | O31: CAS | Q31: debt
A32: power_sales | B32: 动力电池系统收入 | C32: E_BIZ | D32: 316506369 | E32: 1000 | F32: =IF(COUNT(D32,E32)=2,D32*E32,NA()) -> 316506369000 | G32: money | H32: CNY | I32: 宁德时代集团 | J32: consolidated | K32: 2025-01-01 | L32: 2025-12-31 | M32: flow | N32: reported | O32: CAS | Q32: power_sales
A33: power_sales_prior | B33: 动力电池系统收入 上期 | C33: E_BIZ | D33: 253041337 | E33: 1000 | F33: =IF(COUNT(D33,E33)=2,D33*E33,NA()) -> 253041337000 | G33: money | H33: CNY | I33: 宁德时代集团 | J33: consolidated | K33: 2024-01-01 | L33: 2024-12-31 | M33: flow | N33: reported | O33: CAS | Q33: power_sales
A34: storage_sales | B34: 储能电池系统收入 | C34: E_BIZ | D34: 62439820 | E34: 1000 | F34: =IF(COUNT(D34,E34)=2,D34*E34,NA()) -> 62439820000 | G34: money | H34: CNY | I34: 宁德时代集团 | J34: consolidated | K34: 2025-01-01 | L34: 2025-12-31 | M34: flow | N34: reported | O34: CAS | Q34: storage_sales
A35: storage_sales_prior | B35: 储能电池系统收入 上期 | C35: E_BIZ | D35: 57290460 | E35: 1000 | F35: =IF(COUNT(D35,E35)=2,D35*E35,NA()) -> 57290460000 | G35: money | H35: CNY | I35: 宁德时代集团 | J35: consolidated | K35: 2024-01-01 | L35: 2024-12-31 | M35: flow | N35: reported | O35: CAS | Q35: storage_sales
A36: materials_sales | B36: 材料及回收收入 | C36: E_BIZ | D36: 21860936 | E36: 1000 | F36: =IF(COUNT(D36,E36)=2,D36*E36,NA()) -> 21860936000 | G36: money | H36: CNY | I36: 宁德时代集团 | J36: consolidated | K36: 2025-01-01 | L36: 2025-12-31 | M36: flow | N36: reported | O36: CAS | Q36: materials_sales
A37: materials_sales_prior | B37: 材料及回收收入 上期 | C37: E_BIZ | D37: 28699935 | E37: 1000 | F37: =IF(COUNT(D37,E37)=2,D37*E37,NA()) -> 28699935000 | G37: money | H37: CNY | I37: 宁德时代集团 | J37: consolidated | K37: 2024-01-01 | L37: 2024-12-31 | M37: flow | N37: reported | O37: CAS | Q37: materials_sales
A38: ni_parent | B38: 归母净利润 | C38: E_PL | D38: 72201282 | E38: 1000 | F38: =IF(COUNT(D38,E38)=2,D38*E38,NA()) -> 72201282000 | G38: money | H38: CNY | I38: 宁德时代集团 | J38: consolidated | K38: 2025-01-01 | L38: 2025-12-31 | M38: flow | N38: reported | O38: CAS | Q38: ni_parent
A39: ni_nci | B39: 少数股东损益 | C39: E_PL | D39: 4585027 | E39: 1000 | F39: =IF(COUNT(D39,E39)=2,D39*E39,NA()) -> 4585027000 | G39: money | H39: CNY | I39: 宁德时代集团 | J39: consolidated | K39: 2025-01-01 | L39: 2025-12-31 | M39: flow | N39: reported | O39: CAS | Q39: ni_nci
A40: cfi | B40: 投资现金流 | C40: E_CF | D40: -94475790 | E40: 1000 | F40: =IF(COUNT(D40,E40)=2,D40*E40,NA()) -> -94475790000 | G40: money | H40: CNY | I40: 宁德时代集团 | J40: consolidated | K40: 2025-01-01 | L40: 2025-12-31 | M40: flow | N40: reported | O40: CAS | Q40: cfi
A41: cff | B41: 筹资现金流 | C41: E_CF | D41: -6309543 | E41: 1000 | F41: =IF(COUNT(D41,E41)=2,D41*E41,NA()) -> -6309543000 | G41: money | H41: CNY | I41: 宁德时代集团 | J41: consolidated | K41: 2025-01-01 | L41: 2025-12-31 | M41: flow | N41: reported | O41: CAS | Q41: cff
A42: fx | B42: 汇率对现金影响 | C42: E_CF | D42: -2664640 | E42: 1000 | F42: =IF(COUNT(D42,E42)=2,D42*E42,NA()) -> -2664640000 | G42: money | H42: CNY | I42: 宁德时代集团 | J42: consolidated | K42: 2025-01-01 | L42: 2025-12-31 | M42: flow | N42: reported | O42: CAS | Q42: fx
A43: cash_increase | B43: 披露现金净增加 | C43: E_CF | D43: 29770008 | E43: 1000 | F43: =IF(COUNT(D43,E43)=2,D43*E43,NA()) -> 29770008000 | G43: money | H43: CNY | I43: 宁德时代集团 | J43: consolidated | K43: 2025-01-01 | L43: 2025-12-31 | M43: flow | N43: reported | O43: CAS | Q43: cash_increase
... A53: ppe_transfer | B53: 在建转入固定资产 | C53: E_PPE | D53: 60616240 | E53: 1000 | F53: =IF(COUNT(D53,E53)=2,D53*E53,NA()) -> 60616240000 | G53: money | H53: CNY | I53: 宁德时代集团 | J53: consolidated | K53: 2025-01-01 | L53: 2025-12-31 | M53: flow | N53: reported | O53: CAS | Q53: ppe_transfer
A54: liabilities | B54: 负债总额 | C54: E_BS | D54: 603801220 | E54: 1000 | F54: =IF(COUNT(D54,E54)=2,D54*E54,NA()) -> 603801220000 | G54: money | H54: CNY | I54: 宁德时代集团 | J54: consolidated | L54: 2025-12-31 | M54: instant | N54: reported | O54: CAS | Q54: liabilities
A55: book_cash | B55: 货币资金 | C55: E_BS | D55: 333512927 | E55: 1000 | F55: =IF(COUNT(D55,E55)=2,D55*E55,NA()) -> 333512927000 | G55: money | H55: CNY | I55: 宁德时代集团 | J55: consolidated | L55: 2025-12-31 | M55: instant | N55: reported | O55: CAS | Q55: book_cash
A56: cash_excluded | B56: 排除于现金等价物的货币资金 | C56: E_CASH | D56: 33583185 | E56: 1000 | F56: =IF(COUNT(D56,E56)=2,D56*E56,NA()) -> 33583185000 | G56: money | H56: CNY | I56: 宁德时代集团 | J56: consolidated | L56: 2025-12-31 | M56: instant | N56: reported | O56: CAS | Q56: cash_excluded
A57: guarantee_cash | B57: 受限保证金 | C57: E_CASH | D57: 18428631 | E57: 1000 | F57: =IF(COUNT(D57,E57)=2,D57*E57,NA()) -> 18428631000 | G57: money | H57: CNY | I57: 宁德时代集团 | J57: consolidated | L57: 2025-12-31 | M57: instant | N57: reported | O57: CAS | Q57: guarantee_cash
A58: pledged_cash | B58: 质押定期存款 | C58: E_CASH | D58: 461587 | E58: 1000 | F58: =IF(COUNT(D58,E58)=2,D58*E58,NA()) -> 461587000 | G58: money | H58: CNY | I58: 宁德时代集团 | J58: consolidated | L58: 2025-12-31 | M58: instant | N58: reported | O58: CAS | Q58: pledged_cash
...

Sheet Calculations
A1: ID | B1: 指标或桥 | C1: 基础单位公式 | D1: 基础单位结果 | E1: 展示结果 | F1: 状态 | G1: 不计算原因 | H1: 定义 | I1: 解释边界 | J1: 展示单位 | K1: 倍数 | L1: 实体 | M1: 范围 | N1: 开始 | O1: 结束
A2: gross_profit | B2: 毛利 | C2: =(('Facts'!F2-'Facts'!F4))*1 | D2: =(('Facts'!F2-'Facts'!F4))*1 -> 111318537000 | E2: =D2/K2 -> 111318537 | F2: =IF(ISNUMBER(D2),"calculated","not_calculated") -> calculated | G2: =IF(ISNUMBER(D2),"","检查缺失值、分母与输入；口径变更须重跑Python") | H2: 收入减成本 | I2: 收入减成本 | J2: CNY × 1000 | K2: 1000 | L2: 宁德时代集团 | M2: consolidated | N2: 2025-01-01 | O2: 2025-12-31
A3: gross_margin | B3: 毛利率 | C3: =IF('Facts'!F2<=0,NA(),(('Calculations'!D2/'Facts'!F2))*1) | D3: =IF('Facts'!F2<=0,NA(),(('Calculations'!D2/'Facts'!F2))*1) -> 0.26272848 | E3: =D3/K3 -> 0.26272848 | F3: =IF(ISNUMBER(D3),"calculated","not_calculated") -> calculated | G3: =IF(ISNUMBER(D3),"","检查缺失值、分母与输入；口径变更须重跑Python") | H3: 毛利/营业收入 | I3: 毛利/营业收入 | J3: ratio | K3: 1 | L3: 宁德时代集团 | M3: consolidated | N3: 2025-01-01 | O3: 2025-12-31
A4: revenue_growth | B4: 收入同比 | C4: =IF(OR('Facts'!F3<=0,'Facts'!F2<0),NA(),((('Facts'!F2-'Facts'!F3)/'Facts'!F3))*1) | D4: =IF(OR('Facts'!F3<=0,'Facts'!F2<0),NA(),((('Facts'!F2-'Facts'!F3)/'Facts'!F3))*1) -> 0.17040647 | E4: =D4/K4 -> 0.17040647 | F4: =IF(ISNUMBER(D4),"calculated","not_calculated") -> calculated | G4: =IF(ISNUMBER(D4),"","检查缺失值、分母与输入；口径变更须重跑Python") | H4: 同范围本期减上期，再除以上期 | I4: 销量和收入范围仍须核对，不能直接推出售价变化。 | J4: ratio | K4: 1 | L4: 宁德时代集团 | M4: consolidated | N4: 2025-01-01 | O4: 2025-12-31
A5: ni_growth | B5: 合并净利润同比 | C5: =IF(OR('Facts'!F7<=0,'Facts'!F6<0),NA(),((('Facts'!F6-'Facts'!F7)/'Facts'!F7))*1) | D5: =IF(OR('Facts'!F7<=0,'Facts'!F6<0),NA(),((('Facts'!F6-'Facts'!F7)/'Facts'!F7))*1) -> 0.4217898 | E5: =D5/K5 -> 0.4217898 | F5: =IF(ISNUMBER(D5),"calculated","not_calculated") -> calculated | G5: =IF(ISNUMBER(D5),"","检查缺失值、分母与输入；口径变更须重跑Python") | H5: 同范围本期减上期，再除以上期 | I5: 销量和收入范围仍须核对，不能直接推出售价变化。 | J5: ratio | K5: 1 | L5: 宁德时代集团 | M5: consolidated | N5: 2025-01-01 | O5: 2025-12-31
A6: cfo_growth | B6: 经营现金同比 | C6: =IF(OR('Facts'!F9<=0,'Facts'!F8<0),NA(),((('Facts'!F8-'Facts'!F9)/'Facts'!F9))*1) | D6: =IF(OR('Facts'!F9<=0,'Facts'!F8<0),NA(),((('Facts'!F8-'Facts'!F9)/'Facts'!F9))*1) -> 0.37353859 | E6: =D6/K6 -> 0.37353859 | F6: =IF(ISNUMBER(D6),"calculated","not_calculated") -> calculated | G6: =IF(ISNUMBER(D6),"","检查缺失值、分母与输入；口径变更须重跑Python") | H6: 同范围本期减上期，再除以上期 | I6: 销量和收入范围仍须核对，不能直接推出售价变化。 | J6: ratio | K6: 1 | L6: 宁德时代集团 | M6: consolidated | N6: 2025-01-01 | O6: 2025-12-31
A7: power_sales_growth | B7: 动力系统收入同比 | C7: =IF(OR('Facts'!F33<=0,'Facts'!F32<0),NA(),((('Facts'!F32-'Facts'!F33)/'Facts'!F33))*1) | D7: =IF(OR('Facts'!F33<=0,'Facts'!F32<0),NA(),((('Facts'!F32-'Facts'!F33)/'Facts'!F33))*1) -> 0.25080895 | E7: =D7/K7 -> 0.25080895 | F7: =IF(ISNUMBER(D7),"calculated","not_calculated") -> calculated | G7: =IF(ISNUMBER(D7),"","检查缺失值、分母与输入；口径变更须重跑Python") | H7: 同范围本期减上期，再除以上期 | I7: 销量和收入范围仍须核对，不能直接推出售价变化。 | J7: ratio | K7: 1 | L7: 宁德时代集团 | M7: consolidated | N7: 2025-01-01 | O7: 2025-12-31
A8: storage_sales_growth | B8: 储能系统收入同比 | C8: =IF(OR('Facts'!F35<=0,'Facts'!F34<0),NA(),((('Facts'!F34-'Facts'!F35)/'Facts'!F35))*1) | D8: =IF(OR('Facts'!F35<=0,'Facts'!F34<0),NA(),((('Facts'!F34-'Facts'!F35)/'Facts'!F35))*1) -> 0.089881631 | E8: =D8/K8 -> 0.089881631 | F8: =IF(ISNUMBER(D8),"calculated","not_calculated") -> calculated | G8: =IF(ISNUMBER(D8),"","检查缺失值、分母与输入；口径变更须重跑Python") | H8: 同范围本期减上期，再除以上期 | I8: 销量和收入范围仍须核对，不能直接推出售价变化。 | J8: ratio | K8: 1 | L8: 宁德时代集团 | M8: consolidated | N8: 2025-01-01 | O8: 2025-12-31
A9: materials_sales_growth | B9: 材料回收收入同比 | C9: =IF(OR('Facts'!F37<=0,'Facts'!F36<0),NA(),((('Facts'!F36-'Facts'!F37)/'Facts'!F37))*1) | D9: =IF(OR('Facts'!F37<=0,'Facts'!F36<0),NA(),((('Facts'!F36-'Facts'!F37)/'Facts'!F37))*1) -> -0.23829319 | E9: =D9/K9 -> -0.23829319 | F9: =IF(ISNUMBER(D9),"calculated","not_calculated") -> calculated | G9: =IF(ISNUMBER(D9),"","检查缺失值、分母与输入；口径变更须重跑Python") | H9: 同范围本期减上期，再除以上期 | I9: 销量和收入范围仍须核对，不能直接推出售价变化。 | J9: ratio | K9: 1 | L9: 宁德时代集团 | M9: consolidated | N9: 2025-01-01 | O9: 2025-12-31
A10: volume_growth | B10: 销售量同比 | C10: =IF(OR('Facts'!F67<=0,'Facts'!F66<0),NA(),((('Facts'!F66-'Facts'!F67)/'Facts'!F67))*1) | D10: =IF(OR('Facts'!F67<=0,'Facts'!F66<0),NA(),((('Facts'!F66-'Facts'!F67)/'Facts'!F67))*1) -> 0.39157895 | E10: =D10/K10 -> 0.39157895 | F10: =IF(ISNUMBER(D10),"calculated","not_calculated") -> calculated | G10: =IF(ISNUMBER(D10),"","检查缺失值、分母与输入；口径变更须重跑Python") | H10: 同范围本期减上期，再除以上期 | I10: 销量和收入范围仍须核对，不能直接推出售价变化。 | J10: ratio | K10: 1 | L10: 宁德时代集团 | M10: consolidated | N10: 2025-01-01 | O10: 2025-12-31
A11: cfo_profit | B11: CFO与合并净利润之比 | C11: =IF('Facts'!F6<=0,NA(),(('Facts'!F8/'Facts'!F6))*1) | D11: =IF('Facts'!F6<=0,NA(),(('Facts'!F8/'Facts'!F6))*1) -> 1.7349445 | E11: =D11/K11 -> 1.7349445 | F11: =IF(ISNUMBER(D11),"calculated","not_calculated") -> calculated | G11: =IF(ISNUMBER(D11),"","检查缺失值、分母与输入；口径变更须重跑Python") | H11: 同一集团CFO/总净利润 | I11: 经营负债增长可能暂时抬高该比率，不能单独证明盈利质量。 | J11: ratio | K11: 1 | L11: 宁德时代集团 | M11: consolidated | N11: 2025-01-01 | O11: 2025-12-31
A12: cfo_bridge | B12: 净利润至CFO复算 | C12: =(('Facts'!F6*1)+('Facts'!F68*1)+('Facts'!F69*1)+('Facts'!F70*1)+('Facts'!F71*1)+('Facts'!F72*1)+('Facts'!F73*1)+('Facts'!F74*1)+('Facts'!F75*1)+('Facts'!F76*1)+('Facts'!F77*1)+('Facts'!F78*1)+('Facts'!F79*1)+('Facts'!F80*1)+('Facts'!F81*1)+('Facts'!F82*1)+('Facts'!F83*1)+('Facts'!F84*1))*1 | D12: =(('Facts'!F6*1)+('Facts'!F68*1)+('Facts'!F69*1)+('Facts'!F70*1)+('Facts'!F71*1)+('Facts'!F72*1)+('Facts'!F73*1)+('Facts'!F74*1)+('Facts'!F75*1)+('Facts'!F76*1)+('Facts'!F77*1)+('Facts'!F78*1)+('Facts'!F79*1)+('Facts'!F80*1)+('Facts'!F81*1)+('Facts'!F82*1)+('Facts'!F83*1)+('Facts'!F84*1))*1 -> 133219980000 | E12: =D12/K12 -> 133219980 | F12: =IF(ISNUMBER(D12),"calculated","not_calculated") -> calculated | G12: =IF(ISNUMBER(D12),"","检查缺失值、分母与输入；口径变更须重跑Python") | H12: 附注67原始带符号调整之和 | I12: 附注67原始带符号调整之和 | J12: CNY × 1000 | K12: 1000 | L12: 宁德时代集团 | M12: consolidated | N12: 2025-01-01 | O12: 2025-12-31
A13: working_capital_effect | B13: 经营营运资本现金净贡献 | C13: =(('Facts'!F81*1)+('Facts'!F82*1)+('Facts'!F83*1))*1 | D13: =(('Facts'!F81*1)+('Facts'!F82*1)+('Facts'!F83*1))*1 -> 33216205000 | E13: =D13/K13 -> 33216205 | F13: =IF(ISNUMBER(D13),"calculated","not_calculated") -> calculated | G13: =IF(ISNUMBER(D13),"","检查缺失值、分母与输入；口径变更须重跑Python") | H13: 披露的存货、经营应收及经营应付三项之和 | I13: 披露的存货、经营应收及经营应付三项之和 | J13: CNY × 1000 | K13: 1000 | L13: 宁德时代集团 | M13: consolidated | N13: 2025-01-01 | O13: 2025-12-31
A14: fcf_simple | B14: CFO减购建长期资产现金 | C14: =(('Facts'!F8-'Facts'!F44))*1 | D14: =(('Facts'!F8-'Facts'!F44))*1 -> 90875424000 | E14: =D14/K14 -> 90875424 | F14: =IF(ISNUMBER(D14),"calculated","not_calculated") -> calculated | G14: =IF(ISNUMBER(D14),"","检查缺失值、分母与输入；口径变更须重跑Python") | H14: 仅定义为CFO减现金资本支出 | I14: 不是可分配现金；未扣并购、股利、债务偿还或区分维持/扩张投资。 | J14: CNY × 1000 | K14: 1000 | L14: 宁德时代集团 | M14: consolidated | N14: 2025-01-01 | O14: 2025-12-31
A15: cash_flow_change | B15: 现金变动四项之和 | C15: =(('Facts'!F8*1)+('Facts'!F40*1)+('Facts'!F41*1)+('Facts'!F42*1))*1 | D15: =(('Facts'!F8*1)+('Facts'!F40*1)+('Facts'!F41*1)+('Facts'!F42*1))*1 -> 29770009000 | E15: =D15/K15 -> 29770009 | F15: =IF(ISNUMBER(D15),"calculated","not_calculated") -> calculated | G15: =IF(ISNUMBER(D15),"","检查缺失值、分母与输入；口径变更须重跑Python") | H15: 经营+投资+筹资+汇率 | I15: 经营+投资+筹资+汇率 | J15: CNY × 1000 | K15: 1000 | L15: 宁德时代集团 | M15: consolidated | N15: 2025-01-01 | O15: 2025-12-31
A16: cash_rollforward | B16: 期末现金复算 | C16: =(('Facts'!F11*1)+('Facts'!F8*1)+('Facts'!F40*1)+('Facts'!F41*1)+('Facts'!F42*1))*1 | D16: =(('Facts'!F11*1)+('Facts'!F8*1)+('Facts'!F40*1)+('Facts'!F41*1)+('Facts'!F42*1))*1 -> 299929743000 | E16: =D16/K16 -> 299929743 | F16: =IF(ISNUMBER(D16),"calculated","not_calculated") -> calculated | G16: =IF(ISNUMBER(D16),"","检查缺失值、分母与输入；口径变更须重跑Python") | H16: 期初现金加四类变动 | I16: 期初现金加四类变动 | J16: CNY × 1000 | K16: 1000 | L16: 宁德时代集团 | M16: consolidated | N16: 2025-01-01 | O16: 2025-12-31
A17: balance_sheet | B17: 负债加权益 | C17: =(('Facts'!F54*1)+('Facts'!F14*1))*1 | D17: =(('Facts'!F54*1)+('Facts'!F14*1))*1 -> 974827544000 | E17: =D17/K17 -> 974827544 | F17: =IF(ISNUMBER(D17),"calculated","not_calculated") -> calculated | G17: =IF(ISNUMBER(D17),"","检查缺失值、分母与输入；口径变更须重跑Python") | H17: 负债+总权益 | I17: 负债+总权益 | J17: CNY × 1000 | K17: 1000 | L17: 宁德时代集团 | M17: consolidated | O17: 2025-12-31
A18: profit_attribution | B18: 净利润归属合计 | C18: =(('Facts'!F38*1)+('Facts'!F39*1))*1 | D18: =(('Facts'!F38*1)+('Facts'!F39*1))*1 -> 76786309000 | E18: =D18/K18 -> 76786309 | F18: =IF(ISNUMBER(D18),"calculated","not_calculated") -> calculated | G18: =IF(ISNUMBER(D18),"","检查缺失值、分母与输入；口径变更须重跑Python") | H18: 归母+少数损益 | I18: 归母+少数损益 | J18: CNY × 1000 | K18: 1000 | L18: 宁德时代集团 | M18: consolidated | N18: 2025-01-01 | O18: 2025-12-31
A19: equity_rollforward | B19: 权益变动复算 | C19: =(('Facts'!F15*1)+('Facts'!F45*1)+('Facts'!F46*1)+('Facts'!F47*1)+('Facts'!F48*1))*1 | D19: =(('Facts'!F15*1)+('Facts'!F45*1)+('Facts'!F46*1)+('Facts'!F47*1)+('Facts'!F48*1))*1 -> 371026323000 | E19: =D19/K19 -> 371026323 | F19: =IF(ISNUMBER(D19),"calculated","not_calculated") -> calculated | G19: =IF(ISNUMBER(D19),"","检查缺失值、分母与输入；口径变更须重跑Python") | H19: 期初+综合收益+投入减少+分配+专项储备 | I19: 期初+综合收益+投入减少+分配+专项储备 | J19: CNY × 1000 | K19: 1000 | L19: 宁德时代集团 | M19: consolidated | N19: 2025-01-01 | O19: 2025-12-31
A20: debt_rollforward | B20: 筹资负债滚动复算 | C20: =(('Facts'!F31*1)+('Facts'!F49*1)+('Facts'!F50*1)+('Facts'!F51*1))*1 | D20: =(('Facts'!F31*1)+('Facts'!F49*1)+('Facts'!F50*1)+('Facts'!F51*1))*1 -> 119601197000 | E20: =D20/K20 -> 119601197 | F20: =IF(ISNUMBER(D20),"calculated","not_calculated") -> calculated | G20: =IF(ISNUMBER(D20),"","检查缺失值、分母与输入；口径变更须重跑Python") | H20: 期初+现金增减+非现金 | I20: 期初+现金增减+非现金 | J20: CNY × 1000 | K20: 1000 | L20: 宁德时代集团 | M20: consolidated | N20: 2025-01-01 | O20: 2025-12-31
A21: supply_components | B21: 供应商融资构成合计 | C21: =(('Facts'!F60*1)+('Facts'!F61*1))*1 | D21: =(('Facts'!F60*1)+('Facts'!F61*1))*1 -> 37222781000 | E21: =D21/K21 -> 37222781 | F21: =IF(ISNUMBER(D21),"calculated","not_calculated") -> calculated | G21: =IF(ISNUMBER(D21),"","检查缺失值、分母与输入；口径变更须重跑Python") | H21: 融单+反向保理；已收款为子集不再相加 | I21: 融单+反向保理；已收款为子集不再相加 | J21: CNY × 1000 | K21: 1000 | L21: 宁德时代集团 | M21: consolidated | O21: 2025-12-31
A22: supply_change | B22: 供应商融资余额变化 | C22: =(('Facts'!F26-'Facts'!F27))*1 | D22: =(('Facts'!F26-'Facts'!F27))*1 -> -7139628000 | E22: =D22/K22 -> -7139628 | F22: =IF(ISNUMBER(D22),"calculated","not_calculated") -> calculated | G22: =IF(ISNUMBER(D22),"","检查缺失值、分母与输入；口径变更须重跑Python") | H22: 期末减期初 | I22: 期末减期初 | J22: CNY × 1000 | K22: 1000 | L22: 宁德时代集团 | M22: consolidated | O22: 2025-12-31
A23: cash_composition | B23: 货币资金构成复算 | C23: =(('Facts'!F10*1)+('Facts'!F56*1))*1 | D23: =(('Facts'!F10*1)+('Facts'!F56*1))*1 -> 333512926000 | E23: =D23/K23 -> 333512926 | F23: =IF(ISNUMBER(D23),"calculated","not_calculated") -> calculated | G23: =IF(ISNUMBER(D23),"","检查缺失值、分母与输入；口径变更须重跑Python") | H23: 现金等价物+附注排除项目 | I23: 现金等价物+附注排除项目 | J23: CNY × 1000 | K23: 1000 | L23: 宁德时代集团 | M23: consolidated | O23: 2025-12-31
A24: cash_exclusion_sum | B24: 非现金等价物三项之和 | C24: =(('Facts'!F57*1)+('Facts'!F58*1)+('Facts'!F59*1))*1 | D24: =(('Facts'!F57*1)+('Facts'!F58*1)+('Facts'!F59*1))*1 -> 33583186000 | E24: =D24/K24 -> 33583186 | F24: =IF(ISNUMBER(D24),"calculated","not_calculated") -> calculated | G24: =IF(ISNUMBER(D24),"","检查缺失值、分母与输入；口径变更须重跑Python") | H24: 受限保证金+质押定存+不可随时支取定存利息 | I24: 受限保证金+质押定存+不可随时支取定存利息 | J24: CNY × 1000 | K24: 1000 | L24: 宁德时代集团 | M24: consolidated | O24: 2025-12-31
A25: debt_supply_sensitivity | B25: 含供应商融资的债务敏感性口径 | C25: =(('Facts'!F30*1)+('Facts'!F26*1))*1 | D25: =(('Facts'!F30*1)+('Facts'!F26*1))*1 -> 156823978000 | E25: =D25/K25 -> 156823978 | F25: =IF(ISNUMBER(D25),"calculated","not_calculated") -> calculated | G25: =IF(ISNUMBER(D25),"","检查缺失值、分母与输入；口径变更须重跑Python") | H25: 筹资负债台账加供应商融资安排一次 | I25: 分析者敏感性，不改报表债务；需完整合同决定最终信用调整，避免重复计入应付账款。 | J25: CNY × 1000 | K25: 1000 | L25: 宁德时代集团 | M25: consolidated | O25: 2025-12-31
A26: average_parent_equity | B26: 期初期末平均归母权益 | C26: =(AVERAGE('Facts'!F17,'Facts'!F16))*1 | D26: =(AVERAGE('Facts'!F17,'Facts'!F16))*1 -> 292018890000 | E26: =D26/K26 -> 292018890 | F26: =IF(ISNUMBER(D26),"calculated","not_calculated") -> calculated | G26: =IF(ISNUMBER(D26),"","检查缺失值、分母与输入；口径变更须重跑Python") | H26: 两期真实归母权益简单平均 | I26: 两期真实归母权益简单平均 | J26: CNY × 1000 | K26: 1000 | L26: 宁德时代集团 | M26: consolidated | N26: 2025-01-01 | O26: 2025-12-31
A27: roe_simple | B27: 简单平均权益ROE | C27: =IF('Calculations'!D26<=0,NA(),(('Facts'!F38/'Calculations'!D26))*1) | D27: =IF('Calculations'!D26<=0,NA(),(('Facts'!F38/'Calculations'!D26))*1) -> 0.24724867 | E27: =D27/K27 -> 0.24724867 | F27: =IF(ISNUMBER(D27),"calculated","not_calculated") -> calculated | G27: =IF(ISNUMBER(D27),"","检查缺失值、分母与输入；口径变更须重跑Python") | H27: 归母净利润/简单平均归母权益 | I27: 不是发行人披露的加权平均ROE。 | J27: ratio | K27: 1 | L27: 宁德时代集团 | M27: consolidated | N27: 2025-01-01 | O27: 2025-12-31
A28: ppe_imp_recalc | B28: 该组固定资产减值复算 | C28: =(('Facts'!F63-'Facts'!F64))*1 | D28: =(('Facts'!F63-'Facts'!F64))*1 -> 2659992000 | E28: =D28/K28 -> 2659992 | F28: =IF(ISNUMBER(D28),"calculated","not_calculated") -> calculated | G28: =IF(ISNUMBER(D28),"","检查缺失值、分母与输入；口径变更须重跑Python") | H28: 被测资产组账面减可收回额 | I28: 不是全部固定资产的可收回额；不能外推到集团所有产线。 | J28: CNY × 1000 | K28: 1000 | L28: 宁德时代集团 | M28: consolidated | O28: 2025-12-31

Sheet Reconciliations
A1: ID | B1: 勾稽 | C1: 实际 | D1: 目标 | E1: 残差 基础单位 | F1: 容差 基础单位 | G1: 状态 | H1: 容差依据 | I1: 未测试原因
A2: R_BS | B2: 资产负债关系 | C2: balance_sheet | D2: assets | E2: ='Calculations'!D17-'Facts'!F12 -> 0 | F2: 0 | G2: =IF(COUNT(E2,F2)<2,"not_tested",IF(ABS(E2)<=F2,"within_input_tolerance","unexplained_difference")) -> within_input_tolerance | H2: 基础单位人民币；原表以千元披露。按参加计算项目的独立舍入上界保留残差，不将容差内残差强制归零。 | I2: =IF(ISNUMBER(E2),"","missing or unavailable input")
A3: R_NI | B3: 利润归属 | C3: profit_attribution | D3: ni | E3: ='Calculations'!D18-'Facts'!F6 -> 0 | F3: 1000 | G3: =IF(COUNT(E3,F3)<2,"not_tested",IF(ABS(E3)<=F3,"within_input_tolerance","unexplained_difference")) -> within_input_tolerance | H3: 基础单位人民币；原表以千元披露。按参加计算项目的独立舍入上界保留残差，不将容差内残差强制归零。 | I3: =IF(ISNUMBER(E3),"","missing or unavailable input")
A4: R_CFO | B4: 净利润至CFO | C4: cfo_bridge | D4: cfo | E4: ='Calculations'!D12-'Facts'!F8 -> -2000 | F4: 10000 | G4: =IF(COUNT(E4,F4)<2,"not_tested",IF(ABS(E4)<=F4,"within_input_tolerance","unexplained_difference")) -> within_input_tolerance | H4: 基础单位人民币；原表以千元披露。按参加计算项目的独立舍入上界保留残差，不将容差内残差强制归零。 | I4: =IF(ISNUMBER(E4),"","missing or unavailable input")
A5: R_FX | B5: 现金变动含汇率 | C5: cash_flow_change | D5: cash_increase | E5: ='Calculations'!D15-'Facts'!F43 -> 1000 | F5: 2000 | G5: =IF(COUNT(E5,F5)<2,"not_tested",IF(ABS(E5)<=F5,"within_input_tolerance","unexplained_difference")) -> within_input_tolerance | H5: 基础单位人民币；原表以千元披露。按参加计算项目的独立舍入上界保留残差，不将容差内残差强制归零。 | I5: =IF(ISNUMBER(E5),"","missing or unavailable input")
A6: R_CASH | B6: 现金滚动 | C6: cash_rollforward | D6: cash | E6: ='Calculations'!D16-'Facts'!F10 -> 2000 | F6: 3000 | G6: =IF(COUNT(E6,F6)<2,"not_tested",IF(ABS(E6)<=F6,"within_input_tolerance","unexplained_difference")) -> within_input_tolerance | H6: 基础单位人民币；原表以千元披露。按参加计算项目的独立舍入上界保留残差，不将容差内残差强制归零。 | I6: =IF(ISNUMBER(E6),"","missing or unavailable input")
A7: R_EQ | B7: 权益滚动 | C7: equity_rollforward | D7: equity | E7: ='Calculations'!D19-'Facts'!F14 -> -1000 | F7: 3000 | G7: =IF(COUNT(E7,F7)<2,"not_tested",IF(ABS(E7)<=F7,"within_input_tolerance","unexplained_difference")) -> within_input_tolerance | H7: 基础单位人民币；原表以千元披露。按参加计算项目的独立舍入上界保留残差，不将容差内残差强制归零。 | I7: =IF(ISNUMBER(E7),"","missing or unavailable input")
A8: R_DEBT | B8: 融资负债滚动 | C8: debt_rollforward | D8: debt | E8: ='Calculations'!D20-'Facts'!F30 -> 0 | F8: 3000 | G8: =IF(COUNT(E8,F8)<2,"not_tested",IF(ABS(E8)<=F8,"within_input_tolerance","unexplained_difference")) -> within_input_tolerance | H8: 基础单位人民币；原表以千元披露。按参加计算项目的独立舍入上界保留残差，不将容差内残差强制归零。 | I8: =IF(ISNUMBER(E8),"","missing or unavailable input")
A9: R_SUPPLY | B9: 跨页供应商融资 | C9: supply_components | D9: supply | E9: ='Calculations'!D21-'Facts'!F26 -> 0 | F9: 1000 | G9: =IF(COUNT(E9,F9)<2,"not_tested",IF(ABS(E9)<=F9,"within_input_tolerance","unexplained_difference")) -> within_input_tolerance | H9: 基础单位人民币；原表以千元披露。按参加计算项目的独立舍入上界保留残差，不将容差内残差强制归零。 | I9: =IF(ISNUMBER(E9),"","missing or unavailable input")
A10: R_COMPOSITION | B10: 货币资金桥 | C10: cash_composition | D10: book_cash | E10: ='Calculations'!D23-'Facts'!F55 -> -1000 | F10: 2000 | G10: =IF(COUNT(E10,F10)<2,"not_tested",IF(ABS(E10)<=F10,"within_input_tolerance","unexplained_difference")) -> within_input_tolerance | H10: 基础单位人民币；原表以千元披露。按参加计算项目的独立舍入上界保留残差，不将容差内残差强制归零。 | I10: =IF(ISNUMBER(E10),"","missing or unavailable input")
A11: R_EXCLUDED | B11: 排除项目合计 | C11: cash_exclusion_sum | D11: cash_excluded | E11: ='Calculations'!D24-'Facts'!F56 -> 1000 | F11: 2000 | G11: =IF(COUNT(E11,F11)<2,"not_tested",IF(ABS(E11)<=F11,"within_input_tolerance","unexplained_difference")) -> within_input_tolerance | H11: 基础单位人民币；原表以千元披露。按参加计算项目的独立舍入上界保留残差，不将容差内残差强制归零。 | I11: =IF(ISNUMBER(E11),"","missing or unavailable input")

Sheet Sources
A1: ID | B1: 文件 | C1: 链接 | D1: 公布日期 | E1: SHA256 | F1: 时间证据与限制
A2: AR | B2: 宁德时代新能源科技股份有限公司2025年年度报告 | C2: https://static.cninfo.com.cn/finalpage/2026-03-10/1225002214.PDF | D2: 2026-03-10 | E2: c15272977147dee7e6935a38ea0e4fd6855370aabb106f54cfe20f7cf6048ec9

Sheet Evidence
A1: ID | B1: 来源 | C1: 定位 | D1: 观察 | E1: 可靠性与限制
A2: E_BIZ | B2: AR | C2: PDF及印刷页24—27 收入成本与产销表 | D2: 主营电池收入与销量不同范围；产品、地区与合并范围变动分别披露。 | E2: 发行人正式年报；本次读取定位并复算，未独立确认底层交易真实性。
A3: E_BS | B3: AR | C3: PDF及印刷页111—113 合并资产负债表 | D3: 人民币千元；合并资产负债和所有者权益，区别母公司表。 | E3: 发行人正式年报；本次读取定位并复算，未独立确认底层交易真实性。
A4: E_PL | B4: AR | C4: PDF及印刷页116—119 利润表 | D4: 合并总净利润、归母净利润、少数损益与母公司净利润分列。 | E4: 发行人正式年报；本次读取定位并复算，未独立确认底层交易真实性。
A5: E_CF | B5: AR | C5: PDF及印刷页120—121 合并现金流量表 | D5: 经营、投资、筹资和汇率影响分别披露。 | E5: 发行人正式年报；本次读取定位并复算，未独立确认底层交易真实性。
A6: E_EQ | B6: AR | C6: PDF及印刷页123—125 合并权益变动表 | D6: 权益包括综合收益、资本交易、利润分配及专项储备变动。 | E6: 发行人正式年报；本次读取定位并复算，未独立确认底层交易真实性。
A7: E_POLICY | B7: AR | C7: PDF及印刷页134、153 会计基础及收入政策 | D7: 采用CAS与公历年、人民币列报；质量保证不构成单独履约义务，返利为可变对价。 | E7: 发行人正式年报；本次读取定位并复算，未独立确认底层交易真实性。
A8: E_BRIDGE | B8: AR | C8: PDF及印刷页200—201 附注67 现金流补充资料 | D8: 净利润至CFO的非现金调整与经营性存货、应收、应付分别列示。 | E8: 发行人正式年报；本次读取定位并复算，未独立确认底层交易真实性。
A9: E_DEBT | B9: AR | C9: PDF及印刷页200 筹资负债变动表 | D9: 借款、应付债券和租赁的期初、现金及非现金变动与期末。 | E9: 发行人正式年报；本次读取定位并复算，未独立确认底层交易真实性。
A10: E_SUPPLY | B10: AR | C10: PDF及印刷页202—203 附注67 供应商融资 | D10: 跨页包含融单与反向保理；供应商已收款是合计的子集，不能再加一次。 | E10: 发行人正式年报；本次读取定位并复算，未独立确认底层交易真实性。
A11: E_CASH | B11: AR | C11: PDF及印刷页202—203 现金构成与排除项目 | D11: 保证金、质押存款和不可随时支取定期存款排除在现金等价物外。 | E11: 发行人正式年报；本次读取定位并复算，未独立确认底层交易真实性。
A12: E_PPE | B12: AR | C12: PDF及印刷页177—180 固定资产与减值 | D12: 固定资产转固不等于当年现金支出；被测试资产组的账面值、可收回额和减值单列。 | E12: 发行人正式年报；本次读取定位并复算，未独立确认底层交易真实性。
... A14: E_AUDIT | B14: AR | C14: PDF及印刷页107—110 审计报告 | D14: 无保留意见；固定资产减值和收入确认为关键审计事项，原审计程序非本次执行。 | E14: 发行人正式年报；本次读取定位并复算，未独立确认底层交易真实性。

Sheet Findings
A1: ID | B1: 问题 | C1: 结论 | D1: 机制 | E1: 状态 | F1: 依据 | G1: 反证 | H1: 其他解释 | I1: 改变结论条件
A2: F_GROWTH | B2: 增长从何而来 | C2: 收入增长17.04%，动力系统增长25.08%，储能增长8.99%，材料回收同比-23.83%。 | D2: 销量增长高于合并收入，但收入含非电池业务，销量单位与产品结构也不同，不能将两者之比直接称为电池降价。产能扩张与存货增加要求核对投产及订单兑现。 | E2: conditional | F2: E_BIZ, revenue_growth, volume_growth | H2: 产品结构和地区组合变化可能影响收入增速。 并表变化也可能影响同比；未取得同范围量价明细。 | I2: 取得同产品同范围的数量、单价、并购及汇率桥后，重新判断有机增长与单位经济性。
A3: F_CASH | B3: 利润为何低于CFO | C3: CFO为1,332.20 亿元人民币，与总净利润之比173.49%；营运资本三项合计贡献332.16 亿元人民币。 | D3: 存货和经营应收占用被经营应付增加超过，需区分业务规模、客户预收、付款期和融资安排。CFO减现金资本支出为908.75 亿元人民币，尚不是自由可分配资金。 | E3: conditional | F3: E_BRIDGE, cfo_bridge, working_capital_effect, fcf_simple | G3: E_SUPPLY | H3: 采购规模和合同负债变化可能使经营应付增加，并不必然是延迟付款。 期末余额差额受合并、非现金和重分类影响，不能替代现金流附注项目。 | I3: 逐月回款付款、客户预收和供应商账期桥显示资金贡献不可持续时，下调可持续现金假设。
A4: F_SUPPLY | B4: 是否把CFO改善全部归因于融资扩张 | C4: 跨页融资安排合计372.23 亿元人民币，较期初变动-71.40 亿元人民币；供应商已收款307.28 亿元人民币是其中一部分。 | D4: 余额下降反驳“全部现金改善来自供应链融资新增”的解释。把全部安排一次性纳入债务的敏感性口径为1,568.24 亿元人民币；需合同条款决定信用分类。 | E4: conditional | F4: E_SUPPLY, supply_components, supply_change | G4: E_BRIDGE | H4: 余额下降仍可能同时伴随普通贸易应付款上升。 供应商融资可替换其他资金，风险还取决于期限、集中度和终止条款。 | I4: 取得融资机构、到期梯度及撤回条款，重算现金缺口和债务口径；不能把存量总额直接当本期CFO调整额。
A5: F_LIQUIDITY | B5: 集团大额现金意味着怎样的流动性 | C5: 货币资金3,335.13 亿元人民币中，现金及现金等价物2,999.30 亿元人民币，排除项目335.83 亿元人民币；现金桥保留千元级舍入差。 | D5: 排除项目包含受限保证金、质押定存和不可随时支取定存及利息，各类限制不同。集团现金尚需法人、币种、地区、季节性及经营最低现金判断，不能直接抵销全部集团债务。 | E5: conditional | F5: E_CASH, E_CF, cash_composition, debt | H5: 部分定存到期后可用，但时间须匹配债务到期。 境外现金可能受转移或税费限制；年报汇总不足以确认可调度数。 | I5: 按法人取得账户限制、债务期限和承诺授信条件，才能完成分期流动性覆盖。
A6: F_ESTIMATES | B6: 高增长是否证明资产和准备估计充足 | C6: 被测试固定资产组减值前账面28.66 亿元人民币、可收回额2.06 亿元人民币；售后预计负债512.33 亿元人民币。 | D6: 总体产能利用率不能推翻个别旧产线减值。转固606.16 亿元人民币与当期购建现金423.45 亿元人民币反映不同边界。售后预计负债依赖质保内销量、维修率与单位成本，余额增加不能替代费用与实际使用桥。 | E6: conditional | F6: E_PPE, E_WARRANTY, E_POLICY, ppe_imp_recalc | G6: E_BIZ | H6: 技术迭代或客户迁移可使局部产线减值，即使集团需求增长。 准备余额增加可能来自销量、维修率、成本或实际支出节奏，公开表无法分清。 | I6: 取得资产组预算/折现参数与历史兑现，及售后准备新增、使用、冲回和批次维修数据后，形成可收回额和准备敏感性。
A7: F_EQUITY | B7: 股东回报怎样复算 | C7: 归母净利润722.01 亿元人民币与母公司净利润704.14 亿元人民币分开；简单平均权益ROE为24.72%。 | D7: 集团权益增长由综合收益、股东投入与分配共同形成；集团盈利不能直接代表母公司可分红现金。简单平均ROE不是公司披露的加权ROE，香港发行新股也影响分母与资金。 | E7: conditional | F7: E_EQ, E_PL, equity_rollforward, roe_simple | H7: 资本交易和其他综合收益会改变权益而不增加经营利润。 母公司投资收益和子公司分红存在时间及可分配限制。 | I7: 分红能力判断需要母公司可分配利润、法定限制和实际资金，而非只看集团ROE。
A8: F_AUDIT | B8: 关键审计事项能说明什么 | C8: 原报告为无保留意见，固定资产减值和收入确认为关键审计事项；本次只执行披露取证与复算。 | D8: 关键审计事项说明原审计中的重要关注，不等于确认错报。本次需将收入截止、可变对价及资产组估计落实到合同与数据，不能复制原审计师程序为已完成。 | E8: supported | F8: E_AUDIT, E_POLICY, E_PPE | H8: 存在重要估计不等于估计错误。 无保留意见也不意味着每项经营假设均经独立证实。 | I8: 实际合同、验收、返利及资产组证据支持或反驳原判断后更新风险状态。

Sheet Procedures
A1: ID | B1: 事项 | C1: 目的与认定 | D1: 总体 | E1: 选取 | F1: 步骤 | G1: 状态 | H1: 实际结果 | I1: 证据 | J1: 执行者日期
A2: P_RECALC | B2: F_CASH | C2: 复算所选报表与附注关系 / 准确性, 列报 | D2: 本例已列事实所对应的报表及附注 | E2: 按现金、债务、利润归属、权益及供应商融资重要问题选取；非审计抽样 | F2: 按PDF页码读取原始科目及千元单位。 使用同一底稿重新加总桥及残差。 对供应商融资跨页和现金等价物附注回看原页。 | G2: performed | H2: 本次已完成取证和计算输入准备；确定性运行的每项实际残差列于Reconciliations，不能仅据复算证明交易真实性。 | I2: E_CF, E_BRIDGE, E_DEBT, E_EQ, E_SUPPLY | J2: Codex 本次公开资料分析 2026-10-02
A3: P_CONTRACT | B3: F_AUDIT | C3: 验证收入截止及返利估计 / 发生, 截止, 准确性 | D3: 年末前后主要客户交付、验收及返利合同与收入明细 | E3: 待取得总体与重要性后确定；不能以年报披露金额代替总体 | F3: 将合同、验收、发票及期后回款按交易匹配。 检查年末前后交付截止及期后退货折让。 重算返利条款和可变对价限制。 | G3: awaiting_data | H3: 未取得底层合同与明细，未执行细节检查；暂无确认错报金额。

Sheet Requests
A1: ID | B1: 事项 | C1: 所需资料 | D1: 影响 | E1: 责任角色 | F1: 关闭条件
A2: REQ_CASH | B2: F_LIQUIDITY | C2: 取得逐法人、币种、月份的债务本金利息、受限现金、承诺额度到期与提款条件，以及未来经营/投资/分红预算。 | D2: 集团现金汇总不能证明每个到期点的可用资金。 | E2: 资金负责人及信用分析师 | F2: 来源用途与期初现金逐月闭合，融资条件有证据，压力下最小现金和契约时点可重算。
A3: REQ_ESTIMATE | B3: F_ESTIMATES | C3: 取得资产组范围与完整减值预测、折现率依据、历史预算兑现，以及售后准备新增/使用/冲回和质保批次数据。 | D3: 仅年报余额不能验证全部减值及保修估计。 | E3: 资产/售后财务负责人及审计估计负责人 | F3: 账面范围与模型一致，关键参数有证据，独立敏感性可复算，重大差异处理完成。
