Workbook

Sheet Readme
A1: 字段 / field | B1: 内容 / value
A2: 任务 | B2: 科顺股份与科顺转债：年报及信用研究
A3: 版本 | B3: keshun-public-research-2026-06-30
A4: 信息截止 | B4: 2026-06-30
A5: 范围 | B5: 合并主体为主，母公司偿债资源单列；期后季度和历史原口径分别列示
A6: 准则 | B6: 中国企业会计准则
A7: 方法与适用范围 | B7: 联合一般工商V4.1.202606及总论/支持V4.1.202605、债项V3.0.202207；采用公开规则并明示研究适配，不是机构评级复现或发布。
A8: 方法与适用范围 | B8: 四表及附注取证、确定性计算、经营/财务因素与现金条件情景使用同一底稿。
A9: 单位 | B9: Facts D=原始值，E=倍数，F=基础单位。Calculations D=基础单位，E=展示值。
A10: 复算 | B10: 数值公式可编辑；修改主体、期间、币种、规则或资料后须重跑 export.py 复核口径。
A11: 勾稽精度 | B11: 金额残差按本次Decimal输入/计算保留的小数位ROUND，消除Excel二进制尾差，不改变业务容差；提高输入小数精度后须重跑导出。
A12: 缺口 | B12: 空值不是零。未执行程序、假设与已披露数据分别标识。
... A19: 限制 | B19: 来源 ks_r_issue 的正式公布日期未核验；不得据此证明在信息截止日前已公开。当前披露内容可以继续分析，历史时点结论须补充公告时间证据。

Sheet Facts
A1: ID | B1: 原始科目 | C1: 证据 | D1: 原始数值 | E1: 倍数 | F1: 基础单位数值 | G1: 量纲 | H1: 币种 | I1: 实体 | J1: 范围 | K1: 开始 | L1: 结束 | M1: 统计类型 | N1: 状态 | O1: 准则 | P1: 说明 | Q1: 概念 | R1: 实物单位
A2: ks_a_cashbook_2025 | B2: 货币资金 | C2: ks_a_e_bs | D2: 2.3194062e+09 | E2: 1 | F2: =IF(COUNT(D2,E2)=2,D2*E2,NA()) -> 2.3194062e+09 | G2: money | H2: CNY | I2: 科顺防水科技股份有限公司 | J2: 合并 | L2: 2025-12-31 | M2: instant | N2: reported | O2: 中国企业会计准则；2025年报披露及同控重述口径 | P2: 原表行名：货币资金；列：本期/期末 | Q2: cashbook
A3: ks_a_cashbook_2024 | B3: 货币资金 | C3: ks_a_e_bs | D3: 3.4160788e+09 | E3: 1 | F3: =IF(COUNT(D3,E3)=2,D3*E3,NA()) -> 3.4160788e+09 | G3: money | H3: CNY | I3: 科顺防水科技股份有限公司 | J3: 合并 | L3: 2024-12-31 | M3: instant | N3: restated | O3: 中国企业会计准则；2025年报披露及同控重述口径 | P3: 原表行名：货币资金；列：上期/期初；同控比较口径 | Q3: cashbook
A4: ks_a_trading_2025 | B4: 交易性金融资产 | C4: ks_a_e_bs | D4: 3.399301e+08 | E4: 1 | F4: =IF(COUNT(D4,E4)=2,D4*E4,NA()) -> 3.399301e+08 | G4: money | H4: CNY | I4: 科顺防水科技股份有限公司 | J4: 合并 | L4: 2025-12-31 | M4: instant | N4: reported | O4: 中国企业会计准则；2025年报披露及同控重述口径 | P4: 原表行名：交易性金融资产；列：本期/期末 | Q4: trading
A5: ks_a_trading_2024 | B5: 交易性金融资产 | C5: ks_a_e_bs | D5: 2.6657815e+08 | E5: 1 | F5: =IF(COUNT(D5,E5)=2,D5*E5,NA()) -> 2.6657815e+08 | G5: money | H5: CNY | I5: 科顺防水科技股份有限公司 | J5: 合并 | L5: 2024-12-31 | M5: instant | N5: restated | O5: 中国企业会计准则；2025年报披露及同控重述口径 | P5: 原表行名：交易性金融资产；列：上期/期初；同控比较口径 | Q5: trading
A6: ks_a_notes_ar_2025 | B6: 应收票据 | C6: ks_a_e_bs | D6: 12214074 | E6: 1 | F6: =IF(COUNT(D6,E6)=2,D6*E6,NA()) -> 12214074 | G6: money | H6: CNY | I6: 科顺防水科技股份有限公司 | J6: 合并 | L6: 2025-12-31 | M6: instant | N6: reported | O6: 中国企业会计准则；2025年报披露及同控重述口径 | P6: 原表行名：应收票据；列：本期/期末 | Q6: notes_ar
A7: ks_a_notes_ar_2024 | B7: 应收票据 | C7: ks_a_e_bs | D7: 17834988 | E7: 1 | F7: =IF(COUNT(D7,E7)=2,D7*E7,NA()) -> 17834988 | G7: money | H7: CNY | I7: 科顺防水科技股份有限公司 | J7: 合并 | L7: 2024-12-31 | M7: instant | N7: restated | O7: 中国企业会计准则；2025年报披露及同控重述口径 | P7: 原表行名：应收票据；列：上期/期初；同控比较口径 | Q7: notes_ar
A8: ks_a_ar_2025 | B8: 应收账款净额 | C8: ks_a_e_bs | D8: 3.294516e+09 | E8: 1 | F8: =IF(COUNT(D8,E8)=2,D8*E8,NA()) -> 3.294516e+09 | G8: money | H8: CNY | I8: 科顺防水科技股份有限公司 | J8: 合并 | L8: 2025-12-31 | M8: instant | N8: reported | O8: 中国企业会计准则；2025年报披露及同控重述口径 | P8: 原表行名：应收账款净额；列：本期/期末 | Q8: ar
A9: ks_a_ar_2024 | B9: 应收账款净额 | C9: ks_a_e_bs | D9: 4.0727934e+09 | E9: 1 | F9: =IF(COUNT(D9,E9)=2,D9*E9,NA()) -> 4.0727934e+09 | G9: money | H9: CNY | I9: 科顺防水科技股份有限公司 | J9: 合并 | L9: 2024-12-31 | M9: instant | N9: restated | O9: 中国企业会计准则；2025年报披露及同控重述口径 | P9: 原表行名：应收账款净额；列：上期/期初；同控比较口径 | Q9: ar
A10: ks_a_arfin_2025 | B10: 应收款项融资 | C10: ks_a_e_bs | D10: 4.6947436e+08 | E10: 1 | F10: =IF(COUNT(D10,E10)=2,D10*E10,NA()) -> 4.6947436e+08 | G10: money | H10: CNY | I10: 科顺防水科技股份有限公司 | J10: 合并 | L10: 2025-12-31 | M10: instant | N10: reported | O10: 中国企业会计准则；2025年报披露及同控重述口径 | P10: 原表行名：应收款项融资；列：本期/期末 | Q10: arfin
A11: ks_a_arfin_2024 | B11: 应收款项融资 | C11: ks_a_e_bs | D11: 4.9308818e+08 | E11: 1 | F11: =IF(COUNT(D11,E11)=2,D11*E11,NA()) -> 4.9308818e+08 | G11: money | H11: CNY | I11: 科顺防水科技股份有限公司 | J11: 合并 | L11: 2024-12-31 | M11: instant | N11: restated | O11: 中国企业会计准则；2025年报披露及同控重述口径 | P11: 原表行名：应收款项融资；列：上期/期初；同控比较口径 | Q11: arfin
A12: ks_a_prepay_2025 | B12: 预付款项 | C12: ks_a_e_bs | D12: 1.827906e+08 | E12: 1 | F12: =IF(COUNT(D12,E12)=2,D12*E12,NA()) -> 1.827906e+08 | G12: money | H12: CNY | I12: 科顺防水科技股份有限公司 | J12: 合并 | L12: 2025-12-31 | M12: instant | N12: reported | O12: 中国企业会计准则；2025年报披露及同控重述口径 | P12: 原表行名：预付款项；列：本期/期末 | Q12: prepay
A13: ks_a_prepay_2024 | B13: 预付款项 | C13: ks_a_e_bs | D13: 1.6614375e+08 | E13: 1 | F13: =IF(COUNT(D13,E13)=2,D13*E13,NA()) -> 1.6614375e+08 | G13: money | H13: CNY | I13: 科顺防水科技股份有限公司 | J13: 合并 | L13: 2024-12-31 | M13: instant | N13: restated | O13: 中国企业会计准则；2025年报披露及同控重述口径 | P13: 原表行名：预付款项；列：上期/期初；同控比较口径 | Q13: prepay
... A110: ks_a_equity_2024 | B110: 所有者权益合计 | C110: ks_a_e_bs | D110: 5.0670824e+09 | E110: 1 | F110: =IF(COUNT(D110,E110)=2,D110*E110,NA()) -> 5.0670824e+09 | G110: money | H110: CNY | I110: 科顺防水科技股份有限公司 | J110: 合并 | L110: 2024-12-31 | M110: instant | N110: restated | O110: 中国企业会计准则；2025年报披露及同控重述口径 | P110: 原表行名：所有者权益合计；列：上期/期初；同控比较口径 | Q110: equity
A111: ks_a_revenue_2025 | B111: 营业收入 | C111: ks_a_e_is | D111: 6.0441248e+09 | E111: 1 | F111: =IF(COUNT(D111,E111)=2,D111*E111,NA()) -> 6.0441248e+09 | G111: money | H111: CNY | I111: 科顺防水科技股份有限公司 | J111: 合并 | K111: 2025-01-01 | L111: 2025-12-31 | M111: flow | N111: reported | O111: 中国企业会计准则；2025年报披露及同控重述口径 | P111: 原表行名：营业收入；列：本期/期末 | Q111: revenue
A112: ks_a_revenue_2024 | B112: 营业收入 | C112: ks_a_e_is | D112: 6.8288033e+09 | E112: 1 | F112: =IF(COUNT(D112,E112)=2,D112*E112,NA()) -> 6.8288033e+09 | G112: money | H112: CNY | I112: 科顺防水科技股份有限公司 | J112: 合并 | K112: 2024-01-01 | L112: 2024-12-31 | M112: flow | N112: restated | O112: 中国企业会计准则；2025年报披露及同控重述口径 | P112: 原表行名：营业收入；列：上期/期初；同控比较口径 | Q112: revenue
A113: ks_a_cost_2025 | B113: 营业成本 | C113: ks_a_e_is | D113: 4.5813733e+09 | E113: 1 | F113: =IF(COUNT(D113,E113)=2,D113*E113,NA()) -> 4.5813733e+09 | G113: money | H113: CNY | I113: 科顺防水科技股份有限公司 | J113: 合并 | K113: 2025-01-01 | L113: 2025-12-31 | M113: flow | N113: reported | O113: 中国企业会计准则；2025年报披露及同控重述口径 | P113: 原表行名：营业成本；列：本期/期末 | Q113: cost
A114: ks_a_cost_2024 | B114: 营业成本 | C114: ks_a_e_is | D114: 5.3422434e+09 | E114: 1 | F114: =IF(COUNT(D114,E114)=2,D114*E114,NA()) -> 5.3422434e+09 | G114: money | H114: CNY | I114: 科顺防水科技股份有限公司 | J114: 合并 | K114: 2024-01-01 | L114: 2024-12-31 | M114: flow | N114: restated | O114: 中国企业会计准则；2025年报披露及同控重述口径 | P114: 原表行名：营业成本；列：上期/期初；同控比较口径 | Q114: cost
A115: ks_a_surtax_2025 | B115: 税金及附加 | C115: ks_a_e_is | D115: 45777452 | E115: 1 | F115: =IF(COUNT(D115,E115)=2,D115*E115,NA()) -> 45777452 | G115: money | H115: CNY | I115: 科顺防水科技股份有限公司 | J115: 合并 | K115: 2025-01-01 | L115: 2025-12-31 | M115: flow | N115: reported | O115: 中国企业会计准则；2025年报披露及同控重述口径 | P115: 原表行名：税金及附加；列：本期/期末 | Q115: surtax
A116: ks_a_surtax_2024 | B116: 税金及附加 | C116: ks_a_e_is | D116: 43205944 | E116: 1 | F116: =IF(COUNT(D116,E116)=2,D116*E116,NA()) -> 43205944 | G116: money | H116: CNY | I116: 科顺防水科技股份有限公司 | J116: 合并 | K116: 2024-01-01 | L116: 2024-12-31 | M116: flow | N116: restated | O116: 中国企业会计准则；2025年报披露及同控重述口径 | P116: 原表行名：税金及附加；列：上期/期初；同控比较口径 | Q116: surtax
A117: ks_a_selling_2025 | B117: 销售费用 | C117: ks_a_e_is | D117: 5.4189074e+08 | E117: 1 | F117: =IF(COUNT(D117,E117)=2,D117*E117,NA()) -> 5.4189074e+08 | G117: money | H117: CNY | I117: 科顺防水科技股份有限公司 | J117: 合并 | K117: 2025-01-01 | L117: 2025-12-31 | M117: flow | N117: reported | O117: 中国企业会计准则；2025年报披露及同控重述口径 | P117: 原表行名：销售费用；列：本期/期末 | Q117: selling
A118: ks_a_selling_2024 | B118: 销售费用 | C118: ks_a_e_is | D118: 6.1925711e+08 | E118: 1 | F118: =IF(COUNT(D118,E118)=2,D118*E118,NA()) -> 6.1925711e+08 | G118: money | H118: CNY | I118: 科顺防水科技股份有限公司 | J118: 合并 | K118: 2024-01-01 | L118: 2024-12-31 | M118: flow | N118: restated | O118: 中国企业会计准则；2025年报披露及同控重述口径 | P118: 原表行名：销售费用；列：上期/期初；同控比较口径 | Q118: selling
A119: ks_a_admin_2025 | B119: 管理费用 | C119: ks_a_e_is | D119: 3.5051232e+08 | E119: 1 | F119: =IF(COUNT(D119,E119)=2,D119*E119,NA()) -> 3.5051232e+08 | G119: money | H119: CNY | I119: 科顺防水科技股份有限公司 | J119: 合并 | K119: 2025-01-01 | L119: 2025-12-31 | M119: flow | N119: reported | O119: 中国企业会计准则；2025年报披露及同控重述口径 | P119: 原表行名：管理费用；列：本期/期末 | Q119: admin
A120: ks_a_admin_2024 | B120: 管理费用 | C120: ks_a_e_is | D120: 3.6276699e+08 | E120: 1 | F120: =IF(COUNT(D120,E120)=2,D120*E120,NA()) -> 3.6276699e+08 | G120: money | H120: CNY | I120: 科顺防水科技股份有限公司 | J120: 合并 | K120: 2024-01-01 | L120: 2024-12-31 | M120: flow | N120: restated | O120: 中国企业会计准则；2025年报披露及同控重述口径 | P120: 原表行名：管理费用；列：上期/期初；同控比较口径 | Q120: admin
A121: ks_a_rd_2025 | B121: 研发费用 | C121: ks_a_e_is | D121: 2.5283892e+08 | E121: 1 | F121: =IF(COUNT(D121,E121)=2,D121*E121,NA()) -> 2.5283892e+08 | G121: money | H121: CNY | I121: 科顺防水科技股份有限公司 | J121: 合并 | K121: 2025-01-01 | L121: 2025-12-31 | M121: flow | N121: reported | O121: 中国企业会计准则；2025年报披露及同控重述口径 | P121: 原表行名：研发费用；列：本期/期末 | Q121: rd
A122: ks_a_rd_2024 | B122: 研发费用 | C122: ks_a_e_is | D122: 2.7515111e+08 | E122: 1 | F122: =IF(COUNT(D122,E122)=2,D122*E122,NA()) -> 2.7515111e+08 | G122: money | H122: CNY | I122: 科顺防水科技股份有限公司 | J122: 合并 | K122: 2024-01-01 | L122: 2024-12-31 | M122: flow | N122: restated | O122: 中国企业会计准则；2025年报披露及同控重述口径 | P122: 原表行名：研发费用；列：上期/期初；同控比较口径 | Q122: rd
... A227: ks_a_cashdelta_2024 | B227: 现金等价物增减 | C227: ks_a_e_cf | D227: 3.3317046e+08 | E227: 1 | F227: =IF(COUNT(D227,E227)=2,D227*E227,NA()) -> 3.3317046e+08 | G227: money | H227: CNY | I227: 科顺防水科技股份有限公司 | J227: 合并 | K227: 2024-01-01 | L227: 2024-12-31 | M227: flow | N227: restated | O227: 中国企业会计准则；2025年报披露及同控重述口径 | P227: 原表行名：现金等价物增减；列：上期/期初；同控比较口径 | Q227: cashdelta
A228: ks_a_cash_2025 | B228: 期末现金及等价物 | C228: ks_a_e_cash | D228: 1.6077187e+09 | E228: 1 | F228: =IF(COUNT(D228,E228)=2,D228*E228,NA()) -> 1.6077187e+09 | G228: money | H228: CNY | I228: 科顺防水科技股份有限公司 | J228: 合并 | L228: 2025-12-31 | M228: instant | N228: reported | O228: 中国企业会计准则；2025年报披露及同控重述口径 | P228: 原表行名：期末现金及等价物；列：本期/期末 | Q228: cash
A229: ks_a_cash_2024 | B229: 期末现金及等价物 | C229: ks_a_e_cash | D229: 2.3295612e+09 | E229: 1 | F229: =IF(COUNT(D229,E229)=2,D229*E229,NA()) -> 2.3295612e+09 | G229: money | H229: CNY | I229: 科顺防水科技股份有限公司 | J229: 合并 | L229: 2024-12-31 | M229: instant | N229: restated | O229: 中国企业会计准则；2025年报披露及同控重述口径 | P229: 原表行名：期末现金及等价物；列：上期/期初；同控比较口径 | Q229: cash
A230: ks_a_restrictedcash_2025 | B230: 受限货币资金 | C230: ks_a_e_cash | D230: 7.1168755e+08 | E230: 1 | F230: =IF(COUNT(D230,E230)=2,D230*E230,NA()) -> 7.1168755e+08 | G230: money | H230: CNY | I230: 科顺防水科技股份有限公司 | J230: 合并 | L230: 2025-12-31 | M230: instant | N230: reported | O230: 中国企业会计准则；2025年报披露及同控重述口径 | P230: 原表行名：受限货币资金；列：本期/期末 | Q230: restrictedcash
A231: ks_a_restrictedcash_2024 | B231: 受限货币资金 | C231: ks_a_e_cash | D231: 1.0865176e+09 | E231: 1 | F231: =IF(COUNT(D231,E231)=2,D231*E231,NA()) -> 1.0865176e+09 | G231: money | H231: CNY | I231: 科顺防水科技股份有限公司 | J231: 合并 | L231: 2024-12-31 | M231: instant | N231: restated | O231: 中国企业会计准则；2025年报披露及同控重述口径 | P231: 原表行名：受限货币资金；列：上期/期初；同控比较口径 | Q231: restrictedcash
A232: ks_a_frozen_2025 | B232: 冻结资金 | C232: ks_a_e_cash | D232: 15883848 | E232: 1 | F232: =IF(COUNT(D232,E232)=2,D232*E232,NA()) -> 15883848 | G232: money | H232: CNY | I232: 科顺防水科技股份有限公司 | J232: 合并 | L232: 2025-12-31 | M232: instant | N232: reported | O232: 中国企业会计准则；2025年报披露及同控重述口径 | P232: 原表行名：冻结资金；列：本期/期末 | Q232: frozen
A233: ks_a_frozen_2024 | B233: 冻结资金 | C233: ks_a_e_cash | D233: 25198075 | E233: 1 | F233: =IF(COUNT(D233,E233)=2,D233*E233,NA()) -> 25198075 | G233: money | H233: CNY | I233: 科顺防水科技股份有限公司 | J233: 合并 | L233: 2024-12-31 | M233: instant | N233: restated | O233: 中国企业会计准则；2025年报披露及同控重述口径 | P233: 原表行名：冻结资金；列：上期/期初；同控比较口径 | Q233: frozen
A234: ks_a_pledgedtd_2025 | B234: 定期存款质押 | C234: ks_a_e_cash | D234: 423522048 | E234: 1 | F234: =IF(COUNT(D234,E234)=2,D234*E234,NA()) -> 423522048 | G234: money | H234: CNY | I234: 科顺防水科技股份有限公司 | J234: 合并 | L234: 2025-12-31 | M234: instant | N234: reported | O234: 中国企业会计准则；2025年报披露及同控重述口径 | P234: 原表行名：定期存款质押；列：本期/期末 | Q234: pledgedtd
A235: ks_a_pledgedtd_2024 | B235: 定期存款质押 | C235: ks_a_e_cash | D235: 582826000 | E235: 1 | F235: =IF(COUNT(D235,E235)=2,D235*E235,NA()) -> 582826000 | G235: money | H235: CNY | I235: 科顺防水科技股份有限公司 | J235: 合并 | L235: 2024-12-31 | M235: instant | N235: restated | O235: 中国企业会计准则；2025年报披露及同控重述口径 | P235: 原表行名：定期存款质押；列：上期/期初；同控比较口径 | Q235: pledgedtd
A236: ks_a_specialcash_2025 | B236: 专项账户受限金额 | C236: ks_a_e_cash | D236: 19327216 | E236: 1 | F236: =IF(COUNT(D236,E236)=2,D236*E236,NA()) -> 19327216 | G236: money | H236: CNY | I236: 科顺防水科技股份有限公司 | J236: 合并 | L236: 2025-12-31 | M236: instant | N236: reported | O236: 中国企业会计准则；2025年报披露及同控重述口径 | P236: 原表行名：专项账户受限金额；列：本期/期末 | Q236: specialcash
A237: ks_a_specialcash_2024 | B237: 专项账户受限金额 | C237: ks_a_e_cash | D237: 15284768 | E237: 1 | F237: =IF(COUNT(D237,E237)=2,D237*E237,NA()) -> 15284768 | G237: money | H237: CNY | I237: 科顺防水科技股份有限公司 | J237: 合并 | L237: 2024-12-31 | M237: instant | N237: restated | O237: 中国企业会计准则；2025年报披露及同控重述口径 | P237: 原表行名：专项账户受限金额；列：上期/期初；同控比较口径 | Q237: specialcash
A238: ks_a_notesmargin_2025 | B238: 银行承兑汇票保证金 | C238: ks_a_e_cash | D238: 1.9467343e+08 | E238: 1 | F238: =IF(COUNT(D238,E238)=2,D238*E238,NA()) -> 1.9467343e+08 | G238: money | H238: CNY | I238: 科顺防水科技股份有限公司 | J238: 合并 | L238: 2025-12-31 | M238: instant | N238: reported | O238: 中国企业会计准则；2025年报披露及同控重述口径 | P238: 原表行名：银行承兑汇票保证金；列：本期/期末 | Q238: notesmargin
A239: ks_a_notesmargin_2024 | B239: 银行承兑汇票保证金 | C239: ks_a_e_cash | D239: 3.9155347e+08 | E239: 1 | F239: =IF(COUNT(D239,E239)=2,D239*E239,NA()) -> 3.9155347e+08 | G239: money | H239: CNY | I239: 科顺防水科技股份有限公司 | J239: 合并 | L239: 2024-12-31 | M239: instant | N239: restated | O239: 中国企业会计准则；2025年报披露及同控重述口径 | P239: 原表行名：银行承兑汇票保证金；列：上期/期初；同控比较口径 | Q239: notesmargin
... A249: ks_a_restrictedassets_2024 | B249: 受限资产账面净额 | C249: ks_a_e_cash | D249: 1.2673883e+09 | E249: 1 | F249: =IF(COUNT(D249,E249)=2,D249*E249,NA()) -> 1.2673883e+09 | G249: money | H249: CNY | I249: 科顺防水科技股份有限公司 | J249: 合并 | L249: 2024-12-31 | M249: instant | N249: restated | O249: 中国企业会计准则；2025年报披露及同控重述口径 | P249: 原表行名：受限资产账面净额；列：上期/期初；同控比较口径 | Q249: restrictedassets
...

Sheet Calculations
A1: ID | B1: 指标或桥 | C1: 基础单位公式 | D1: 基础单位结果 | E1: 展示结果 | F1: 状态 | G1: 不计算原因 | H1: 定义 | I1: 解释边界 | J1: 展示单位 | K1: 倍数 | L1: 实体 | M1: 范围 | N1: 开始 | O1: 结束
A2: ks_a_sum_currentassets_2025 | B2: 流动资产加总 | C2: =(('Facts'!F2*1)+('Facts'!F4*1)+('Facts'!F6*1)+('Facts'!F8*1)+('Facts'!F10*1)+('Facts'!F12*1)+('Facts'!F14*1)+('Facts'!F16*1)+('Facts'!F18*1)+('Facts'!F21*1))*1 | D2: =(('Facts'!F2*1)+('Facts'!F4*1)+('Facts'!F6*1)+('Facts'!F8*1)+('Facts'!F10*1)+('Facts'!F12*1)+('Facts'!F14*1)+('Facts'!F16*1)+('Facts'!F18*1)+('Facts'!F21*1))*1 -> 7.9877563e+09 | E2: =D2/K2 -> 7.9877563e+09 | F2: =IF(ISNUMBER(D2),"calculated","not_calculated") -> calculated | G2: =IF(ISNUMBER(D2),"","检查缺失值、分母与输入；口径变更须重跑Python") | H2: 流动资产加总 | I2: 仅按列明财务口径运算；不单独决定信用等级。 | J2: CNY | K2: 1 | L2: 科顺防水科技股份有限公司 | M2: 合并 | O2: 2025-12-31
A3: ks_a_sum_noncurrentassets_2025 | B3: 非流动资产加总 | C3: =(('Facts'!F26*1)+('Facts'!F28*1)+('Facts'!F30*1)+('Facts'!F32*1)+('Facts'!F34*1)+('Facts'!F36*1)+('Facts'!F38*1)+('Facts'!F40*1)+('Facts'!F42*1)+('Facts'!F44*1)+('Facts'!F46*1)+('Facts'!F48*1))*1 | D3: =(('Facts'!F26*1)+('Facts'!F28*1)+('Facts'!F30*1)+('Facts'!F32*1)+('Facts'!F34*1)+('Facts'!F36*1)+('Facts'!F38*1)+('Facts'!F40*1)+('Facts'!F42*1)+('Facts'!F44*1)+('Facts'!F46*1)+('Facts'!F48*1))*1 -> 4.4123196e+09 | E3: =D3/K3 -> 4.4123196e+09 | F3: =IF(ISNUMBER(D3),"calculated","not_calculated") -> calculated | G3: =IF(ISNUMBER(D3),"","检查缺失值、分母与输入；口径变更须重跑Python") | H3: 非流动资产加总 | I3: 仅按列明财务口径运算；不单独决定信用等级。 | J3: CNY | K3: 1 | L3: 科顺防水科技股份有限公司 | M3: 合并 | O3: 2025-12-31
A4: ks_a_sum_currentliab_2025 | B4: 流动负债加总 | C4: =(('Facts'!F54*1)+('Facts'!F56*1)+('Facts'!F58*1)+('Facts'!F60*1)+('Facts'!F62*1)+('Facts'!F64*1)+('Facts'!F66*1)+('Facts'!F68*1)+('Facts'!F70*1))*1 | D4: =(('Facts'!F54*1)+('Facts'!F56*1)+('Facts'!F58*1)+('Facts'!F60*1)+('Facts'!F62*1)+('Facts'!F64*1)+('Facts'!F66*1)+('Facts'!F68*1)+('Facts'!F70*1))*1 -> 5.6924055e+09 | E4: =D4/K4 -> 5.6924055e+09 | F4: =IF(ISNUMBER(D4),"calculated","not_calculated") -> calculated | G4: =IF(ISNUMBER(D4),"","检查缺失值、分母与输入；口径变更须重跑Python") | H4: 流动负债加总 | I4: 仅按列明财务口径运算；不单独决定信用等级。 | J4: CNY | K4: 1 | L4: 科顺防水科技股份有限公司 | M4: 合并 | O4: 2025-12-31
A5: ks_a_sum_noncurrentliab_2025 | B5: 非流动负债加总 | C5: =(('Facts'!F74*1)+('Facts'!F76*1)+('Facts'!F78*1)+('Facts'!F80*1)+('Facts'!F82*1)+('Facts'!F84*1))*1 | D5: =(('Facts'!F74*1)+('Facts'!F76*1)+('Facts'!F78*1)+('Facts'!F80*1)+('Facts'!F82*1)+('Facts'!F84*1))*1 -> 2.6555965e+09 | E5: =D5/K5 -> 2.6555965e+09 | F5: =IF(ISNUMBER(D5),"calculated","not_calculated") -> calculated | G5: =IF(ISNUMBER(D5),"","检查缺失值、分母与输入；口径变更须重跑Python") | H5: 非流动负债加总 | I5: 仅按列明财务口径运算；不单独决定信用等级。 | J5: CNY | K5: 1 | L5: 科顺防水科技股份有限公司 | M5: 合并 | O5: 2025-12-31
A6: ks_a_sum_ownerequity_2025 | B6: 归母权益分项加总 | C6: =(('Facts'!F90*1)+('Facts'!F92*1)+('Facts'!F94*1)+('Facts'!F96*1)+('Facts'!F98*1)+('Facts'!F100*1)+('Facts'!F103*1))*1 | D6: =(('Facts'!F90*1)+('Facts'!F92*1)+('Facts'!F94*1)+('Facts'!F96*1)+('Facts'!F98*1)+('Facts'!F100*1)+('Facts'!F103*1))*1 -> 3.9687971e+09 | E6: =D6/K6 -> 3.9687971e+09 | F6: =IF(ISNUMBER(D6),"calculated","not_calculated") -> calculated | G6: =IF(ISNUMBER(D6),"","检查缺失值、分母与输入；口径变更须重跑Python") | H6: 归母权益分项加总 | I6: 仅按列明财务口径运算；不单独决定信用等级。 | J6: CNY | K6: 1 | L6: 科顺防水科技股份有限公司 | M6: 合并 | O6: 2025-12-31
A7: ks_a_sum_equity_2025 | B7: 权益归属加总 | C7: =(('Facts'!F105*1)+('Facts'!F107*1))*1 | D7: =(('Facts'!F105*1)+('Facts'!F107*1))*1 -> 4.0520738e+09 | E7: =D7/K7 -> 4.0520738e+09 | F7: =IF(ISNUMBER(D7),"calculated","not_calculated") -> calculated | G7: =IF(ISNUMBER(D7),"","检查缺失值、分母与输入；口径变更须重跑Python") | H7: 权益归属加总 | I7: 仅按列明财务口径运算；不单独决定信用等级。 | J7: CNY | K7: 1 | L7: 科顺防水科技股份有限公司 | M7: 合并 | O7: 2025-12-31
A8: ks_a_sum_assets_2025 | B8: 资产总额加总 | C8: =(('Facts'!F23*1)+('Facts'!F50*1))*1 | D8: =(('Facts'!F23*1)+('Facts'!F50*1))*1 -> 1.2400076e+10 | E8: =D8/K8 -> 1.2400076e+10 | F8: =IF(ISNUMBER(D8),"calculated","not_calculated") -> calculated | G8: =IF(ISNUMBER(D8),"","检查缺失值、分母与输入；口径变更须重跑Python") | H8: 资产总额加总 | I8: 仅按列明财务口径运算；不单独决定信用等级。 | J8: CNY | K8: 1 | L8: 科顺防水科技股份有限公司 | M8: 合并 | O8: 2025-12-31
A9: ks_a_sum_liab_2025 | B9: 负债总额加总 | C9: =(('Facts'!F72*1)+('Facts'!F86*1))*1 | D9: =(('Facts'!F72*1)+('Facts'!F86*1))*1 -> 8.3480021e+09 | E9: =D9/K9 -> 8.3480021e+09 | F9: =IF(ISNUMBER(D9),"calculated","not_calculated") -> calculated | G9: =IF(ISNUMBER(D9),"","检查缺失值、分母与输入；口径变更须重跑Python") | H9: 负债总额加总 | I9: 仅按列明财务口径运算；不单独决定信用等级。 | J9: CNY | K9: 1 | L9: 科顺防水科技股份有限公司 | M9: 合并 | O9: 2025-12-31
A10: ks_a_le_sum_2025 | B10: 负债加权益 | C10: =(('Facts'!F88*1)+('Facts'!F109*1))*1 | D10: =(('Facts'!F88*1)+('Facts'!F109*1))*1 -> 1.2400076e+10 | E10: =D10/K10 -> 1.2400076e+10 | F10: =IF(ISNUMBER(D10),"calculated","not_calculated") -> calculated | G10: =IF(ISNUMBER(D10),"","检查缺失值、分母与输入；口径变更须重跑Python") | H10: 负债加权益 | I10: 仅按列明财务口径运算；不单独决定信用等级。 | J10: CNY | K10: 1 | L10: 科顺防水科技股份有限公司 | M10: 合并 | O10: 2025-12-31
A11: ks_a_recalc_totalcost_2025 | B11: 营业总成本重算 | C11: =(('Facts'!F113*1)+('Facts'!F115*1)+('Facts'!F117*1)+('Facts'!F119*1)+('Facts'!F121*1)+('Facts'!F123*1))*1 | D11: =(('Facts'!F113*1)+('Facts'!F115*1)+('Facts'!F117*1)+('Facts'!F119*1)+('Facts'!F121*1)+('Facts'!F123*1))*1 -> 5.8478473e+09 | E11: =D11/K11 -> 5.8478473e+09 | F11: =IF(ISNUMBER(D11),"calculated","not_calculated") -> calculated | G11: =IF(ISNUMBER(D11),"","检查缺失值、分母与输入；口径变更须重跑Python") | H11: 营业总成本重算 | I11: 仅按列明财务口径运算；不单独决定信用等级。 | J11: CNY | K11: 1 | L11: 科顺防水科技股份有限公司 | M11: 合并 | N11: 2025-01-01 | O11: 2025-12-31
A12: ks_a_recalc_pbt_2025 | B12: 营业利润加营业外净额 | C12: =(('Facts'!F143*1)+('Facts'!F145*1)+('Facts'!F147*-1))*1 | D12: =(('Facts'!F143*1)+('Facts'!F145*1)+('Facts'!F147*-1))*1 -> -5.9219421e+08 | E12: =D12/K12 -> -5.9219421e+08 | F12: =IF(ISNUMBER(D12),"calculated","not_calculated") -> calculated | G12: =IF(ISNUMBER(D12),"","检查缺失值、分母与输入；口径变更须重跑Python") | H12: 营业利润加营业外净额 | I12: 仅按列明财务口径运算；不单独决定信用等级。 | J12: CNY | K12: 1 | L12: 科顺防水科技股份有限公司 | M12: 合并 | N12: 2025-01-01 | O12: 2025-12-31
A13: ks_a_recalc_netincome_2025 | B13: 税前减所得税 | C13: =(('Facts'!F149-'Facts'!F151))*1 | D13: =(('Facts'!F149-'Facts'!F151))*1 -> -5.4779522e+08 | E13: =D13/K13 -> -5.4779522e+08 | F13: =IF(ISNUMBER(D13),"calculated","not_calculated") -> calculated | G13: =IF(ISNUMBER(D13),"","检查缺失值、分母与输入；口径变更须重跑Python") | H13: 税前减所得税 | I13: 仅按列明财务口径运算；不单独决定信用等级。 | J13: CNY | K13: 1 | L13: 科顺防水科技股份有限公司 | M13: 合并 | N13: 2025-01-01 | O13: 2025-12-31
A14: ks_a_recalc_ci_2025 | B14: 综合收益重算 | C14: =(('Facts'!F153*1)+('Facts'!F159*1))*1 | D14: =(('Facts'!F153*1)+('Facts'!F159*1))*1 -> -5.623635e+08 | E14: =D14/K14 -> -5.623635e+08 | F14: =IF(ISNUMBER(D14),"calculated","not_calculated") -> calculated | G14: =IF(ISNUMBER(D14),"","检查缺失值、分母与输入；口径变更须重跑Python") | H14: 综合收益重算 | I14: 仅按列明财务口径运算；不单独决定信用等级。 | J14: CNY | K14: 1 | L14: 科顺防水科技股份有限公司 | M14: 合并 | N14: 2025-01-01 | O14: 2025-12-31
A15: ks_a_recalc_opcashin_2025 | B15: 经营现金流入重算 | C15: =(('Facts'!F163*1)+('Facts'!F165*1)+('Facts'!F167*1))*1 | D15: =(('Facts'!F163*1)+('Facts'!F165*1)+('Facts'!F167*1))*1 -> 7.4428619e+09 | E15: =D15/K15 -> 7.4428619e+09 | F15: =IF(ISNUMBER(D15),"calculated","not_calculated") -> calculated | G15: =IF(ISNUMBER(D15),"","检查缺失值、分母与输入；口径变更须重跑Python") | H15: 经营现金流入重算 | I15: 仅按列明财务口径运算；不单独决定信用等级。 | J15: CNY | K15: 1 | L15: 科顺防水科技股份有限公司 | M15: 合并 | N15: 2025-01-01 | O15: 2025-12-31
A16: ks_a_recalc_opcashout_2025 | B16: 经营现金流出重算 | C16: =(('Facts'!F171*1)+('Facts'!F173*1)+('Facts'!F175*1)+('Facts'!F177*1))*1 | D16: =(('Facts'!F171*1)+('Facts'!F173*1)+('Facts'!F175*1)+('Facts'!F177*1))*1 -> 7.1232338e+09 | E16: =D16/K16 -> 7.1232338e+09 | F16: =IF(ISNUMBER(D16),"calculated","not_calculated") -> calculated | G16: =IF(ISNUMBER(D16),"","检查缺失值、分母与输入；口径变更须重跑Python") | H16: 经营现金流出重算 | I16: 仅按列明财务口径运算；不单独决定信用等级。 | J16: CNY | K16: 1 | L16: 科顺防水科技股份有限公司 | M16: 合并 | N16: 2025-01-01 | O16: 2025-12-31
A17: ks_a_recalc_cfo_2025 | B17: 直接法经营净现金 | C17: =(('Facts'!F169-'Facts'!F179))*1 | D17: =(('Facts'!F169-'Facts'!F179))*1 -> 3.1962802e+08 | E17: =D17/K17 -> 3.1962802e+08 | F17: =IF(ISNUMBER(D17),"calculated","not_calculated") -> calculated | G17: =IF(ISNUMBER(D17),"","检查缺失值、分母与输入；口径变更须重跑Python") | H17: 直接法经营净现金 | I17: 仅按列明财务口径运算；不单独决定信用等级。 | J17: CNY | K17: 1 | L17: 科顺防水科技股份有限公司 | M17: 合并 | N17: 2025-01-01 | O17: 2025-12-31
A18: ks_a_recalc_cfi_2025 | B18: 投资净现金 | C18: =(('Facts'!F192-'Facts'!F202))*1 | D18: =(('Facts'!F192-'Facts'!F202))*1 -> -4.3330754e+08 | E18: =D18/K18 -> -4.3330754e+08 | F18: =IF(ISNUMBER(D18),"calculated","not_calculated") -> calculated | G18: =IF(ISNUMBER(D18),"","检查缺失值、分母与输入；口径变更须重跑Python") | H18: 投资净现金 | I18: 仅按列明财务口径运算；不单独决定信用等级。 | J18: CNY | K18: 1 | L18: 科顺防水科技股份有限公司 | M18: 合并 | N18: 2025-01-01 | O18: 2025-12-31
A19: ks_a_recalc_cff_2025 | B19: 筹资净现金 | C19: =(('Facts'!F212-'Facts'!F220))*1 | D19: =(('Facts'!F212-'Facts'!F220))*1 -> -6.0109942e+08 | E19: =D19/K19 -> -6.0109942e+08 | F19: =IF(ISNUMBER(D19),"calculated","not_calculated") -> calculated | G19: =IF(ISNUMBER(D19),"","检查缺失值、分母与输入；口径变更须重跑Python") | H19: 筹资净现金 | I19: 仅按列明财务口径运算；不单独决定信用等级。 | J19: CNY | K19: 1 | L19: 科顺防水科技股份有限公司 | M19: 合并 | N19: 2025-01-01 | O19: 2025-12-31
A20: ks_a_recalc_cashdelta_2025 | B20: 现金三类活动加汇率 | C20: =(('Facts'!F181*1)+('Facts'!F204*1)+('Facts'!F222*1)+('Facts'!F224*1))*1 | D20: =(('Facts'!F181*1)+('Facts'!F204*1)+('Facts'!F222*1)+('Facts'!F224*1))*1 -> -7.2184254e+08 | E20: =D20/K20 -> -7.2184254e+08 | F20: =IF(ISNUMBER(D20),"calculated","not_calculated") -> calculated | G20: =IF(ISNUMBER(D20),"","检查缺失值、分母与输入；口径变更须重跑Python") | H20: 现金三类活动加汇率 | I20: 仅按列明财务口径运算；不单独决定信用等级。 | J20: CNY | K20: 1 | L20: 科顺防水科技股份有限公司 | M20: 合并 | N20: 2025-01-01 | O20: 2025-12-31
A21: ks_a_plattrib_2025 | B21: 净利归属重算 | C21: =(('Facts'!F155*1)+('Facts'!F157*1))*1 | D21: =(('Facts'!F155*1)+('Facts'!F157*1))*1 -> -5.4779522e+08 | E21: =D21/K21 -> -5.4779522e+08 | F21: =IF(ISNUMBER(D21),"calculated","not_calculated") -> calculated | G21: =IF(ISNUMBER(D21),"","检查缺失值、分母与输入；口径变更须重跑Python") | H21: 净利归属重算 | I21: 仅按列明财务口径运算；不单独决定信用等级。 | J21: CNY | K21: 1 | L21: 科顺防水科技股份有限公司 | M21: 合并 | N21: 2025-01-01 | O21: 2025-12-31
A22: ks_a_calc_opprofit_2025 | B22: 营业利润全项目重算 | C22: =(('Facts'!F111*1)+('Facts'!F129*-1)+('Facts'!F131*1)+('Facts'!F133*1)+('Facts'!F135*1)+('Facts'!F137*1)+('Facts'!F139*1)+('Facts'!F141*1))*1 | D22: =(('Facts'!F111*1)+('Facts'!F129*-1)+('Facts'!F131*1)+('Facts'!F133*1)+('Facts'!F135*1)+('Facts'!F137*1)+('Facts'!F139*1)+('Facts'!F141*1))*1 -> -5.7569684e+08 | E22: =D22/K22 -> -5.7569684e+08 | F22: =IF(ISNUMBER(D22),"calculated","not_calculated") -> calculated | G22: =IF(ISNUMBER(D22),"","检查缺失值、分母与输入；口径变更须重跑Python") | H22: 营业利润全项目重算 | I22: 仅按列明财务口径运算；不单独决定信用等级。 | J22: CNY | K22: 1 | L22: 科顺防水科技股份有限公司 | M22: 合并 | N22: 2025-01-01 | O22: 2025-12-31
A23: ks_a_cashbridge_2025 | B23: 现金期初加净变动 | C23: =(('Facts'!F229*1)+('Facts'!F226*1))*1 | D23: =(('Facts'!F229*1)+('Facts'!F226*1))*1 -> 1.6077187e+09 | E23: =D23/K23 -> 1.6077187e+09 | F23: =IF(ISNUMBER(D23),"calculated","not_calculated") -> calculated | G23: =IF(ISNUMBER(D23),"","检查缺失值、分母与输入；口径变更须重跑Python") | H23: 现金期初加净变动 | I23: 仅按列明财务口径运算；不单独决定信用等级。 | J23: CNY | K23: 1 | L23: 科顺防水科技股份有限公司 | M23: 合并 | N23: 2025-01-01 | O23: 2025-12-31
A24: ks_a_cashrestrict_2025 | B24: 现金等价物加受限资金 | C24: =(('Facts'!F228*1)+('Facts'!F230*1))*1 | D24: =(('Facts'!F228*1)+('Facts'!F230*1))*1 -> 2.3194062e+09 | E24: =D24/K24 -> 2.3194062e+09 | F24: =IF(ISNUMBER(D24),"calculated","not_calculated") -> calculated | G24: =IF(ISNUMBER(D24),"","检查缺失值、分母与输入；口径变更须重跑Python") | H24: 现金等价物加受限资金 | I24: 仅按列明财务口径运算；不单独决定信用等级。 | J24: CNY | K24: 1 | L24: 科顺防水科技股份有限公司 | M24: 合并 | O24: 2025-12-31
A25: ks_a_restrictdetail_2025 | B25: 受限现金明细加总 | C25: =(('Facts'!F232*1)+('Facts'!F234*1)+('Facts'!F236*1)+('Facts'!F238*1)+('Facts'!F240*1)+('Facts'!F242*1)+('Facts'!F244*1))*1 | D25: =(('Facts'!F232*1)+('Facts'!F234*1)+('Facts'!F236*1)+('Facts'!F238*1)+('Facts'!F240*1)+('Facts'!F242*1)+('Facts'!F244*1))*1 -> 7.1168755e+08 | E25: =D25/K25 -> 7.1168755e+08 | F25: =IF(ISNUMBER(D25),"calculated","not_calculated") -> calculated | G25: =IF(ISNUMBER(D25),"","检查缺失值、分母与输入；口径变更须重跑Python") | H25: 受限现金明细加总 | I25: 仅按列明财务口径运算；不单独决定信用等级。 | J25: CNY | K25: 1 | L25: 科顺防水科技股份有限公司 | M25: 合并 | O25: 2025-12-31
A26: ks_a_indirect_cfo_2025 | B26: 净利润间接法现金桥 | C26: =(('Facts'!F153*1)+('Facts'!F364*1)+('Facts'!F366*1)+('Facts'!F368*1)+('Facts'!F370*1)+('Facts'!F372*1)+('Facts'!F374*1)+('Facts'!F376*1)+('Facts'!F378*1)+('Facts'!F380*1)+('Facts'!F382*1)+('Facts'!F384*1)+('Facts'!F386*1)+('Facts'!F388*1)+('Facts'!F390*1)+('Facts'!F392*1)+('Facts'!F394*1))*1 | D26: =(('Facts'!F153*1)+('Facts'!F364*1)+('Facts'!F366*1)+('Facts'!F368*1)+('Facts'!F370*1)+('Facts'!F372*1)+('Facts'!F374*1)+('Facts'!F376*1)+('Facts'!F378*1)+('Facts'!F380*1)+('Facts'!F382*1)+('Facts'!F384*1)+('Facts'!F386*1)+('Facts'!F388*1)+('Facts'!F390*1)+('Facts'!F392*1)+('Facts'!F394*1))*1 -> 3.1962802e+08 | E26: =D26/K26 -> 3.1962802e+08 | F26: =IF(ISNUMBER(D26),"calculated","not_calculated") -> calculated | G26: =IF(ISNUMBER(D26),"","检查缺失值、分母与输入；口径变更须重跑Python") | H26: 净利润间接法现金桥 | I26: 仅按列明财务口径运算；不单独决定信用等级。 | J26: CNY | K26: 1 | L26: 科顺防水科技股份有限公司 | M26: 合并 | N26: 2025-01-01 | O26: 2025-12-31
A27: ks_a_ar_netcalc_2025 | B27: ar原值减准备 | C27: =(('Facts'!F264-'Facts'!F266))*1 | D27: =(('Facts'!F264-'Facts'!F266))*1 -> 3.294516e+09 | E27: =D27/K27 -> 3.294516e+09 | F27: =IF(ISNUMBER(D27),"calculated","not_calculated") -> calculated | G27: =IF(ISNUMBER(D27),"","检查缺失值、分母与输入；口径变更须重跑Python") | H27: ar原值减准备 | I27: 仅按列明财务口径运算；不单独决定信用等级。 | J27: CNY | K27: 1 | L27: 科顺防水科技股份有限公司 | M27: 合并 | O27: 2025-12-31
A28: ks_a_otherar_netcalc_2025 | B28: otherar原值减准备 | C28: =(('Facts'!F304-'Facts'!F306))*1 | D28: =(('Facts'!F304-'Facts'!F306))*1 -> 3.3966516e+08 | E28: =D28/K28 -> 3.3966516e+08 | F28: =IF(ISNUMBER(D28),"calculated","not_calculated") -> calculated | G28: =IF(ISNUMBER(D28),"","检查缺失值、分母与输入；口径变更须重跑Python") | H28: otherar原值减准备 | I28: 仅按列明财务口径运算；不单独决定信用等级。 | J28: CNY | K28: 1 | L28: 科顺防水科技股份有限公司 | M28: 合并 | O28: 2025-12-31
A29: ks_a_inventory_netcalc_2025 | B29: inventory原值减准备 | C29: =(('Facts'!F312-'Facts'!F314))*1 | D29: =(('Facts'!F312-'Facts'!F314))*1 -> 4.2416976e+08 | E29: =D29/K29 -> 4.2416976e+08 | F29: =IF(ISNUMBER(D29),"calculated","not_calculated") -> calculated | G29: =IF(ISNUMBER(D29),"","检查缺失值、分母与输入；口径变更须重跑Python") | H29: inventory原值减准备 | I29: 仅按列明财务口径运算；不单独决定信用等级。 | J29: CNY | K29: 1 | L29: 科顺防水科技股份有限公司 | M29: 合并 | O29: 2025-12-31
A30: ks_a_contract_netcalc_2025 | B30: contract原值减准备 | C30: =(('Facts'!F290-'Facts'!F292))*1 | D30: =(('Facts'!F290-'Facts'!F292))*1 -> 3.9130259e+08 | E30: =D30/K30 -> 3.9130259e+08 | F30: =IF(ISNUMBER(D30),"calculated","not_calculated") -> calculated | G30: =IF(ISNUMBER(D30),"","检查缺失值、分母与输入；口径变更须重跑Python") | H30: contract原值减准备 | I30: 仅按列明财务口径运算；不单独决定信用等级。 | J30: CNY | K30: 1 | L30: 科顺防水科技股份有限公司 | M30: 合并 | O30: 2025-12-31
A31: ks_a_longcontract_netcalc_2025 | B31: longcontract原值减准备 | C31: =(('Facts'!F294-'Facts'!F296))*1 | D31: =(('Facts'!F294-'Facts'!F296))*1 -> 83837684 | E31: =D31/K31 -> 83837684 | F31: =IF(ISNUMBER(D31),"calculated","not_calculated") -> calculated | G31: =IF(ISNUMBER(D31),"","检查缺失值、分母与输入；口径变更须重跑Python") | H31: longcontract原值减准备 | I31: 仅按列明财务口径运算；不单独决定信用等级。 | J31: CNY | K31: 1 | L31: 科顺防水科技股份有限公司 | M31: 合并 | O31: 2025-12-31
A32: ks_a_propertynet_netcalc_2025 | B32: propertynet原值减准备 | C32: =(('Facts'!F316-'Facts'!F318))*1 | D32: =(('Facts'!F316-'Facts'!F318))*1 -> 7.8614144e+08 | E32: =D32/K32 -> 7.8614144e+08 | F32: =IF(ISNUMBER(D32),"calculated","not_calculated") -> calculated | G32: =IF(ISNUMBER(D32),"","检查缺失值、分母与输入；口径变更须重跑Python") | H32: propertynet原值减准备 | I32: 仅按列明财务口径运算；不单独决定信用等级。 | J32: CNY | K32: 1 | L32: 科顺防水科技股份有限公司 | M32: 合并 | O32: 2025-12-31
A33: ks_a_arge_sum_2025 | B33: 应收账龄原值合计 | C33: =(('Facts'!F268*1)+('Facts'!F270*1)+('Facts'!F272*1)+('Facts'!F274*1))*1 | D33: =(('Facts'!F268*1)+('Facts'!F270*1)+('Facts'!F272*1)+('Facts'!F274*1))*1 -> 5.1613498e+09 | E33: =D33/K33 -> 5.1613498e+09 | F33: =IF(ISNUMBER(D33),"calculated","not_calculated") -> calculated | G33: =IF(ISNUMBER(D33),"","检查缺失值、分母与输入；口径变更须重跑Python") | H33: 应收账龄原值合计 | I33: 仅按列明财务口径运算；不单独决定信用等级。 | J33: CNY | K33: 1 | L33: 科顺防水科技股份有限公司 | M33: 合并 | O33: 2025-12-31
A34: ks_a_supplier_sum_2025 | B34: 供应商融资列报加总 | C34: =(('Facts'!F398*1)+('Facts'!F400*1))*1 | D34: =(('Facts'!F398*1)+('Facts'!F400*1))*1 -> 4.6007953e+08 | E34: =D34/K34 -> 4.6007953e+08 | F34: =IF(ISNUMBER(D34),"calculated","not_calculated") -> calculated | G34: =IF(ISNUMBER(D34),"","检查缺失值、分母与输入；口径变更须重跑Python") | H34: 供应商融资列报加总 | I34: 仅按列明财务口径运算；不单独决定信用等级。 | J34: CNY | K34: 1 | L34: 科顺防水科技股份有限公司 | M34: 合并 | O34: 2025-12-31
A35: ks_a_interest_check_2025 | B35: 全部利息减资本化 | C35: =(('Facts'!F358-'Facts'!F360))*1 | D35: =(('Facts'!F358-'Facts'!F360))*1 -> 99603250 | E35: =D35/K35 -> 99603250 | F35: =IF(ISNUMBER(D35),"calculated","not_calculated") -> calculated | G35: =IF(ISNUMBER(D35),"","检查缺失值、分母与输入；口径变更须重跑Python") | H35: 全部利息减资本化 | I35: 仅按列明财务口径运算；不单独决定信用等级。 | J35: CNY | K35: 1 | L35: 科顺防水科技股份有限公司 | M35: 合并 | N35: 2025-01-01 | O35: 2025-12-31
A36: ks_a_grossprofit_2025 | B36: 毛利润 | C36: =(('Facts'!F111-'Facts'!F113))*1 | D36: =(('Facts'!F111-'Facts'!F113))*1 -> 1.4627515e+09 | E36: =D36/K36 -> 1.4627515e+09 | F36: =IF(ISNUMBER(D36),"calculated","not_calculated") -> calculated | G36: =IF(ISNUMBER(D36),"","检查缺失值、分母与输入；口径变更须重跑Python") | H36: 毛利润 | I36: 仅按列明财务口径运算；不单独决定信用等级。 | J36: CNY | K36: 1 | L36: 科顺防水科技股份有限公司 | M36: 合并 | N36: 2025-01-01 | O36: 2025-12-31
A37: ks_a_grossmargin_2025 | B37: 毛利率 | C37: =IF('Facts'!F111<=0,NA(),(('Calculations'!D36/'Facts'!F111))*1) | D37: =IF('Facts'!F111<=0,NA(),(('Calculations'!D36/'Facts'!F111))*1) -> 0.24201213 | E37: =D37/K37 -> 0.24201213 | F37: =IF(ISNUMBER(D37),"calculated","not_calculated") -> calculated | G37: =IF(ISNUMBER(D37),"","检查缺失值、分母与输入；口径变更须重跑Python") | H37: 毛利率 | I37: 仅按列明财务口径运算；不单独决定信用等级。 | J37: % | K37: 1 | L37: 科顺防水科技股份有限公司 | M37: 合并 | N37: 2025-01-01 | O37: 2025-12-31
A38: ks_a_ebit_2025 | B38: 税前利润加费用化利息 | C38: =(('Facts'!F149*1)+('Facts'!F125*1))*1 | D38: =(('Facts'!F149*1)+('Facts'!F125*1))*1 -> -4.9259096e+08 | E38: =D38/K38 -> -4.9259096e+08 | F38: =IF(ISNUMBER(D38),"calculated","not_calculated") -> calculated | G38: =IF(ISNUMBER(D38),"","检查缺失值、分母与输入；口径变更须重跑Python") | H38: 税前利润加费用化利息 | I38: 仅按列明财务口径运算；不单独决定信用等级。 | J38: CNY | K38: 1 | L38: 科顺防水科技股份有限公司 | M38: 合并 | N38: 2025-01-01 | O38: 2025-12-31
A39: ks_a_ebitda_2025 | B39: 会计EBITDA（含减值影响） | C39: =(('Calculations'!D38*1)+('Facts'!F366*1)+('Facts'!F368*1)+('Facts'!F370*1)+('Facts'!F372*1))*1 | D39: =(('Calculations'!D38*1)+('Facts'!F366*1)+('Facts'!F368*1)+('Facts'!F370*1)+('Facts'!F372*1))*1 -> -2.1090943e+08 | E39: =D39/K39 -> -2.1090943e+08 | F39: =IF(ISNUMBER(D39),"calculated","not_calculated") -> calculated | G39: =IF(ISNUMBER(D39),"","检查缺失值、分母与输入；口径变更须重跑Python") | H39: 利润总额+费用化利息+固定/IP折旧+使用权折旧+无形和长期待摊摊销；保留经常信用成本及资产减值，不等同经营现金。 | I39: 仅按列明财务口径运算；不单独决定信用等级。 | J39: CNY | K39: 1 | L39: 科顺防水科技股份有限公司 | M39: 合并 | N39: 2025-01-01 | O39: 2025-12-31
A40: ks_a_debt_2025 | B40: 广义利息债（含全部应付票据） | C40: =(('Facts'!F404*1)+('Facts'!F56*1)+('Facts'!F258*1))*1 | D40: =(('Facts'!F404*1)+('Facts'!F56*1)+('Facts'!F258*1))*1 -> 5.2730528e+09 | E40: =D40/K40 -> 5.2730528e+09 | F40: =IF(ISNUMBER(D40),"calculated","not_calculated") -> calculated | G40: =IF(ISNUMBER(D40),"","检查缺失值、分母与输入；口径变更须重跑Python") | H40: 附注筹资相关负债+全部应付票据+其他应付款借款；租赁和转债账面负债已在筹资小计中；供应商借款已在短借中，AP部分未加入基准债务；不含质量预计负债。 | I40: 仅按列明财务口径运算；不单独决定信用等级。 | J40: CNY | K40: 1 | L40: 科顺防水科技股份有限公司 | M40: 合并 | O40: 2025-12-31
...

Sheet Reconciliations
A1: ID | B1: 勾稽 | C1: 实际 | D1: 目标 | E1: 残差 基础单位 | F1: 容差 基础单位 | G1: 状态 | H1: 容差依据 | I1: 未测试原因 | J1: 金额残差小数位
A2: ks_a_r_currentassets_2025 | B2: 流动资产加总 | C2: ks_a_currentassets_2025 | D2: ks_a_sum_currentassets_2025 | E2: =ROUND('Facts'!F23-'Calculations'!D2,J2) -> 0 | F2: 0.02 | G2: =IF(COUNT(E2,F2)<2,"not_tested",IF(ABS(E2)<=F2,"within_input_tolerance","unexplained_difference")) -> within_input_tolerance | H2: 原件元单位数值重算；差额保留，不设评级准入门槛 | I2: =IF(ISNUMBER(E2),"","missing or unavailable input") | J2: 2
A3: ks_a_r_noncurrentassets_2025 | B3: 非流动资产加总 | C3: ks_a_noncurrentassets_2025 | D3: ks_a_sum_noncurrentassets_2025 | E3: =ROUND('Facts'!F50-'Calculations'!D3,J3) -> 0 | F3: 0.02 | G3: =IF(COUNT(E3,F3)<2,"not_tested",IF(ABS(E3)<=F3,"within_input_tolerance","unexplained_difference")) -> within_input_tolerance | H3: 原件元单位数值重算；差额保留，不设评级准入门槛 | I3: =IF(ISNUMBER(E3),"","missing or unavailable input") | J3: 2
A4: ks_a_r_currentliab_2025 | B4: 流动负债加总 | C4: ks_a_currentliab_2025 | D4: ks_a_sum_currentliab_2025 | E4: =ROUND('Facts'!F72-'Calculations'!D4,J4) -> 0 | F4: 0.02 | G4: =IF(COUNT(E4,F4)<2,"not_tested",IF(ABS(E4)<=F4,"within_input_tolerance","unexplained_difference")) -> within_input_tolerance | H4: 原件元单位数值重算；差额保留，不设评级准入门槛 | I4: =IF(ISNUMBER(E4),"","missing or unavailable input") | J4: 2
A5: ks_a_r_noncurrentliab_2025 | B5: 非流动负债加总 | C5: ks_a_noncurrentliab_2025 | D5: ks_a_sum_noncurrentliab_2025 | E5: =ROUND('Facts'!F86-'Calculations'!D5,J5) -> 0 | F5: 0.02 | G5: =IF(COUNT(E5,F5)<2,"not_tested",IF(ABS(E5)<=F5,"within_input_tolerance","unexplained_difference")) -> within_input_tolerance | H5: 原件元单位数值重算；差额保留，不设评级准入门槛 | I5: =IF(ISNUMBER(E5),"","missing or unavailable input") | J5: 2
A6: ks_a_r_ownerequity_2025 | B6: 归母权益分项加总 | C6: ks_a_ownerequity_2025 | D6: ks_a_sum_ownerequity_2025 | E6: =ROUND('Facts'!F105-'Calculations'!D6,J6) -> 0 | F6: 0.02 | G6: =IF(COUNT(E6,F6)<2,"not_tested",IF(ABS(E6)<=F6,"within_input_tolerance","unexplained_difference")) -> within_input_tolerance | H6: 原件元单位数值重算；差额保留，不设评级准入门槛 | I6: =IF(ISNUMBER(E6),"","missing or unavailable input") | J6: 2
A7: ks_a_r_equity_2025 | B7: 权益归属加总 | C7: ks_a_equity_2025 | D7: ks_a_sum_equity_2025 | E7: =ROUND('Facts'!F109-'Calculations'!D7,J7) -> 0 | F7: 0.02 | G7: =IF(COUNT(E7,F7)<2,"not_tested",IF(ABS(E7)<=F7,"within_input_tolerance","unexplained_difference")) -> within_input_tolerance | H7: 原件元单位数值重算；差额保留，不设评级准入门槛 | I7: =IF(ISNUMBER(E7),"","missing or unavailable input") | J7: 2
A8: ks_a_r_assets_2025 | B8: 资产总额加总 | C8: ks_a_assets_2025 | D8: ks_a_sum_assets_2025 | E8: =ROUND('Facts'!F52-'Calculations'!D8,J8) -> 0 | F8: 0.02 | G8: =IF(COUNT(E8,F8)<2,"not_tested",IF(ABS(E8)<=F8,"within_input_tolerance","unexplained_difference")) -> within_input_tolerance | H8: 原件元单位数值重算；差额保留，不设评级准入门槛 | I8: =IF(ISNUMBER(E8),"","missing or unavailable input") | J8: 2
A9: ks_a_r_liab_2025 | B9: 负债总额加总 | C9: ks_a_liab_2025 | D9: ks_a_sum_liab_2025 | E9: =ROUND('Facts'!F88-'Calculations'!D9,J9) -> 0 | F9: 0.02 | G9: =IF(COUNT(E9,F9)<2,"not_tested",IF(ABS(E9)<=F9,"within_input_tolerance","unexplained_difference")) -> within_input_tolerance | H9: 原件元单位数值重算；差额保留，不设评级准入门槛 | I9: =IF(ISNUMBER(E9),"","missing or unavailable input") | J9: 2
A10: ks_a_r_balance_2025 | B10: 资产等于负债加权益 | C10: ks_a_assets_2025 | D10: ks_a_le_sum_2025 | E10: =ROUND('Facts'!F52-'Calculations'!D10,J10) -> 0 | F10: 0.02 | G10: =IF(COUNT(E10,F10)<2,"not_tested",IF(ABS(E10)<=F10,"within_input_tolerance","unexplained_difference")) -> within_input_tolerance | H10: 原件元单位数值重算；差额保留，不设评级准入门槛 | I10: =IF(ISNUMBER(E10),"","missing or unavailable input") | J10: 2
A11: ks_a_r_totalcost_2025 | B11: 营业总成本重算 | C11: ks_a_totalcost_2025 | D11: ks_a_recalc_totalcost_2025 | E11: =ROUND('Facts'!F129-'Calculations'!D11,J11) -> 0 | F11: 0.02 | G11: =IF(COUNT(E11,F11)<2,"not_tested",IF(ABS(E11)<=F11,"within_input_tolerance","unexplained_difference")) -> within_input_tolerance | H11: 原件元单位数值重算；差额保留，不设评级准入门槛 | I11: =IF(ISNUMBER(E11),"","missing or unavailable input") | J11: 2
A12: ks_a_r_pbt_2025 | B12: 营业利润加营业外净额 | C12: ks_a_pbt_2025 | D12: ks_a_recalc_pbt_2025 | E12: =ROUND('Facts'!F149-'Calculations'!D12,J12) -> 0 | F12: 0.02 | G12: =IF(COUNT(E12,F12)<2,"not_tested",IF(ABS(E12)<=F12,"within_input_tolerance","unexplained_difference")) -> within_input_tolerance | H12: 原件元单位数值重算；差额保留，不设评级准入门槛 | I12: =IF(ISNUMBER(E12),"","missing or unavailable input") | J12: 2
A13: ks_a_r_netincome_2025 | B13: 税前减所得税 | C13: ks_a_netincome_2025 | D13: ks_a_recalc_netincome_2025 | E13: =ROUND('Facts'!F153-'Calculations'!D13,J13) -> 0 | F13: 0.02 | G13: =IF(COUNT(E13,F13)<2,"not_tested",IF(ABS(E13)<=F13,"within_input_tolerance","unexplained_difference")) -> within_input_tolerance | H13: 原件元单位数值重算；差额保留，不设评级准入门槛 | I13: =IF(ISNUMBER(E13),"","missing or unavailable input") | J13: 2
A14: ks_a_r_ci_2025 | B14: 综合收益重算 | C14: ks_a_ci_2025 | D14: ks_a_recalc_ci_2025 | E14: =ROUND('Facts'!F161-'Calculations'!D14,J14) -> 0 | F14: 0.02 | G14: =IF(COUNT(E14,F14)<2,"not_tested",IF(ABS(E14)<=F14,"within_input_tolerance","unexplained_difference")) -> within_input_tolerance | H14: 原件元单位数值重算；差额保留，不设评级准入门槛 | I14: =IF(ISNUMBER(E14),"","missing or unavailable input") | J14: 2
A15: ks_a_r_opcashin_2025 | B15: 经营现金流入重算 | C15: ks_a_opcashin_2025 | D15: ks_a_recalc_opcashin_2025 | E15: =ROUND('Facts'!F169-'Calculations'!D15,J15) -> 0 | F15: 0.02 | G15: =IF(COUNT(E15,F15)<2,"not_tested",IF(ABS(E15)<=F15,"within_input_tolerance","unexplained_difference")) -> within_input_tolerance | H15: 原件元单位数值重算；差额保留，不设评级准入门槛 | I15: =IF(ISNUMBER(E15),"","missing or unavailable input") | J15: 2
A16: ks_a_r_opcashout_2025 | B16: 经营现金流出重算 | C16: ks_a_opcashout_2025 | D16: ks_a_recalc_opcashout_2025 | E16: =ROUND('Facts'!F179-'Calculations'!D16,J16) -> 0 | F16: 0.02 | G16: =IF(COUNT(E16,F16)<2,"not_tested",IF(ABS(E16)<=F16,"within_input_tolerance","unexplained_difference")) -> within_input_tolerance | H16: 原件元单位数值重算；差额保留，不设评级准入门槛 | I16: =IF(ISNUMBER(E16),"","missing or unavailable input") | J16: 2
A17: ks_a_r_cfo_2025 | B17: 直接法经营净现金 | C17: ks_a_cfo_2025 | D17: ks_a_recalc_cfo_2025 | E17: =ROUND('Facts'!F181-'Calculations'!D17,J17) -> 0 | F17: 0.02 | G17: =IF(COUNT(E17,F17)<2,"not_tested",IF(ABS(E17)<=F17,"within_input_tolerance","unexplained_difference")) -> within_input_tolerance | H17: 原件元单位数值重算；差额保留，不设评级准入门槛 | I17: =IF(ISNUMBER(E17),"","missing or unavailable input") | J17: 2
A18: ks_a_r_cfi_2025 | B18: 投资净现金 | C18: ks_a_cfi_2025 | D18: ks_a_recalc_cfi_2025 | E18: =ROUND('Facts'!F204-'Calculations'!D18,J18) -> 0 | F18: 0.02 | G18: =IF(COUNT(E18,F18)<2,"not_tested",IF(ABS(E18)<=F18,"within_input_tolerance","unexplained_difference")) -> within_input_tolerance | H18: 原件元单位数值重算；差额保留，不设评级准入门槛 | I18: =IF(ISNUMBER(E18),"","missing or unavailable input") | J18: 2
A19: ks_a_r_cff_2025 | B19: 筹资净现金 | C19: ks_a_cff_2025 | D19: ks_a_recalc_cff_2025 | E19: =ROUND('Facts'!F222-'Calculations'!D19,J19) -> 0 | F19: 0.02 | G19: =IF(COUNT(E19,F19)<2,"not_tested",IF(ABS(E19)<=F19,"within_input_tolerance","unexplained_difference")) -> within_input_tolerance | H19: 原件元单位数值重算；差额保留，不设评级准入门槛 | I19: =IF(ISNUMBER(E19),"","missing or unavailable input") | J19: 2
A20: ks_a_r_cashdelta_2025 | B20: 现金三类活动加汇率 | C20: ks_a_cashdelta_2025 | D20: ks_a_recalc_cashdelta_2025 | E20: =ROUND('Facts'!F226-'Calculations'!D20,J20) -> 0 | F20: 0.02 | G20: =IF(COUNT(E20,F20)<2,"not_tested",IF(ABS(E20)<=F20,"within_input_tolerance","unexplained_difference")) -> within_input_tolerance | H20: 原件元单位数值重算；差额保留，不设评级准入门槛 | I20: =IF(ISNUMBER(E20),"","missing or unavailable input") | J20: 2
A21: ks_a_r_plattrib_2025 | B21: 净利归属 | C21: ks_a_netincome_2025 | D21: ks_a_plattrib_2025 | E21: =ROUND('Facts'!F153-'Calculations'!D21,J21) -> 0 | F21: 0.02 | G21: =IF(COUNT(E21,F21)<2,"not_tested",IF(ABS(E21)<=F21,"within_input_tolerance","unexplained_difference")) -> within_input_tolerance | H21: 原件元单位数值重算；差额保留，不设评级准入门槛 | I21: =IF(ISNUMBER(E21),"","missing or unavailable input") | J21: 2
A22: ks_a_r_opprofit_2025 | B22: 营业利润 | C22: ks_a_opprofit_2025 | D22: ks_a_calc_opprofit_2025 | E22: =ROUND('Facts'!F143-'Calculations'!D22,J22) -> 0 | F22: 0.02 | G22: =IF(COUNT(E22,F22)<2,"not_tested",IF(ABS(E22)<=F22,"within_input_tolerance","unexplained_difference")) -> within_input_tolerance | H22: 原件元单位数值重算；差额保留，不设评级准入门槛 | I22: =IF(ISNUMBER(E22),"","missing or unavailable input") | J22: 2
A23: ks_a_r_cash_2025 | B23: 现金滚动 | C23: ks_a_cash_2025 | D23: ks_a_cashbridge_2025 | E23: =ROUND('Facts'!F228-'Calculations'!D23,J23) -> 0 | F23: 0.02 | G23: =IF(COUNT(E23,F23)<2,"not_tested",IF(ABS(E23)<=F23,"within_input_tolerance","unexplained_difference")) -> within_input_tolerance | H23: 原件元单位数值重算；差额保留，不设评级准入门槛 | I23: =IF(ISNUMBER(E23),"","missing or unavailable input") | J23: 2
A24: ks_a_r_cashbook_2025 | B24: 现金与账面资金 | C24: ks_a_cashbook_2025 | D24: ks_a_cashrestrict_2025 | E24: =ROUND('Facts'!F2-'Calculations'!D24,J24) -> 0 | F24: 0.02 | G24: =IF(COUNT(E24,F24)<2,"not_tested",IF(ABS(E24)<=F24,"within_input_tolerance","unexplained_difference")) -> within_input_tolerance | H24: 原件元单位数值重算；差额保留，不设评级准入门槛 | I24: =IF(ISNUMBER(E24),"","missing or unavailable input") | J24: 2
A25: ks_a_r_restrictdetail_2025 | B25: 受限资金明细 | C25: ks_a_restrictedcash_2025 | D25: ks_a_restrictdetail_2025 | E25: =ROUND('Facts'!F230-'Calculations'!D25,J25) -> 0 | F25: 0.02 | G25: =IF(COUNT(E25,F25)<2,"not_tested",IF(ABS(E25)<=F25,"within_input_tolerance","unexplained_difference")) -> within_input_tolerance | H25: 原件元单位数值重算；差额保留，不设评级准入门槛 | I25: =IF(ISNUMBER(E25),"","missing or unavailable input") | J25: 2
A26: ks_a_r_indirect_cfo_2025 | B26: 间接法经营现金 | C26: ks_a_cfo_2025 | D26: ks_a_indirect_cfo_2025 | E26: =ROUND('Facts'!F181-'Calculations'!D26,J26) -> 0 | F26: 0.02 | G26: =IF(COUNT(E26,F26)<2,"not_tested",IF(ABS(E26)<=F26,"within_input_tolerance","unexplained_difference")) -> within_input_tolerance | H26: 原件元单位数值重算；差额保留，不设评级准入门槛 | I26: =IF(ISNUMBER(E26),"","missing or unavailable input") | J26: 2
A27: ks_a_r_ar_netcalc_2025 | B27: ar净额 | C27: ks_a_ar_2025 | D27: ks_a_ar_netcalc_2025 | E27: =ROUND('Facts'!F8-'Calculations'!D27,J27) -> 0 | F27: 0.02 | G27: =IF(COUNT(E27,F27)<2,"not_tested",IF(ABS(E27)<=F27,"within_input_tolerance","unexplained_difference")) -> within_input_tolerance | H27: 原件元单位数值重算；差额保留，不设评级准入门槛 | I27: =IF(ISNUMBER(E27),"","missing or unavailable input") | J27: 2
A28: ks_a_r_otherar_netcalc_2025 | B28: otherar净额 | C28: ks_a_otherar_2025 | D28: ks_a_otherar_netcalc_2025 | E28: =ROUND('Facts'!F14-'Calculations'!D28,J28) -> 0 | F28: 0.02 | G28: =IF(COUNT(E28,F28)<2,"not_tested",IF(ABS(E28)<=F28,"within_input_tolerance","unexplained_difference")) -> within_input_tolerance | H28: 原件元单位数值重算；差额保留，不设评级准入门槛 | I28: =IF(ISNUMBER(E28),"","missing or unavailable input") | J28: 2
A29: ks_a_r_inventory_netcalc_2025 | B29: inventory净额 | C29: ks_a_inventory_2025 | D29: ks_a_inventory_netcalc_2025 | E29: =ROUND('Facts'!F16-'Calculations'!D29,J29) -> 0 | F29: 0.02 | G29: =IF(COUNT(E29,F29)<2,"not_tested",IF(ABS(E29)<=F29,"within_input_tolerance","unexplained_difference")) -> within_input_tolerance | H29: 原件元单位数值重算；差额保留，不设评级准入门槛 | I29: =IF(ISNUMBER(E29),"","missing or unavailable input") | J29: 2
A30: ks_a_r_contract_netcalc_2025 | B30: contract净额 | C30: ks_a_contract_2025 | D30: ks_a_contract_netcalc_2025 | E30: =ROUND('Facts'!F18-'Calculations'!D30,J30) -> 0 | F30: 0.02 | G30: =IF(COUNT(E30,F30)<2,"not_tested",IF(ABS(E30)<=F30,"within_input_tolerance","unexplained_difference")) -> within_input_tolerance | H30: 原件元单位数值重算；差额保留，不设评级准入门槛 | I30: =IF(ISNUMBER(E30),"","missing or unavailable input") | J30: 2
A31: ks_a_r_longcontract_netcalc_2025 | B31: longcontract净额 | C31: ks_a_longcontract_2025 | D31: ks_a_longcontract_netcalc_2025 | E31: =ROUND('Facts'!F298-'Calculations'!D31,J31) -> 0 | F31: 0.02 | G31: =IF(COUNT(E31,F31)<2,"not_tested",IF(ABS(E31)<=F31,"within_input_tolerance","unexplained_difference")) -> within_input_tolerance | H31: 原件元单位数值重算；差额保留，不设评级准入门槛 | I31: =IF(ISNUMBER(E31),"","missing or unavailable input") | J31: 2
A32: ks_a_r_propertynet_netcalc_2025 | B32: propertynet净额 | C32: ks_a_propertynet_2025 | D32: ks_a_propertynet_netcalc_2025 | E32: =ROUND('Facts'!F320-'Calculations'!D32,J32) -> 0 | F32: 0.02 | G32: =IF(COUNT(E32,F32)<2,"not_tested",IF(ABS(E32)<=F32,"within_input_tolerance","unexplained_difference")) -> within_input_tolerance | H32: 原件元单位数值重算；差额保留，不设评级准入门槛 | I32: =IF(ISNUMBER(E32),"","missing or unavailable input") | J32: 2
A33: ks_a_r_arge_2025 | B33: 应收账龄 | C33: ks_a_argross_2025 | D33: ks_a_arge_sum_2025 | E33: =ROUND('Facts'!F264-'Calculations'!D33,J33) -> 0 | F33: 0.02 | G33: =IF(COUNT(E33,F33)<2,"not_tested",IF(ABS(E33)<=F33,"within_input_tolerance","unexplained_difference")) -> within_input_tolerance | H33: 原件元单位数值重算；差额保留，不设评级准入门槛 | I33: =IF(ISNUMBER(E33),"","missing or unavailable input") | J33: 2
A34: ks_a_r_supplier_sum_2025 | B34: 供应商融资分类 | C34: ks_a_supplierfinance_2025 | D34: ks_a_supplier_sum_2025 | E34: =ROUND('Facts'!F396-'Calculations'!D34,J34) -> 0 | F34: 0.02 | G34: =IF(COUNT(E34,F34)<2,"not_tested",IF(ABS(E34)<=F34,"within_input_tolerance","unexplained_difference")) -> within_input_tolerance | H34: 原件元单位数值重算；差额保留，不设评级准入门槛 | I34: =IF(ISNUMBER(E34),"","missing or unavailable input") | J34: 2
A35: ks_a_r_interest_2025 | B35: 利息费用勾稽 | C35: ks_a_interest_exp_2025 | D35: ks_a_interest_check_2025 | E35: =ROUND('Facts'!F125-'Calculations'!D35,J35) -> 0 | F35: 0.02 | G35: =IF(COUNT(E35,F35)<2,"not_tested",IF(ABS(E35)<=F35,"within_input_tolerance","unexplained_difference")) -> within_input_tolerance | H35: 原件元单位数值重算；差额保留，不设评级准入门槛 | I35: =IF(ISNUMBER(E35),"","missing or unavailable input") | J35: 2
A36: ks_a_r_productrev_2025 | B36: 产品收入勾稽 | C36: ks_a_revenue_2025 | D36: ks_a_product_rev_2025 | E36: =ROUND('Facts'!F111-'Calculations'!D68,J36) -> 0 | F36: 0.02 | G36: =IF(COUNT(E36,F36)<2,"not_tested",IF(ABS(E36)<=F36,"within_input_tolerance","unexplained_difference")) -> within_input_tolerance | H36: 原件元单位数值重算；差额保留，不设评级准入门槛 | I36: =IF(ISNUMBER(E36),"","missing or unavailable input") | J36: 2
A37: ks_a_r_productcost_2025 | B37: 产品成本勾稽 | C37: ks_a_cost_2025 | D37: ks_a_product_cost_2025 | E37: =ROUND('Facts'!F113-'Calculations'!D69,J37) -> 0 | F37: 0.02 | G37: =IF(COUNT(E37,F37)<2,"not_tested",IF(ABS(E37)<=F37,"within_input_tolerance","unexplained_difference")) -> within_input_tolerance | H37: 原件元单位数值重算；差额保留，不设评级准入门槛 | I37: =IF(ISNUMBER(E37),"","missing or unavailable input") | J37: 2
A38: ks_a_r_currentassets_2024 | B38: 流动资产加总 | C38: ks_a_currentassets_2024 | D38: ks_a_sum_currentassets_2024 | E38: =ROUND('Facts'!F24-'Calculations'!D70,J38) -> 0 | F38: 0.02 | G38: =IF(COUNT(E38,F38)<2,"not_tested",IF(ABS(E38)<=F38,"within_input_tolerance","unexplained_difference")) -> within_input_tolerance | H38: 原件元单位数值重算；差额保留，不设评级准入门槛 | I38: =IF(ISNUMBER(E38),"","missing or unavailable input") | J38: 2
A39: ks_a_r_noncurrentassets_2024 | B39: 非流动资产加总 | C39: ks_a_noncurrentassets_2024 | D39: ks_a_sum_noncurrentassets_2024 | E39: =ROUND('Facts'!F51-'Calculations'!D71,J39) -> 0 | F39: 0.02 | G39: =IF(COUNT(E39,F39)<2,"not_tested",IF(ABS(E39)<=F39,"within_input_tolerance","unexplained_difference")) -> within_input_tolerance | H39: 原件元单位数值重算；差额保留，不设评级准入门槛 | I39: =IF(ISNUMBER(E39),"","missing or unavailable input") | J39: 2
A40: ks_a_r_currentliab_2024 | B40: 流动负债加总 | C40: ks_a_currentliab_2024 | D40: ks_a_sum_currentliab_2024 | E40: =ROUND('Facts'!F73-'Calculations'!D72,J40) -> 0 | F40: 0.02 | G40: =IF(COUNT(E40,F40)<2,"not_tested",IF(ABS(E40)<=F40,"within_input_tolerance","unexplained_difference")) -> within_input_tolerance | H40: 原件元单位数值重算；差额保留，不设评级准入门槛 | I40: =IF(ISNUMBER(E40),"","missing or unavailable input") | J40: 2
...

Sheet Sources
A1: ID | B1: 文件 | C1: 链接 | D1: 公布日期 | E1: SHA256 | F1: 时间证据与限制
A2: ks_a_s_25 | B2: 科顺防水科技股份有限公司2025年年度报告 | C2: https://disc.static.szse.cn/disc/disk03/finalpage/2026-04-24/8d1711bc-c88b-410a-8b72-7bae6b960a12.PDF | D2: 2026-04-24 | E2: a28e4d8699b586369812b69cd2aa8f027369b7b916c6477d67646f7ecd7fb66d | F2: 公开披露日不晚于研究截止日；原件按本来源URL和SHA256定位
A3: ks_a_s_24 | B3: 科顺防水科技股份有限公司2024年年度报告 | C3: https://static.cninfo.com.cn/finalpage/2025-04-25/1223275058.PDF | D3: 2025-04-25 | E3: 81f75b4c75f7ea2f474099b81ae59671bc94101fe1c314def82c888b77eaa31e | F3: 公开披露日不晚于研究截止日；原件按本来源URL和SHA256定位
A4: ks_a_s_q1 | B4: 科顺防水科技股份有限公司2026年第一季度报告 | C4: https://static.cninfo.com.cn/finalpage/2026-04-24/1225172706.PDF | D4: 2026-04-24 | E4: ec88c2b30e216c8ebeff8eba54c49391a16aab6b5bbcecd6260fa8b817f804ba | F4: 公开披露日不晚于研究截止日；原件按本来源URL和SHA256定位
A5: ks_a_s_control_audit | B5: 科顺防水科技股份有限公司2025年度内部控制审计报告 | C5: https://static.cninfo.com.cn/finalpage/2026-04-24/1225172719.PDF | D5: 2026-04-24 | E5: 0ddd1290e9f1b417cd7bb6b1b136ef3cd3b7abbfb2b921202b9a9a207d80ac03 | F5: 公开披露日不晚于研究截止日；原件按本来源URL和SHA256定位
A6: ks_a_s_control_self | B6: 科顺防水科技股份有限公司2025年度内部控制自我评价报告 | C6: https://static.cninfo.com.cn/finalpage/2026-04-24/1225172718.PDF | D6: 2026-04-24 | E6: 36597e1cf4286729b58b0e3d8492762b56f58af0e34c191b7e622810630cc260 | F6: 公开披露日不晚于研究截止日；原件按本来源URL和SHA256定位
A7: ks_a_s_policy | B7: 科顺防水科技股份有限公司关于会计政策变更的公告 | C7: https://static.cninfo.com.cn/finalpage/2026-04-24/1225172716.PDF | D7: 2026-04-24 | E7: 9ca4890618d7cfcd6a1c434a534e3571d2a404fcd10941abb53f0de3bd7f8bc1 | F7: 公开披露日不晚于研究截止日；原件按本来源URL和SHA256定位
A8: ks_a_s_proceeds | B8: 科顺防水科技股份有限公司募集资金2025年度存放、管理与使用情况鉴证报告 | C8: https://static.cninfo.com.cn/finalpage/2026-04-24/1225172703.PDF | D8: 2026-04-24 | E8: 6a7ec3339b37ee7b814ebee09922d2a685373c2a1902bbd2bd62e058ca655c4f | F8: 公开披露日不晚于研究截止日；原件按本来源URL和SHA256定位
A9: ks_a_s_return26 | B9: 关于归还暂时用于补充流动资金的闲置募集资金的公告（2026-002） | C9: https://static.cninfo.com.cn/finalpage/2026-01-06/1224921562.PDF | D9: 2026-01-06 | E9: 68b6fc95fc64d13f76cbdaa7ce1c7ca34bcf7f45180fe28c341154c4addd6828 | F9: 公开披露日不晚于研究截止日；原件按本来源URL和SHA256定位
A10: ks_a_s_renew26 | B10: 关于使用部分闲置募集资金暂时补充流动资金的公告（2026-006） | C10: https://static.cninfo.com.cn/finalpage/2026-01-09/1224927241.PDF | D10: 2026-01-09 | E10: 9e482f617a1097007b92a876ead8af540221bf03c15ba94db0955d795cc815cf | F10: 公开披露日不晚于研究截止日；原件按本来源URL和SHA256定位
A11: ks_b_s03 | B11: 联合资信一般工商企业信用评级方法与模型V4.1.202606 | C11: https://www.lhratings.com/file/8622bc88-5377-4572-8c93-afc6d796339d.pdf | D11: 2026-06-09 | E11: 958d18f68933123770332153692406ceca1e111e76edacce16043c9d5489cb43 | F11: 公开/可得时间依据：2026-06-09；已读：PDF27–29原图（印刷26–28）；限制：最终已按同原件及公开目录核实日期，见ks_r_method；仅因素定义、营业收入区间及净营业周期公式，非发行人既有评级/因素值
A12: ks_b_s04 | B12: 东方雨虹2025年年度报告 | C12: https://static.cninfo.com.cn/finalpage/2026-04-17/1225114217.PDF | D12: 2026-04-17 | E12: 2acc7211e677a62512a68bda6687e2cb5d5cf79cc5ff3652848c108740c9244d | F12: 公开/可得时间依据：2026-04-17；已读：PDF10–12、27–31；图像复核29；限制：材料/施工/砂浆和多元业务并存；不以合并收入推防水份额，不采用机构评价；同行财务比较另已核读PDF页：7, 142, 143, 144, 146, 147, 148, 150, 151, 152, 199, 217, 218, 219, 220, 231, 232, 233, 234, 235, 236, 237, 238, 239, 242, 247, 248, 249, 250, 253, 254, 255
... A33: ks_d_s_l4 | B33: 中国证监会决定修改的规范性文件（2025年汇编，含修订后的上市公司监管指引第4号） | C33: https://www.csrc.gov.cn/csrc/c101954/c7547906/7547906/files/%E9%99%84%E4%BB%B61-1%EF%BC%9A%E4%B8%AD%E5%9B%BD%E8%AF%81%E7%9B%91%E4%BC%9A%E5%86%B3%E5%AE%9A%E4%BF%AE%E6%94%B9%E7%9A%84%E8%A7%84%E8%8C%83%E6%80%A7%E6%96%87%E4%BB%B6.pdf | D33: 2025-03-27 | E33: 2ceadc064ff390d8b53cbf5f24cdf7757ec0794c77639d09f46a7b243bd9e540 | F33: 正文已取得并实读；页码均为 PDF 物理页，从 1 开始。 原件按本来源URL和SHA256定位。
A34: ks_d_s_l1 | B34: 证券期货法律适用意见第18号（2023年发行时原文） | C34: https://www.csrc.gov.cn/csrc/c101954/c7122002/7122002/files/%E9%99%84%E4%BB%B61%EF%BC%9A%EF%BC%88%E5%86%8D%E8%9E%8D%E8%B5%84%EF%BC%89%E8%AF%81%E5%88%B8%E6%9C%9F%E8%B4%A7%E6%B3%95%E5%BE%8B%E9%80%82%E7%94%A8%E6%84%8F%E8%A7%81%E7%AC%AC18%E5%8F%B7.pdf | D34: 2023-02-17 | F34: 官方原文已在线阅读，仅使用已实读的第六至七页；本地原件未保存，未编造 SHA256。 仅用于发行时适用的发行条件口径背景，不视为对存续承诺的专门解释；后续修订附件未取得。
A35: ks_r_method | B35: 联合资信一般工商企业信用评级方法与模型V4.1.202606 | C35: https://www.lhratings.com/file/8622bc88-5377-4572-8c93-afc6d796339d.pdf | D35: 2026-06-09 | E35: 958d18f68933123770332153692406ceca1e111e76edacce16043c9d5489cb43 | F35: 公开目录及正文确认发布即生效。原件PDF2–33已有逐页视觉研究；原文参数与本案研究选择分别记录。
A36: ks_r_principles | B36: 联合资信企业信用评级方法总论V4.1.202605 | C36: https://www.lhratings.com/file/57da1b35-2001-44e0-9505-8f33baebef39.pdf | D36: 2026-05-29 | E36: fd1ddb7792082570d7b97936c70449d5c14809b34f0d6325cb385a5ced339ad7 | F36: 全文16页已作视觉研究，专业判断许可不等于本案取得该机构批准。
A37: ks_r_support | B37: 联合资信外部支持评估方法V4.1.202605 | C37: https://www.lhratings.com/file/2c5877a1-7aca-42c5-b0b9-6cfd0fc0e9bd.pdf | D37: 2026-05-29 | E37: ddcffdf8a749d30f710ae746cad109a7835ec4dec4c8c19883cd689fd4378095 | F37: 全文10页已作视觉研究；政府路径与企业法人股东路径分别判断。
A38: ks_r_issue | B38: 联合资信债项评级基本方法V3.0.202207 | C38: https://www.lhratings.com/file/461ba035-33a2-4901-a0da-72c52a66766a.pdf | D38: 未核验 | E38: 59610c3278c76fe471adcdc0fca8292cf9f5cddf032830145d1e56dbc5ca5fe4 | F38: 封面2022年7月，正文明确2022-08-01起施行；精确首次公布日未另证，适用时间早于本案截止日。全文10页文本已读。
A39: ks_r_application | B39: 2026科顺跟踪报告的方法适用性与通用等级定义页 | C39: https://www.lhratings.com/reports/B010330-P61284-2021-GZ2026.pdf | D39: 2026-06-23 | E39: 846ba87096506c375195e9d1fe772781316c30a5f3e54239d54b31faea4fec41 | F39: 仅使用PDF6、8的方法适用性及23的通用等级/展望定义。发行人既有等级、机构因素得分和预测未作本案输入或校准目标。

Sheet Evidence
A1: ID | B1: 来源 | C1: 定位 | D1: 观察 | E1: 可靠性与限制
A2: ks_a_e_coverage | B2: ks_a_s_25 | C2: PDF页码与印刷页码一致 | D2: 文本实际覆盖第1—92、97—245页；不使用第93—96页。选定表格46页提取矩阵；视觉读第114、119、125、128、185、208、209、210页；其余为文本及矩阵核读。2024补充只读第10、116—124、127—130、164、184、191、192、194、195、203、208—210页，未声称阅读全文。2026Q1全部12页文本已读。内控审计4页、自评11页、政策变更2页全部文本已读；募集资金鉴证11页，其中第10、11页为扫描图视觉阅读。 追加独立视觉复读2025第168页、2024第210页；补流归还及续作公告全部2页和6页已读。 2024年报第126、131—134页后续补读，含原2023合并权益变动表。 | E2: 覆盖记录，阅读范围可由抽取文件及实际源页追溯；非审计保证
A3: ks_a_e_summary | B3: ks_a_s_25 | C3: 第10—12页，主要会计数据（元），2025/2024调整前后/2023调整前后及分季度指标 | D3: 摘要因同一控制下收购横琴逸东公司调整往年；列示2023重述后收入、归母净利、扣非净利、CFO、资产及归母权益，不列全部四表。 | E3: 发行人正式披露；财务报表经审计，但本分析未复做审计程序
A4: ks_a_e_bs | B4: ks_a_s_25 | C4: 第102—105页，合并资产负债表，单位元，列2025-12-31及2025-01-01 | D4: 主表资产、负债、权益及流动/非流动项目；期初为同控重述。空白项目未机械当零。 | E4: 发行人正式披露；财务报表经审计，但本分析未复做审计程序
A5: ks_a_e_parent | B5: ks_a_s_25 | C5: 第105—107、109—113、125—131及242页，母公司四表与追溯权益说明，单位元 | D5: 母公司利润及现金含子公司分红和集团往来；母公司2025权益表期初另有权益法追溯调整，和资产负债表期初需分开。 | E5: 发行人正式披露；财务报表经审计，但本分析未复做审计程序
A6: ks_a_e_is | B6: ks_a_s_25 | C6: 第107—109页，合并利润表，单位元，2025年度/2024年度 | D6: 成本费用、减值、投资及公允价值、税项和损益归属均按原符号保留。 | E6: 发行人正式披露；财务报表经审计，但本分析未复做审计程序
A7: ks_a_e_cf | B7: ks_a_s_25 | C7: 第111—113页，合并现金流量表，单位元，2025年度/2024年度 | D7: 直接法经营、投资、筹资、汇率影响及现金期初期末；不是资产负债表货币资金总额。 | E7: 发行人正式披露；财务报表经审计，但本分析未复做审计程序
A8: ks_a_e_equity | B8: ks_a_s_25 | C8: 第114—124页，合并所有者权益变动表，单位元 | D8: 本年期初、综合收益、所有者投入、分配、专项储备及其他滚动；同控对期初比较及资本公积的影响需分栏。 | E8: 发行人正式披露；财务报表经审计，但本分析未复做审计程序
A9: ks_a_e_policies | B9: ks_a_s_25 | C9: 第132—162页，编制基础、合并及各项会计政策/重要估计、税项 | D9: 持续经营基础；收入按交付验收/交承运人/报关/客户确认工程量等具体业务确认；应收及合同资产预期信用损失；存货成本与可变现净值孰低；固定资产和投资性房地产折旧、长期资产减值；研发全部费用化；租赁表内确认；安全生产专项储备；所得税分主体适用优惠。2025无重要会计政策或估计变更。 | E9: 发行人正式披露；财务报表经审计，但本分析未复做审计程序
A10: ks_a_e_audit | B10: ks_a_s_25 | C10: 第97—101页，审计报告 | D10: 致同出具无保留意见；收入确认，以及应收账款、合同资产和其他非流动资产中的合同资产减值这两项关键审计事项的审计程序由审计师实施，不作为本分析已实施程序。审计意见不保证无任何错报或未来偿债。 | E10: 发行人正式披露；财务报表经审计，但本分析未复做审计程序
A11: ks_a_e_cash | B11: ks_a_s_25 | C11: 第162—164、190—191、209—210页，货币资金/受限资产/现金等价物 | D11: 现金等价物排除定存质押、票据及保函保证金、冻结、专户等；需区分账面货币资金、报表可随时支付现金及经济上无用途约束现金。 | E11: 发行人正式披露；财务报表经审计，但本分析未复做审计程序
A12: ks_a_e_ar | B12: ks_a_s_25 | C12: 第165—168页，应收账款，单位元；账龄、单项与组合及准备滚动 | D12: 应收账款账龄延长，单项信用减值与组合按不同方法；本年坏账核销与非现金抵债影响净额变化，净额下降不能直接视为现金回收。 | E12: 发行人正式披露；财务报表经审计，但本分析未复做审计程序
... A162: ks_r_e_bond_buckets | B162: ks_a_s_25 | C162: 2025年报PDF218，未折现剩余合同现金流表；期末余额，应付债券行，原单位万元；列为一年以内/一至三年/三年以上/合计。 | D162: 原页图像复核四列为1098.92、5494.62、256706.51、263300.05；按2025末面值及合同票息另作不转股条件比较，保留不同假设或列报口径的可能性。 | E162: 正式原件明示的期限表；未取得计算假设或发行人解释，不直接判错报。

Sheet Findings
A1: ID | B1: 问题 | C1: 结论 | D1: 机制 | E1: 状态 | F1: 依据 | G1: 反证 | H1: 其他解释 | I1: 改变结论条件
A2: ks_r_recommendation | B2: 所选境内方法下，证据如何形成具体建议？ | C2: 以信息截止日的公开证据和明示判断，基准建议主体及科顺转债为BBB+、负面展望。经营C、财务F4的指示单元格为a-/bbb+，选择bbb+；不计可证实的额外支持增益，普通无担保直接债项暂同级。建议以常态融资渠道仍运行、未证实到期不支付，且实际付款日前资金与用途安排足以覆盖为条件。母公司可调度资金和持续承诺后果未核实，不能作为无条件正式评级发布。 | D2: 环境3.25 分、自身竞争力3.78 分，财务主方案4.17 分；先权金额为3.74 分仍属F4。选较弱端基于最新负EBITDA、母公司负经营现金、第四季回款依赖及资金用途约束；已进基础因素的弱项不重复扣档。 | E2: conditional | F2: ks_r_e_business, ks_r_e_finance, ks_r_e_matrix, ks_a_ebitda_2025, ks_d_c_book_ratio | G2: ks_a_e_q1, ks_a_e_control | H2: 区间代表值和历史适配具有判断空间；可比三年数据或可靠前瞻可能改变档位。 无保留审计及季度盈利、银行新增借款支持持续经营，但不能单独排除现金或合同限制。 | I2: 若更新事实使经营D、财务仍F4，研究分支为BB+；经营C而财务F5为BBB-；两者同时恶化为BB。若证实近期无法按约付款，立即退出上述常态分支，不能只保留负面展望。
A3: ks_r_liquidity | B3: 年末正现金是否掩盖更早缺口？ | C3: 从三月末实际集团现金接续的无新增融资模型中，基准季度低点1.44 亿元人民币，恶化低点-3.38 亿元人民币；基准再少收4.88%客户现金即触及季度末零现金。基准另预留用途资金后低点-5.06 亿元人民币。这些是条件值，不能替代六月实际数或月内、母公司支付证明。 | D3: 经营采购和票据结算在CFO内只扣一次；融资本金和现金利息另扣，未把非现金AP转借款再扣为现金。募集金恢复用途是现金限制敏感性，不是新增外部债本金。负数后续行只显示未融资缺口，晚收款不能抹去先前支付失败。 | E3: conditional | F3: ks_d_l_e_cash_actual, ks_d_l_e_season, ks_r_base_cash_min, ks_r_worse_cash_min | G3: ks_a_e_q1, ks_a_e_maturity | H3: 银行续贷、资产变现或真实现金上划可能补足缺口，但须有可执行额度、条件和时点。 实际采购、建设支出或回款季节性可能不同于研究假设，需用实际付款台账替换。 | I3: 若现金短缺由已落实融资或可合法延后支出覆盖，重跑现金表并判断是否足以维持BBB+；若缺口在已核实付款日仍存在，先确认具体偿付事件并重定主体及受影响债项。
A4: ks_r_parent_risk | B4: 母公司怎样实际取得偿债资源？ | C4: 母公司年末现金减短借及一年内非流动账面代理后余量1.05 亿元人民币，不能证明完整短期覆盖；与固定本金未来到期价的静态差额为-12.24 亿元人民币。后者说明未来需产现、上划或融资的量级，并非债券在本年到期或已经发生缺口。缺一季末母公司表，集团一季现金不替代。 | D4: 发行人自身经营现金为负，投资收益现金不等于每年可重复的全部子公司分红。集团内票据及往来在合并层抵销，但现金移转仍依赖对手现金、合法决策、少数股东权益、融资约束和实际到账。 | E4: conditional | F4: ks_a_e_parent, ks_r_parent_screen, ks_r_parent_maturity_gap | G4: ks_d_l_f_parent_investment_cash, ks_a_e_equity | H4: 子公司分红或往来回收能改善母公司资金，但不能按合并余额自动推算。 债券未来转换可能降低现金本金，须等真实转股事实确认，不能预先免偿。 | I4: 取得主要子公司的可分配现金、债务和用途限制、上划决议及实际到账后，重建发行人月度来源用途；若可上划路径受阻且本部不足，主体与直接债项结论须同步下调。
A5: ks_r_support_assessment | B5: 哪些支持能力与意愿证据能够改变独立信用？ | C5: 基准不计额外支持增益。自然人控制及对特定银行义务的保证未证明本债或全部偿债需要有及时支持；普通政府补助未证明困难时救助。该选择是现有证据下的研究处理，不是“民企无支持”或未来不会支持的事实判断。 | D5: 政府路径分别核持股/控制、地方重要性、违约声誉影响、成本收益和支持历史：已知自然人控制、可替代竞争及普通补助，未识别具体救助方、独立财力及承诺。企业法人股东分支不能机械套自然人；个人保证有具体对象和财力限制。支持可能性不能与能力分开，也不能把多项潜在支持累加。 | E5: conditional | F5: ks_r_e_support, ks_b_e_ownership, ks_a_e_related | G5: ks_a_e_related, ks_a_e_post | H5: 地方就业、技术或项目重要性可能增加协助意愿，但需具体规模和可执行资金支持。 股东可投入资金，但股权质押、已有保证和未核个人资源使支持额度未定。 | I5: 取得具体支持方独立偿债能力、合法决策、覆盖义务、付款触发及到账时间，再按同一支持方法重做提升；不把普通授信或既有补助重新加成一档。
