Workbook

Sheet Overview
A1: 项目 | B1: 内容 | C1: 证据
A2: 贵州茅台酒股份有限公司 | B2: 600519.SH | A-share | CAS | consolidated | 2024-12-31 | CNY | 亿元
A3: 数值精度 | B3: Excel数值使用浮点数；原始十进制文本保存在Raw中。货币计算列保留基础单位，Display列使用展示单位。
A4: 主要发现 | B4: 披露事实 2024年营业收入1708.99亿元、归母净利润862.28亿元，均高于2023年。营业收入与包含利息收入的营业总收入1741.44亿元是不同口径。 | C4: revenue_2024 [ar2024] PDF p. 63 / 印刷页 63，合并报表，2024年列，营业收入; revenue_2023 [ar2024] PDF p. 63 / 印刷页 63，合并报表，2023年列，营业收入; parent_net_income_2024 [ar2024] PDF p. 64 / 印刷页 64，合并报表，2024年列，归属于母公司股东的净利润; parent_net_income_2023 [ar2024] PDF p. 64 / 印刷页 64，合并报表，2023年列，归属于母公司股东的净利润; [business] 贵州茅台2024年年度报告：业务与经营变动 PDF p. 7-9 / 印刷页 7-9，管理层讨论与分析
A5: 主要发现 | B5: 分析判断 经营现金流超过合并净利润，但现金增长包含财务公司归集成员单位资金的影响，不能据此独立认定酒业利润全部实现了现金回收。 | C5: cfo_2024 [ar2024] PDF p. 67 / 印刷页 67，合并报表，2024年列，经营活动产生的现金流量净额; net_income_2024 [ar2024] PDF p. 64 / 印刷页 64，合并报表，2024年列，合并净利润; [business] 贵州茅台2024年年度报告：业务与经营变动 PDF p. 7-9 / 印刷页 7-9，管理层讨论与分析; [cashnote] 贵州茅台2024年年度报告：现金流量补充资料与现金构成 PDF p. 116-117 / 印刷页 116-117，附注七57; [related] 贵州茅台2024年年度报告：财务公司关联金融业务 PDF p. 131-132 / 印刷页 131-132，附注十四4(8)
A6: 主要发现 | B6: 披露事实 无保留审计意见；收入确认、关联方及交易为关键审计事项。关键审计事项表示审计关注，并非造假结论。 | C6: [audit] 贵州茅台2024年年度报告：审计报告 PDF p. 55-58 / 印刷页 55-58，天健审〔2025〕8-171号，2025-04-01
A7: 业务与收入变化 | B7: 管理层表述 公司主营茅台酒及系列酒，使用批发代理和直销渠道；管理层将收入增长归因于销量增长及茅台酒主要产品价格调整。 | C7: [business] 贵州茅台2024年年度报告：业务与经营变动 PDF p. 7-9 / 印刷页 7-9，管理层讨论与分析
A8: 业务与收入变化 | B8: 披露事实 2024年其他系列酒主营收入同比增长19.65%，茅台酒增长15.28%；直销增长11.32%，批发代理增长19.73%。这些为年报披露口径，不应替换合并营业收入增长率。 | C8: [business] 贵州茅台2024年年度报告：业务与经营变动 PDF p. 7-9 / 印刷页 7-9，管理层讨论与分析
A9: 现金、利润与资本支出 | B9: 披露事实 合并现金流量补充资料将净利润调节至经营现金流；其中存货增加调减79.08亿元，经营性应付项目增加调增80.66亿元。 | C9: [cashnote] 贵州茅台2024年年度报告：现金流量补充资料与现金构成 PDF p. 116-117 / 印刷页 116-117，附注七57
A10: 现金、利润与资本支出 | B10: 分析判断 CFO减资本支出可作为本例的简单现金余量指标，但包含财务公司业务现金流，也未扣除所有资本配置需求，不能直接称为可分配给股东的现金。 | C10: cfo_2024 [ar2024] PDF p. 67 / 印刷页 67，合并报表，2024年列，经营活动产生的现金流量净额; capex_2024 [ar2024] PDF p. 67 / 印刷页 67，合并报表，2024年列，购建固定资产、无形资产和其他长期资产支付的现金; [related] 贵州茅台2024年年度报告：财务公司关联金融业务 PDF p. 131-132 / 印刷页 131-132，附注十四4(8); [commitments] 贵州茅台2024年年度报告：资本承诺与期后事项 PDF p. 135-136 / 印刷页 135-136，附注十五至十七
A11: 现金、利润与资本支出 | B11: 披露事实 2024年期末现金及现金等价物1699.70亿元包含存放同业款项和买入返售金融资产；法定存款准备金74.04亿元未计入现金及现金等价物。 | C11: [cashnote] 贵州茅台2024年年度报告：现金流量补充资料与现金构成 PDF p. 116-117 / 印刷页 116-117，附注七57
A12: 资产、负债与附注观察 | B12: 分析判断 存货由464.35亿元增至543.43亿元；合同负债从141.26亿元降至95.92亿元。长期贮存工艺与渠道预收共同影响营运资金，单一存货天数或合同负债变化不能证明需求恶化。 | C12: inventory_2024 [ar2024] PDF p. 59 / 印刷页 59，合并报表，2024年列，存货; inventory_2023 [ar2024] PDF p. 59 / 印刷页 59，合并报表，2023年列，存货; [outlook] 贵州茅台2024年年度报告：管理层未来发展与目标 PDF p. 20-21 / 印刷页 20-21; [business] 贵州茅台2024年年度报告：业务与经营变动 PDF p. 7-9 / 印刷页 7-9，管理层讨论与分析; [cashnote] 贵州茅台2024年年度报告：现金流量补充资料与现金构成 PDF p. 116-117 / 印刷页 116-117，附注七57; [balance] 贵州茅台2024年年度报告：合并资产负债表 PDF p. 58-61 / 印刷页 58-61；合同负债见第60页
A13: 资产、负债与附注观察 | B13: 披露事实 财务公司存放同业款项中100亿元不能随时支取；公司对两只产业基金尚未履行的认缴出资余额各30亿元。 | C13: [restricted] 贵州茅台2024年年度报告：货币资金与拆出资金附注 PDF p. 86 / 印刷页 86，附注七1-2; [commitments] 贵州茅台2024年年度报告：资本承诺与期后事项 PDF p. 135-136 / 印刷页 135-136，附注十五至十七
A14: 审计、会计口径与扣非 | B14: 披露事实 天健审〔2025〕8-171号审计报告日期为2025年4月1日；财务报表采用中国企业会计准则和持续经营基础。 | C14: [audit] 贵州茅台2024年年度报告：审计报告 PDF p. 55-58 / 印刷页 55-58，天健审〔2025〕8-171号，2025-04-01; [policy] 贵州茅台2024年年度报告：编制基础与会计政策变更 PDF p. 74-75、85 / 印刷页 74-75、85
A15: 审计、会计口径与扣非 | B15: 披露事实 年报披露2024年重要会计政策、会计估计变更及首次执行准则涉及年初调整均不适用。本底稿使用本报告的2023年比较数；2023年权益变动表内仍列示更早的期初会计政策调整，不能据此称历史上从无调整。 | C15: [policy] 贵州茅台2024年年度报告：编制基础与会计政策变更 PDF p. 74-75、85 / 印刷页 74-75、85; [equitynote] 贵州茅台2024年年度报告：合并所有者权益变动表 PDF p. 70-72 / 印刷页 70-72
... A23: 待核问题 | B23: 两只产业基金剩余认缴及后续回购、分红安排将如何影响可用资金？需结合后续公告逐项跟踪。 | C23: [commitments] 贵州茅台2024年年度报告：资本承诺与期后事项 PDF p. 135-136 / 印刷页 135-136，附注十五至十七
A24: 局限 | B24: 仅对底稿coverage注明的报表和指定章节核验，未声称通读全部143页；未取得审计工作底稿、经营合同或独立函证。
A25: 局限 | B25: 样例固定于2024年年报及其中比较信息，不是截至2026年10月2日的最新投资分析；未核验2025年目标完成情况和后来公告。
A26: 局限 | B26: 主体主营非金融业务但合并财务公司，通用利润率、CFO/利润、流动比率及营运资金指标存在混合业务口径限制，不用于跨行业机械排序。
A27: 局限 | B27: 本例ROE使用期初期末平均归母权益的分析口径时，不等于年报披露的加权平均净资产收益率36.02%。
A28: 局限 | B28: 2023年所有者交易净额未录入，未用期末权益倒算；缺少2022年完整资产、存货、应收账款等期初数的指标应显示不可得。
A29: 局限 | B29: 资本支出采用披露的固定资产、无形资产和其他长期资产购建现金支出，不区分维持性及扩张性支出；未包括产业基金投资。
A30: 局限 | B30: 金额先换算为同一币种基本单位；不自动换汇。指标为分析定义，非会计准则结论。平均余额使用期初期末均值。

Sheet Raw
A1: ID | B1: Label | C1: Raw text | D1: Value exact text | E1: Value numeric | F1: Multiplier | G1: Currency | H1: Start | I1: End | J1: Scope | K1: Standard | L1: Basis | M1: Restated | N1: Use for analysis | O1: Source | P1: Locator | Q1: Note
A2: revenue_2024 | B2: 营业收入 | C2: 170,899,152,276.34 | D2: 170899152276.34 | E2: 1.7089915e+11 | F2: 1 | G2: CNY | H2: 2024-01-01 | I2: 2024-12-31 | J2: consolidated | K2: CAS | L2: reported | M2: False | N2: True | O2: ar2024 | P2: PDF p. 63 / 印刷页 63，合并报表，2024年列，营业收入 | Q2: 采用营业收入，未使用含财务公司利息收入的营业总收入；2024年营业总收入为174,144,069,958.25元。
A3: revenue_2023 | B3: 营业收入 | C3: 147,693,604,994.14 | D3: 147693604994.14 | E3: 1.476936e+11 | F3: 1 | G3: CNY | H3: 2023-01-01 | I3: 2023-12-31 | J3: consolidated | K3: CAS | L3: reported | M3: False | N3: True | O3: ar2024 | P3: PDF p. 63 / 印刷页 63，合并报表，2023年列，营业收入 | Q3: 采用营业收入，未使用含财务公司利息收入的营业总收入；2024年营业总收入为174,144,069,958.25元。
A4: cost_of_sales_2024 | B4: 营业成本 | C4: 13,789,482,367.98 | D4: 13789482367.98 | E4: 1.3789482e+10 | F4: 1 | G4: CNY | H4: 2024-01-01 | I4: 2024-12-31 | J4: consolidated | K4: CAS | L4: reported | M4: False | N4: True | O4: ar2024 | P4: PDF p. 63 / 印刷页 63，合并报表，2024年列，营业成本
A5: cost_of_sales_2023 | B5: 营业成本 | C5: 11,867,273,851.78 | D5: 11867273851.78 | E5: 1.1867274e+10 | F5: 1 | G5: CNY | H5: 2023-01-01 | I5: 2023-12-31 | J5: consolidated | K5: CAS | L5: reported | M5: False | N5: True | O5: ar2024 | P5: PDF p. 63 / 印刷页 63，合并报表，2023年列，营业成本
A6: net_income_2024 | B6: 合并净利润 | C6: 89,334,728,025.90 | D6: 89334728025.90 | E6: 8.9334728e+10 | F6: 1 | G6: CNY | H6: 2024-01-01 | I6: 2024-12-31 | J6: consolidated | K6: CAS | L6: reported | M6: False | N6: True | O6: ar2024 | P6: PDF p. 64 / 印刷页 64，合并报表，2024年列，合并净利润
A7: net_income_2023 | B7: 合并净利润 | C7: 77,521,476,277.80 | D7: 77521476277.80 | E7: 7.7521476e+10 | F7: 1 | G7: CNY | H7: 2023-01-01 | I7: 2023-12-31 | J7: consolidated | K7: CAS | L7: reported | M7: False | N7: True | O7: ar2024 | P7: PDF p. 64 / 印刷页 64，合并报表，2023年列，合并净利润
A8: parent_net_income_2024 | B8: 归属于母公司股东的净利润 | C8: 86,228,146,421.62 | D8: 86228146421.62 | E8: 8.6228146e+10 | F8: 1 | G8: CNY | H8: 2024-01-01 | I8: 2024-12-31 | J8: consolidated | K8: CAS | L8: reported | M8: False | N8: True | O8: ar2024 | P8: PDF p. 64 / 印刷页 64，合并报表，2024年列，归属于母公司股东的净利润
A9: parent_net_income_2023 | B9: 归属于母公司股东的净利润 | C9: 74,734,071,550.75 | D9: 74734071550.75 | E9: 7.4734072e+10 | F9: 1 | G9: CNY | H9: 2023-01-01 | I9: 2023-12-31 | J9: consolidated | K9: CAS | L9: reported | M9: False | N9: True | O9: ar2024 | P9: PDF p. 64 / 印刷页 64，合并报表，2023年列，归属于母公司股东的净利润
A10: minority_net_income_2024 | B10: 少数股东损益 | C10: 3,106,581,604.28 | D10: 3106581604.28 | E10: 3.1065816e+09 | F10: 1 | G10: CNY | H10: 2024-01-01 | I10: 2024-12-31 | J10: consolidated | K10: CAS | L10: reported | M10: False | N10: True | O10: ar2024 | P10: PDF p. 64 / 印刷页 64，合并报表，2024年列，少数股东损益
A11: minority_net_income_2023 | B11: 少数股东损益 | C11: 2,787,404,727.05 | D11: 2787404727.05 | E11: 2.7874047e+09 | F11: 1 | G11: CNY | H11: 2023-01-01 | I11: 2023-12-31 | J11: consolidated | K11: CAS | L11: reported | M11: False | N11: True | O11: ar2024 | P11: PDF p. 64 / 印刷页 64，合并报表，2023年列，少数股东损益
A12: assets_2024 | B12: 资产总计 | C12: 298,944,579,918.70 | D12: 298944579918.70 | E12: 2.9894458e+11 | F12: 1 | G12: CNY | I12: 2024-12-31 | J12: consolidated | K12: CAS | L12: reported | M12: False | N12: True | O12: ar2024 | P12: PDF p. 59 / 印刷页 59，合并报表，2024年列，资产总计
A13: assets_2023 | B13: 资产总计 | C13: 272,699,660,092.25 | D13: 272699660092.25 | E13: 2.7269966e+11 | F13: 1 | G13: CNY | I13: 2023-12-31 | J13: consolidated | K13: CAS | L13: reported | M13: False | N13: True | O13: ar2024 | P13: PDF p. 59 / 印刷页 59，合并报表，2023年列，资产总计
A14: liabilities_2024 | B14: 负债合计 | C14: 56,933,264,798.10 | D14: 56933264798.10 | E14: 5.6933265e+10 | F14: 1 | G14: CNY | I14: 2024-12-31 | J14: consolidated | K14: CAS | L14: reported | M14: False | N14: True | O14: ar2024 | P14: PDF p. 60 / 印刷页 60，合并报表，2024年列，负债合计
A15: liabilities_2023 | B15: 负债合计 | C15: 49,043,190,797.43 | D15: 49043190797.43 | E15: 4.9043191e+10 | F15: 1 | G15: CNY | I15: 2023-12-31 | J15: consolidated | K15: CAS | L15: reported | M15: False | N15: True | O15: ar2024 | P15: PDF p. 60 / 印刷页 60，合并报表，2023年列，负债合计
A16: equity_2024 | B16: 所有者权益合计 | C16: 242,011,315,120.60 | D16: 242011315120.60 | E16: 2.4201132e+11 | F16: 1 | G16: CNY | I16: 2024-12-31 | J16: consolidated | K16: CAS | L16: reported | M16: False | N16: True | O16: ar2024 | P16: PDF p. 61 / 印刷页 61，合并报表，2024年列，所有者权益合计
A17: equity_2023 | B17: 所有者权益合计 | C17: 223,656,469,294.82 | D17: 223656469294.82 | E17: 2.2365647e+11 | F17: 1 | G17: CNY | I17: 2023-12-31 | J17: consolidated | K17: CAS | L17: reported | M17: False | N17: True | O17: ar2024 | P17: PDF p. 61 / 印刷页 61，合并报表，2023年列，所有者权益合计
A18: parent_equity_2024 | B18: 归属于母公司所有者权益合计 | C18: 233,105,984,399.47 | D18: 233105984399.47 | E18: 2.3310598e+11 | F18: 1 | G18: CNY | I18: 2024-12-31 | J18: consolidated | K18: CAS | L18: reported | M18: False | N18: True | O18: ar2024 | P18: PDF p. 61 / 印刷页 61，合并报表，2024年列，归属于母公司所有者权益合计
A19: parent_equity_2023 | B19: 归属于母公司所有者权益合计 | C19: 215,668,571,607.43 | D19: 215668571607.43 | E19: 2.1566857e+11 | F19: 1 | G19: CNY | I19: 2023-12-31 | J19: consolidated | K19: CAS | L19: reported | M19: False | N19: True | O19: ar2024 | P19: PDF p. 61 / 印刷页 61，合并报表，2023年列，归属于母公司所有者权益合计
A20: current_assets_2024 | B20: 流动资产合计 | C20: 251,726,674,636.66 | D20: 251726674636.66 | E20: 2.5172667e+11 | F20: 1 | G20: CNY | I20: 2024-12-31 | J20: consolidated | K20: CAS | L20: reported | M20: False | N20: True | O20: ar2024 | P20: PDF p. 59 / 印刷页 59，合并报表，2024年列，流动资产合计
A21: current_assets_2023 | B21: 流动资产合计 | C21: 225,172,517,821.28 | D21: 225172517821.28 | E21: 2.2517252e+11 | F21: 1 | G21: CNY | I21: 2023-12-31 | J21: consolidated | K21: CAS | L21: reported | M21: False | N21: True | O21: ar2024 | P21: PDF p. 59 / 印刷页 59，合并报表，2023年列，流动资产合计
A22: current_liabilities_2024 | B22: 流动负债合计 | C22: 56,515,990,618.96 | D22: 56515990618.96 | E22: 5.6515991e+10 | F22: 1 | G22: CNY | I22: 2024-12-31 | J22: consolidated | K22: CAS | L22: reported | M22: False | N22: True | O22: ar2024 | P22: PDF p. 60 / 印刷页 60，合并报表，2024年列，流动负债合计
A23: current_liabilities_2023 | B23: 流动负债合计 | C23: 48,697,611,501.20 | D23: 48697611501.20 | E23: 4.8697612e+10 | F23: 1 | G23: CNY | I23: 2023-12-31 | J23: consolidated | K23: CAS | L23: reported | M23: False | N23: True | O23: ar2024 | P23: PDF p. 60 / 印刷页 60，合并报表，2023年列，流动负债合计
... A25: inventory_2023 | B25: 存货 | C25: 46,435,185,061.53 | D25: 46435185061.53 | E25: 4.6435185e+10 | F25: 1 | G25: CNY | I25: 2023-12-31 | J25: consolidated | K25: CAS | L25: reported | M25: False | N25: True | O25: ar2024 | P25: PDF p. 59 / 印刷页 59，合并报表，2023年列，存货
A26: receivables_2024 | B26: 应收账款 | C26: 18,974,192.75 | D26: 18974192.75 | E26: 18974193 | F26: 1 | G26: CNY | I26: 2024-12-31 | J26: consolidated | K26: CAS | L26: reported | M26: False | N26: True | O26: ar2024 | P26: PDF p. 59 / 印刷页 59，合并报表，2024年列，应收账款 | Q26: 应收账款净额，不含应收票据及其他应收款；周转指标只能解释此限定口径。
A27: receivables_2023 | B27: 应收账款 | C27: 60,373,410.41 | D27: 60373410.41 | E27: 60373410 | F27: 1 | G27: CNY | I27: 2023-12-31 | J27: consolidated | K27: CAS | L27: reported | M27: False | N27: True | O27: ar2024 | P27: PDF p. 59 / 印刷页 59，合并报表，2023年列，应收账款 | Q27: 应收账款净额，不含应收票据及其他应收款；周转指标只能解释此限定口径。
A28: cfo_2024 | B28: 经营活动产生的现金流量净额 | C28: 92,463,692,168.43 | D28: 92463692168.43 | E28: 9.2463692e+10 | F28: 1 | G28: CNY | H28: 2024-01-01 | I28: 2024-12-31 | J28: consolidated | K28: CAS | L28: reported | M28: False | N28: True | O28: ar2024 | P28: PDF p. 67 / 印刷页 67，合并报表，2024年列，经营活动产生的现金流量净额 | Q28: 合并范围包括财务公司；含成员单位存款、同业及贷款相关现金变动，不能等同酒业经营回款。
A29: cfo_2023 | B29: 经营活动产生的现金流量净额 | C29: 66,593,247,721.09 | D29: 66593247721.09 | E29: 6.6593248e+10 | F29: 1 | G29: CNY | H29: 2023-01-01 | I29: 2023-12-31 | J29: consolidated | K29: CAS | L29: reported | M29: False | N29: True | O29: ar2024 | P29: PDF p. 67 / 印刷页 67，合并报表，2023年列，经营活动产生的现金流量净额 | Q29: 合并范围包括财务公司；含成员单位存款、同业及贷款相关现金变动，不能等同酒业经营回款。
A30: cfi_2024 | B30: 投资活动产生的现金流量净额 | C30: -1,785,202,630.71 | D30: -1785202630.71 | E30: -1.7852026e+09 | F30: 1 | G30: CNY | H30: 2024-01-01 | I30: 2024-12-31 | J30: consolidated | K30: CAS | L30: reported | M30: False | N30: True | O30: ar2024 | P30: PDF p. 67 / 印刷页 67，合并报表，2024年列，投资活动产生的现金流量净额
A31: cfi_2023 | B31: 投资活动产生的现金流量净额 | C31: -9,724,414,015.16 | D31: -9724414015.16 | E31: -9.724414e+09 | F31: 1 | G31: CNY | H31: 2023-01-01 | I31: 2023-12-31 | J31: consolidated | K31: CAS | L31: reported | M31: False | N31: True | O31: ar2024 | P31: PDF p. 67 / 印刷页 67，合并报表，2023年列，投资活动产生的现金流量净额
A32: cff_2024 | B32: 筹资活动产生的现金流量净额 | C32: -71,067,506,484.81 | D32: -71067506484.81 | E32: -7.1067506e+10 | F32: 1 | G32: CNY | H32: 2024-01-01 | I32: 2024-12-31 | J32: consolidated | K32: CAS | L32: reported | M32: False | N32: True | O32: ar2024 | P32: PDF p. 67 / 印刷页 67，合并报表，2024年列，筹资活动产生的现金流量净额
A33: cff_2023 | B33: 筹资活动产生的现金流量净额 | C33: -58,889,101,991.94 | D33: -58889101991.94 | E33: -5.8889102e+10 | F33: 1 | G33: CNY | H33: 2023-01-01 | I33: 2023-12-31 | J33: consolidated | K33: CAS | L33: reported | M33: False | N33: True | O33: ar2024 | P33: PDF p. 67 / 印刷页 67，合并报表，2023年列，筹资活动产生的现金流量净额
A34: fx_effect_2024 | B34: 汇率变动对现金及现金等价物的影响 | C34: -1,082,747.55 | D34: -1082747.55 | E34: -1082747.6 | F34: 1 | G34: CNY | H34: 2024-01-01 | I34: 2024-12-31 | J34: consolidated | K34: CAS | L34: reported | M34: False | N34: True | O34: ar2024 | P34: PDF p. 68 / 印刷页 68，合并报表，2024年列，汇率变动对现金及现金等价物的影响
A35: fx_effect_2023 | B35: 汇率变动对现金及现金等价物的影响 | C35: 1,718,255.65 | D35: 1718255.65 | E35: 1718255.6 | F35: 1 | G35: CNY | H35: 2023-01-01 | I35: 2023-12-31 | J35: consolidated | K35: CAS | L35: reported | M35: False | N35: True | O35: ar2024 | P35: PDF p. 68 / 印刷页 68，合并报表，2023年列，汇率变动对现金及现金等价物的影响
A36: cash_equivalents_2024 | B36: 现金及现金等价物期末余额 | C36: 169,970,089,257.83 | D36: 169970089257.83 | E36: 1.6997009e+11 | F36: 1 | G36: CNY | I36: 2024-12-31 | J36: consolidated | K36: CAS | L36: reported | M36: False | N36: True | O36: ar2024 | P36: PDF p. 68 / 印刷页 68，合并报表，2024年列，现金及现金等价物期末余额
A37: cash_equivalents_2023 | B37: 现金及现金等价物期末余额 | C37: 150,360,188,952.47 | D37: 150360188952.47 | E37: 1.5036019e+11 | F37: 1 | G37: CNY | I37: 2023-12-31 | J37: consolidated | K37: CAS | L37: reported | M37: False | N37: True | O37: ar2024 | P37: PDF p. 68 / 印刷页 68，合并报表，2023年列，现金及现金等价物期末余额
A38: capex_2024 | B38: 购建固定资产、无形资产和其他长期资产支付的现金 | C38: 4,678,712,053.56 | D38: 4678712053.56 | E38: 4.6787121e+09 | F38: 1 | G38: CNY | H38: 2024-01-01 | I38: 2024-12-31 | J38: consolidated | K38: CAS | L38: reported | M38: False | N38: True | O38: ar2024 | P38: PDF p. 67 / 印刷页 67，合并报表，2024年列，购建固定资产、无形资产和其他长期资产支付的现金 | Q38: 采用报表披露的购建固定资产、无形资产和其他长期资产现金支出；不含投资支付的现金和企业收购，未进一步拆分维持性/扩张性支出。
A39: capex_2023 | B39: 购建固定资产、无形资产和其他长期资产支付的现金 | C39: 2,619,755,888.79 | D39: 2619755888.79 | E39: 2.6197559e+09 | F39: 1 | G39: CNY | H39: 2023-01-01 | I39: 2023-12-31 | J39: consolidated | K39: CAS | L39: reported | M39: False | N39: True | O39: ar2024 | P39: PDF p. 67 / 印刷页 67，合并报表，2023年列，购建固定资产、无形资产和其他长期资产支付的现金 | Q39: 采用报表披露的购建固定资产、无形资产和其他长期资产现金支出；不含投资支付的现金和企业收购，未进一步拆分维持性/扩张性支出。
A40: comprehensive_income_2024 | B40: 综合收益总额 | C40: 89,330,873,528.72 | D40: 89330873528.72 | E40: 8.9330874e+10 | F40: 1 | G40: CNY | H40: 2024-01-01 | I40: 2024-12-31 | J40: consolidated | K40: CAS | L40: reported | M40: False | N40: True | O40: ar2024 | P40: PDF p. 65 / 印刷页 65，合并报表，2024年列，综合收益总额
A41: comprehensive_income_2023 | B41: 综合收益总额 | C41: 77,526,191,457.62 | D41: 77526191457.62 | E41: 7.7526191e+10 | F41: 1 | G41: CNY | H41: 2023-01-01 | I41: 2023-12-31 | J41: consolidated | K41: CAS | L41: reported | M41: False | N41: True | O41: ar2024 | P41: PDF p. 65 / 印刷页 65，合并报表，2023年列，综合收益总额
...

Sheet Normalized
A1: ID | B1: Label | C1: Base currency value | D1: Currency | E1: Scope | F1: Basis | G1: Period end | H1: Status
A2: revenue_2024 | B2: 营业收入 | C2: =Raw!E2*Raw!F2 -> 1.7089915e+11 | D2: CNY | E2: consolidated | F2: reported | G2: 2024-12-31
A3: revenue_2023 | B3: 营业收入 | C3: =Raw!E3*Raw!F3 -> 1.476936e+11 | D3: CNY | E3: consolidated | F3: reported | G3: 2023-12-31
A4: cost_of_sales_2024 | B4: 营业成本 | C4: =Raw!E4*Raw!F4 -> 1.3789482e+10 | D4: CNY | E4: consolidated | F4: reported | G4: 2024-12-31
A5: cost_of_sales_2023 | B5: 营业成本 | C5: =Raw!E5*Raw!F5 -> 1.1867274e+10 | D5: CNY | E5: consolidated | F5: reported | G5: 2023-12-31
A6: net_income_2024 | B6: 合并净利润 | C6: =Raw!E6*Raw!F6 -> 8.9334728e+10 | D6: CNY | E6: consolidated | F6: reported | G6: 2024-12-31
A7: net_income_2023 | B7: 合并净利润 | C7: =Raw!E7*Raw!F7 -> 7.7521476e+10 | D7: CNY | E7: consolidated | F7: reported | G7: 2023-12-31
A8: parent_net_income_2024 | B8: 归属于母公司股东的净利润 | C8: =Raw!E8*Raw!F8 -> 8.6228146e+10 | D8: CNY | E8: consolidated | F8: reported | G8: 2024-12-31
A9: parent_net_income_2023 | B9: 归属于母公司股东的净利润 | C9: =Raw!E9*Raw!F9 -> 7.4734072e+10 | D9: CNY | E9: consolidated | F9: reported | G9: 2023-12-31
A10: minority_net_income_2024 | B10: 少数股东损益 | C10: =Raw!E10*Raw!F10 -> 3.1065816e+09 | D10: CNY | E10: consolidated | F10: reported | G10: 2024-12-31
A11: minority_net_income_2023 | B11: 少数股东损益 | C11: =Raw!E11*Raw!F11 -> 2.7874047e+09 | D11: CNY | E11: consolidated | F11: reported | G11: 2023-12-31
A12: assets_2024 | B12: 资产总计 | C12: =Raw!E12*Raw!F12 -> 2.9894458e+11 | D12: CNY | E12: consolidated | F12: reported | G12: 2024-12-31
A13: assets_2023 | B13: 资产总计 | C13: =Raw!E13*Raw!F13 -> 2.7269966e+11 | D13: CNY | E13: consolidated | F13: reported | G13: 2023-12-31
... A43: owner_transactions_2024 | B43: 所有者交易净额（对所有者的分配） | C43: =Raw!E43*Raw!F43 -> -7.0976028e+10 | D43: CNY | E43: consolidated | F43: reported | G43: 2024-12-31

Sheet Calculations
A1: ID | B1: Label | C1: Value (base units) | D1: Display | E1: Unit | F1: Expression | G1: Inputs | H1: Status / Reason | I1: Tolerance (base units) | J1: Evidence
A2: revenue_change | B2: 营业收入变动额 | C2: ='Normalized'!$C$2-'Normalized'!$C$3 -> 2.3205547e+10 | D2: =C2/100000000 -> 232.05547 | E2: 亿元 | F2: {revenue_2024}-{revenue_2023} | G2: revenue_2024, revenue_2023 | J2: revenue_2024 [ar2024] PDF p. 63 / 印刷页 63，合并报表，2024年列，营业收入; revenue_2023 [ar2024] PDF p. 63 / 印刷页 63，合并报表，2023年列，营业收入
A3: revenue_growth | B3: 营业收入同比 | C3: =('Normalized'!$C$2-'Normalized'!$C$3)/'Normalized'!$C$3 -> 0.15711951 | D3: =C3 -> 0.15711951 | E3: percent | F3: ({revenue_2024}-{revenue_2023})/{revenue_2023} | G3: revenue_2024, revenue_2023 | J3: revenue_2024 [ar2024] PDF p. 63 / 印刷页 63，合并报表，2024年列，营业收入; revenue_2023 [ar2024] PDF p. 63 / 印刷页 63，合并报表，2023年列，营业收入
A4: net_income_change | B4: 净利润变动额 | C4: ='Normalized'!$C$6-'Normalized'!$C$7 -> 1.1813252e+10 | D4: =C4/100000000 -> 118.13252 | E4: 亿元 | F4: {net_income_2024}-{net_income_2023} | G4: net_income_2024, net_income_2023 | J4: net_income_2024 [ar2024] PDF p. 64 / 印刷页 64，合并报表，2024年列，合并净利润; net_income_2023 [ar2024] PDF p. 64 / 印刷页 64，合并报表，2023年列，合并净利润
A5: net_income_growth | B5: 净利润同比 | C5: =('Normalized'!$C$6-'Normalized'!$C$7)/'Normalized'!$C$7 -> 0.15238683 | D5: =C5 -> 0.15238683 | E5: percent | F5: ({net_income_2024}-{net_income_2023})/{net_income_2023} | G5: net_income_2024, net_income_2023 | J5: net_income_2024 [ar2024] PDF p. 64 / 印刷页 64，合并报表，2024年列，合并净利润; net_income_2023 [ar2024] PDF p. 64 / 印刷页 64，合并报表，2023年列，合并净利润
A6: gross_margin | B6: 毛利率 | C6: =('Normalized'!$C$2-'Normalized'!$C$4)/'Normalized'!$C$2 -> 0.91931217 | D6: =C6 -> 0.91931217 | E6: percent | F6: ({revenue_2024}-{cost_of_sales_2024})/{revenue_2024} | G6: cost_of_sales_2024, revenue_2024 | J6: cost_of_sales_2024 [ar2024] PDF p. 63 / 印刷页 63，合并报表，2024年列，营业成本; revenue_2024 [ar2024] PDF p. 63 / 印刷页 63，合并报表，2024年列，营业收入
A7: net_margin | B7: 净利率 | C7: ='Normalized'!$C$6/'Normalized'!$C$2 -> 0.52273359 | D7: =C7 -> 0.52273359 | E7: percent | F7: {net_income_2024}/{revenue_2024} | G7: net_income_2024, revenue_2024 | J7: net_income_2024 [ar2024] PDF p. 64 / 印刷页 64，合并报表，2024年列，合并净利润; revenue_2024 [ar2024] PDF p. 63 / 印刷页 63，合并报表，2024年列，营业收入
A8: cash_profit_ratio | B8: 经营现金流与净利润比 | C8: ='Normalized'!$C$28/'Normalized'!$C$6 -> 1.0350252 | D8: =C8 -> 1.0350252 | E8: ratio | F8: {cfo_2024}/{net_income_2024} | G8: cfo_2024, net_income_2024 | J8: cfo_2024 [ar2024] PDF p. 67 / 印刷页 67，合并报表，2024年列，经营活动产生的现金流量净额; net_income_2024 [ar2024] PDF p. 64 / 印刷页 64，合并报表，2024年列，合并净利润
A9: current_ratio | B9: 流动比率 | C9: ='Normalized'!$C$20/'Normalized'!$C$22 -> 4.4540788 | D9: =C9 -> 4.4540788 | E9: ratio | F9: {current_assets_2024}/{current_liabilities_2024} | G9: current_assets_2024, current_liabilities_2024 | J9: current_assets_2024 [ar2024] PDF p. 59 / 印刷页 59，合并报表，2024年列，流动资产合计; current_liabilities_2024 [ar2024] PDF p. 60 / 印刷页 60，合并报表，2024年列，流动负债合计
A10: liabilities_assets | B10: 资产负债率 | C10: ='Normalized'!$C$14/'Normalized'!$C$12 -> 0.19044756 | D10: =C10 -> 0.19044756 | E10: percent | F10: {liabilities_2024}/{assets_2024} | G10: liabilities_2024, assets_2024 | J10: liabilities_2024 [ar2024] PDF p. 60 / 印刷页 60，合并报表，2024年列，负债合计; assets_2024 [ar2024] PDF p. 59 / 印刷页 59，合并报表，2024年列，资产总计
A11: roe | B11: 简化归母ROE | C11: ='Normalized'!$C$8/(('Normalized'!$C$19+'Normalized'!$C$18)/2) -> 0.38428269 | D11: =C11 -> 0.38428269 | E11: percent | F11: {parent_net_income_2024}/(({parent_equity_2023}+{parent_equity_2024})/2) | G11: parent_net_income_2024, parent_equity_2023, parent_equity_2024 | J11: parent_net_income_2024 [ar2024] PDF p. 64 / 印刷页 64，合并报表，2024年列，归属于母公司股东的净利润; parent_equity_2023 [ar2024] PDF p. 61 / 印刷页 61，合并报表，2023年列，归属于母公司所有者权益合计; parent_equity_2024 [ar2024] PDF p. 61 / 印刷页 61，合并报表，2024年列，归属于母公司所有者权益合计
A12: roa | B12: ROA 净利润口径 | C12: ='Normalized'!$C$6/(('Normalized'!$C$13+'Normalized'!$C$12)/2) -> 0.31255358 | D12: =C12 -> 0.31255358 | E12: percent | F12: {net_income_2024}/(({assets_2023}+{assets_2024})/2) | G12: net_income_2024, assets_2023, assets_2024 | J12: net_income_2024 [ar2024] PDF p. 64 / 印刷页 64，合并报表，2024年列，合并净利润; assets_2023 [ar2024] PDF p. 59 / 印刷页 59，合并报表，2023年列，资产总计; assets_2024 [ar2024] PDF p. 59 / 印刷页 59，合并报表，2024年列，资产总计
A13: inventory_days | B13: 存货周转天数 | C13: =('Normalized'!$C$25+'Normalized'!$C$24)/2/'Normalized'!$C$4*366 -> 1337.4295 | D13: =C13 -> 1337.4295 | E13: days | F13: ({inventory_2023}+{inventory_2024})/2/{cost_of_sales_2024}*366 | G13: inventory_2023, inventory_2024, cost_of_sales_2024 | J13: inventory_2023 [ar2024] PDF p. 59 / 印刷页 59，合并报表，2023年列，存货; inventory_2024 [ar2024] PDF p. 59 / 印刷页 59，合并报表，2024年列，存货; cost_of_sales_2024 [ar2024] PDF p. 63 / 印刷页 63，合并报表，2024年列，营业成本
A14: receivable_days | B14: 应收账款周转天数 | C14: =('Normalized'!$C$27+'Normalized'!$C$26)/2/'Normalized'!$C$2*366 -> 0.084965965 | D14: =C14 -> 0.084965965 | E14: days | F14: ({receivables_2023}+{receivables_2024})/2/{revenue_2024}*366 | G14: receivables_2023, receivables_2024, revenue_2024 | J14: receivables_2023 [ar2024] PDF p. 59 / 印刷页 59，合并报表，2023年列，应收账款; receivables_2024 [ar2024] PDF p. 59 / 印刷页 59，合并报表，2024年列，应收账款; revenue_2024 [ar2024] PDF p. 63 / 印刷页 63，合并报表，2024年列，营业收入
A15: free_cash_flow | B15: 自由现金流 CFO减资本开支 | C15: ='Normalized'!$C$28-'Normalized'!$C$38 -> 8.778498e+10 | D15: =C15/100000000 -> 877.8498 | E15: 亿元 | F15: {cfo_2024}-{capex_2024} | G15: cfo_2024, capex_2024 | J15: cfo_2024 [ar2024] PDF p. 67 / 印刷页 67，合并报表，2024年列，经营活动产生的现金流量净额; capex_2024 [ar2024] PDF p. 67 / 印刷页 67，合并报表，2024年列，购建固定资产、无形资产和其他长期资产支付的现金

Sheet Checks
A1: ID | B1: Label | C1: Value (base units) | D1: Display | E1: Unit | F1: Expression | G1: Inputs | H1: Status / Reason | I1: Tolerance (base units) | J1: Evidence
A2: balance_sheet | B2: 资产减负债减权益 | C2: ='Normalized'!$C$12-'Normalized'!$C$14-'Normalized'!$C$16 -> 0 | D2: =C2/100000000 -> 0 | E2: 亿元 | F2: {assets_2024}-{liabilities_2024}-{equity_2024} | G2: assets_2024, liabilities_2024, equity_2024 | H2: matched | I2: 0.015 | J2: assets_2024 [ar2024] PDF p. 59 / 印刷页 59，合并报表，2024年列，资产总计; liabilities_2024 [ar2024] PDF p. 60 / 印刷页 60，合并报表，2024年列，负债合计; equity_2024 [ar2024] PDF p. 61 / 印刷页 61，合并报表，2024年列，所有者权益合计
A3: profit_attribution | B3: 净利润归属勾稽 | C3: ='Normalized'!$C$6-'Normalized'!$C$8-'Normalized'!$C$10 -> 0 | D3: =C3/100000000 -> 0 | E3: 亿元 | F3: {net_income_2024}-{parent_net_income_2024}-{minority_net_income_2024} | G3: net_income_2024, parent_net_income_2024, minority_net_income_2024 | H3: matched | I3: 0.015 | J3: net_income_2024 [ar2024] PDF p. 64 / 印刷页 64，合并报表，2024年列，合并净利润; parent_net_income_2024 [ar2024] PDF p. 64 / 印刷页 64，合并报表，2024年列，归属于母公司股东的净利润; minority_net_income_2024 [ar2024] PDF p. 64 / 印刷页 64，合并报表，2024年列，少数股东损益
A4: cash_rollforward | B4: 现金及等价物变动勾稽 含汇率影响 | C4: ='Normalized'!$C$36-'Normalized'!$C$37-'Normalized'!$C$28-'Normalized'!$C$30-'Normalized'!$C$32-'Normalized'!$C$34 -> 0 | D4: =C4/100000000 -> 0 | E4: 亿元 | F4: {cash_equivalents_2024}-{cash_equivalents_2023}-{cfo_2024}-{cfi_2024}-{cff_2024}-{fx_effect_2024} | G4: cash_equivalents_2024, cash_equivalents_2023, cfo_2024, cfi_2024, cff_2024, fx_effect_2024 | H4: matched | I4: 0.03 | J4: cash_equivalents_2024 [ar2024] PDF p. 68 / 印刷页 68，合并报表，2024年列，现金及现金等价物期末余额; cash_equivalents_2023 [ar2024] PDF p. 68 / 印刷页 68，合并报表，2023年列，现金及现金等价物期末余额; cfo_2024 [ar2024] PDF p. 67 / 印刷页 67，合并报表，2024年列，经营活动产生的现金流量净额; cfi_2024 [ar2024] PDF p. 67 / 印刷页 67，合并报表，2024年列，投资活动产生的现金流量净额; cff_2024 [ar2024] PDF p. 67 / 印刷页 67，合并报表，2024年列，筹资活动产生的现金流量净额; fx_effect_2024 [ar2024] PDF p. 68 / 印刷页 68，合并报表，2024年列，汇率变动对现金及现金等价物的影响
A5: equity_rollforward | B5: 权益变动勾稽 | C5: ='Normalized'!$C$16-'Normalized'!$C$17-'Normalized'!$C$40-'Normalized'!$C$43 -> 0 | D5: =C5/100000000 -> 0 | E5: 亿元 | F5: {equity_2024}-{equity_2023}-{comprehensive_income_2024}-{owner_transactions_2024} | G5: equity_2024, equity_2023, comprehensive_income_2024, owner_transactions_2024 | H5: matched | I5: 0.02 | J5: equity_2024 [ar2024] PDF p. 61 / 印刷页 61，合并报表，2024年列，所有者权益合计; equity_2023 [ar2024] PDF p. 61 / 印刷页 61，合并报表，2023年列，所有者权益合计; comprehensive_income_2024 [ar2024] PDF p. 65 / 印刷页 65，合并报表，2024年列，综合收益总额; owner_transactions_2024 [ar2024] PDF p. 70-71 / 印刷页 70-71，2024年合并权益变动表：对所有者（或股东）的分配，所有者权益合计列

Sheet Sources
A1: ID | B1: Title | C1: URL / upload | D1: Published | E1: Locator | F1: SHA256
A2: ar2024 | B2: 贵州茅台2024年年度报告 | C2: https://static.cninfo.com.cn/finalpage/2025-04-03/1222993920.PDF | D2: 2025-04-03 | F2: 5299f4940e2ce4e91084b73dc457d558b9d335fa76fbfee6227e4254eb7f4a30
A3: business | B3: 贵州茅台2024年年度报告：业务与经营变动 | C3: https://static.cninfo.com.cn/finalpage/2025-04-03/1222993920.PDF | D3: 2025-04-03 | E3: PDF p. 7-9 / 印刷页 7-9，管理层讨论与分析 | F3: 5299f4940e2ce4e91084b73dc457d558b9d335fa76fbfee6227e4254eb7f4a30
A4: outlook | B4: 贵州茅台2024年年度报告：管理层未来发展与目标 | C4: https://static.cninfo.com.cn/finalpage/2025-04-03/1222993920.PDF | D4: 2025-04-03 | E4: PDF p. 20-21 / 印刷页 20-21 | F4: 5299f4940e2ce4e91084b73dc457d558b9d335fa76fbfee6227e4254eb7f4a30
A5: audit | B5: 贵州茅台2024年年度报告：审计报告 | C5: https://static.cninfo.com.cn/finalpage/2025-04-03/1222993920.PDF | D5: 2025-04-03 | E5: PDF p. 55-58 / 印刷页 55-58，天健审〔2025〕8-171号，2025-04-01 | F5: 5299f4940e2ce4e91084b73dc457d558b9d335fa76fbfee6227e4254eb7f4a30
A6: governance | B6: 贵州茅台2024年年度报告：审计委员会与董事履职 | C6: https://static.cninfo.com.cn/finalpage/2025-04-03/1222993920.PDF | D6: 2025-04-03 | E6: PDF p. 31-32 / 印刷页 31-32 | F6: 5299f4940e2ce4e91084b73dc457d558b9d335fa76fbfee6227e4254eb7f4a30
A7: policy | B7: 贵州茅台2024年年度报告：编制基础与会计政策变更 | C7: https://static.cninfo.com.cn/finalpage/2025-04-03/1222993920.PDF | D7: 2025-04-03 | E7: PDF p. 74-75、85 / 印刷页 74-75、85 | F7: 5299f4940e2ce4e91084b73dc457d558b9d335fa76fbfee6227e4254eb7f4a30
A8: nonrecurring | B8: 贵州茅台2024年年度报告：主要指标及非经常性损益 | C8: https://static.cninfo.com.cn/finalpage/2025-04-03/1222993920.PDF | D8: 2025-04-03 | E8: PDF p. 5-7 / 印刷页 5-7 | F8: 5299f4940e2ce4e91084b73dc457d558b9d335fa76fbfee6227e4254eb7f4a30
A9: cashnote | B9: 贵州茅台2024年年度报告：现金流量补充资料与现金构成 | C9: https://static.cninfo.com.cn/finalpage/2025-04-03/1222993920.PDF | D9: 2025-04-03 | E9: PDF p. 116-117 / 印刷页 116-117，附注七57 | F9: 5299f4940e2ce4e91084b73dc457d558b9d335fa76fbfee6227e4254eb7f4a30
A10: restricted | B10: 贵州茅台2024年年度报告：货币资金与拆出资金附注 | C10: https://static.cninfo.com.cn/finalpage/2025-04-03/1222993920.PDF | D10: 2025-04-03 | E10: PDF p. 86 / 印刷页 86，附注七1-2 | F10: 5299f4940e2ce4e91084b73dc457d558b9d335fa76fbfee6227e4254eb7f4a30
A11: related | B11: 贵州茅台2024年年度报告：财务公司关联金融业务 | C11: https://static.cninfo.com.cn/finalpage/2025-04-03/1222993920.PDF | D11: 2025-04-03 | E11: PDF p. 131-132 / 印刷页 131-132，附注十四4(8) | F11: 5299f4940e2ce4e91084b73dc457d558b9d335fa76fbfee6227e4254eb7f4a30
A12: commitments | B12: 贵州茅台2024年年度报告：资本承诺与期后事项 | C12: https://static.cninfo.com.cn/finalpage/2025-04-03/1222993920.PDF | D12: 2025-04-03 | E12: PDF p. 135-136 / 印刷页 135-136，附注十五至十七 | F12: 5299f4940e2ce4e91084b73dc457d558b9d335fa76fbfee6227e4254eb7f4a30
A13: equitynote | B13: 贵州茅台2024年年度报告：合并所有者权益变动表 | C13: https://static.cninfo.com.cn/finalpage/2025-04-03/1222993920.PDF | D13: 2025-04-03 | E13: PDF p. 70-72 / 印刷页 70-72 | F13: 5299f4940e2ce4e91084b73dc457d558b9d335fa76fbfee6227e4254eb7f4a30
A14: balance | B14: 贵州茅台2024年年度报告：合并资产负债表 | C14: https://static.cninfo.com.cn/finalpage/2025-04-03/1222993920.PDF | D14: 2025-04-03 | E14: PDF p. 58-61 / 印刷页 58-61；合同负债见第60页 | F14: 5299f4940e2ce4e91084b73dc457d558b9d335fa76fbfee6227e4254eb7f4a30

Sheet Coverage
A1: Section | B1: Status | C1: Source | D1: Locator | E1: Note
A2: 合并资产负债表 | B2: reviewed | C2: ar2024 | D2: PDF p. 58-61 / 印刷页58-61 | E2: 核验单位、两期列及所录入项目，查看59-61页图像。
A3: 合并利润表 | B3: reviewed | C3: ar2024 | D3: PDF p. 63-65 / 印刷页63-65 | E3: 区分营业收入/营业总收入与合并净利润/归母净利润，查看63-64页图像。
A4: 合并现金流量表 | B4: reviewed | C4: ar2024 | D4: PDF p. 66-68 / 印刷页66-68 | E4: 核验两期现金流与FX；67-68页图像核对。
A5: 合并权益变动表 | B5: partial | C5: equitynote | D5: PDF p. 70-72 / 印刷页70-72 | E5: 核验2024年分配及权益桥，读取2023年期初政策变更；未录入2023年完整所有者交易。
A6: 审计报告 | B6: reviewed | C6: audit | D6: PDF p. 55-58 / 印刷页55-58 | E6: 读取意见、关键审计事项、其他信息与责任段。
A7: 管理层讨论与分析 | B7: partial | C7: business | D7: PDF p. 7-9、17-21 / 印刷页7-9、17-21 | E7: 仅阅读业务、变动说明、渠道、投资及未来目标，未把全部MD&A标已读。
A8: 会计政策与编制基础 | B8: partial | C8: policy | D8: PDF p. 74-75、85 / 印刷页74-75、85 | E8: 确认准则、期间、合并原则、重要性及政策变更，未逐项复核全部政策。
A9: 现金与受限资金附注 | B9: reviewed | C9: cashnote | D9: PDF p. 86、116-117 / 印刷页86、116-117 | E9: 核对现金构成、受限资金和利润现金调节；117页图像核对。
A10: 关联方附注 | B10: partial | C10: related | D10: PDF p. 125-126、131-132、135 / 印刷页125-126、131-132、135 | E10: 重点阅读关联金融业务；未逐项核对全部关联采购销售及往来。
A11: 治理 | B11: partial | C11: governance | D11: PDF p. 31-32 / 印刷页31-32 | E11: 只阅读董事履职与审计委员会，未验证治理实际效果。
A12: 承诺及期后事项 | B12: reviewed | C12: commitments | D12: PDF p. 135-136 / 印刷页135-136 | E12: 读取未履行基金出资、拟分红及披露的回购安排，不代表后来执行情况。
A13: 2025年及后续披露 | B13: unavailable | C13: ar2024 | E13: 本次示例未纳入后续年度或季度资料。
