Workbook

Sheet Readme
A1: 字段 / field | B1: 内容 / value
A2: 任务 | B2: 港交所2025：经营增长、会计质量与资本现金连接
A3: 版本 | B3: hkex-2025-example-v1
A4: 信息截止 | B4: 2026-10-02
A5: 范围 | B5: consolidated
A6: 准则 | B6: HKFRS
A7: 单位 | B7: Facts D=原始值，E=倍数，F=基础单位。Calculations D=基础单位，E=展示值。
A8: 复算 | B8: 数值公式可编辑；修改主体、期间、币种、规则或资料后须重跑 export.py 复核口径。
A9: 勾稽精度 | B9: 金额残差按本次Decimal输入/计算保留的小数位ROUND，消除Excel二进制尾差，不改变业务容差；提高输入小数精度后须重跑导出。
A10: 缺口 | B10: 空值不是零。未执行程序、假设与已披露数据分别标识。
A11: 限制 | B11: 仅公开年报选定重大事项分析，不声称逐页全文或所有合同与控制已验证。
A12: 限制 | B12: 首次公告日未单独核验；批准报出日为2026-02-26。
... A15: 限制 | B15: 来源 annual, sr 的正式公布日期未核验；不得据此证明在信息截止日前已公开。当前披露内容可以继续分析，历史时点结论须补充公告时间证据。

Sheet Facts
A1: ID | B1: 原始科目 | C1: 证据 | D1: 原始数值 | E1: 倍数 | F1: 基础单位数值 | G1: 量纲 | H1: 币种 | I1: 实体 | J1: 范围 | K1: 开始 | L1: 结束 | M1: 统计类型 | N1: 状态 | O1: 准则 | P1: 说明 | Q1: 概念 | R1: 实物单位
A2: rev25 | B2: 营业收入 | C2: e_profit | D2: 23745 | E2: 1000000 | F2: =IF(COUNT(D2,E2)=2,D2*E2,NA()) -> 23745000000 | G2: money | H2: HKD | I2: 香港交易及结算所有限公司 | J2: consolidated | K2: 2025-01-01 | L2: 2025-12-31 | M2: flow | N2: reported | O2: HKFRS | Q2: rev
A3: rev24 | B3: 营业收入 | C3: e_profit | D3: 17346 | E3: 1000000 | F3: =IF(COUNT(D3,E3)=2,D3*E3,NA()) -> 17346000000 | G3: money | H3: HKD | I3: 香港交易及结算所有限公司 | J3: consolidated | K3: 2024-01-01 | L3: 2024-12-31 | M3: flow | N3: reported | O3: HKFRS | Q3: rev
A4: total_income25 | B4: 收入及其他收益 | C4: e_profit | D4: 29161 | E4: 1000000 | F4: =IF(COUNT(D4,E4)=2,D4*E4,NA()) -> 29161000000 | G4: money | H4: HKD | I4: 香港交易及结算所有限公司 | J4: consolidated | K4: 2025-01-01 | L4: 2025-12-31 | M4: flow | N4: reported | O4: HKFRS | Q4: total_income
A5: total_income24 | B5: 收入及其他收益 | C5: e_profit | D5: 22374 | E5: 1000000 | F5: =IF(COUNT(D5,E5)=2,D5*E5,NA()) -> 22374000000 | G5: money | H5: HKD | I5: 香港交易及结算所有限公司 | J5: consolidated | K5: 2024-01-01 | L5: 2024-12-31 | M5: flow | N5: reported | O5: HKFRS | Q5: total_income
A6: ni25 | B6: 净投资收益 | C6: e_profit | D6: 5111 | E6: 1000000 | F6: =IF(COUNT(D6,E6)=2,D6*E6,NA()) -> 5111000000 | G6: money | H6: HKD | I6: 香港交易及结算所有限公司 | J6: consolidated | K6: 2025-01-01 | L6: 2025-12-31 | M6: flow | N6: reported | O6: HKFRS | Q6: ni
A7: ni24 | B7: 净投资收益 | C7: e_profit | D7: 4927 | E7: 1000000 | F7: =IF(COUNT(D7,E7)=2,D7*E7,NA()) -> 4927000000 | G7: money | H7: HKD | I7: 香港交易及结算所有限公司 | J7: consolidated | K7: 2024-01-01 | L7: 2024-12-31 | M7: flow | N7: reported | O7: HKFRS | Q7: ni
A8: pbt25 | B8: 税前利润 | C8: e_profit | D8: 21158 | E8: 1000000 | F8: =IF(COUNT(D8,E8)=2,D8*E8,NA()) -> 21158000000 | G8: money | H8: HKD | I8: 香港交易及结算所有限公司 | J8: consolidated | K8: 2025-01-01 | L8: 2025-12-31 | M8: flow | N8: reported | O8: HKFRS | Q8: pbt
A9: pbt24 | B9: 税前利润 | C9: e_profit | D9: 14853 | E9: 1000000 | F9: =IF(COUNT(D9,E9)=2,D9*E9,NA()) -> 14853000000 | G9: money | H9: HKD | I9: 香港交易及结算所有限公司 | J9: consolidated | K9: 2024-01-01 | L9: 2024-12-31 | M9: flow | N9: reported | O9: HKFRS | Q9: pbt
A10: tax25 | B10: 所得税费用 | C10: e_profit | D10: 3321 | E10: 1000000 | F10: =IF(COUNT(D10,E10)=2,D10*E10,NA()) -> 3321000000 | G10: money | H10: HKD | I10: 香港交易及结算所有限公司 | J10: consolidated | K10: 2025-01-01 | L10: 2025-12-31 | M10: flow | N10: reported | O10: HKFRS | Q10: tax
A11: tax24 | B11: 所得税费用 | C11: e_profit | D11: 1698 | E11: 1000000 | F11: =IF(COUNT(D11,E11)=2,D11*E11,NA()) -> 1698000000 | G11: money | H11: HKD | I11: 香港交易及结算所有限公司 | J11: consolidated | K11: 2024-01-01 | L11: 2024-12-31 | M11: flow | N11: reported | O11: HKFRS | Q11: tax
A12: profit25 | B12: 集团净利润 | C12: e_profit | D12: 17837 | E12: 1000000 | F12: =IF(COUNT(D12,E12)=2,D12*E12,NA()) -> 17837000000 | G12: money | H12: HKD | I12: 香港交易及结算所有限公司 | J12: consolidated | K12: 2025-01-01 | L12: 2025-12-31 | M12: flow | N12: reported | O12: HKFRS | Q12: profit
A13: profit24 | B13: 集团净利润 | C13: e_profit | D13: 13155 | E13: 1000000 | F13: =IF(COUNT(D13,E13)=2,D13*E13,NA()) -> 13155000000 | G13: money | H13: HKD | I13: 香港交易及结算所有限公司 | J13: consolidated | K13: 2024-01-01 | L13: 2024-12-31 | M13: flow | N13: reported | O13: HKFRS | Q13: profit
... A48: divpaid | B48: 归母股息实付 | C48: e_cf | D48: 13722 | E48: 1000000 | F48: =IF(COUNT(D48,E48)=2,D48*E48,NA()) -> 13722000000 | G48: money | H48: HKD | I48: 香港交易及结算所有限公司 | J48: consolidated | K48: 2025-01-01 | L48: 2025-12-31 | M48: flow | N48: reported | O48: HKFRS | Q48: divpaid
A49: cfopen | B49: 现金流期初现金 | C49: e_cash | D49: 13910 | E49: 1000000 | F49: =IF(COUNT(D49,E49)=2,D49*E49,NA()) -> 13910000000 | G49: money | H49: HKD | I49: 香港交易及结算所有限公司 | J49: consolidated | L49: 2024-12-31 | M49: instant | N49: reported | O49: HKFRS | Q49: cfopen
A50: cfclose | B50: 现金流期末现金 | C50: e_cash | D50: 19353 | E50: 1000000 | F50: =IF(COUNT(D50,E50)=2,D50*E50,NA()) -> 19353000000 | G50: money | H50: HKD | I50: 香港交易及结算所有限公司 | J50: consolidated | L50: 2025-12-31 | M50: instant | N50: reported | O50: HKFRS | Q50: cfclose
A51: cash_bs | B51: 资产负债表现金 | C51: e_cash | D51: 182724 | E51: 1000000 | F51: =IF(COUNT(D51,E51)=2,D51*E51,NA()) -> 182724000000 | G51: money | H51: HKD | I51: 香港交易及结算所有限公司 | J51: consolidated | L51: 2025-12-31 | M51: instant | N51: reported | O51: HKFRS | Q51: cash_bs
A52: cash_a | B52: A股现金 | C52: e_cash | D52: 2549 | E52: 1000000 | F52: =IF(COUNT(D52,E52)=2,D52*E52,NA()) -> 2549000000 | G52: money | H52: HKD | I52: 香港交易及结算所有限公司 | J52: consolidated | L52: 2025-12-31 | M52: instant | N52: reported | O52: HKFRS | Q52: cash_a
A53: cash_corp | B53: 公司基金现金 | C53: e_cash | D53: 20676 | E53: 1000000 | F53: =IF(COUNT(D53,E53)=2,D53*E53,NA()) -> 20676000000 | G53: money | H53: HKD | I53: 香港交易及结算所有限公司 | J53: consolidated | L53: 2025-12-31 | M53: instant | N53: reported | O53: HKFRS | Q53: cash_corp
A54: cash_margin | B54: 保证金现金 | C54: e_cash | D54: 130052 | E54: 1000000 | F54: =IF(COUNT(D54,E54)=2,D54*E54,NA()) -> 130052000000 | G54: money | H54: HKD | I54: 香港交易及结算所有限公司 | J54: consolidated | L54: 2025-12-31 | M54: instant | N54: reported | O54: HKFRS | Q54: cash_margin
A55: cash_clearing | B55: 清算基金现金 | C55: e_cash | D55: 29447 | E55: 1000000 | F55: =IF(COUNT(D55,E55)=2,D55*E55,NA()) -> 29447000000 | G55: money | H55: HKD | I55: 香港交易及结算所有限公司 | J55: consolidated | L55: 2025-12-31 | M55: instant | N55: reported | O55: HKFRS | Q55: cash_clearing
A56: cash_skin | B56: 公司专用现金 | C56: e_cash | D56: 1323 | E56: 1000000 | F56: =IF(COUNT(D56,E56)=2,D56*E56,NA()) -> 1323000000 | G56: money | H56: HKD | I56: 香港交易及结算所有限公司 | J56: consolidated | L56: 2025-12-31 | M56: instant | N56: reported | O56: HKFRS | Q56: cash_skin
A57: margin_fvoci | B57: 保证金FVOCI | C57: e_margin | D57: 48327 | E57: 1000000 | F57: =IF(COUNT(D57,E57)=2,D57*E57,NA()) -> 48327000000 | G57: money | H57: HKD | I57: 香港交易及结算所有限公司 | J57: consolidated | L57: 2025-12-31 | M57: instant | N57: reported | O57: HKFRS | Q57: margin_fvoci
A58: margin_amort | B58: 保证金摊余成本 | C58: e_margin | D58: 69176 | E58: 1000000 | F58: =IF(COUNT(D58,E58)=2,D58*E58,NA()) -> 69176000000 | G58: money | H58: HKD | I58: 香港交易及结算所有限公司 | J58: consolidated | L58: 2025-12-31 | M58: instant | N58: reported | O58: HKFRS | Q58: margin_amort
A59: margin_china | B59: ChinaClear持有 | C59: e_margin | D59: 20867 | E59: 1000000 | F59: =IF(COUNT(D59,E59)=2,D59*E59,NA()) -> 20867000000 | G59: money | H59: HKD | I59: 香港交易及结算所有限公司 | J59: consolidated | L59: 2025-12-31 | M59: instant | N59: reported | O59: HKFRS | Q59: margin_china
A60: margin_shch | B60: SHCH持有 | C60: e_margin | D60: 799 | E60: 1000000 | F60: =IF(COUNT(D60,E60)=2,D60*E60,NA()) -> 799000000 | G60: money | H60: HKD | I60: 香港交易及结算所有限公司 | J60: consolidated | L60: 2025-12-31 | M60: instant | N60: reported | O60: HKFRS | Q60: margin_shch
... A69: eqopen | B69: 集团权益期初 | C69: e_equity | D69: 54407 | E69: 1000000 | F69: =IF(COUNT(D69,E69)=2,D69*E69,NA()) -> 54407000000 | G69: money | H69: HKD | I69: 香港交易及结算所有限公司 | J69: consolidated | L69: 2024-12-31 | M69: instant | N69: reported | O69: HKFRS | Q69: eqopen
A70: oci | B70: 其他综合收益 | C70: e_equity | D70: 369 | E70: 1000000 | F70: =IF(COUNT(D70,E70)=2,D70*E70,NA()) -> 369000000 | G70: money | H70: HKD | I70: 香港交易及结算所有限公司 | J70: consolidated | K70: 2025-01-01 | L70: 2025-12-31 | M70: flow | N70: reported | O70: HKFRS | Q70: oci
A71: divdec1 | B71: 本期确认上年末次股息 | C71: e_equity | D71: -6193 | E71: 1000000 | F71: =IF(COUNT(D71,E71)=2,D71*E71,NA()) -> -6193000000 | G71: money | H71: HKD | I71: 香港交易及结算所有限公司 | J71: consolidated | K71: 2025-01-01 | L71: 2025-12-31 | M71: flow | N71: reported | O71: HKFRS | Q71: divdec
A72: divdec2 | B72: 本期确认中期股息 | C72: e_equity | D72: -7583 | E72: 1000000 | F72: =IF(COUNT(D72,E72)=2,D72*E72,NA()) -> -7583000000 | G72: money | H72: HKD | I72: 香港交易及结算所有限公司 | J72: consolidated | K72: 2025-01-01 | L72: 2025-12-31 | M72: flow | N72: reported | O72: HKFRS | Q72: divdec
A73: divforfeit | B73: 未领股息没收权益 | C73: e_equity | D73: 34 | E73: 1000000 | F73: =IF(COUNT(D73,E73)=2,D73*E73,NA()) -> 34000000 | G73: money | H73: HKD | I73: 香港交易及结算所有限公司 | J73: consolidated | K73: 2025-01-01 | L73: 2025-12-31 | M73: flow | N73: reported | O73: HKFRS | Q73: divforfeit
A74: awardpurchase | B74: 奖励股份购买 | C74: e_equity | D74: -512 | E74: 1000000 | F74: =IF(COUNT(D74,E74)=2,D74*E74,NA()) -> -512000000 | G74: money | H74: HKD | I74: 香港交易及结算所有限公司 | J74: consolidated | K74: 2025-01-01 | L74: 2025-12-31 | M74: flow | N74: reported | O74: HKFRS | Q74: awardpurchase
A75: awardtax | B75: 奖励税项权益 | C75: e_equity | D75: 9 | E75: 1000000 | F75: =IF(COUNT(D75,E75)=2,D75*E75,NA()) -> 9000000 | G75: money | H75: HKD | I75: 香港交易及结算所有限公司 | J75: consolidated | K75: 2025-01-01 | L75: 2025-12-31 | M75: flow | N75: reported | O75: HKFRS | Q75: awardtax
A76: putinterest | B76: 看跌期权利息 | C76: e_equity | D76: 5 | E76: 1000000 | F76: =IF(COUNT(D76,E76)=2,D76*E76,NA()) -> 5000000 | G76: money | H76: HKD | I76: 香港交易及结算所有限公司 | J76: consolidated | K76: 2025-01-01 | L76: 2025-12-31 | M76: flow | N76: reported | O76: HKFRS | Q76: putinterest
A77: ncidiv | B77: 子公司非控股分配 | C77: e_equity | D77: 59 | E77: 1000000 | F77: =IF(COUNT(D77,E77)=2,D77*E77,NA()) -> 59000000 | G77: money | H77: HKD | I77: 香港交易及结算所有限公司 | J77: consolidated | K77: 2025-01-01 | L77: 2025-12-31 | M77: flow | N77: reported | O77: HKFRS | Q77: ncidiv
A78: putopen | B78: 看跌期权债务期初 | C78: e_equity | D78: 452 | E78: 1000000 | F78: =IF(COUNT(D78,E78)=2,D78*E78,NA()) -> 452000000 | G78: money | H78: HKD | I78: 香港交易及结算所有限公司 | J78: consolidated | L78: 2024-12-31 | M78: instant | N78: reported | O78: HKFRS | Q78: putopen
A79: putclose | B79: 看跌期权债务期末 | C79: e_equity | D79: 398 | E79: 1000000 | F79: =IF(COUNT(D79,E79)=2,D79*E79,NA()) -> 398000000 | G79: money | H79: HKD | I79: 香港交易及结算所有限公司 | J79: consolidated | L79: 2025-12-31 | M79: instant | N79: reported | O79: HKFRS | Q79: putclose
A80: gwopen | B80: 商誉期初 | C80: e_estimate | D80: 13297 | E80: 1000000 | F80: =IF(COUNT(D80,E80)=2,D80*E80,NA()) -> 13297000000 | G80: money | H80: HKD | I80: 香港交易及结算所有限公司 | J80: consolidated | L80: 2024-12-31 | M80: instant | N80: reported | O80: HKFRS | Q80: gwopen
A81: gwclose | B81: 商誉期末 | C81: e_estimate | D81: 13274 | E81: 1000000 | F81: =IF(COUNT(D81,E81)=2,D81*E81,NA()) -> 13274000000 | G81: money | H81: HKD | I81: 香港交易及结算所有限公司 | J81: consolidated | L81: 2025-12-31 | M81: instant | N81: reported | O81: HKFRS | Q81: gwclose
A82: gwfx | B82: 商誉汇兑 | C82: e_estimate | D82: 32 | E82: 1000000 | F82: =IF(COUNT(D82,E82)=2,D82*E82,NA()) -> 32000000 | G82: money | H82: HKD | I82: 香港交易及结算所有限公司 | J82: consolidated | K82: 2025-01-01 | L82: 2025-12-31 | M82: flow | N82: reported | O82: HKFRS | Q82: gwfx
...

Sheet Calculations
A1: ID | B1: 指标或桥 | C1: 基础单位公式 | D1: 基础单位结果 | E1: 展示结果 | F1: 状态 | G1: 不计算原因 | H1: 定义 | I1: 解释边界 | J1: 展示单位 | K1: 倍数 | L1: 实体 | M1: 范围 | N1: 开始 | O1: 结束
A2: rev_growth | B2: rev同比 | C2: =IF(OR('Facts'!F3<=0,'Facts'!F2<0),NA(),((('Facts'!F2-'Facts'!F3)/'Facts'!F3))*1) | D2: =IF(OR('Facts'!F3<=0,'Facts'!F2<0),NA(),((('Facts'!F2-'Facts'!F3)/'Facts'!F3))*1) -> 0.36890349 | E2: =D2/K2 -> 0.36890349 | F2: =IF(ISNUMBER(D2),"calculated","not_calculated") -> calculated | G2: =IF(ISNUMBER(D2),"","检查缺失值、分母与输入；口径变更须重跑Python") | H2: 同口径两年全年变化 | I2: 仅证明所列口径的算式；经济实质和完整性另据原文及反证判断。 | J2: % | K2: 1 | L2: 香港交易及结算所有限公司 | M2: consolidated | N2: 2025-01-01 | O2: 2025-12-31
A3: profit_growth | B3: profit同比 | C3: =IF(OR('Facts'!F13<=0,'Facts'!F12<0),NA(),((('Facts'!F12-'Facts'!F13)/'Facts'!F13))*1) | D3: =IF(OR('Facts'!F13<=0,'Facts'!F12<0),NA(),((('Facts'!F12-'Facts'!F13)/'Facts'!F13))*1) -> 0.3559103 | E3: =D3/K3 -> 0.3559103 | F3: =IF(ISNUMBER(D3),"calculated","not_calculated") -> calculated | G3: =IF(ISNUMBER(D3),"","检查缺失值、分母与输入；口径变更须重跑Python") | H3: 同口径两年全年变化 | I3: 仅证明所列口径的算式；经济实质和完整性另据原文及反证判断。 | J3: % | K3: 1 | L3: 香港交易及结算所有限公司 | M3: consolidated | N3: 2025-01-01 | O3: 2025-12-31
A4: pbt_growth | B4: pbt同比 | C4: =IF(OR('Facts'!F9<=0,'Facts'!F8<0),NA(),((('Facts'!F8-'Facts'!F9)/'Facts'!F9))*1) | D4: =IF(OR('Facts'!F9<=0,'Facts'!F8<0),NA(),((('Facts'!F8-'Facts'!F9)/'Facts'!F9))*1) -> 0.42449337 | E4: =D4/K4 -> 0.42449337 | F4: =IF(ISNUMBER(D4),"calculated","not_calculated") -> calculated | G4: =IF(ISNUMBER(D4),"","检查缺失值、分母与输入；口径变更须重跑Python") | H4: 同口径两年全年变化 | I4: 仅证明所列口径的算式；经济实质和完整性另据原文及反证判断。 | J4: % | K4: 1 | L4: 香港交易及结算所有限公司 | M4: consolidated | N4: 2025-01-01 | O4: 2025-12-31
A5: ni_growth | B5: ni同比 | C5: =IF(OR('Facts'!F7<=0,'Facts'!F6<0),NA(),((('Facts'!F6-'Facts'!F7)/'Facts'!F7))*1) | D5: =IF(OR('Facts'!F7<=0,'Facts'!F6<0),NA(),((('Facts'!F6-'Facts'!F7)/'Facts'!F7))*1) -> 0.037345241 | E5: =D5/K5 -> 0.037345241 | F5: =IF(ISNUMBER(D5),"calculated","not_calculated") -> calculated | G5: =IF(ISNUMBER(D5),"","检查缺失值、分母与输入；口径变更须重跑Python") | H5: 同口径两年全年变化 | I5: 仅证明所列口径的算式；经济实质和完整性另据原文及反证判断。 | J5: % | K5: 1 | L5: 香港交易及结算所有限公司 | M5: consolidated | N5: 2025-01-01 | O5: 2025-12-31
A6: revgain | B6: 收入增量 | C6: =(('Facts'!F2-'Facts'!F3))*1 | D6: =(('Facts'!F2-'Facts'!F3))*1 -> 6399000000 | E6: =D6/K6 -> 6399 | F6: =IF(ISNUMBER(D6),"calculated","not_calculated") -> calculated | G6: =IF(ISNUMBER(D6),"","检查缺失值、分母与输入；口径变更须重跑Python") | H6: 营业收入同比增量 | I6: 仅证明所列口径的算式；经济实质和完整性另据原文及反证判断。 | J6: HKD × 1000000 | K6: 1000000 | L6: 香港交易及结算所有限公司 | M6: consolidated | N6: 2025-01-01 | O6: 2025-12-31
A7: totalgain | B7: 收入及收益增量 | C7: =(('Facts'!F4-'Facts'!F5))*1 | D7: =(('Facts'!F4-'Facts'!F5))*1 -> 6787000000 | E7: =D7/K7 -> 6787 | F7: =IF(ISNUMBER(D7),"calculated","not_calculated") -> calculated | G7: =IF(ISNUMBER(D7),"","检查缺失值、分母与输入；口径变更须重跑Python") | H7: 总收益增量 | I7: 仅证明所列口径的算式；经济实质和完整性另据原文及反证判断。 | J7: HKD × 1000000 | K7: 1000000 | L7: 香港交易及结算所有限公司 | M7: consolidated | N7: 2025-01-01 | O7: 2025-12-31
A8: revgainshare | B8: 收入对总增量比 | C8: =IF('Calculations'!D7<=0,NA(),(('Calculations'!D6/'Calculations'!D7))*1) | D8: =IF('Calculations'!D7<=0,NA(),(('Calculations'!D6/'Calculations'!D7))*1) -> 0.94283188 | E8: =D8/K8 -> 0.94283188 | F8: =IF(ISNUMBER(D8),"calculated","not_calculated") -> calculated | G8: =IF(ISNUMBER(D8),"","检查缺失值、分母与输入；口径变更须重跑Python") | H8: 同口径增量占比 | I8: 仅证明所列口径的算式；经济实质和完整性另据原文及反证判断。 | J8: % | K8: 1 | L8: 香港交易及结算所有限公司 | M8: consolidated | N8: 2025-01-01 | O8: 2025-12-31
A9: cashebitdagain | B9: 现金分部EBITDA增量 | C9: =(('Facts'!F14-'Facts'!F15))*1 | D9: =(('Facts'!F14-'Facts'!F15))*1 -> 5229000000 | E9: =D9/K9 -> 5229 | F9: =IF(ISNUMBER(D9),"calculated","not_calculated") -> calculated | G9: =IF(ISNUMBER(D9),"","检查缺失值、分母与输入；口径变更须重跑Python") | H9: 公司定义EBITDA增量 | I9: 仅证明所列口径的算式；经济实质和完整性另据原文及反证判断。 | J9: HKD × 1000000 | K9: 1000000 | L9: 香港交易及结算所有限公司 | M9: consolidated | N9: 2025-01-01 | O9: 2025-12-31
A10: ebitdagain | B10: 集团EBITDA增量 | C10: =(('Facts'!F16-'Facts'!F17))*1 | D10: =(('Facts'!F16-'Facts'!F17))*1 -> 6515000000 | E10: =D10/K10 -> 6515 | F10: =IF(ISNUMBER(D10),"calculated","not_calculated") -> calculated | G10: =IF(ISNUMBER(D10),"","检查缺失值、分母与输入；口径变更须重跑Python") | H10: 公司定义EBITDA增量 | I10: 仅证明所列口径的算式；经济实质和完整性另据原文及反证判断。 | J10: HKD × 1000000 | K10: 1000000 | L10: 香港交易及结算所有限公司 | M10: consolidated | N10: 2025-01-01 | O10: 2025-12-31
A11: cashgainshare | B11: 现金分部占EBITDA增量比 | C11: =IF('Calculations'!D10<=0,NA(),(('Calculations'!D9/'Calculations'!D10))*1) | D11: =IF('Calculations'!D10<=0,NA(),(('Calculations'!D9/'Calculations'!D10))*1) -> 0.80260936 | E11: =D11/K11 -> 0.80260936 | F11: =IF(ISNUMBER(D11),"calculated","not_calculated") -> calculated | G11: =IF(ISNUMBER(D11),"","检查缺失值、分母与输入；口径变更须重跑Python") | H11: 增长集中程度而非份额因果 | I11: 仅证明所列口径的算式；经济实质和完整性另据原文及反证判断。 | J11: % | K11: 1 | L11: 香港交易及结算所有限公司 | M11: consolidated | N11: 2025-01-01 | O11: 2025-12-31
A12: ops_rebuilt | B12: 税前利润至主营运现金复算 | C12: =(('Facts'!F8*1)+('Facts'!F18*1)+('Facts'!F19*1)+('Facts'!F20*1)+('Facts'!F21*1)+('Facts'!F22*1)+('Facts'!F23*1)+('Facts'!F24*1)+('Facts'!F25*1)+('Facts'!F26*1)+('Facts'!F27*1)+('Facts'!F28*1)+('Facts'!F29*1)+('Facts'!F30*1)+('Facts'!F31*1)+('Facts'!F32*1)+('Facts'!F33*1)+('Facts'!F34*1))*1 | D12: =(('Facts'!F8*1)+('Facts'!F18*1)+('Facts'!F19*1)+('Facts'!F20*1)+('Facts'!F21*1)+('Facts'!F22*1)+('Facts'!F23*1)+('Facts'!F24*1)+('Facts'!F25*1)+('Facts'!F26*1)+('Facts'!F27*1)+('Facts'!F28*1)+('Facts'!F29*1)+('Facts'!F30*1)+('Facts'!F31*1)+('Facts'!F32*1)+('Facts'!F33*1)+('Facts'!F34*1))*1 -> 19005000000 | E12: =D12/K12 -> 19005 | F12: =IF(ISNUMBER(D12),"calculated","not_calculated") -> calculated | G12: =IF(ISNUMBER(D12),"","检查缺失值、分母与输入；口径变更须重跑Python") | H12: 逐行使用附注47(a)带符号调整 | I12: 仅证明所列口径的算式；经济实质和完整性另据原文及反证判断。 | J12: HKD × 1000000 | K12: 1000000 | L12: 香港交易及结算所有限公司 | M12: consolidated | N12: 2025-01-01 | O12: 2025-12-31
A13: principal_rebuilt | B13: 主要经营现金复算 | C13: =(('Calculations'!D12*1)+('Facts'!F36*1)+('Facts'!F37*1)+('Facts'!F38*1)+('Facts'!F39*1))*1 | D13: =(('Calculations'!D12*1)+('Facts'!F36*1)+('Facts'!F37*1)+('Facts'!F38*1)+('Facts'!F39*1))*1 -> 19855000000 | E13: =D13/K13 -> 19855 | F13: =IF(ISNUMBER(D13),"calculated","not_calculated") -> calculated | G13: =IF(ISNUMBER(D13),"","检查缺失值、分母与输入；口径变更须重跑Python") | H13: 由主营运小计连接税息及互换现金 | I13: 仅证明所列口径的算式；经济实质和完整性另据原文及反证判断。 | J13: HKD × 1000000 | K13: 1000000 | L13: 香港交易及结算所有限公司 | M13: consolidated | N13: 2025-01-01 | O13: 2025-12-31
A14: cfo_rebuilt | B14: CFO复算 | C14: =(('Calculations'!D13*1)+('Facts'!F41*1))*1 | D14: =(('Calculations'!D13*1)+('Facts'!F41*1))*1 -> 25627000000 | E14: =D14/K14 -> 25627 | F14: =IF(ISNUMBER(D14),"calculated","not_calculated") -> calculated | G14: =IF(ISNUMBER(D14),"","检查缺失值、分母与输入；口径变更须重跑Python") | H14: HKAS7 CFO含外部投资组合赎回 | I14: 仅证明所列口径的算式；经济实质和完整性另据原文及反证判断。 | J14: HKD × 1000000 | K14: 1000000 | L14: 香港交易及结算所有限公司 | M14: consolidated | N14: 2025-01-01 | O14: 2025-12-31
A15: cash_rebuilt | B15: 期末现金滚动 | C15: =(('Facts'!F49*1)+('Facts'!F42*1)+('Facts'!F43*1)+('Facts'!F44*1)+('Facts'!F45*1))*1 | D15: =(('Facts'!F49*1)+('Facts'!F42*1)+('Facts'!F43*1)+('Facts'!F44*1)+('Facts'!F45*1))*1 -> 19353000000 | E15: =D15/K15 -> 19353 | F15: =IF(ISNUMBER(D15),"calculated","not_calculated") -> calculated | G15: =IF(ISNUMBER(D15),"","检查缺失值、分母与输入；口径变更须重跑Python") | H15: 仅现金流量表定义范围 | I15: 仅证明所列口径的算式；经济实质和完整性另据原文及反证判断。 | J15: HKD × 1000000 | K15: 1000000 | L15: 香港交易及结算所有限公司 | M15: consolidated | N15: 2025-01-01 | O15: 2025-12-31
A16: cash_total_rebuilt | B16: 报表现金分池 | C16: =(('Facts'!F52*1)+('Facts'!F53*1)+('Facts'!F54*1)+('Facts'!F55*1))*1 | D16: =(('Facts'!F52*1)+('Facts'!F53*1)+('Facts'!F54*1)+('Facts'!F55*1))*1 -> 182724000000 | E16: =D16/K16 -> 182724 | F16: =IF(ISNUMBER(D16),"calculated","not_calculated") -> calculated | G16: =IF(ISNUMBER(D16),"","检查缺失值、分母与输入；口径变更须重跑Python") | H16: 四池相加 | I16: 仅证明所列口径的算式；经济实质和完整性另据原文及反证判断。 | J16: HKD × 1000000 | K16: 1000000 | L16: 香港交易及结算所有限公司 | M16: consolidated | O16: 2025-12-31
A17: corp_cash_rebuilt | B17: 公司非清算专用现金 | C17: =(('Facts'!F53-'Facts'!F56))*1 | D17: =(('Facts'!F53-'Facts'!F56))*1 -> 19353000000 | E17: =D17/K17 -> 19353 | F17: =IF(ISNUMBER(D17),"calculated","not_calculated") -> calculated | G17: =IF(ISNUMBER(D17),"","检查缺失值、分母与输入；口径变更须重跑Python") | H17: 公司基金扣披露专用现金，不证明母公司自由调拨 | I17: 仅证明所列口径的算式；经济实质和完整性另据原文及反证判断。 | J17: HKD × 1000000 | K17: 1000000 | L17: 香港交易及结算所有限公司 | M17: consolidated | O17: 2025-12-31
A18: margin_rebuilt | B18: 保证金资产义务桥 | C18: =(('Facts'!F54*1)+('Facts'!F57*1)+('Facts'!F58*1)+('Facts'!F59*1)+('Facts'!F60*1)+('Facts'!F61*1))*1 | D18: =(('Facts'!F54*1)+('Facts'!F57*1)+('Facts'!F58*1)+('Facts'!F59*1)+('Facts'!F60*1)+('Facts'!F61*1))*1 -> 269243000000 | E18: =D18/K18 -> 269243 | F18: =IF(ISNUMBER(D18),"calculated","not_calculated") -> calculated | G18: =IF(ISNUMBER(D18),"","检查缺失值、分母与输入；口径变更须重跑Python") | H18: 全列六项原披露资产 | I18: 仅证明所列口径的算式；经济实质和完整性另据原文及反证判断。 | J18: HKD × 1000000 | K18: 1000000 | L18: 香港交易及结算所有限公司 | M18: consolidated | O18: 2025-12-31
A19: clear_rebuilt | B19: 清算基金净资产 | C19: =(('Facts'!F55*1)+('Facts'!F63*1)+('Facts'!F64*-1))*1 | D19: =(('Facts'!F55*1)+('Facts'!F63*1)+('Facts'!F64*-1))*1 -> 35796000000 | E19: =D19/K19 -> 35796 | F19: =IF(ISNUMBER(D19),"calculated","not_calculated") -> calculated | G19: =IF(ISNUMBER(D19),"","检查缺失值、分母与输入；口径变更须重跑Python") | H19: 清算基金资产扣特定其他金融负债 | I19: 仅证明所列口径的算式；经济实质和完整性另据原文及反证判断。 | J19: HKD × 1000000 | K19: 1000000 | L19: 香港交易及结算所有限公司 | M19: consolidated | O19: 2025-12-31
A20: eq_balance | B20: 资产减负债 | C20: =(('Facts'!F66-'Facts'!F67))*1 | D20: =(('Facts'!F66-'Facts'!F67))*1 -> 58729000000 | E20: =D20/K20 -> 58729 | F20: =IF(ISNUMBER(D20),"calculated","not_calculated") -> calculated | G20: =IF(ISNUMBER(D20),"","检查缺失值、分母与输入；口径变更须重跑Python") | H20: 集团总权益 | I20: 仅证明所列口径的算式；经济实质和完整性另据原文及反证判断。 | J20: HKD × 1000000 | K20: 1000000 | L20: 香港交易及结算所有限公司 | M20: consolidated | O20: 2025-12-31
A21: eq_rebuilt | B21: 全权益滚动 | C21: =(('Facts'!F69*1)+('Facts'!F12*1)+('Facts'!F70*1)+('Facts'!F71*1)+('Facts'!F72*1)+('Facts'!F73*1)+('Facts'!F74*1)+('Facts'!F23*1)+('Facts'!F75*1))*1 | D21: =(('Facts'!F69*1)+('Facts'!F12*1)+('Facts'!F70*1)+('Facts'!F71*1)+('Facts'!F72*1)+('Facts'!F73*1)+('Facts'!F74*1)+('Facts'!F23*1)+('Facts'!F75*1))*1 -> 58729000000 | E21: =D21/K21 -> 58729 | F21: =IF(ISNUMBER(D21),"calculated","not_calculated") -> calculated | G21: =IF(ISNUMBER(D21),"","检查缺失值、分母与输入；口径变更须重跑Python") | H21: 完整Total equity列；储备转拨、股份归属与非控股分配的总权益净额为零，原列位另留证 | I21: 仅证明所列口径的算式；经济实质和完整性另据原文及反证判断。 | J21: HKD × 1000000 | K21: 1000000 | L21: 香港交易及结算所有限公司 | M21: consolidated | N21: 2025-01-01 | O21: 2025-12-31
A22: put_rebuilt | B22: 看跌期权负债滚动 | C22: =(('Facts'!F78*1)+('Facts'!F76*1)+('Facts'!F77*-1))*1 | D22: =(('Facts'!F78*1)+('Facts'!F76*1)+('Facts'!F77*-1))*1 -> 398000000 | E22: =D22/K22 -> 398 | F22: =IF(ISNUMBER(D22),"calculated","not_calculated") -> calculated | G22: =IF(ISNUMBER(D22),"","检查缺失值、分母与输入；口径变更须重跑Python") | H22: 分配减少负债并非本期集团权益减少 | I22: 仅证明所列口径的算式；经济实质和完整性另据原文及反证判断。 | J22: HKD × 1000000 | K22: 1000000 | L22: 香港交易及结算所有限公司 | M22: consolidated | N22: 2025-01-01 | O22: 2025-12-31
A23: gw_rebuilt | B23: 商誉滚动 | C23: =(('Facts'!F80*1)+('Facts'!F82*1)+('Facts'!F83*-1))*1 | D23: =(('Facts'!F80*1)+('Facts'!F82*1)+('Facts'!F83*-1))*1 -> 13274000000 | E23: =D23/K23 -> 13274 | F23: =IF(ISNUMBER(D23),"calculated","not_calculated") -> calculated | G23: =IF(ISNUMBER(D23),"","检查缺失值、分母与输入；口径变更须重跑Python") | H23: 汇兑与减值分开 | I23: 仅证明所列口径的算式；经济实质和完整性另据原文及反证判断。 | J23: HKD × 1000000 | K23: 1000000 | L23: 香港交易及结算所有限公司 | M23: consolidated | N23: 2025-01-01 | O23: 2025-12-31
A24: sw_rebuilt | B24: 软件净值滚动 | C24: =(('Facts'!F91*1)+('Facts'!F84*1)+('Facts'!F85*1)+('Facts'!F86*-1)+('Facts'!F87*-1)+('Facts'!F88*-1)+('Facts'!F89*1))*1 | D24: =(('Facts'!F91*1)+('Facts'!F84*1)+('Facts'!F85*1)+('Facts'!F86*-1)+('Facts'!F87*-1)+('Facts'!F88*-1)+('Facts'!F89*1))*1 -> 4341000000 | E24: =D24/K24 -> 4341 | F24: =IF(ISNUMBER(D24),"calculated","not_calculated") -> calculated | G24: =IF(ISNUMBER(D24),"","检查缺失值、分母与输入；口径变更须重跑Python") | H24: 成本和累计摊销分别读取后净额桥 | I24: 仅证明所列口径的算式；经济实质和完整性另据原文及反证判断。 | J24: HKD × 1000000 | K24: 1000000 | L24: 香港交易及结算所有限公司 | M24: consolidated | N24: 2025-01-01 | O24: 2025-12-31
A25: selected_cash | B25: 主要经营现金减长期经营资产现金付款 | C25: =(('Facts'!F40*1)+('Facts'!F46*-1)+('Facts'!F47*-1))*1 | D25: =(('Facts'!F40*1)+('Facts'!F46*-1)+('Facts'!F47*-1))*1 -> 14974000000 | E25: =D25/K25 -> 14974 | F25: =IF(ISNUMBER(D25),"calculated","not_calculated") -> calculated | G25: =IF(ISNUMBER(D25),"","检查缺失值、分母与输入；口径变更须重跑Python") | H25: 不含投资组合赎回；未扣其他投资、租赁、股息，不称FCFF | I25: 仅证明所列口径的算式；经济实质和完整性另据原文及反证判断。 | J25: HKD × 1000000 | K25: 1000000 | L25: 香港交易及结算所有限公司 | M25: consolidated | N25: 2025-01-01 | O25: 2025-12-31
A26: after_div | B26: 上述现金指标减归母股息实付 | C26: =(('Calculations'!D25-'Facts'!F48))*1 | D26: =(('Calculations'!D25-'Facts'!F48))*1 -> 1252000000 | E26: =D26/K26 -> 1252 | F26: =IF(ISNUMBER(D26),"calculated","not_calculated") -> calculated | G26: =IF(ISNUMBER(D26),"","检查缺失值、分母与输入；口径变更须重跑Python") | H26: 只作已列付款覆盖观察，不替代融资流动性预测 | I26: 仅证明所列口径的算式；经济实质和完整性另据原文及反证判断。 | J26: HKD × 1000000 | K26: 1000000 | L26: 香港交易及结算所有限公司 | M26: consolidated | N26: 2025-01-01 | O26: 2025-12-31
A27: etr25 | B27: 本年有效税率 | C27: =IF('Facts'!F8<=0,NA(),(('Facts'!F10/'Facts'!F8))*1) | D27: =IF('Facts'!F8<=0,NA(),(('Facts'!F10/'Facts'!F8))*1) -> 0.15696191 | E27: =D27/K27 -> 0.15696191 | F27: =IF(ISNUMBER(D27),"calculated","not_calculated") -> calculated | G27: =IF(ISNUMBER(D27),"","检查缺失值、分母与输入；口径变更须重跑Python") | H27: 合并所得税除税前利润 | I27: 仅证明所列口径的算式；经济实质和完整性另据原文及反证判断。 | J27: % | K27: 1 | L27: 香港交易及结算所有限公司 | M27: consolidated | N27: 2025-01-01 | O27: 2025-12-31
A28: taxgain | B28: 所得税增量 | C28: =(('Facts'!F10-'Facts'!F11))*1 | D28: =(('Facts'!F10-'Facts'!F11))*1 -> 1623000000 | E28: =D28/K28 -> 1623 | F28: =IF(ISNUMBER(D28),"calculated","not_calculated") -> calculated | G28: =IF(ISNUMBER(D28),"","检查缺失值、分母与输入；口径变更须重跑Python") | H28: 同口径两年税额差 | I28: 仅证明所列口径的算式；经济实质和完整性另据原文及反证判断。 | J28: HKD × 1000000 | K28: 1000000 | L28: 香港交易及结算所有限公司 | M28: consolidated | N28: 2025-01-01 | O28: 2025-12-31
A29: topupshare | B29: 补足税占税增量 | C29: =IF('Calculations'!D28<=0,NA(),(('Facts'!F90/'Calculations'!D28))*1) | D29: =IF('Calculations'!D28<=0,NA(),(('Facts'!F90/'Calculations'!D28))*1) -> 0.4319162 | E29: =D29/K29 -> 0.4319162 | F29: =IF(ISNUMBER(D29),"calculated","not_calculated") -> calculated | G29: =IF(ISNUMBER(D29),"","检查缺失值、分母与输入；口径变更须重跑Python") | H29: 税额增量归因的一部分，不是整体ETR因果归因 | I29: 仅证明所列口径的算式；经济实质和完整性另据原文及反证判断。 | J29: % | K29: 1 | L29: 香港交易及结算所有限公司 | M29: consolidated | N29: 2025-01-01 | O29: 2025-12-31

Sheet Reconciliations
A1: ID | B1: 勾稽 | C1: 实际 | D1: 目标 | E1: 残差 基础单位 | F1: 容差 基础单位 | G1: 状态 | H1: 容差依据 | I1: 未测试原因 | J1: 金额残差小数位
A2: r_ops | B2: r_ops | C2: ops_rebuilt | D2: netops | E2: =ROUND('Calculations'!D12-'Facts'!F35,J2) -> 0 | F2: 0 | G2: =IF(COUNT(E2,F2)<2,"not_tested",IF(ABS(E2)<=F2,"within_input_tolerance","unexplained_difference")) -> within_input_tolerance | H2: 本次选择的披露百万元整数可以精确闭合，未以审计重要性设容差。 | I2: =IF(ISNUMBER(E2),"","missing or unavailable input") | J2: 0
A3: r_principal | B3: r_principal | C3: principal_rebuilt | D3: principal | E3: =ROUND('Calculations'!D13-'Facts'!F40,J3) -> 0 | F3: 0 | G3: =IF(COUNT(E3,F3)<2,"not_tested",IF(ABS(E3)<=F3,"within_input_tolerance","unexplained_difference")) -> within_input_tolerance | H3: 本次选择的披露百万元整数可以精确闭合，未以审计重要性设容差。 | I3: =IF(ISNUMBER(E3),"","missing or unavailable input") | J3: 0
A4: r_cfo | B4: r_cfo | C4: cfo_rebuilt | D4: cfo | E4: =ROUND('Calculations'!D14-'Facts'!F42,J4) -> 0 | F4: 0 | G4: =IF(COUNT(E4,F4)<2,"not_tested",IF(ABS(E4)<=F4,"within_input_tolerance","unexplained_difference")) -> within_input_tolerance | H4: 本次选择的披露百万元整数可以精确闭合，未以审计重要性设容差。 | I4: =IF(ISNUMBER(E4),"","missing or unavailable input") | J4: 0
A5: r_cash | B5: r_cash | C5: cash_rebuilt | D5: cfclose | E5: =ROUND('Calculations'!D15-'Facts'!F50,J5) -> 0 | F5: 0 | G5: =IF(COUNT(E5,F5)<2,"not_tested",IF(ABS(E5)<=F5,"within_input_tolerance","unexplained_difference")) -> within_input_tolerance | H5: 本次选择的披露百万元整数可以精确闭合，未以审计重要性设容差。 | I5: =IF(ISNUMBER(E5),"","missing or unavailable input") | J5: 0
A6: r_cash_total | B6: r_cash_total | C6: cash_total_rebuilt | D6: cash_bs | E6: =ROUND('Calculations'!D16-'Facts'!F51,J6) -> 0 | F6: 0 | G6: =IF(COUNT(E6,F6)<2,"not_tested",IF(ABS(E6)<=F6,"within_input_tolerance","unexplained_difference")) -> within_input_tolerance | H6: 本次选择的披露百万元整数可以精确闭合，未以审计重要性设容差。 | I6: =IF(ISNUMBER(E6),"","missing or unavailable input") | J6: 0
A7: r_corp_cash | B7: r_corp_cash | C7: corp_cash_rebuilt | D7: cfclose | E7: =ROUND('Calculations'!D17-'Facts'!F50,J7) -> 0 | F7: 0 | G7: =IF(COUNT(E7,F7)<2,"not_tested",IF(ABS(E7)<=F7,"within_input_tolerance","unexplained_difference")) -> within_input_tolerance | H7: 本次选择的披露百万元整数可以精确闭合，未以审计重要性设容差。 | I7: =IF(ISNUMBER(E7),"","missing or unavailable input") | J7: 0
A8: r_margin | B8: r_margin | C8: margin_rebuilt | D8: margin_total | E8: =ROUND('Calculations'!D18-'Facts'!F62,J8) -> 0 | F8: 0 | G8: =IF(COUNT(E8,F8)<2,"not_tested",IF(ABS(E8)<=F8,"within_input_tolerance","unexplained_difference")) -> within_input_tolerance | H8: 本次选择的披露百万元整数可以精确闭合，未以审计重要性设容差。 | I8: =IF(ISNUMBER(E8),"","missing or unavailable input") | J8: 0
A9: r_clearing | B9: r_clearing | C9: clear_rebuilt | D9: clear_total | E9: =ROUND('Calculations'!D19-'Facts'!F65,J9) -> 0 | F9: 0 | G9: =IF(COUNT(E9,F9)<2,"not_tested",IF(ABS(E9)<=F9,"within_input_tolerance","unexplained_difference")) -> within_input_tolerance | H9: 本次选择的披露百万元整数可以精确闭合，未以审计重要性设容差。 | I9: =IF(ISNUMBER(E9),"","missing or unavailable input") | J9: 0
A10: r_bs | B10: r_bs | C10: eq_balance | D10: eqclose | E10: =ROUND('Calculations'!D20-'Facts'!F68,J10) -> 0 | F10: 0 | G10: =IF(COUNT(E10,F10)<2,"not_tested",IF(ABS(E10)<=F10,"within_input_tolerance","unexplained_difference")) -> within_input_tolerance | H10: 本次选择的披露百万元整数可以精确闭合，未以审计重要性设容差。 | I10: =IF(ISNUMBER(E10),"","missing or unavailable input") | J10: 0
A11: r_equity | B11: r_equity | C11: eq_rebuilt | D11: eqclose | E11: =ROUND('Calculations'!D21-'Facts'!F68,J11) -> 0 | F11: 0 | G11: =IF(COUNT(E11,F11)<2,"not_tested",IF(ABS(E11)<=F11,"within_input_tolerance","unexplained_difference")) -> within_input_tolerance | H11: 本次选择的披露百万元整数可以精确闭合，未以审计重要性设容差。 | I11: =IF(ISNUMBER(E11),"","missing or unavailable input") | J11: 0
A12: r_put | B12: r_put | C12: put_rebuilt | D12: putclose | E12: =ROUND('Calculations'!D22-'Facts'!F79,J12) -> 0 | F12: 0 | G12: =IF(COUNT(E12,F12)<2,"not_tested",IF(ABS(E12)<=F12,"within_input_tolerance","unexplained_difference")) -> within_input_tolerance | H12: 本次选择的披露百万元整数可以精确闭合，未以审计重要性设容差。 | I12: =IF(ISNUMBER(E12),"","missing or unavailable input") | J12: 0
A13: r_goodwill | B13: r_goodwill | C13: gw_rebuilt | D13: gwclose | E13: =ROUND('Calculations'!D23-'Facts'!F81,J13) -> 0 | F13: 0 | G13: =IF(COUNT(E13,F13)<2,"not_tested",IF(ABS(E13)<=F13,"within_input_tolerance","unexplained_difference")) -> within_input_tolerance | H13: 本次选择的披露百万元整数可以精确闭合，未以审计重要性设容差。 | I13: =IF(ISNUMBER(E13),"","missing or unavailable input") | J13: 0
A14: r_software | B14: r_software | C14: sw_rebuilt | D14: swclose | E14: =ROUND('Calculations'!D24-'Facts'!F92,J14) -> 0 | F14: 0 | G14: =IF(COUNT(E14,F14)<2,"not_tested",IF(ABS(E14)<=F14,"within_input_tolerance","unexplained_difference")) -> within_input_tolerance | H14: 本次选择的披露百万元整数可以精确闭合，未以审计重要性设容差。 | I14: =IF(ISNUMBER(E14),"","missing or unavailable input") | J14: 0

Sheet Sources
A1: ID | B1: 文件 | C1: 链接 | D1: 公布日期 | E1: SHA256 | F1: 时间证据与限制
A2: annual | B2: HKEX Annual Report 2025 | C2: https://www.hkexnews.hk/listedco/listconews/sehk/2026/0316/2026031600319.pdf | D2: 未核验 | E2: 01f90f3b213f368e1ed66887ec6ec862f5129c74d5c89d3c11cf5b0fda8887ee | F2: 收到官方URL原件；PDF批准日2026-02-26，未以URL日期冒充首次公开日。
A3: fca | B3: FCA Final Notice: London Metal Exchange | C3: https://www.fca.org.uk/publication/final-notices/london-metal-exchange-2025.pdf | D3: 2025-03-20 | E3: 8fee698e2f844433e57039749c3765b404b1309edc9229d21ea8b599a491b915 | F3: 最终文书日期2025-03-19；FCA官网新闻首发2025-03-20。已读取PDF1-3、6-8页。
A4: sr | B4: HKEX Sustainability Report 2025 | C4: https://www.hkexgroup.com/-/media/HKEX-Group-Site/ssd/Investor-Relations/Regulatory-Reports/documents/2026/260316sr_e.pdf | D4: 未核验 | E4: ea0deef0b3f3a0d31c01d7936d60a652e4a3b9a6dd41b7d5351a80fba6b4af5f | F4: 已取得76页原件；读取PDF42-43、56-58、71-72页，首次公告日未单独核验。

Sheet Evidence
A1: ID | B1: 来源 | C1: 定位 | D1: 观察 | E1: 可靠性与限制
A2: e_scope | B2: annual | C2: PDF物理页3、6、22-23、46-48、65、68、75-81、111-115、129、131、139-150、153-158、164-168、185-187、189-190、193-195、205-210、230-231 | D2: 目录用于范围识别；上述章节中重点页全文阅读，业务、委员会及风险部分为定向读取；未声称未列页面和独立可持续报告已读。四张主表、现金附注、会员资源、商誉、总部与税务是本次重点。 | E2: 原件公开披露；仅支持披露层结论，不是本次交易真实性或控制运行测试
A3: e_profit | B3: annual | C3: PDF物理页143、153-154 | D3: 合并损益两列为2025、2024；金额HKD百万元。2025收入23745、收入及其他收益29161、净投资收益5111、税前21158、税3321、净利润17837、归母17754。现金分部EBITDA13398，2024为8169；集团22796、16281。分部EBITDA为公司定义的non-HKFRS，不是审计准则指标。 | E3: 原件公开披露；仅支持披露层结论，不是本次交易真实性或控制运行测试
A4: e_business | B4: annual | C4: PDF物理页23、46-48、65、68、131、155-156 | D4: 管理层称股票ADT为249.8十亿港元、同比90%；Stock Connect和衍生品增长有不同驱动；交易收费按成交日、部分清算收费按次日、上市费按服务期。经营牌照、网络与互联互通有价值；不能从成交量增幅直接推净费率不变。LME量、OTC名义清算额与股票金额不可直接混算。 | E4: 原件公开披露；仅支持披露层结论，不是本次交易真实性或控制运行测试
A5: e_cf | B5: annual | C5: PDF物理页147、205 | D5: 已视觉核对PDF205两列表头2025/2024及所有带符号行；2025税前21158，依次调整-5111,+94,-76,+96,+1568,+361,-26,+1,-80198,+80386,-7073,+6866,-374,-196,-145,-11679,+13353=19005，再+7519-4626-510-1533=19855。147页外部基金赎回5772，CFO25627，CFI-5565，CFF-14635，汇兑16；期初13910、期末19353。 | E5: 原件公开披露；仅支持披露层结论，不是本次交易真实性或控制运行测试
A6: e_cash | B6: annual | C6: PDF物理页145、167-168 | D6: PDF167原页已视觉核：2025列按A股现金/Corporate/Margin/Clearing House/Total依次2549/20676/130052/29447/182724，单位HKD百万元。Corporate内1323仅支持清算基金用途；168页(c)说明这些用途限制款不进入现金流量表现金。19353仍是集团口径，并非母公司可任意分配金额。 | E6: 原件公开披露；仅支持披露层结论，不是本次交易真实性或控制运行测试
A7: e_margin | B7: annual | C7: PDF物理页78、190、193 | D7: 2025保证金负债269243；资产现金130052、FVOCI48327、摊余成本69176、ChinaClear20867、SHCH799、会员应收22。分列资金用途。清算基金资产现金29447+FVOCI6361-其他负债12=35796；构成为会员33991+OTC资源156+基金储备1649。Corporate的Skin-in-the-Game及credits2276不应重复加为会员资产。 | E7: 原件公开披露；仅支持披露层结论，不是本次交易真实性或控制运行测试
A8: e_equity | B8: annual | C8: PDF物理页145-146、194-195、206 | D8: PDF146完整表头视觉核对：2025最右Total equity列期初54407、净利润17837、OCI369；直接权益行-6193,-7583,+34,-512,vesting合计零,+361,+9,储备转拨合计零,NCI dividend合计零；期末58729。最后一行NCI分红归母储备+59、NCI-59，总权益零，现金和看跌期权负债减少59另在147/195/206反映。 | E8: 原件公开披露；仅支持披露层结论，不是本次交易真实性或控制运行测试
A9: e_bs | B9: annual | C9: PDF物理页145 | D9: 2025合并资产580775、负债522046、权益58729；归母58147、NCI582。金额HKD百万元，资产列Current/Non-current/Total，取Total列。 | E9: 原件公开披露；仅支持披露层结论，不是本次交易真实性或控制运行测试
A10: e_estimate | B10: annual | C10: PDF物理页185-187 | D10: PDF185完整列名Goodwill/Tradenames/Customer relationships/Software systems/Total已视觉核。商誉13297+汇兑32-减值55=13274；软件净额3860，成本增加1285、成本汇兑20、累计摊销汇兑13、摊销810、处置成本60及累计摊销59，期末4341。Data and Connectivity商誉55；减值来自BayConnect预期协同下降、深圳自有技术中心定位变化。Commodities商誉13219、商标894；未来五年EBITDA margin61%，折现8%、终值增长3%，管理层称合理可能变化不改变无减值判断，未给本次可独立验证完整模型。 | E10: 原件公开披露；仅支持披露层结论，不是本次交易真实性或控制运行测试
A11: e_capital | B11: annual | C11: PDF物理页79、147、189、206 | D11: 总部购置总考虑6.3十亿港元；已确认土地ROU2332、物业ROU34、固定资产67，现金支付3148；未来分期至2027，承诺3424。资本承诺总5285中还有已签未拨备固定104/无形183及批准未签固定758/无形816。会计确认、现金、承诺不同计量和范围，不能用差额认定错报。租赁负债1294+112-312+41-251-41+8=851；ROU总部新增不能等同融资租赁负债新增。 | E11: 原件公开披露；仅支持披露层结论，不是本次交易真实性或控制运行测试
A12: e_tax | B12: annual | C12: PDF物理页164-165 | D12: 2025税务桥3567-1082+121+14+701=3321；香港最低补足税701作为当期税额，原文称2025起适用；该额未等于本期现金支付。税费2024为1698，税前14853；英国当期多计拨回93有同额递延税费用抵消，不应全额当税收永久优惠。此处以公司披露为事实，不另给法律适用意见。 | E12: 原件公开披露；仅支持披露层结论，不是本次交易真实性或控制运行测试
... A16: e_sr | B16: sr | C16: PDF42-43、56-58、71-72；印刷40-41、54-56、69-70 | D16: 披露网络独立专家验证、数据中心ISO27001、定期演练、2025第三方隐私复核；风灾期间交易结算正常是正面执行实例。气候评估覆盖17个自有及租用站点，比较NGFS路径并连接交易收入、资产损害/能源成本；存在公司表现不变及技术不变等假设。HKQAA声明为ISAE3000有限保证，非本次网络运行或气候模型验证。 | E16: 公司独立报告与第三方有限保证原件；管理层模型结果与保证范围均保留限制

Sheet Findings
A1: ID | B1: 问题 | C1: 结论 | D1: 机制 | E1: 状态 | F1: 依据 | G1: 反证 | H1: 其他解释 | I1: 改变结论条件
A2: f_business | B2: 盈利改善是否只来自利率和投资收益？ | C2: 营业收入同比36.89%，集团净利润同比35.59%。营业收入增量6,399.00 HKD × 1000000占收入及其他收益增量的94.28%；现金分部占公司定义EBITDA增量80.26%。 | D2: 牌照及互联互通网络将活跃交易转化为交易、清算和存管收入；量增同时扩大清算资源和IT容量需求。不能把所有收入机械乘股票ADT。 | E2: supported | F2: e_profit, e_business | G2: e_estimate | H2: 市场整体行情与互联互通参与增加可能比公司特有定价更重要。 清算及交易费率、市场份额、交易产品组合未单独隔离。 | I2: 同口径份额或净费率下降、交易量回落或系统瓶颈，将削弱持续增长判断。
A3: f_cash | B3: CFO与会员资金能否直接解释为可分配现金？ | C3: 逐行桥得到主要经营现金19,855.00 HKD × 1000000、HKAS7 CFO25,627.00 HKD × 1000000；其中外部基金赎回为5,772.00 HKD × 1000000。现金流量表现金19,353.00 HKD × 1000000与资产负债表现金182,724.00 HKD × 1000000是不同范围。 | D3: 附注披露的会员配对资金通过经营现金桥但不可用于其他活动；清算与公司不同用途资源不能混用。其他负债增加与应收增加只能解释原合计行，未分解前不能称供应商占款。 | E3: supported | F3: e_cf, e_cash, e_margin | G3: e_parent | H3: 高CFO部分来自外部资产赎回，而不是重复性收费现金。 期末资金池受市场保证金需求影响，不能用总额判断公司债务偿还能力。 | I3: 取得日内、分法人及币种的实际可调度资金和支付义务后可进一步判断压力现金。
A4: f_fmi | B4: 资源总额能否证明清算风险已覆盖？ | C4: 保证金资产重建269,243.00 HKD × 1000000对应义务269,243.00 HKD × 1000000；清算基金净资产35,796.00 HKD × 1000000与披露一致。 | D4: 资产用途、期限与服务级法律顺序决定可用性；非现金会员抵押并未上表，跨CCP及币种资金不能简单互抵；年度账面闭合不回答日内支付和极端平仓损失。 | E4: conditional | F4: e_margin, e_cash | H4: 高质量投资和隔离账户是积极缓释，但仍有期限和时点错配。 | I4: 服务级同日损失、违约瀑布、成员份额和支付窗口证据才能支持覆盖结论。
A5: f_equity | B5: 股东分配能否只读现金流表？ | C5: 全权益滚动58,729.00 HKD × 1000000、资产负债差58,729.00 HKD × 1000000与集团权益58,729.00 HKD × 1000000一致；看跌期权债务重建398.00 HKD × 1000000。 | D5: 非控股分配59.00 HKD × 1000000现金流出同时降低看跌期权负债，并在权益内把NCI转至归母储备，集团权益该行净零。宣告分配与实付股息另列，避免把权益增减全部理解成现金。 | E5: supported | F5: e_equity, e_bs | H5: 权益转拨形式无集团净额但改变归属和少数股东权益。 | I5: 期权条款变化、分红对应的负债调整或范围差异会改变解释。
A6: f_estimate | B6: 资产估计是否与业务战略一致？ | C6: 商誉重建13,274.00 HKD × 1000000，本年减值55.00 HKD × 1000000；软件净值重建4,341.00 HKD × 1000000。BayConnect协同预期下调已有会计后果，不能将减值全当无关紧要的非现金项目。 | D6: 深圳技术中心定位改变降低BayConnect协同；LME等商品CGU仍承载主要商誉和商标，管理层提高利润率假设是增长解释，也是应挑战的估计输入。软件资本化与收入系统依赖连接未来摊销及运营韧性。 | E6: conditional | F6: e_estimate, e_business, e_governance | H6: 商品市场盈利提升可以支持更高预测利润率。 未取得预测、资本开支和税/折现匹配，不能独立证明无减值或计算应调整额。 | I6: 实际利润/现金低于预测，开发项目不可用或关键假设恶化将触发重新估值。
A7: f_capital | B7: 当年高经营现金是否足够说明资本配置无约束？ | C7: 主要经营现金减总部和其他长期经营资产付款为14,974.00 HKD × 1000000，再减归母股息实付剩1,252.00 HKD × 1000000；尚有总部已签承诺3,424.00 HKD × 1000000及其他资本安排。 | D7: 该观察未扣联营投资、奖励股份、租赁和其他资金变动；总部ROU/固定资产确认与付款及未来承诺不同步，不能把会计新增当现金支出。母公司现金2,870.00 HKD × 1000000也不同于集团资金。 | E7: conditional | F7: e_capital, e_cf, e_parent | H7: 现金余额和资本投资可支持未来容量与持续经营，不能仅凭本期付款增加评为负面。 | I7: 逐期投入收益、法人可分配与上划能力以及承诺付款时间表会改变分配余量判断。
A8: f_tax | B8: 税后增速与税前增长为何不同？ | C8: 税前利润同比42.45%，净利润同比35.59%；本年有效税率15.70%。最低补足税701.00 HKD × 1000000占所得税费用增量43.19%。 | D8: 最低税有明确本期税额；英国当期税抵扣与递延税相抵，不能只引用当期税利好。税费和实付税不同，未付税还影响未来现金。 | E8: supported | F8: e_tax, e_profit | H8: 地区盈利结构、永久差异与递延项目也影响总税率，不能把差额全部归因最低税。 | I8: 按法域纳税及GloBE计算、支付时点和下一期暂时性差异变化会改变持续税负预测。
A9: f_governance | B9: 无保留意见是否足以关闭收入与运营风险？ | C9: 收入系统是原审计师关键审计事项；本次仅读取其程序与结论，没有执行系统控制测试。报告期仍按现行HKFRS列报，未来列报变更需要可比桥。 | D9: 同一交易系统同时影响收费完整性、日内清算和业务连续性；委员会审阅是治理动作，不是独立运行证据。HKFRS18公司投资收益、会员利息回拨重分类将影响营业口径，不能误读为经济利润变化。 | E9: conditional | F9: e_governance, e_business, e_fca | G9: e_sr | H9: 原审计意见与委员会监督提供积极公开证据。 官方FCA最终文书已取得；其同时记录历史控制不足与后续缓释，不支持将处罚结束解释为所有运营风险消失。 | I9: 进一步取得系统运行样本、日内升级日志及事件整改关闭测试后，更新对运行韧性与剩余风险的判断。
A10: f_resilience | B10: 治理叙述是否已经连接业务和会计后果？ | C10: 补充公开报告已取得。风灾中交易结算正常、网络演练和第三方隐私复核为积极证据；极端天气和网络中断仍通过交易收入、清算付款及资产/运营成本传导。 | D10: 可持续报告已把场景连接站点、收入与费用，不能重复请求整份公开报告。其模型的企业表现和技术不变假设需要挑战；有限保证不替代本次关键系统运行和模型复算。 | E10: conditional | F10: e_sr, e_fca | G10: e_governance | H10: 已有防洪、业务连续性、保险及恶劣天气交易安排可以降低损失。 管理层无重大财务影响判断仍受预测和范围限制。 | I10: 未来停机、支付延迟、站点损害或模型假设变化，需同时更新收入、支出、资产估计和清算压力。

Sheet Procedures
A1: ID | B1: 事项 | C1: 目的与认定 | D1: 总体 | E1: 选取 | F1: 步骤 | G1: 状态 | H1: 实际结果 | I1: 证据 | J1: 执行者日期
A2: p_cash | B2: f_cash | C2: 验证所列原表关系和口径 / 准确性及列报 | D2: 原年报已列相关表与附注，不代表逐笔总体 | E2: 本次自主选择的关键桥全部原披露行 | F2: 从带表头原页定位并记录所选行。 逐项执行：19,005.00 HKD × 1000000、19,855.00 HKD × 1000000、25,627.00 HKD × 1000000、19,353.00 HKD × 1000000 | G2: performed | H2: 本次逐行复算，所列现金桥残差均为零；只完成算术和公开口径验证。 | I2: ops_rebuilt, principal_rebuilt, cfo_rebuilt, cash_rebuilt | J2: AI公开资料会计分析 2026-10-02
A3: p_equity | B3: f_equity | C3: 验证所列原表关系和口径 / 准确性及列报 | D3: 原年报已列相关表与附注，不代表逐笔总体 | E3: 本次自主选择的关键桥全部原披露行 | F3: 从带表头原页定位并记录所选行。 逐项执行：58,729.00 HKD × 1000000、398.00 HKD × 1000000、58,729.00 HKD × 1000000 | G3: performed | H3: 本次核对权益全列原页并复算，残差零；未执行权益和期权交易真实性测试。 | I3: eq_rebuilt, put_rebuilt, eq_balance | J3: AI公开资料会计分析 2026-10-02
A4: p_estimate | B4: f_estimate | C4: 验证所列原表关系和口径 / 准确性及列报 | D4: 原年报已列相关表与附注，不代表逐笔总体 | E4: 本次自主选择的关键桥全部原披露行 | F4: 从带表头原页定位并记录所选行。 逐项执行：13,274.00 HKD × 1000000、4,341.00 HKD × 1000000 | G4: performed | H4: 本次复算商誉、软件净值滚动，残差零；未执行CGU模型验证。 | I4: gw_rebuilt, sw_rebuilt | J4: AI公开资料会计分析 2026-10-02
A5: p_fmi | B5: f_fmi | C5: 验证所列原表关系和口径 / 准确性及列报 | D5: 原年报已列相关表与附注，不代表逐笔总体 | E5: 本次自主选择的关键桥全部原披露行 | F5: 从带表头原页定位并记录所选行。 逐项执行：269,243.00 HKD × 1000000、35,796.00 HKD × 1000000 | G5: performed | H5: 本次复算保证金及清算基金资产义务勾稽，残差零；未验证违约瀑布与日内压力。 | I5: margin_rebuilt, clear_rebuilt | J5: AI公开资料会计分析 2026-10-02

Sheet Requests
A1: ID | B1: 事项 | C1: 所需资料 | D1: 影响 | E1: 责任角色 | F1: 关闭条件
A2: q_fmi | B2: f_fmi | C2: 各CCP同日PFMI定量表、现行服务规则、压力损失、成员基金份额与币种时点支付数据 | D2: 确定压力损失后的资源顺序和日内现金，不得由账面闭合推安全 | E2: 风险与清算负责人 | F2: 逐服务核实重复计算、法律用途和可用时点，并重做至少一个压力路径
A3: q_estimate | B3: f_estimate | C3: 商品及BayConnect CGU完整估值模型、预算兑现及软件资本化/验收依据 | D3: 检验利润率改善、资本开支、折现与开发可回收性 | E3: 财务与技术负责人 | F3: 匹配模型口径后可独立重做关键敏感性及临界条件
A4: q_capital | B4: f_capital | C4: 总部合同付款与资产确认明细、集团法人资金上划及未来分配计划 | D4: 确定确认与现金差异及承诺付款流动性 | E4: 财务与资金负责人 | F4: 确认每笔口径与时点并完成逐期资本现金桥
A5: q_control | B5: f_governance | C5: 关键收费/清算系统控制运行样本、事故升级日志和整改关闭测试；已披露气候模型的站点假设及原始结果 | D5: FCA最终文书及独立可持续报告已经取得，剩余是运行与模型证据；不再请求公开报告本身。 | E5: 技术风险与合规负责人 | F5: 用具体运行样本、整改结果与模型数据更新判断；保留第三方有限保证的范围边界。
