Workbook

Sheet Readme
A1: 字段 / field | B1: 内容 / value
A2: 任务 | B2: A股电池企业：原始披露与历史时点验证
A3: 版本 | B3: real-disclosure-example-v1
A4: 信息截止 | B4: 2026-10-02
A5: 范围 | B5: 各报告当期合并范围
A6: 准则 | B6: CAS
A7: 单位 | B7: Facts D=原始值，E=倍数，F=基础单位。Calculations D=基础单位，E=展示值。
A8: 复算 | B8: 数值公式可编辑；修改主体、期间、币种、规则或资料后须重跑 export.py 复核口径。
A9: 勾稽精度 | B9: 金额残差按本次Decimal输入/计算保留的小数位ROUND，消除Excel二进制尾差，不改变业务容差；提高输入小数精度后须重跑导出。
A10: 缺口 | B10: 空值不是零。未执行程序、假设与已披露数据分别标识。
A11: 限制 | B11: 仅四家事先选定企业，产品结构和合并范围不同；不是全市场样本或完全同质同业。
A12: 限制 | B12: 公告日期来自官方列表，次日零点仅为日级证据的保守边界；没有证明历史精确字节从未替换。
... A17: 限制 | B17: 来源 s_300014_2022 的正式公布日期未核验；不得据此证明在信息截止日前已公开。当前披露内容可以继续分析，历史时点结论须补充公告时间证据。

Sheet Facts
A1: ID | B1: 原始科目 | C1: 证据 | D1: 原始数值 | E1: 倍数 | F1: 基础单位数值 | G1: 量纲 | H1: 币种 | I1: 实体 | J1: 范围 | K1: 开始 | L1: 结束 | M1: 统计类型 | N1: 状态 | O1: 准则 | P1: 说明 | Q1: 概念 | R1: 实物单位
A2: 002074_2022_revenue | B2: 国轩高科股份有限公司2022其中：营业收入 | C2: e_002074_2022 | D2: 2.3051701e+10 | E2: 1 | F2: =IF(COUNT(D2,E2)=2,D2*E2,NA()) -> 2.3051701e+10 | G2: money | H2: CNY | I2: 国轩高科股份有限公司 | J2: consolidated | K2: 2022-01-01 | L2: 2022-12-31 | M2: flow | N2: reported | O2: CAS | P2: 原报告当期值。不以后年比较数回填。 | Q2: revenue
A3: 002074_2022_cost_of_sales | B3: 国轩高科股份有限公司2022其中：营业成本 | C3: e_002074_2022 | D3: 1.8949696e+10 | E3: 1 | F3: =IF(COUNT(D3,E3)=2,D3*E3,NA()) -> 1.8949696e+10 | G3: money | H3: CNY | I3: 国轩高科股份有限公司 | J3: consolidated | K3: 2022-01-01 | L3: 2022-12-31 | M3: flow | N3: reported | O3: CAS | P3: 原报告当期值。不以后年比较数回填。 | Q3: cost_of_sales
A4: 002074_2022_total_assets | B4: 国轩高科股份有限公司2022资产总计 | C4: e_002074_2022 | D4: 7.2627365e+10 | E4: 1 | F4: =IF(COUNT(D4,E4)=2,D4*E4,NA()) -> 7.2627365e+10 | G4: money | H4: CNY | I4: 国轩高科股份有限公司 | J4: consolidated | L4: 2022-12-31 | M4: instant | N4: reported | O4: CAS | P4: 原报告当期值。不以后年比较数回填。 | Q4: total_assets
A5: 002074_2023_revenue | B5: 国轩高科股份有限公司2023其中：营业收入 | C5: e_002074_2023 | D5: 3.160549e+10 | E5: 1 | F5: =IF(COUNT(D5,E5)=2,D5*E5,NA()) -> 3.160549e+10 | G5: money | H5: CNY | I5: 国轩高科股份有限公司 | J5: consolidated | K5: 2023-01-01 | L5: 2023-12-31 | M5: flow | N5: reported | O5: CAS | P5: 原报告当期值。不以后年比较数回填。 | Q5: revenue
A6: 002074_2023_cost_of_sales | B6: 国轩高科股份有限公司2023其中：营业成本 | C6: e_002074_2023 | D6: 2.6257212e+10 | E6: 1 | F6: =IF(COUNT(D6,E6)=2,D6*E6,NA()) -> 2.6257212e+10 | G6: money | H6: CNY | I6: 国轩高科股份有限公司 | J6: consolidated | K6: 2023-01-01 | L6: 2023-12-31 | M6: flow | N6: reported | O6: CAS | P6: 原报告当期值。不以后年比较数回填。 | Q6: cost_of_sales
A7: 002074_2023_total_assets | B7: 国轩高科股份有限公司2023资产总计 | C7: e_002074_2023 | D7: 9.3592652e+10 | E7: 1 | F7: =IF(COUNT(D7,E7)=2,D7*E7,NA()) -> 9.3592652e+10 | G7: money | H7: CNY | I7: 国轩高科股份有限公司 | J7: consolidated | L7: 2023-12-31 | M7: instant | N7: reported | O7: CAS | P7: 原报告当期值。不以后年比较数回填。 | Q7: total_assets
A8: 002074_2024_revenue | B8: 国轩高科股份有限公司2024其中：营业收入 | C8: e_002074_2024 | D8: 3.5391817e+10 | E8: 1 | F8: =IF(COUNT(D8,E8)=2,D8*E8,NA()) -> 3.5391817e+10 | G8: money | H8: CNY | I8: 国轩高科股份有限公司 | J8: consolidated | K8: 2024-01-01 | L8: 2024-12-31 | M8: flow | N8: reported | O8: CAS | P8: 原报告当期值。不以后年比较数回填。 | Q8: revenue
A9: 002074_2024_cost_of_sales | B9: 国轩高科股份有限公司2024其中：营业成本 | C9: e_002074_2024 | D9: 2.9020131e+10 | E9: 1 | F9: =IF(COUNT(D9,E9)=2,D9*E9,NA()) -> 2.9020131e+10 | G9: money | H9: CNY | I9: 国轩高科股份有限公司 | J9: consolidated | K9: 2024-01-01 | L9: 2024-12-31 | M9: flow | N9: reported | O9: CAS | P9: 原报告当期值。不以后年比较数回填。 | Q9: cost_of_sales
A10: 002074_2024_total_assets | B10: 国轩高科股份有限公司2024资产总计 | C10: e_002074_2024 | D10: 1.0783969e+11 | E10: 1 | F10: =IF(COUNT(D10,E10)=2,D10*E10,NA()) -> 1.0783969e+11 | G10: money | H10: CNY | I10: 国轩高科股份有限公司 | J10: consolidated | L10: 2024-12-31 | M10: instant | N10: reported | O10: CAS | P10: 原报告当期值。不以后年比较数回填。 | Q10: total_assets
A11: 002074_2025_revenue | B11: 国轩高科股份有限公司2025其中：营业收入 | C11: e_002074_2025 | D11: 4.5070462e+10 | E11: 1 | F11: =IF(COUNT(D11,E11)=2,D11*E11,NA()) -> 4.5070462e+10 | G11: money | H11: CNY | I11: 国轩高科股份有限公司 | J11: consolidated | K11: 2025-01-01 | L11: 2025-12-31 | M11: flow | N11: reported | O11: CAS | P11: 原报告当期值。不以后年比较数回填。 | Q11: revenue
A12: 002074_2025_cost_of_sales | B12: 国轩高科股份有限公司2025其中：营业成本 | C12: e_002074_2025 | D12: 3.7780369e+10 | E12: 1 | F12: =IF(COUNT(D12,E12)=2,D12*E12,NA()) -> 3.7780369e+10 | G12: money | H12: CNY | I12: 国轩高科股份有限公司 | J12: consolidated | K12: 2025-01-01 | L12: 2025-12-31 | M12: flow | N12: reported | O12: CAS | P12: 原报告当期值。不以后年比较数回填。 | Q12: cost_of_sales
A13: 002074_2025_total_assets | B13: 国轩高科股份有限公司2025资产总计 | C13: e_002074_2025 | D13: 1.2721452e+11 | E13: 1 | F13: =IF(COUNT(D13,E13)=2,D13*E13,NA()) -> 1.2721452e+11 | G13: money | H13: CNY | I13: 国轩高科股份有限公司 | J13: consolidated | L13: 2025-12-31 | M13: instant | N13: reported | O13: CAS | P13: 原报告当期值。不以后年比较数回填。 | Q13: total_assets
A14: 300014_2022_revenue | B14: 惠州亿纬锂能股份有限公司2022其中：营业收入 | C14: e_300014_2022 | D14: 3.6303948e+10 | E14: 1 | F14: =IF(COUNT(D14,E14)=2,D14*E14,NA()) -> 3.6303948e+10 | G14: money | H14: CNY | I14: 惠州亿纬锂能股份有限公司 | J14: consolidated | K14: 2022-01-01 | L14: 2022-12-31 | M14: flow | N14: reported | O14: CAS | P14: 原报告当期值。历史时点版本未核实，仅保留当前内容核查。 | Q14: revenue
A15: 300014_2022_cost_of_sales | B15: 惠州亿纬锂能股份有限公司2022其中：营业成本 | C15: e_300014_2022 | D15: 3.0338441e+10 | E15: 1 | F15: =IF(COUNT(D15,E15)=2,D15*E15,NA()) -> 3.0338441e+10 | G15: money | H15: CNY | I15: 惠州亿纬锂能股份有限公司 | J15: consolidated | K15: 2022-01-01 | L15: 2022-12-31 | M15: flow | N15: reported | O15: CAS | P15: 原报告当期值。历史时点版本未核实，仅保留当前内容核查。 | Q15: cost_of_sales
A16: 300014_2022_total_assets | B16: 惠州亿纬锂能股份有限公司2022资产总计 | C16: e_300014_2022 | D16: 8.3637813e+10 | E16: 1 | F16: =IF(COUNT(D16,E16)=2,D16*E16,NA()) -> 8.3637813e+10 | G16: money | H16: CNY | I16: 惠州亿纬锂能股份有限公司 | J16: consolidated | L16: 2022-12-31 | M16: instant | N16: reported | O16: CAS | P16: 原报告当期值。历史时点版本未核实，仅保留当前内容核查。 | Q16: total_assets
A17: 300014_2023_revenue | B17: 惠州亿纬锂能股份有限公司2023其中：营业收入 | C17: e_300014_2023 | D17: 4.8783587e+10 | E17: 1 | F17: =IF(COUNT(D17,E17)=2,D17*E17,NA()) -> 4.8783587e+10 | G17: money | H17: CNY | I17: 惠州亿纬锂能股份有限公司 | J17: consolidated | K17: 2023-01-01 | L17: 2023-12-31 | M17: flow | N17: reported | O17: CAS | P17: 原报告当期值。不以后年比较数回填。 | Q17: revenue
A18: 300014_2023_cost_of_sales | B18: 惠州亿纬锂能股份有限公司2023其中：营业成本 | C18: e_300014_2023 | D18: 4.0473297e+10 | E18: 1 | F18: =IF(COUNT(D18,E18)=2,D18*E18,NA()) -> 4.0473297e+10 | G18: money | H18: CNY | I18: 惠州亿纬锂能股份有限公司 | J18: consolidated | K18: 2023-01-01 | L18: 2023-12-31 | M18: flow | N18: reported | O18: CAS | P18: 原报告当期值。不以后年比较数回填。 | Q18: cost_of_sales
A19: 300014_2023_total_assets | B19: 惠州亿纬锂能股份有限公司2023资产总计 | C19: e_300014_2023 | D19: 9.4355338e+10 | E19: 1 | F19: =IF(COUNT(D19,E19)=2,D19*E19,NA()) -> 9.4355338e+10 | G19: money | H19: CNY | I19: 惠州亿纬锂能股份有限公司 | J19: consolidated | L19: 2023-12-31 | M19: instant | N19: reported | O19: CAS | P19: 原报告当期值。不以后年比较数回填。 | Q19: total_assets
A20: 300014_2024_revenue | B20: 惠州亿纬锂能股份有限公司2024其中：营业收入 | C20: e_300014_2024 | D20: 4.8614557e+10 | E20: 1 | F20: =IF(COUNT(D20,E20)=2,D20*E20,NA()) -> 4.8614557e+10 | G20: money | H20: CNY | I20: 惠州亿纬锂能股份有限公司 | J20: consolidated | K20: 2024-01-01 | L20: 2024-12-31 | M20: flow | N20: reported | O20: CAS | P20: 原报告当期值。不以后年比较数回填。 | Q20: revenue
A21: 300014_2024_cost_of_sales | B21: 惠州亿纬锂能股份有限公司2024其中：营业成本 | C21: e_300014_2024 | D21: 4.0149208e+10 | E21: 1 | F21: =IF(COUNT(D21,E21)=2,D21*E21,NA()) -> 4.0149208e+10 | G21: money | H21: CNY | I21: 惠州亿纬锂能股份有限公司 | J21: consolidated | K21: 2024-01-01 | L21: 2024-12-31 | M21: flow | N21: reported | O21: CAS | P21: 原报告当期值。不以后年比较数回填。 | Q21: cost_of_sales
A22: 300014_2024_total_assets | B22: 惠州亿纬锂能股份有限公司2024资产总计 | C22: e_300014_2024 | D22: 1.0089062e+11 | E22: 1 | F22: =IF(COUNT(D22,E22)=2,D22*E22,NA()) -> 1.0089062e+11 | G22: money | H22: CNY | I22: 惠州亿纬锂能股份有限公司 | J22: consolidated | L22: 2024-12-31 | M22: instant | N22: reported | O22: CAS | P22: 原报告当期值。不以后年比较数回填。 | Q22: total_assets
A23: 300014_2025_revenue | B23: 惠州亿纬锂能股份有限公司2025其中：营业收入 | C23: e_300014_2025 | D23: 6.1469631e+10 | E23: 1 | F23: =IF(COUNT(D23,E23)=2,D23*E23,NA()) -> 6.1469631e+10 | G23: money | H23: CNY | I23: 惠州亿纬锂能股份有限公司 | J23: consolidated | K23: 2025-01-01 | L23: 2025-12-31 | M23: flow | N23: reported | O23: CAS | P23: 原报告当期值。不以后年比较数回填。 | Q23: revenue
A24: 300014_2025_cost_of_sales | B24: 惠州亿纬锂能股份有限公司2025其中：营业成本 | C24: e_300014_2025 | D24: 5.1528492e+10 | E24: 1 | F24: =IF(COUNT(D24,E24)=2,D24*E24,NA()) -> 5.1528492e+10 | G24: money | H24: CNY | I24: 惠州亿纬锂能股份有限公司 | J24: consolidated | K24: 2025-01-01 | L24: 2025-12-31 | M24: flow | N24: reported | O24: CAS | P24: 原报告当期值。不以后年比较数回填。 | Q24: cost_of_sales
A25: 300014_2025_total_assets | B25: 惠州亿纬锂能股份有限公司2025资产总计 | C25: e_300014_2025 | D25: 1.255423e+11 | E25: 1 | F25: =IF(COUNT(D25,E25)=2,D25*E25,NA()) -> 1.255423e+11 | G25: money | H25: CNY | I25: 惠州亿纬锂能股份有限公司 | J25: consolidated | L25: 2025-12-31 | M25: instant | N25: reported | O25: CAS | P25: 原报告当期值。不以后年比较数回填。 | Q25: total_assets
A26: 300207_2022_revenue | B26: 欣旺达电子股份有限公司2022其中：营业收入 | C26: e_300207_2022 | D26: 5.2162269e+10 | E26: 1 | F26: =IF(COUNT(D26,E26)=2,D26*E26,NA()) -> 5.2162269e+10 | G26: money | H26: CNY | I26: 欣旺达电子股份有限公司 | J26: consolidated | K26: 2022-01-01 | L26: 2022-12-31 | M26: flow | N26: reported | O26: CAS | P26: 原报告当期值。不以后年比较数回填。 | Q26: revenue
A27: 300207_2022_cost_of_sales | B27: 欣旺达电子股份有限公司2022其中：营业成本 | C27: e_300207_2022 | D27: 4.4942949e+10 | E27: 1 | F27: =IF(COUNT(D27,E27)=2,D27*E27,NA()) -> 4.4942949e+10 | G27: money | H27: CNY | I27: 欣旺达电子股份有限公司 | J27: consolidated | K27: 2022-01-01 | L27: 2022-12-31 | M27: flow | N27: reported | O27: CAS | P27: 原报告当期值。不以后年比较数回填。 | Q27: cost_of_sales
A28: 300207_2022_total_assets | B28: 欣旺达电子股份有限公司2022资产总计 | C28: e_300207_2022 | D28: 7.4494462e+10 | E28: 1 | F28: =IF(COUNT(D28,E28)=2,D28*E28,NA()) -> 7.4494462e+10 | G28: money | H28: CNY | I28: 欣旺达电子股份有限公司 | J28: consolidated | L28: 2022-12-31 | M28: instant | N28: reported | O28: CAS | P28: 原报告当期值。不以后年比较数回填。 | Q28: total_assets
A29: 300207_2023_revenue | B29: 欣旺达电子股份有限公司2023其中：营业收入 | C29: e_300207_2023 | D29: 4.7862227e+10 | E29: 1 | F29: =IF(COUNT(D29,E29)=2,D29*E29,NA()) -> 4.7862227e+10 | G29: money | H29: CNY | I29: 欣旺达电子股份有限公司 | J29: consolidated | K29: 2023-01-01 | L29: 2023-12-31 | M29: flow | N29: reported | O29: CAS | P29: 原报告当期值。不以后年比较数回填。 | Q29: revenue
A30: 300207_2023_cost_of_sales | B30: 欣旺达电子股份有限公司2023其中：营业成本 | C30: e_300207_2023 | D30: 4.0876302e+10 | E30: 1 | F30: =IF(COUNT(D30,E30)=2,D30*E30,NA()) -> 4.0876302e+10 | G30: money | H30: CNY | I30: 欣旺达电子股份有限公司 | J30: consolidated | K30: 2023-01-01 | L30: 2023-12-31 | M30: flow | N30: reported | O30: CAS | P30: 原报告当期值。不以后年比较数回填。 | Q30: cost_of_sales
A31: 300207_2023_total_assets | B31: 欣旺达电子股份有限公司2023资产总计 | C31: e_300207_2023 | D31: 7.9261259e+10 | E31: 1 | F31: =IF(COUNT(D31,E31)=2,D31*E31,NA()) -> 7.9261259e+10 | G31: money | H31: CNY | I31: 欣旺达电子股份有限公司 | J31: consolidated | L31: 2023-12-31 | M31: instant | N31: reported | O31: CAS | P31: 原报告当期值。不以后年比较数回填。 | Q31: total_assets
A32: 300207_2024_revenue | B32: 欣旺达电子股份有限公司2024其中：营业收入 | C32: e_300207_2024 | D32: 5.6020634e+10 | E32: 1 | F32: =IF(COUNT(D32,E32)=2,D32*E32,NA()) -> 5.6020634e+10 | G32: money | H32: CNY | I32: 欣旺达电子股份有限公司 | J32: consolidated | K32: 2024-01-01 | L32: 2024-12-31 | M32: flow | N32: reported | O32: CAS | P32: 原报告当期值。不以后年比较数回填。 | Q32: revenue
A33: 300207_2024_cost_of_sales | B33: 欣旺达电子股份有限公司2024其中：营业成本 | C33: e_300207_2024 | D33: 4.7518997e+10 | E33: 1 | F33: =IF(COUNT(D33,E33)=2,D33*E33,NA()) -> 4.7518997e+10 | G33: money | H33: CNY | I33: 欣旺达电子股份有限公司 | J33: consolidated | K33: 2024-01-01 | L33: 2024-12-31 | M33: flow | N33: reported | O33: CAS | P33: 原报告当期值。不以后年比较数回填。 | Q33: cost_of_sales
A34: 300207_2024_total_assets | B34: 欣旺达电子股份有限公司2024资产总计 | C34: e_300207_2024 | D34: 8.7322727e+10 | E34: 1 | F34: =IF(COUNT(D34,E34)=2,D34*E34,NA()) -> 8.7322727e+10 | G34: money | H34: CNY | I34: 欣旺达电子股份有限公司 | J34: consolidated | L34: 2024-12-31 | M34: instant | N34: reported | O34: CAS | P34: 原报告当期值。不以后年比较数回填。 | Q34: total_assets
A35: 300207_2025_revenue | B35: 欣旺达电子股份有限公司2025其中：营业收入 | C35: e_300207_2025 | D35: 6.3246252e+10 | E35: 1 | F35: =IF(COUNT(D35,E35)=2,D35*E35,NA()) -> 6.3246252e+10 | G35: money | H35: CNY | I35: 欣旺达电子股份有限公司 | J35: consolidated | K35: 2025-01-01 | L35: 2025-12-31 | M35: flow | N35: reported | O35: CAS | P35: 原报告当期值。不以后年比较数回填。 | Q35: revenue
A36: 300207_2025_cost_of_sales | B36: 欣旺达电子股份有限公司2025其中：营业成本 | C36: e_300207_2025 | D36: 5.442926e+10 | E36: 1 | F36: =IF(COUNT(D36,E36)=2,D36*E36,NA()) -> 5.442926e+10 | G36: money | H36: CNY | I36: 欣旺达电子股份有限公司 | J36: consolidated | K36: 2025-01-01 | L36: 2025-12-31 | M36: flow | N36: reported | O36: CAS | P36: 原报告当期值。不以后年比较数回填。 | Q36: cost_of_sales
A37: 300207_2025_total_assets | B37: 欣旺达电子股份有限公司2025资产总计 | C37: e_300207_2025 | D37: 1.0807223e+11 | E37: 1 | F37: =IF(COUNT(D37,E37)=2,D37*E37,NA()) -> 1.0807223e+11 | G37: money | H37: CNY | I37: 欣旺达电子股份有限公司 | J37: consolidated | L37: 2025-12-31 | M37: instant | N37: reported | O37: CAS | P37: 原报告当期值。不以后年比较数回填。 | Q37: total_assets
A38: 300750_2022_revenue | B38: 宁德时代新能源科技股份有限公司2022其中：营业收入 | C38: e_300750_2022 | D38: 32859399 | E38: 10000 | F38: =IF(COUNT(D38,E38)=2,D38*E38,NA()) -> 328593987500 | G38: money | H38: CNY | I38: 宁德时代新能源科技股份有限公司 | J38: consolidated | K38: 2022-01-01 | L38: 2022-12-31 | M38: flow | N38: reported | O38: CAS | P38: 原报告当期值。不以后年比较数回填。 | Q38: revenue
A39: 300750_2022_cost_of_sales | B39: 宁德时代新能源科技股份有限公司2022其中：营业成本 | C39: e_300750_2022 | D39: 26204961 | E39: 10000 | F39: =IF(COUNT(D39,E39)=2,D39*E39,NA()) -> 262049609200 | G39: money | H39: CNY | I39: 宁德时代新能源科技股份有限公司 | J39: consolidated | K39: 2022-01-01 | L39: 2022-12-31 | M39: flow | N39: reported | O39: CAS | P39: 原报告当期值。不以后年比较数回填。 | Q39: cost_of_sales
A40: 300750_2022_total_assets | B40: 宁德时代新能源科技股份有限公司2022资产总计 | C40: e_300750_2022 | D40: 60095235 | E40: 10000 | F40: =IF(COUNT(D40,E40)=2,D40*E40,NA()) -> 600952351900 | G40: money | H40: CNY | I40: 宁德时代新能源科技股份有限公司 | J40: consolidated | L40: 2022-12-31 | M40: instant | N40: reported | O40: CAS | P40: 原报告当期值。不以后年比较数回填。 | Q40: total_assets
...

Sheet Calculations
A1: ID | B1: 指标或桥 | C1: 基础单位公式 | D1: 基础单位结果 | E1: 展示结果 | F1: 状态 | G1: 不计算原因 | H1: 定义 | I1: 解释边界 | J1: 展示单位 | K1: 倍数 | L1: 实体 | M1: 范围 | N1: 开始 | O1: 结束
A2: 002074_2022_gross | B2: 国轩高科股份有限公司2022毛利 | C2: =(('Facts'!F2-'Facts'!F3))*1 | D2: =(('Facts'!F2-'Facts'!F3))*1 -> 4.1020053e+09 | E2: =D2/K2 -> 4.1020053e+09 | F2: =IF(ISNUMBER(D2),"calculated","not_calculated") -> calculated | G2: =IF(ISNUMBER(D2),"","检查缺失值、分母与输入；口径变更须重跑Python") | H2: 当期合并营业收入减营业成本 | I2: 原报告列报口径；成本重分类会改变毛利。 | J2: CNY | K2: 1 | L2: 国轩高科股份有限公司 | M2: consolidated | N2: 2022-01-01 | O2: 2022-12-31
A3: 002074_2022_margin | B3: 国轩高科股份有限公司2022毛利率 | C3: =IF('Facts'!F2<=0,NA(),(('Calculations'!D2/'Facts'!F2))*1) | D3: =IF('Facts'!F2<=0,NA(),(('Calculations'!D2/'Facts'!F2))*1) -> 0.17794805 | E3: =D3/K3 -> 0.17794805 | F3: =IF(ISNUMBER(D3),"calculated","not_calculated") -> calculated | G3: =IF(ISNUMBER(D3),"","检查缺失值、分母与输入；口径变更须重跑Python") | H3: 当期毛利/营业收入 | I3: 不代表同口径经济利润变化或下一年保证。 | J3: ratio | K3: 1 | L3: 国轩高科股份有限公司 | M3: consolidated | N3: 2022-01-01 | O3: 2022-12-31
A4: 002074_2023_gross | B4: 国轩高科股份有限公司2023毛利 | C4: =(('Facts'!F5-'Facts'!F6))*1 | D4: =(('Facts'!F5-'Facts'!F6))*1 -> 5.3482781e+09 | E4: =D4/K4 -> 5.3482781e+09 | F4: =IF(ISNUMBER(D4),"calculated","not_calculated") -> calculated | G4: =IF(ISNUMBER(D4),"","检查缺失值、分母与输入；口径变更须重跑Python") | H4: 当期合并营业收入减营业成本 | I4: 原报告列报口径；成本重分类会改变毛利。 | J4: CNY | K4: 1 | L4: 国轩高科股份有限公司 | M4: consolidated | N4: 2023-01-01 | O4: 2023-12-31
A5: 002074_2023_margin | B5: 国轩高科股份有限公司2023毛利率 | C5: =IF('Facts'!F5<=0,NA(),(('Calculations'!D4/'Facts'!F5))*1) | D5: =IF('Facts'!F5<=0,NA(),(('Calculations'!D4/'Facts'!F5))*1) -> 0.16921991 | E5: =D5/K5 -> 0.16921991 | F5: =IF(ISNUMBER(D5),"calculated","not_calculated") -> calculated | G5: =IF(ISNUMBER(D5),"","检查缺失值、分母与输入；口径变更须重跑Python") | H5: 当期毛利/营业收入 | I5: 不代表同口径经济利润变化或下一年保证。 | J5: ratio | K5: 1 | L5: 国轩高科股份有限公司 | M5: consolidated | N5: 2023-01-01 | O5: 2023-12-31
A6: 002074_2024_gross | B6: 国轩高科股份有限公司2024毛利 | C6: =(('Facts'!F8-'Facts'!F9))*1 | D6: =(('Facts'!F8-'Facts'!F9))*1 -> 6.3716857e+09 | E6: =D6/K6 -> 6.3716857e+09 | F6: =IF(ISNUMBER(D6),"calculated","not_calculated") -> calculated | G6: =IF(ISNUMBER(D6),"","检查缺失值、分母与输入；口径变更须重跑Python") | H6: 当期合并营业收入减营业成本 | I6: 原报告列报口径；成本重分类会改变毛利。 | J6: CNY | K6: 1 | L6: 国轩高科股份有限公司 | M6: consolidated | N6: 2024-01-01 | O6: 2024-12-31
A7: 002074_2024_margin | B7: 国轩高科股份有限公司2024毛利率 | C7: =IF('Facts'!F8<=0,NA(),(('Calculations'!D6/'Facts'!F8))*1) | D7: =IF('Facts'!F8<=0,NA(),(('Calculations'!D6/'Facts'!F8))*1) -> 0.18003274 | E7: =D7/K7 -> 0.18003274 | F7: =IF(ISNUMBER(D7),"calculated","not_calculated") -> calculated | G7: =IF(ISNUMBER(D7),"","检查缺失值、分母与输入；口径变更须重跑Python") | H7: 当期毛利/营业收入 | I7: 不代表同口径经济利润变化或下一年保证。 | J7: ratio | K7: 1 | L7: 国轩高科股份有限公司 | M7: consolidated | N7: 2024-01-01 | O7: 2024-12-31
A8: 002074_2025_gross | B8: 国轩高科股份有限公司2025毛利 | C8: =(('Facts'!F11-'Facts'!F12))*1 | D8: =(('Facts'!F11-'Facts'!F12))*1 -> 7.2900926e+09 | E8: =D8/K8 -> 7.2900926e+09 | F8: =IF(ISNUMBER(D8),"calculated","not_calculated") -> calculated | G8: =IF(ISNUMBER(D8),"","检查缺失值、分母与输入；口径变更须重跑Python") | H8: 当期合并营业收入减营业成本 | I8: 原报告列报口径；成本重分类会改变毛利。 | J8: CNY | K8: 1 | L8: 国轩高科股份有限公司 | M8: consolidated | N8: 2025-01-01 | O8: 2025-12-31
A9: 002074_2025_margin | B9: 国轩高科股份有限公司2025毛利率 | C9: =IF('Facts'!F11<=0,NA(),(('Calculations'!D8/'Facts'!F11))*1) | D9: =IF('Facts'!F11<=0,NA(),(('Calculations'!D8/'Facts'!F11))*1) -> 0.16174879 | E9: =D9/K9 -> 0.16174879 | F9: =IF(ISNUMBER(D9),"calculated","not_calculated") -> calculated | G9: =IF(ISNUMBER(D9),"","检查缺失值、分母与输入；口径变更须重跑Python") | H9: 当期毛利/营业收入 | I9: 不代表同口径经济利润变化或下一年保证。 | J9: ratio | K9: 1 | L9: 国轩高科股份有限公司 | M9: consolidated | N9: 2025-01-01 | O9: 2025-12-31
A10: 002074_2025_gpa | B10: 国轩高科股份有限公司2025毛利/期末资产 | C10: =IF('Facts'!F13<=0,NA(),(('Calculations'!D8/'Facts'!F13))*1) | D10: =IF('Facts'!F13<=0,NA(),(('Calculations'!D8/'Facts'!F13))*1) -> 0.057305507 | E10: =D10/K10 -> 0.057305507 | F10: =IF(ISNUMBER(D10),"calculated","not_calculated") -> calculated | G10: =IF(ISNUMBER(D10),"","检查缺失值、分母与输入；口径变更须重跑Python") | H10: 当期毛利/当期期末总资产 | I10: 明确采用期末资产；不是使用平均资产的ROA。 | J10: ratio | K10: 1 | L10: 国轩高科股份有限公司 | M10: consolidated | N10: 2025-01-01 | O10: 2025-12-31
A11: 300014_2022_gross | B11: 惠州亿纬锂能股份有限公司2022毛利 | C11: =(('Facts'!F14-'Facts'!F15))*1 | D11: =(('Facts'!F14-'Facts'!F15))*1 -> 5.9655072e+09 | E11: =D11/K11 -> 5.9655072e+09 | F11: =IF(ISNUMBER(D11),"calculated","not_calculated") -> calculated | G11: =IF(ISNUMBER(D11),"","检查缺失值、分母与输入；口径变更须重跑Python") | H11: 当期合并营业收入减营业成本 | I11: 原报告列报口径；成本重分类会改变毛利。 | J11: CNY | K11: 1 | L11: 惠州亿纬锂能股份有限公司 | M11: consolidated | N11: 2022-01-01 | O11: 2022-12-31
A12: 300014_2022_margin | B12: 惠州亿纬锂能股份有限公司2022毛利率 | C12: =IF('Facts'!F14<=0,NA(),(('Calculations'!D11/'Facts'!F14))*1) | D12: =IF('Facts'!F14<=0,NA(),(('Calculations'!D11/'Facts'!F14))*1) -> 0.16432117 | E12: =D12/K12 -> 0.16432117 | F12: =IF(ISNUMBER(D12),"calculated","not_calculated") -> calculated | G12: =IF(ISNUMBER(D12),"","检查缺失值、分母与输入；口径变更须重跑Python") | H12: 当期毛利/营业收入 | I12: 不代表同口径经济利润变化或下一年保证。 | J12: ratio | K12: 1 | L12: 惠州亿纬锂能股份有限公司 | M12: consolidated | N12: 2022-01-01 | O12: 2022-12-31
A13: 300014_2023_gross | B13: 惠州亿纬锂能股份有限公司2023毛利 | C13: =(('Facts'!F17-'Facts'!F18))*1 | D13: =(('Facts'!F17-'Facts'!F18))*1 -> 8.3102904e+09 | E13: =D13/K13 -> 8.3102904e+09 | F13: =IF(ISNUMBER(D13),"calculated","not_calculated") -> calculated | G13: =IF(ISNUMBER(D13),"","检查缺失值、分母与输入；口径变更须重跑Python") | H13: 当期合并营业收入减营业成本 | I13: 原报告列报口径；成本重分类会改变毛利。 | J13: CNY | K13: 1 | L13: 惠州亿纬锂能股份有限公司 | M13: consolidated | N13: 2023-01-01 | O13: 2023-12-31
A14: 300014_2023_margin | B14: 惠州亿纬锂能股份有限公司2023毛利率 | C14: =IF('Facts'!F17<=0,NA(),(('Calculations'!D13/'Facts'!F17))*1) | D14: =IF('Facts'!F17<=0,NA(),(('Calculations'!D13/'Facts'!F17))*1) -> 0.17035013 | E14: =D14/K14 -> 0.17035013 | F14: =IF(ISNUMBER(D14),"calculated","not_calculated") -> calculated | G14: =IF(ISNUMBER(D14),"","检查缺失值、分母与输入；口径变更须重跑Python") | H14: 当期毛利/营业收入 | I14: 不代表同口径经济利润变化或下一年保证。 | J14: ratio | K14: 1 | L14: 惠州亿纬锂能股份有限公司 | M14: consolidated | N14: 2023-01-01 | O14: 2023-12-31
A15: 300014_2024_gross | B15: 惠州亿纬锂能股份有限公司2024毛利 | C15: =(('Facts'!F20-'Facts'!F21))*1 | D15: =(('Facts'!F20-'Facts'!F21))*1 -> 8.4653483e+09 | E15: =D15/K15 -> 8.4653483e+09 | F15: =IF(ISNUMBER(D15),"calculated","not_calculated") -> calculated | G15: =IF(ISNUMBER(D15),"","检查缺失值、分母与输入；口径变更须重跑Python") | H15: 当期合并营业收入减营业成本 | I15: 原报告列报口径；成本重分类会改变毛利。 | J15: CNY | K15: 1 | L15: 惠州亿纬锂能股份有限公司 | M15: consolidated | N15: 2024-01-01 | O15: 2024-12-31
A16: 300014_2024_margin | B16: 惠州亿纬锂能股份有限公司2024毛利率 | C16: =IF('Facts'!F20<=0,NA(),(('Calculations'!D15/'Facts'!F20))*1) | D16: =IF('Facts'!F20<=0,NA(),(('Calculations'!D15/'Facts'!F20))*1) -> 0.17413197 | E16: =D16/K16 -> 0.17413197 | F16: =IF(ISNUMBER(D16),"calculated","not_calculated") -> calculated | G16: =IF(ISNUMBER(D16),"","检查缺失值、分母与输入；口径变更须重跑Python") | H16: 当期毛利/营业收入 | I16: 不代表同口径经济利润变化或下一年保证。 | J16: ratio | K16: 1 | L16: 惠州亿纬锂能股份有限公司 | M16: consolidated | N16: 2024-01-01 | O16: 2024-12-31
A17: 300014_2025_gross | B17: 惠州亿纬锂能股份有限公司2025毛利 | C17: =(('Facts'!F23-'Facts'!F24))*1 | D17: =(('Facts'!F23-'Facts'!F24))*1 -> 9.9411393e+09 | E17: =D17/K17 -> 9.9411393e+09 | F17: =IF(ISNUMBER(D17),"calculated","not_calculated") -> calculated | G17: =IF(ISNUMBER(D17),"","检查缺失值、分母与输入；口径变更须重跑Python") | H17: 当期合并营业收入减营业成本 | I17: 原报告列报口径；成本重分类会改变毛利。 | J17: CNY | K17: 1 | L17: 惠州亿纬锂能股份有限公司 | M17: consolidated | N17: 2025-01-01 | O17: 2025-12-31
A18: 300014_2025_margin | B18: 惠州亿纬锂能股份有限公司2025毛利率 | C18: =IF('Facts'!F23<=0,NA(),(('Calculations'!D17/'Facts'!F23))*1) | D18: =IF('Facts'!F23<=0,NA(),(('Calculations'!D17/'Facts'!F23))*1) -> 0.1617244 | E18: =D18/K18 -> 0.1617244 | F18: =IF(ISNUMBER(D18),"calculated","not_calculated") -> calculated | G18: =IF(ISNUMBER(D18),"","检查缺失值、分母与输入；口径变更须重跑Python") | H18: 当期毛利/营业收入 | I18: 不代表同口径经济利润变化或下一年保证。 | J18: ratio | K18: 1 | L18: 惠州亿纬锂能股份有限公司 | M18: consolidated | N18: 2025-01-01 | O18: 2025-12-31
A19: 300014_2025_gpa | B19: 惠州亿纬锂能股份有限公司2025毛利/期末资产 | C19: =IF('Facts'!F25<=0,NA(),(('Calculations'!D17/'Facts'!F25))*1) | D19: =IF('Facts'!F25<=0,NA(),(('Calculations'!D17/'Facts'!F25))*1) -> 0.079185577 | E19: =D19/K19 -> 0.079185577 | F19: =IF(ISNUMBER(D19),"calculated","not_calculated") -> calculated | G19: =IF(ISNUMBER(D19),"","检查缺失值、分母与输入；口径变更须重跑Python") | H19: 当期毛利/当期期末总资产 | I19: 明确采用期末资产；不是使用平均资产的ROA。 | J19: ratio | K19: 1 | L19: 惠州亿纬锂能股份有限公司 | M19: consolidated | N19: 2025-01-01 | O19: 2025-12-31
A20: 300207_2022_gross | B20: 欣旺达电子股份有限公司2022毛利 | C20: =(('Facts'!F26-'Facts'!F27))*1 | D20: =(('Facts'!F26-'Facts'!F27))*1 -> 7.21932e+09 | E20: =D20/K20 -> 7.21932e+09 | F20: =IF(ISNUMBER(D20),"calculated","not_calculated") -> calculated | G20: =IF(ISNUMBER(D20),"","检查缺失值、分母与输入；口径变更须重跑Python") | H20: 当期合并营业收入减营业成本 | I20: 原报告列报口径；成本重分类会改变毛利。 | J20: CNY | K20: 1 | L20: 欣旺达电子股份有限公司 | M20: consolidated | N20: 2022-01-01 | O20: 2022-12-31
A21: 300207_2022_margin | B21: 欣旺达电子股份有限公司2022毛利率 | C21: =IF('Facts'!F26<=0,NA(),(('Calculations'!D20/'Facts'!F26))*1) | D21: =IF('Facts'!F26<=0,NA(),(('Calculations'!D20/'Facts'!F26))*1) -> 0.13840119 | E21: =D21/K21 -> 0.13840119 | F21: =IF(ISNUMBER(D21),"calculated","not_calculated") -> calculated | G21: =IF(ISNUMBER(D21),"","检查缺失值、分母与输入；口径变更须重跑Python") | H21: 当期毛利/营业收入 | I21: 不代表同口径经济利润变化或下一年保证。 | J21: ratio | K21: 1 | L21: 欣旺达电子股份有限公司 | M21: consolidated | N21: 2022-01-01 | O21: 2022-12-31
A22: 300207_2023_gross | B22: 欣旺达电子股份有限公司2023毛利 | C22: =(('Facts'!F29-'Facts'!F30))*1 | D22: =(('Facts'!F29-'Facts'!F30))*1 -> 6.985925e+09 | E22: =D22/K22 -> 6.985925e+09 | F22: =IF(ISNUMBER(D22),"calculated","not_calculated") -> calculated | G22: =IF(ISNUMBER(D22),"","检查缺失值、分母与输入；口径变更须重跑Python") | H22: 当期合并营业收入减营业成本 | I22: 原报告列报口径；成本重分类会改变毛利。 | J22: CNY | K22: 1 | L22: 欣旺达电子股份有限公司 | M22: consolidated | N22: 2023-01-01 | O22: 2023-12-31
A23: 300207_2023_margin | B23: 欣旺达电子股份有限公司2023毛利率 | C23: =IF('Facts'!F29<=0,NA(),(('Calculations'!D22/'Facts'!F29))*1) | D23: =IF('Facts'!F29<=0,NA(),(('Calculations'!D22/'Facts'!F29))*1) -> 0.14595905 | E23: =D23/K23 -> 0.14595905 | F23: =IF(ISNUMBER(D23),"calculated","not_calculated") -> calculated | G23: =IF(ISNUMBER(D23),"","检查缺失值、分母与输入；口径变更须重跑Python") | H23: 当期毛利/营业收入 | I23: 不代表同口径经济利润变化或下一年保证。 | J23: ratio | K23: 1 | L23: 欣旺达电子股份有限公司 | M23: consolidated | N23: 2023-01-01 | O23: 2023-12-31
A24: 300207_2024_gross | B24: 欣旺达电子股份有限公司2024毛利 | C24: =(('Facts'!F32-'Facts'!F33))*1 | D24: =(('Facts'!F32-'Facts'!F33))*1 -> 8.5016372e+09 | E24: =D24/K24 -> 8.5016372e+09 | F24: =IF(ISNUMBER(D24),"calculated","not_calculated") -> calculated | G24: =IF(ISNUMBER(D24),"","检查缺失值、分母与输入；口径变更须重跑Python") | H24: 当期合并营业收入减营业成本 | I24: 原报告列报口径；成本重分类会改变毛利。 | J24: CNY | K24: 1 | L24: 欣旺达电子股份有限公司 | M24: consolidated | N24: 2024-01-01 | O24: 2024-12-31
A25: 300207_2024_margin | B25: 欣旺达电子股份有限公司2024毛利率 | C25: =IF('Facts'!F32<=0,NA(),(('Calculations'!D24/'Facts'!F32))*1) | D25: =IF('Facts'!F32<=0,NA(),(('Calculations'!D24/'Facts'!F32))*1) -> 0.15175903 | E25: =D25/K25 -> 0.15175903 | F25: =IF(ISNUMBER(D25),"calculated","not_calculated") -> calculated | G25: =IF(ISNUMBER(D25),"","检查缺失值、分母与输入；口径变更须重跑Python") | H25: 当期毛利/营业收入 | I25: 不代表同口径经济利润变化或下一年保证。 | J25: ratio | K25: 1 | L25: 欣旺达电子股份有限公司 | M25: consolidated | N25: 2024-01-01 | O25: 2024-12-31
A26: 300207_2025_gross | B26: 欣旺达电子股份有限公司2025毛利 | C26: =(('Facts'!F35-'Facts'!F36))*1 | D26: =(('Facts'!F35-'Facts'!F36))*1 -> 8.8169922e+09 | E26: =D26/K26 -> 8.8169922e+09 | F26: =IF(ISNUMBER(D26),"calculated","not_calculated") -> calculated | G26: =IF(ISNUMBER(D26),"","检查缺失值、分母与输入；口径变更须重跑Python") | H26: 当期合并营业收入减营业成本 | I26: 原报告列报口径；成本重分类会改变毛利。 | J26: CNY | K26: 1 | L26: 欣旺达电子股份有限公司 | M26: consolidated | N26: 2025-01-01 | O26: 2025-12-31
A27: 300207_2025_margin | B27: 欣旺达电子股份有限公司2025毛利率 | C27: =IF('Facts'!F35<=0,NA(),(('Calculations'!D26/'Facts'!F35))*1) | D27: =IF('Facts'!F35<=0,NA(),(('Calculations'!D26/'Facts'!F35))*1) -> 0.13940735 | E27: =D27/K27 -> 0.13940735 | F27: =IF(ISNUMBER(D27),"calculated","not_calculated") -> calculated | G27: =IF(ISNUMBER(D27),"","检查缺失值、分母与输入；口径变更须重跑Python") | H27: 当期毛利/营业收入 | I27: 不代表同口径经济利润变化或下一年保证。 | J27: ratio | K27: 1 | L27: 欣旺达电子股份有限公司 | M27: consolidated | N27: 2025-01-01 | O27: 2025-12-31
A28: 300207_2025_gpa | B28: 欣旺达电子股份有限公司2025毛利/期末资产 | C28: =IF('Facts'!F37<=0,NA(),(('Calculations'!D26/'Facts'!F37))*1) | D28: =IF('Facts'!F37<=0,NA(),(('Calculations'!D26/'Facts'!F37))*1) -> 0.081584257 | E28: =D28/K28 -> 0.081584257 | F28: =IF(ISNUMBER(D28),"calculated","not_calculated") -> calculated | G28: =IF(ISNUMBER(D28),"","检查缺失值、分母与输入；口径变更须重跑Python") | H28: 当期毛利/当期期末总资产 | I28: 明确采用期末资产；不是使用平均资产的ROA。 | J28: ratio | K28: 1 | L28: 欣旺达电子股份有限公司 | M28: consolidated | N28: 2025-01-01 | O28: 2025-12-31
A29: 300750_2022_gross | B29: 宁德时代新能源科技股份有限公司2022毛利 | C29: =(('Facts'!F38-'Facts'!F39))*1 | D29: =(('Facts'!F38-'Facts'!F39))*1 -> 66544378300 | E29: =D29/K29 -> 66544378300 | F29: =IF(ISNUMBER(D29),"calculated","not_calculated") -> calculated | G29: =IF(ISNUMBER(D29),"","检查缺失值、分母与输入；口径变更须重跑Python") | H29: 当期合并营业收入减营业成本 | I29: 原报告列报口径；成本重分类会改变毛利。 | J29: CNY | K29: 1 | L29: 宁德时代新能源科技股份有限公司 | M29: consolidated | N29: 2022-01-01 | O29: 2022-12-31
A30: 300750_2022_margin | B30: 宁德时代新能源科技股份有限公司2022毛利率 | C30: =IF('Facts'!F38<=0,NA(),(('Calculations'!D29/'Facts'!F38))*1) | D30: =IF('Facts'!F38<=0,NA(),(('Calculations'!D29/'Facts'!F38))*1) -> 0.20251246 | E30: =D30/K30 -> 0.20251246 | F30: =IF(ISNUMBER(D30),"calculated","not_calculated") -> calculated | G30: =IF(ISNUMBER(D30),"","检查缺失值、分母与输入；口径变更须重跑Python") | H30: 当期毛利/营业收入 | I30: 不代表同口径经济利润变化或下一年保证。 | J30: ratio | K30: 1 | L30: 宁德时代新能源科技股份有限公司 | M30: consolidated | N30: 2022-01-01 | O30: 2022-12-31
A31: 300750_2023_gross | B31: 宁德时代新能源科技股份有限公司2023毛利 | C31: =(('Facts'!F41-'Facts'!F42))*1 | D31: =(('Facts'!F41-'Facts'!F42))*1 -> 91846610900 | E31: =D31/K31 -> 91846610900 | F31: =IF(ISNUMBER(D31),"calculated","not_calculated") -> calculated | G31: =IF(ISNUMBER(D31),"","检查缺失值、分母与输入；口径变更须重跑Python") | H31: 当期合并营业收入减营业成本 | I31: 原报告列报口径；成本重分类会改变毛利。 | J31: CNY | K31: 1 | L31: 宁德时代新能源科技股份有限公司 | M31: consolidated | N31: 2023-01-01 | O31: 2023-12-31
A32: 300750_2023_margin | B32: 宁德时代新能源科技股份有限公司2023毛利率 | C32: =IF('Facts'!F41<=0,NA(),(('Calculations'!D31/'Facts'!F41))*1) | D32: =IF('Facts'!F41<=0,NA(),(('Calculations'!D31/'Facts'!F41))*1) -> 0.22909131 | E32: =D32/K32 -> 0.22909131 | F32: =IF(ISNUMBER(D32),"calculated","not_calculated") -> calculated | G32: =IF(ISNUMBER(D32),"","检查缺失值、分母与输入；口径变更须重跑Python") | H32: 当期毛利/营业收入 | I32: 不代表同口径经济利润变化或下一年保证。 | J32: ratio | K32: 1 | L32: 宁德时代新能源科技股份有限公司 | M32: consolidated | N32: 2023-01-01 | O32: 2023-12-31
A33: 300750_2024_gross | B33: 宁德时代新能源科技股份有限公司2024毛利 | C33: =(('Facts'!F44-'Facts'!F45))*1 | D33: =(('Facts'!F44-'Facts'!F45))*1 -> 88493595000 | E33: =D33/K33 -> 88493595000 | F33: =IF(ISNUMBER(D33),"calculated","not_calculated") -> calculated | G33: =IF(ISNUMBER(D33),"","检查缺失值、分母与输入；口径变更须重跑Python") | H33: 当期合并营业收入减营业成本 | I33: 原报告列报口径；成本重分类会改变毛利。 | J33: CNY | K33: 1 | L33: 宁德时代新能源科技股份有限公司 | M33: consolidated | N33: 2024-01-01 | O33: 2024-12-31
A34: 300750_2024_margin | B34: 宁德时代新能源科技股份有限公司2024毛利率 | C34: =IF('Facts'!F44<=0,NA(),(('Calculations'!D33/'Facts'!F44))*1) | D34: =IF('Facts'!F44<=0,NA(),(('Calculations'!D33/'Facts'!F44))*1) -> 0.24444897 | E34: =D34/K34 -> 0.24444897 | F34: =IF(ISNUMBER(D34),"calculated","not_calculated") -> calculated | G34: =IF(ISNUMBER(D34),"","检查缺失值、分母与输入；口径变更须重跑Python") | H34: 当期毛利/营业收入 | I34: 不代表同口径经济利润变化或下一年保证。 | J34: ratio | K34: 1 | L34: 宁德时代新能源科技股份有限公司 | M34: consolidated | N34: 2024-01-01 | O34: 2024-12-31
A35: 300750_2025_gross | B35: 宁德时代新能源科技股份有限公司2025毛利 | C35: =(('Facts'!F47-'Facts'!F48))*1 | D35: =(('Facts'!F47-'Facts'!F48))*1 -> 111318537000 | E35: =D35/K35 -> 111318537000 | F35: =IF(ISNUMBER(D35),"calculated","not_calculated") -> calculated | G35: =IF(ISNUMBER(D35),"","检查缺失值、分母与输入；口径变更须重跑Python") | H35: 当期合并营业收入减营业成本 | I35: 原报告列报口径；成本重分类会改变毛利。 | J35: CNY | K35: 1 | L35: 宁德时代新能源科技股份有限公司 | M35: consolidated | N35: 2025-01-01 | O35: 2025-12-31
A36: 300750_2025_margin | B36: 宁德时代新能源科技股份有限公司2025毛利率 | C36: =IF('Facts'!F47<=0,NA(),(('Calculations'!D35/'Facts'!F47))*1) | D36: =IF('Facts'!F47<=0,NA(),(('Calculations'!D35/'Facts'!F47))*1) -> 0.26272848 | E36: =D36/K36 -> 0.26272848 | F36: =IF(ISNUMBER(D36),"calculated","not_calculated") -> calculated | G36: =IF(ISNUMBER(D36),"","检查缺失值、分母与输入；口径变更须重跑Python") | H36: 当期毛利/营业收入 | I36: 不代表同口径经济利润变化或下一年保证。 | J36: ratio | K36: 1 | L36: 宁德时代新能源科技股份有限公司 | M36: consolidated | N36: 2025-01-01 | O36: 2025-12-31
A37: 300750_2025_gpa | B37: 宁德时代新能源科技股份有限公司2025毛利/期末资产 | C37: =IF('Facts'!F49<=0,NA(),(('Calculations'!D35/'Facts'!F49))*1) | D37: =IF('Facts'!F49<=0,NA(),(('Calculations'!D35/'Facts'!F49))*1) -> 0.11419306 | E37: =D37/K37 -> 0.11419306 | F37: =IF(ISNUMBER(D37),"calculated","not_calculated") -> calculated | G37: =IF(ISNUMBER(D37),"","检查缺失值、分母与输入；口径变更须重跑Python") | H37: 当期毛利/当期期末总资产 | I37: 明确采用期末资产；不是使用平均资产的ROA。 | J37: ratio | K37: 1 | L37: 宁德时代新能源科技股份有限公司 | M37: consolidated | N37: 2025-01-01 | O37: 2025-12-31

Sheet Reconciliations
A1: ID | B1: 勾稽 | C1: 实际 | D1: 目标 | E1: 残差 基础单位 | F1: 容差 基础单位 | G1: 状态 | H1: 容差依据 | I1: 未测试原因 | J1: 金额残差小数位

Sheet Sources
A1: ID | B1: 文件 | C1: 链接 | D1: 公布日期 | E1: SHA256 | F1: 时间证据与限制
A2: s_002074_2022 | B2: 国轩高科股份有限公司 2022 年度报告 | C2: https://static.cninfo.com.cn/finalpage/2023-04-28/1216662624.PDF | D2: 2023-04-28 | E2: 5f1037d1f4e4ef525605ec8c2274c095346ffae05a20d49ce54354cf3e166cfb | F2: 官方列表日期2023-04-28；保守可用时点2023-04-29T00:00:00+08:00。现时官方公告列表与已获取全文进行关联；未声称查尽所有历史修订或已证明初始披露字节未被替换。PDF元数据只用于发现矛盾，不能证明历史公开可得时间。
A3: s_002074_2023 | B3: 国轩高科股份有限公司 2023 年度报告 | C3: https://static.cninfo.com.cn/finalpage/2024-04-20/1219700973.PDF | D3: 2024-04-20 | E3: 865d69b0da6dfa059de2c924e16eb8a4e5b11fabc1b19c985769baf44c94739d | F3: 官方列表日期2024-04-20；保守可用时点2024-04-21T00:00:00+08:00。现时官方公告列表与已获取全文进行关联；未声称查尽所有历史修订或已证明初始披露字节未被替换。PDF元数据只用于发现矛盾，不能证明历史公开可得时间。
A4: s_002074_2024 | B4: 国轩高科股份有限公司 2024 年度报告 | C4: https://static.cninfo.com.cn/finalpage/2025-04-25/1223284129.PDF | D4: 2025-04-25 | E4: cacf470f2dea6d0cf64ed9aa61872c726f739129a3715876a0b1059d2a9168ba | F4: 官方列表日期2025-04-25；保守可用时点2025-04-26T00:00:00+08:00。现时官方公告列表与已获取全文进行关联；未声称查尽所有历史修订或已证明初始披露字节未被替换。PDF元数据只用于发现矛盾，不能证明历史公开可得时间。
A5: s_002074_2025 | B5: 国轩高科股份有限公司 2025 年度报告 | C5: https://static.cninfo.com.cn/finalpage/2026-04-29/1225254220.pdf | D5: 2026-04-29 | E5: 2a255f70026f280deb60691a7937b662615a1b1addb2ce379a56e95698e358fb | F5: 官方列表日期2026-04-29；保守可用时点2026-04-30T00:00:00+08:00。现时官方公告列表与已获取全文进行关联；未声称查尽所有历史修订或已证明初始披露字节未被替换。PDF元数据只用于发现矛盾，不能证明历史公开可得时间。；先前检索到同日候选1225241936.PDF，正常请求返回404；本次官网IR及巨潮列表均指向1225254220.pdf。后者元数据为2026-04-29 16:11:55+08:00，同日版本先后/差异未核实；采用日结束后的保守时点，不称其为唯一初始版本。
A6: s_300014_2022 | B6: 惠州亿纬锂能股份有限公司 2022 年度报告 | C6: https://static.cninfo.com.cn/finalpage/2023-04-18/1218857751.PDF | D6: 未核验 | E6: b681916e887b793ea79dee427de10af98a70cc2de52f28af030eb5da93d48dcf | F6: 官方列表日期2023-04-18；保守可用时点None。现时官方公告列表与已获取全文进行关联；未声称查尽所有历史修订或已证明初始披露字节未被替换。PDF元数据只用于发现矛盾，不能证明历史公开可得时间。；当前巨潮PDF与另行取得的深交所PDF的CreationDate/ModDate均为2024-01-10，晚于列表标注的2023-04-18；未查得可证实为2023首次发布的官方全文版本，故available_at留空，不得用于该时点训练或回测。
A7: s_300014_2023 | B7: 惠州亿纬锂能股份有限公司 2023 年度报告 | C7: https://static.cninfo.com.cn/finalpage/2024-04-19/1219668064.PDF | D7: 2024-04-19 | E7: 959d6d51d529fd5129c829d1358ad41d384c95560ef2f8dc23caedd91e01f33e | F7: 官方列表日期2024-04-19；保守可用时点2024-04-20T00:00:00+08:00。现时官方公告列表与已获取全文进行关联；未声称查尽所有历史修订或已证明初始披露字节未被替换。PDF元数据只用于发现矛盾，不能证明历史公开可得时间。
A8: s_300014_2024 | B8: 惠州亿纬锂能股份有限公司 2024 年度报告 | C8: https://static.cninfo.com.cn/finalpage/2025-04-18/1223125812.PDF | D8: 2025-04-18 | E8: 06be1a045d1ec713113cdcf626abfa534e2068f358770d5940975818a5a538aa | F8: 官方列表日期2025-04-18；保守可用时点2025-04-19T00:00:00+08:00。现时官方公告列表与已获取全文进行关联；未声称查尽所有历史修订或已证明初始披露字节未被替换。PDF元数据只用于发现矛盾，不能证明历史公开可得时间。
A9: s_300014_2025 | B9: 惠州亿纬锂能股份有限公司 2025 年度报告 | C9: https://static.cninfo.com.cn/finalpage/2026-03-28/1225045391.PDF | D9: 2026-03-28 | E9: 3bee0ca9a6232c60c53f195d078446a45fd4941bd997258b474cebe835eea3b8 | F9: 官方列表日期2026-03-28；保守可用时点2026-03-29T00:00:00+08:00。现时官方公告列表与已获取全文进行关联；未声称查尽所有历史修订或已证明初始披露字节未被替换。PDF元数据只用于发现矛盾，不能证明历史公开可得时间。
A10: s_300207_2022 | B10: 欣旺达电子股份有限公司 2022 年度报告 | C10: https://static.cninfo.com.cn/finalpage/2023-04-27/1216623719.PDF | D10: 2023-04-27 | E10: 7533c4ae926b324b7059aa590c89b6e6775c296f9122ada0f4f388c91c30ac57 | F10: 官方列表日期2023-04-27；保守可用时点2023-04-28T00:00:00+08:00。本次巨潮年度报告分类公开查询仅观察到这四份全文及对应摘要；未检出另外的修订全文，但未声称穷尽所有历史版本。SHA-256固定本次下载字节，不证明历史时点的文件内容从未被替换。；未取得公告当日的独立历史快照或字节校验值；当前PDF自述时间早于公告日，只能作为一致性信号，不能证明当前字节在公告日已经存在，也不能证明链接从未替换。
A11: s_300207_2023 | B11: 欣旺达电子股份有限公司 2023 年度报告 | C11: https://static.cninfo.com.cn/finalpage/2024-04-11/1219567241.PDF | D11: 2024-04-11 | E11: 2b607a8320966d5648b7d819dbe53cd0b9a0e9fabf0e873f07ebfe0f83a6d821 | F11: 官方列表日期2024-04-11；保守可用时点2024-04-12T00:00:00+08:00。本次巨潮年度报告分类公开查询仅观察到这四份全文及对应摘要；未检出另外的修订全文，但未声称穷尽所有历史版本。SHA-256固定本次下载字节，不证明历史时点的文件内容从未被替换。；未取得公告当日的独立历史快照或字节校验值；当前PDF自述时间早于公告日，只能作为一致性信号，不能证明当前字节在公告日已经存在，也不能证明链接从未替换。
A12: s_300207_2024 | B12: 欣旺达电子股份有限公司 2024 年度报告 | C12: https://static.cninfo.com.cn/finalpage/2025-04-22/1223194845.PDF | D12: 2025-04-22 | E12: c12b433318341147f879c878899bdb03ffd875505b04ba6a51bb649d6d574c92 | F12: 官方列表日期2025-04-22；保守可用时点2025-04-23T00:00:00+08:00。本次巨潮年度报告分类公开查询仅观察到这四份全文及对应摘要；未检出另外的修订全文，但未声称穷尽所有历史版本。SHA-256固定本次下载字节，不证明历史时点的文件内容从未被替换。；未取得公告当日的独立历史快照或字节校验值；当前PDF自述时间早于公告日，只能作为一致性信号，不能证明当前字节在公告日已经存在，也不能证明链接从未替换。
... A17: s_300750_2025 | B17: 宁德时代新能源科技股份有限公司 2025 年度报告 | C17: https://static.cninfo.com.cn/finalpage/2026-03-10/1225002214.PDF | D17: 2026-03-10 | E17: c15272977147dee7e6935a38ea0e4fd6855370aabb106f54cfe20f7cf6048ec9 | F17: 官方列表日期2026-03-10；保守可用时点2026-03-11T00:00:00+08:00。当前官方文件与官方公告记录对应；无观察到晚生成信号，但未取得当日独立字节快照，不能证明从未替换或穷尽修订。

Sheet Evidence
A1: ID | B1: 来源 | C1: 定位 | D1: 观察 | E1: 可靠性与限制
A2: e_002074_2022 | B2: s_002074_2022 | C2: 其中：营业收入：PDF物理页164，2022年度，原单位元；其中：营业成本：PDF物理页164，2022年度，原单位元；资产总计：PDF物理页161，2022年12月31日，原单位元 | D2: 当年合并表本期数及期末余额；收入、营业成本、资产总计分别取证。官方日期证据与已见重列差异见sources.json。 | E2: 现时官方公告列表与已获取全文进行关联；未声称查尽所有历史修订或已证明初始披露字节未被替换。PDF元数据只用于发现矛盾，不能证明历史公开可得时间。历史可用性与跨期经济可比性仍需分别判断。
A3: e_002074_2023 | B3: s_002074_2023 | C3: 其中：营业收入：PDF物理页122，2023年度，原单位元；其中：营业成本：PDF物理页122，2023年度，原单位元；资产总计：PDF物理页119，2023年12月31日，原单位元 | D3: 当年合并表本期数及期末余额；收入、营业成本、资产总计分别取证。官方日期证据与已见重列差异见sources.json。 | E3: 现时官方公告列表与已获取全文进行关联；未声称查尽所有历史修订或已证明初始披露字节未被替换。PDF元数据只用于发现矛盾，不能证明历史公开可得时间。历史可用性与跨期经济可比性仍需分别判断。
A4: e_002074_2024 | B4: s_002074_2024 | C4: 其中：营业收入：PDF物理页132，2024年度，原单位元；其中：营业成本：PDF物理页132，2024年度，原单位元；资产总计：PDF物理页128，期末余额，原单位元 | D4: 当年合并表本期数及期末余额；收入、营业成本、资产总计分别取证。官方日期证据与已见重列差异见sources.json。 | E4: 现时官方公告列表与已获取全文进行关联；未声称查尽所有历史修订或已证明初始披露字节未被替换。PDF元数据只用于发现矛盾，不能证明历史公开可得时间。历史可用性与跨期经济可比性仍需分别判断。
A5: p_002074_2024 | B5: s_002074_2024 | C5: PDF物理页[132, 183]，会计政策变更及比较数 | D5: 2024年报告披露保证类质量保证金从销售费用重分类至营业成本，调整363,418,904.40元。保留2023年报告本年列，不回填重分类后的比较数。 | E5: 记录已观察重列；未穷尽其他历史修订或证明业务范围恒定。
A6: e_002074_2025 | B6: s_002074_2025 | C6: 其中：营业收入：PDF物理页127，2025年度，原单位元；其中：营业成本：PDF物理页127，2025年度，原单位元；资产总计：PDF物理页124，期末余额，原单位元 | D6: 当年合并表本期数及期末余额；收入、营业成本、资产总计分别取证。官方日期证据与已见重列差异见sources.json。 | E6: 现时官方公告列表与已获取全文进行关联；未声称查尽所有历史修订或已证明初始披露字节未被替换。PDF元数据只用于发现矛盾，不能证明历史公开可得时间。；先前检索到同日候选1225241936.PDF，正常请求返回404；本次官网IR及巨潮列表均指向1225254220.pdf。后者元数据为2026-04-29 16:11:55+08:00，同日版本先后/差异未核实；采用日结束后的保守时点，不称其为唯一初始版本。历史可用性与跨期经济可比性仍需分别判断。
A7: e_300014_2022 | B7: s_300014_2022 | C7: 其中：营业收入：PDF物理页97，2022年度，原单位元；其中：营业成本：PDF物理页97，2022年度，原单位元；资产总计：PDF物理页93，2022年12月31日，原单位元 | D7: 当年合并表本期数及期末余额；收入、营业成本、资产总计分别取证。官方日期证据与已见重列差异见sources.json。 | E7: 现时官方公告列表与已获取全文进行关联；未声称查尽所有历史修订或已证明初始披露字节未被替换。PDF元数据只用于发现矛盾，不能证明历史公开可得时间。；当前巨潮PDF与另行取得的深交所PDF的CreationDate/ModDate均为2024-01-10，晚于列表标注的2023-04-18；未查得可证实为2023首次发布的官方全文版本，故available_at留空，不得用于该时点训练或回测。历史可用性与跨期经济可比性仍需分别判断。
A8: e_300014_2023 | B8: s_300014_2023 | C8: 其中：营业收入：PDF物理页99，2023年度，原单位元；其中：营业成本：PDF物理页99，2023年度，原单位元；资产总计：PDF物理页95，2023年12月31日，原单位元 | D8: 当年合并表本期数及期末余额；收入、营业成本、资产总计分别取证。官方日期证据与已见重列差异见sources.json。 | E8: 现时官方公告列表与已获取全文进行关联；未声称查尽所有历史修订或已证明初始披露字节未被替换。PDF元数据只用于发现矛盾，不能证明历史公开可得时间。历史可用性与跨期经济可比性仍需分别判断。
A9: e_300014_2024 | B9: s_300014_2024 | C9: 其中：营业收入：PDF物理页97，2024年度，原单位元；其中：营业成本：PDF物理页97，2024年度，原单位元；资产总计：PDF物理页93，期末余额，原单位元 | D9: 当年合并表本期数及期末余额；收入、营业成本、资产总计分别取证。官方日期证据与已见重列差异见sources.json。 | E9: 现时官方公告列表与已获取全文进行关联；未声称查尽所有历史修订或已证明初始披露字节未被替换。PDF元数据只用于发现矛盾，不能证明历史公开可得时间。历史可用性与跨期经济可比性仍需分别判断。
A10: p_300014_2024 | B10: s_300014_2024 | C10: PDF物理页[97, 140]，会计政策变更及比较数 | D10: 2024年报告披露保证类质保费用重分类，将2023年比较营业成本增加190,977,076.26元。保留2023年报告本年列，不回填重分类后的比较数。 | E10: 记录已观察重列；未穷尽其他历史修订或证明业务范围恒定。
A11: e_300014_2025 | B11: s_300014_2025 | C11: 其中：营业收入：PDF物理页90，2025年度，原单位元；其中：营业成本：PDF物理页90，2025年度，原单位元；资产总计：PDF物理页86，期末余额，原单位元 | D11: 当年合并表本期数及期末余额；收入、营业成本、资产总计分别取证。官方日期证据与已见重列差异见sources.json。 | E11: 现时官方公告列表与已获取全文进行关联；未声称查尽所有历史修订或已证明初始披露字节未被替换。PDF元数据只用于发现矛盾，不能证明历史公开可得时间。历史可用性与跨期经济可比性仍需分别判断。
A12: e_300207_2022 | B12: s_300207_2022 | C12: 其中：营业收入：PDF物理页138，2022年度，原单位元；其中：营业成本：PDF物理页138，2022年度，原单位元；资产总计：PDF物理页135，2022-12-31期末余额，原单位元 | D12: 当年合并表本期数及期末余额；收入、营业成本、资产总计分别取证。官方日期证据与已见重列差异见sources.json。 | E12: 本次巨潮年度报告分类公开查询仅观察到这四份全文及对应摘要；未检出另外的修订全文，但未声称穷尽所有历史版本。SHA-256固定本次下载字节，不证明历史时点的文件内容从未被替换。；未取得公告当日的独立历史快照或字节校验值；当前PDF自述时间早于公告日，只能作为一致性信号，不能证明当前字节在公告日已经存在，也不能证明链接从未替换。历史可用性与跨期经济可比性仍需分别判断。
... A21: e_300750_2025 | B21: s_300750_2025 | C21: 其中：营业收入：PDF物理页116，2025年度，原单位千元；其中：营业成本：PDF物理页116，2025年度，原单位千元；资产总计：PDF物理页112，2025-12-31期末余额，原单位千元 | D21: 当年合并表本期数及期末余额；收入、营业成本、资产总计分别取证。官方日期证据与已见重列差异见sources.json。 | E21: 当前官方文件与官方公告记录对应；无观察到晚生成信号，但未取得当日独立字节快照，不能证明从未替换或穷尽修订。历史可用性与跨期经济可比性仍需分别判断。

Sheet Findings
A1: ID | B1: 问题 | C1: 结论 | D1: 机制 | E1: 状态 | F1: 依据 | G1: 反证 | H1: 其他解释 | I1: 改变结论条件
A2: vintage | B2: 历史文件与公告日能否对应？ | C2: 可用记录按固定截止分割；亿纬2022保留内容但不参与历史模型。日期级官方记录不能证明精确字节的历史可得。 | D2: 后生成文件若沿用早期公告日，会引入未来信息。 | E2: conditional | F2: e_300014_2022 | H2: 列报政策、样本选择及业务结构差异不能由一个比率模型消除。 | I2: 取得原始字节版及可验证历史时间后，另立版本重新运行并报告变化。
A3: classification | B3: 毛利变化是否全部来自经营？ | C3: 2024报告中的保证类质量保证列报变化使旧期比较成本重列；模型保留原报告值，估计对象是原始披露毛利率。 | D3: 销售费用转入营业成本可以改变毛利率，而不因此改变利润总额；不能将全部毛利变化解释为经营改善或恶化。 | E3: conditional | F3: p_300750_2024, p_300207_2024, p_002074_2024, p_300014_2024 | H3: 列报政策、样本选择及业务结构差异不能由一个比率模型消除。 | I3: 若研究目的改为经济可比趋势，需要另建截至当时可得的调整桥，不能覆盖原版本。
A4: holdout | B4: 固定OLS是否优于沿用上期值？ | C4: 训练、留出及未成熟记录均按预先约定划分，逐公司误差及两项MAE见模型表。本案例不据结果选择模型。 | D4: 三个训练配对只支持代数拟合；产品结构、政策断点及共同周期限制外推。 | E4: conditional | F4: e_300750_2022, e_300207_2022, e_002074_2022 | H4: 列报政策、样本选择及业务结构差异不能由一个比率模型消除。 | I4: 需要更多历史可用版本、不同周期和预先独立设定的验证任务，才可评价推广表现。
A5: peers | B5: 同业位置能否直接转成质量评级？ | C5: 毛利/期末资产及百分位仅描述四家公司当前所给样本，不映射健康分数、违约概率或投资评级。 | D5: 电池品类、资产投入阶段、外协比例和合并范围都会影响该指标。 | E5: conditional | F5: 002074_2025_gpa, 300014_2025_gpa, 300207_2025_gpa, 300750_2025_gpa | H5: 列报政策、样本选择及业务结构差异不能由一个比率模型消除。 | I5: 取得可比产品和分部信息后才可形成更细的经营解释。

Sheet Procedures
A1: ID | B1: 事项 | C1: 目的与认定 | D1: 总体 | E1: 选取 | F1: 步骤 | G1: 状态 | H1: 实际结果 | I1: 证据 | J1: 执行者日期

Sheet Requests
A1: ID | B1: 事项 | C1: 所需资料 | D1: 影响 | E1: 责任角色 | F1: 关闭条件

Sheet Q1Records
A1: id | B1: entity | C1: period_end | D1: available_at | E1: version | F1: revenue | G1: cost_of_sales | H1: total_assets | I1: industry | J1: accounting_basis | K1: currency | L1: source
A2: 002074_2022 | B2: 国轩高科股份有限公司 | C2: 2022-12-31 | D2: 2023-04-29T00:00:00+08:00 | E2: own-year-report-current-column | F2: 2.3051701e+10 | G2: 1.8949696e+10 | H2: 7.2627365e+10 | I2: battery-industrial | J2: CAS | K2: CNY | L2: https://static.cninfo.com.cn/finalpage/2023-04-28/1216662624.PDF
A3: 002074_2023 | B3: 国轩高科股份有限公司 | C3: 2023-12-31 | D3: 2024-04-21T00:00:00+08:00 | E3: own-year-report-current-column | F3: 3.160549e+10 | G3: 2.6257212e+10 | H3: 9.3592652e+10 | I3: battery-industrial | J3: CAS | K3: CNY | L3: https://static.cninfo.com.cn/finalpage/2024-04-20/1219700973.PDF
A4: 002074_2024 | B4: 国轩高科股份有限公司 | C4: 2024-12-31 | D4: 2025-04-26T00:00:00+08:00 | E4: own-year-report-current-column | F4: 3.5391817e+10 | G4: 2.9020131e+10 | H4: 1.0783969e+11 | I4: battery-industrial | J4: CAS | K4: CNY | L4: https://static.cninfo.com.cn/finalpage/2025-04-25/1223284129.PDF
A5: 002074_2025 | B5: 国轩高科股份有限公司 | C5: 2025-12-31 | D5: 2026-04-30T00:00:00+08:00 | E5: own-year-report-current-column | F5: 4.5070462e+10 | G5: 3.7780369e+10 | H5: 1.2721452e+11 | I5: battery-industrial | J5: CAS | K5: CNY | L5: https://static.cninfo.com.cn/finalpage/2026-04-29/1225254220.pdf
A6: 300014_2023 | B6: 惠州亿纬锂能股份有限公司 | C6: 2023-12-31 | D6: 2024-04-20T00:00:00+08:00 | E6: own-year-report-current-column | F6: 4.8783587e+10 | G6: 4.0473297e+10 | H6: 9.4355338e+10 | I6: battery-industrial | J6: CAS | K6: CNY | L6: https://static.cninfo.com.cn/finalpage/2024-04-19/1219668064.PDF
A7: 300014_2024 | B7: 惠州亿纬锂能股份有限公司 | C7: 2024-12-31 | D7: 2025-04-19T00:00:00+08:00 | E7: own-year-report-current-column | F7: 4.8614557e+10 | G7: 4.0149208e+10 | H7: 1.0089062e+11 | I7: battery-industrial | J7: CAS | K7: CNY | L7: https://static.cninfo.com.cn/finalpage/2025-04-18/1223125812.PDF
A8: 300014_2025 | B8: 惠州亿纬锂能股份有限公司 | C8: 2025-12-31 | D8: 2026-03-29T00:00:00+08:00 | E8: own-year-report-current-column | F8: 6.1469631e+10 | G8: 5.1528492e+10 | H8: 1.255423e+11 | I8: battery-industrial | J8: CAS | K8: CNY | L8: https://static.cninfo.com.cn/finalpage/2026-03-28/1225045391.PDF
A9: 300207_2022 | B9: 欣旺达电子股份有限公司 | C9: 2022-12-31 | D9: 2023-04-28T00:00:00+08:00 | E9: own-year-report-current-column | F9: 5.2162269e+10 | G9: 4.4942949e+10 | H9: 7.4494462e+10 | I9: battery-industrial | J9: CAS | K9: CNY | L9: https://static.cninfo.com.cn/finalpage/2023-04-27/1216623719.PDF
A10: 300207_2023 | B10: 欣旺达电子股份有限公司 | C10: 2023-12-31 | D10: 2024-04-12T00:00:00+08:00 | E10: own-year-report-current-column | F10: 4.7862227e+10 | G10: 4.0876302e+10 | H10: 7.9261259e+10 | I10: battery-industrial | J10: CAS | K10: CNY | L10: https://static.cninfo.com.cn/finalpage/2024-04-11/1219567241.PDF
A11: 300207_2024 | B11: 欣旺达电子股份有限公司 | C11: 2024-12-31 | D11: 2025-04-23T00:00:00+08:00 | E11: own-year-report-current-column | F11: 5.6020634e+10 | G11: 4.7518997e+10 | H11: 8.7322727e+10 | I11: battery-industrial | J11: CAS | K11: CNY | L11: https://static.cninfo.com.cn/finalpage/2025-04-22/1223194845.PDF
A12: 300207_2025 | B12: 欣旺达电子股份有限公司 | C12: 2025-12-31 | D12: 2026-04-25T00:00:00+08:00 | E12: own-year-report-current-column | F12: 6.3246252e+10 | G12: 5.442926e+10 | H12: 1.0807223e+11 | I12: battery-industrial | J12: CAS | K12: CNY | L12: https://static.cninfo.com.cn/finalpage/2026-04-24/1225160491.PDF
A13: 300750_2022 | B13: 宁德时代新能源科技股份有限公司 | C13: 2022-12-31 | D13: 2023-03-11T00:00:00+08:00 | E13: own-year-report-current-column | F13: 328593987500 | G13: 262049609200 | H13: 600952351900 | I13: battery-industrial | J13: CAS | K13: CNY | L13: https://static.cninfo.com.cn/finalpage/2023-03-10/1216084559.PDF
... A16: 300750_2025 | B16: 宁德时代新能源科技股份有限公司 | C16: 2025-12-31 | D16: 2026-03-11T00:00:00+08:00 | E16: own-year-report-current-column | F16: 423701834000 | G16: 312383297000 | H16: 974827544000 | I16: battery-industrial | J16: CAS | K16: CNY | L16: https://static.cninfo.com.cn/finalpage/2026-03-10/1225002214.PDF

Sheet Q1Peers
A1: 企业 | B1: 选用记录 | C1: 可用时间 | D1: 版本 | E1: 毛利率 | F1: 毛利/期末资产 | G1: 样本内百分位 | H1: 有效同业数
A2: 宁德时代新能源科技股份有限公司 | B2: 300750_2025 | C2: 2026-03-11T00:00:00+08:00 | D2: own-year-report-current-column | E2: =IFERROR(IF(AND(COUNT('Q1Records'!F16:G16)=2,'Q1Records'!F16>0),('Q1Records'!F16-'Q1Records'!G16)/'Q1Records'!F16,NA()),NA()) -> 0.26272848 | F2: =IF(AND(COUNT('Q1Records'!F16:H16)=3,'Q1Records'!H16>0),('Q1Records'!F16-'Q1Records'!G16)/'Q1Records'!H16,NA()) -> 0.11419306 | G2: =IF(ISNUMBER(F2),IFERROR((COUNTIF(F$2:F$5,"<"&F2)+(COUNTIF(F$2:F$5,F2)+1)/2)/COUNT(F$2:F$5),NA()),NA()) -> 1 | H2: =COUNT(F$2:F$5) -> 4
A3: 惠州亿纬锂能股份有限公司 | B3: 300014_2025 | C3: 2026-03-29T00:00:00+08:00 | D3: own-year-report-current-column | E3: =IFERROR(IF(AND(COUNT('Q1Records'!F8:G8)=2,'Q1Records'!F8>0),('Q1Records'!F8-'Q1Records'!G8)/'Q1Records'!F8,NA()),NA()) -> 0.1617244 | F3: =IF(AND(COUNT('Q1Records'!F8:H8)=3,'Q1Records'!H8>0),('Q1Records'!F8-'Q1Records'!G8)/'Q1Records'!H8,NA()) -> 0.079185577 | G3: =IF(ISNUMBER(F3),IFERROR((COUNTIF(F$2:F$5,"<"&F3)+(COUNTIF(F$2:F$5,F3)+1)/2)/COUNT(F$2:F$5),NA()),NA()) -> 0.5 | H3: =COUNT(F$2:F$5) -> 4
A4: 欣旺达电子股份有限公司 | B4: 300207_2025 | C4: 2026-04-25T00:00:00+08:00 | D4: own-year-report-current-column | E4: =IFERROR(IF(AND(COUNT('Q1Records'!F12:G12)=2,'Q1Records'!F12>0),('Q1Records'!F12-'Q1Records'!G12)/'Q1Records'!F12,NA()),NA()) -> 0.13940735 | F4: =IF(AND(COUNT('Q1Records'!F12:H12)=3,'Q1Records'!H12>0),('Q1Records'!F12-'Q1Records'!G12)/'Q1Records'!H12,NA()) -> 0.081584257 | G4: =IF(ISNUMBER(F4),IFERROR((COUNTIF(F$2:F$5,"<"&F4)+(COUNTIF(F$2:F$5,F4)+1)/2)/COUNT(F$2:F$5),NA()),NA()) -> 0.75 | H4: =COUNT(F$2:F$5) -> 4
A5: 国轩高科股份有限公司 | B5: 002074_2025 | C5: 2026-04-30T00:00:00+08:00 | D5: own-year-report-current-column | E5: =IFERROR(IF(AND(COUNT('Q1Records'!F5:G5)=2,'Q1Records'!F5>0),('Q1Records'!F5-'Q1Records'!G5)/'Q1Records'!F5,NA()),NA()) -> 0.16174879 | F5: =IF(AND(COUNT('Q1Records'!F5:H5)=3,'Q1Records'!H5>0),('Q1Records'!F5-'Q1Records'!G5)/'Q1Records'!H5,NA()) -> 0.057305507 | G5: =IF(ISNUMBER(F5),IFERROR((COUNTIF(F$2:F$5,"<"&F5)+(COUNTIF(F$2:F$5,F5)+1)/2)/COUNT(F$2:F$5),NA()),NA()) -> 0.25 | H5: =COUNT(F$2:F$5) -> 4

Sheet Q1Train
A1: 企业 | B1: 首次起点记录 | C1: 首次目标记录 | D1: 当前毛利率 | E1: 下一年毛利率
A2: 宁德时代新能源科技股份有限公司 | B2: 300750_2022 | C2: 300750_2023 | D2: =IF(AND(COUNT('Q1Records'!F13:G13)=2,'Q1Records'!F13>0),('Q1Records'!F13-'Q1Records'!G13)/'Q1Records'!F13,NA()) -> 0.20251246 | E2: =IF(AND(COUNT('Q1Records'!F14:G14)=2,'Q1Records'!F14>0),('Q1Records'!F14-'Q1Records'!G14)/'Q1Records'!F14,NA()) -> 0.22909131
A3: 欣旺达电子股份有限公司 | B3: 300207_2022 | C3: 300207_2023 | D3: =IF(AND(COUNT('Q1Records'!F9:G9)=2,'Q1Records'!F9>0),('Q1Records'!F9-'Q1Records'!G9)/'Q1Records'!F9,NA()) -> 0.13840119 | E3: =IF(AND(COUNT('Q1Records'!F10:G10)=2,'Q1Records'!F10>0),('Q1Records'!F10-'Q1Records'!G10)/'Q1Records'!F10,NA()) -> 0.14595905
A4: 国轩高科股份有限公司 | B4: 002074_2022 | C4: 002074_2023 | D4: =IF(AND(COUNT('Q1Records'!F2:G2)=2,'Q1Records'!F2>0),('Q1Records'!F2-'Q1Records'!G2)/'Q1Records'!F2,NA()) -> 0.17794805 | E4: =IF(AND(COUNT('Q1Records'!F3:G3)=2,'Q1Records'!F3>0),('Q1Records'!F3-'Q1Records'!G3)/'Q1Records'!F3,NA()) -> 0.16921991

Sheet Q1Model
A1: 字段 | B1: 结果
A2: training_n | B2: 3
A3: test_n | B3: 4
A4: intercept | B4: =IFERROR(INTERCEPT('Q1Train'!E2:E4,'Q1Train'!D2:D4),NA()) -> -0.031277977
A5: slope | B5: =IFERROR(SLOPE('Q1Train'!E2:E4,'Q1Train'!D2:D4),NA()) -> 1.2298156
A6: test_mae | B6: =AVERAGE('Q1Test'!G2:G5) -> 0.018024777
A7: baseline_mae | B7: =AVERAGE('Q1Test'!H2:H5) -> 0.015330677
A8: status | B8: estimated
A9: 解释 | B9: 样本/时间/版本改变须重跑panel.py；固定样本数值变化可复算OLS及留出误差。不是PD或显著性证明。

Sheet Q1Test
A1: 企业 | B1: 起点记录 | C1: 目标记录 | D1: 当前值 | E1: 实际下一期 | F1: 预测 | G1: 预测绝对误差 | H1: Last-value绝对误差 | I1: 起点可用时间 | J1: 目标可用时间
A2: 宁德时代新能源科技股份有限公司 | B2: 300750_2024 | C2: 300750_2025 | D2: =IF(AND(COUNT('Q1Records'!F15:G15)=2,'Q1Records'!F15>0),('Q1Records'!F15-'Q1Records'!G15)/'Q1Records'!F15,NA()) -> 0.24444897 | E2: =IF(AND(COUNT('Q1Records'!F16:G16)=2,'Q1Records'!F16>0),('Q1Records'!F16-'Q1Records'!G16)/'Q1Records'!F16,NA()) -> 0.26272848 | F2: ='Q1Model'!B4+'Q1Model'!B5*D2 -> 0.26934917 | G2: =ABS(F2-E2) -> 0.0066206914 | H2: =ABS(D2-E2) -> 0.018279508 | I2: 2025-03-16T00:00:00+08:00 | J2: 2026-03-11T00:00:00+08:00
A3: 惠州亿纬锂能股份有限公司 | B3: 300014_2024 | C3: 300014_2025 | D3: =IF(AND(COUNT('Q1Records'!F7:G7)=2,'Q1Records'!F7>0),('Q1Records'!F7-'Q1Records'!G7)/'Q1Records'!F7,NA()) -> 0.17413197 | E3: =IF(AND(COUNT('Q1Records'!F8:G8)=2,'Q1Records'!F8>0),('Q1Records'!F8-'Q1Records'!G8)/'Q1Records'!F8,NA()) -> 0.1617244 | F3: ='Q1Model'!B4+'Q1Model'!B5*D3 -> 0.18287222 | G3: =ABS(F3-E3) -> 0.021147823 | H3: =ABS(D3-E3) -> 0.012407564 | I3: 2025-04-19T00:00:00+08:00 | J3: 2026-03-29T00:00:00+08:00
A4: 欣旺达电子股份有限公司 | B4: 300207_2024 | C4: 300207_2025 | D4: =IF(AND(COUNT('Q1Records'!F11:G11)=2,'Q1Records'!F11>0),('Q1Records'!F11-'Q1Records'!G11)/'Q1Records'!F11,NA()) -> 0.15175903 | E4: =IF(AND(COUNT('Q1Records'!F12:G12)=2,'Q1Records'!F12>0),('Q1Records'!F12-'Q1Records'!G12)/'Q1Records'!F12,NA()) -> 0.13940735 | F4: ='Q1Model'!B4+'Q1Model'!B5*D4 -> 0.15535764 | G4: =ABS(F4-E4) -> 0.015950294 | H4: =ABS(D4-E4) -> 0.012351684 | I4: 2025-04-23T00:00:00+08:00 | J4: 2026-04-25T00:00:00+08:00
A5: 国轩高科股份有限公司 | B5: 002074_2024 | C5: 002074_2025 | D5: =IF(AND(COUNT('Q1Records'!F4:G4)=2,'Q1Records'!F4>0),('Q1Records'!F4-'Q1Records'!G4)/'Q1Records'!F4,NA()) -> 0.18003274 | E5: =IF(AND(COUNT('Q1Records'!F5:G5)=2,'Q1Records'!F5>0),('Q1Records'!F5-'Q1Records'!G5)/'Q1Records'!F5,NA()) -> 0.16174879 | F5: ='Q1Model'!B4+'Q1Model'!B5*D5 -> 0.19012909 | G5: =ABS(F5-E5) -> 0.028380298 | H5: =ABS(D5-E5) -> 0.01828395 | I5: 2025-04-26T00:00:00+08:00 | J5: 2026-04-30T00:00:00+08:00

Sheet Q1Selection
A1: 类别 | B1: 记录 | C1: 原因
A2: pending | B2: 300750_2025 | C2: next-year outcome is not yet observed by as_of
A3: pending | B3: 300014_2025 | C3: next-year outcome is not yet observed by as_of
A4: pending | B4: 300207_2025 | C4: next-year outcome is not yet observed by as_of
A5: pending | B5: 002074_2025 | C5: next-year outcome is not yet observed by as_of
A6: excluded | B6: 300750_2023 | C6: label immature at training cutoff; origin is not out of time
A7: excluded | B7: 300207_2023 | C7: label immature at training cutoff; origin is not out of time
A8: excluded | B8: 300014_2023 | C8: label immature at training cutoff; origin is not out of time
A9: excluded | B9: 002074_2023 | C9: label immature at training cutoff; origin is not out of time

Sheet Quant1Notes
A1: field | B1: value
A2: method | B2: pit_margin_persistence_v1
A3: as_of | B3: 2026-10-02
A4: input references | B4: 002074_2022_revenue, 002074_2022_cost_of_sales, 002074_2022_total_assets, 002074_2023_revenue, 002074_2023_cost_of_sales, 002074_2023_total_assets, 002074_2024_revenue, 002074_2024_cost_of_sales, 002074_2024_total_assets, 002074_2025_revenue, 002074_2025_cost_of_sales, 002074_2025_total_assets, 300014_2023_revenue, 300014_2023_cost_of_sales, 300014_2023_total_assets, 300014_2024_revenue, 300014_2024_cost_of_sales, 300014_2024_total_assets, 300014_2025_revenue, 300014_2025_cost_of_sales, 300014_2025_total_assets, 300207_2022_revenue, 300207_2022_cost_of_sales, 300207_2022_total_assets, 300207_2023_revenue, 300207_2023_cost_of_sales, 300207_2023_total_assets, 300207_2024_revenue, 300207_2024_cost_of_sales, 300207_2024_total_assets, 300207_2025_revenue, 300207_2025_cost_of_sales, 300207_2025_total_assets, 300750_2022_revenue, 300750_2022_cost_of_sales, 300750_2022_total_assets, 300750_2023_revenue, 300750_2023_cost_of_sales, 300750_2023_total_assets, 300750_2024_revenue, 300750_2024_cost_of_sales, 300750_2024_total_assets, 300750_2025_revenue, 300750_2025_cost_of_sales, 300750_2025_total_assets
A5: assumptions | B5: Supplied universe: 事先选定宁德时代、亿纬锂能、国轩高科、欣旺达2022至2025官方合并披露；只取available_at已核对的记录。不是市场总体。 Current peers use the latest version available at as_of, with period-end assets as denominator. Historical x and y use first-publication gross margins; future restatements never replace them. One frozen pooled OLS: next-year gross margin = intercept + slope × current gross margin. Training pairs must have both releases available by 2024-10-02T00:00:00+08:00.
A6: limitations | B6: Industrial annual statements only; gross profitability is not comparable for banks and insurers. Ranks describe the supplied universe, not the whole market; no missing or delisted companies are invented. Missing or non-positive revenue is not zero margin; negative gross profits remain valid observations. Three observations only establish algebraic identifiability, not empirical reliability or cycle coverage. Holdout MAE is descriptive; no independence assumption, significance, causality, PD or investment return is claimed. Model is frozen at one cutoff, not tuned on holdout; observed firms may recur in the holdout. Unconstrained OLS predictions are not clipped to an economically plausible interval; inspect extrapolation. 仅四家事先选定企业，产品结构和合并范围不同；不是全市场样本或完全同质同业。 公告日期来自官方列表，次日零点仅为日级证据的保守边界；没有证明历史精确字节从未替换。 亿纬2022当前官方PDF的生成时间晚于原公告，历史可用时间为空，不纳入时点模型。 2024年保证类质量保证成本重分类造成列报断点；原报告毛利率不等于跨年同口径经营质量。 研究在2026年事后完成，研究者已知部分后期披露；这是固定方法流程演示，不是前瞻注册实验。 留出误差只描述本次样本，不证明预测优势、统计显著性、因果、收益、违约概率或评级。
A7: reproduction | B7: See quantitative-panel.json input_snapshot and method version
