Workbook

Sheet Readme
A1: 字段 / field | B1: 内容 / value
A2: 任务 | B2: Crown Castle 年报与Fiber出售分析
A3: 版本 | B3: crown-castle-2025-public-4
A4: 信息截止 | B4: 2026-06-30
A5: 范围 | B5: 合并报表；明确区分持续经营、终止经营及契约借款人口径
A6: 准则 | B6: US GAAP
A7: 方法与适用范围 | B7: 下载官方 PDF，以 pypdf 提取；关键表逐页图像复核；原件 SHA-256 留存
A8: 方法与适用范围 | B8: 仅采用截止日前公开原件；分别保留原报、重列比较期和期后事项，禁止跨期倒填
A9: 方法与适用范围 | B9: 以共同底稿复算四表及交易调节；金额按原表百万美元记录，勾稽差额以美元列示
A10: 方法与适用范围 | B10: 已执行程序仅为公开资料阅读、版本对照和计算；内部审计证据列为待核请求
A11: 方法与适用范围 | B11: 读取出售备考、签署出售协议和新旧信贷定义，将备考假设、实际交割收付及尚未完成的计划分列。
A12: 方法与适用范围 | B12: 按S&P Ratios and Adjustments 2025-12-17及Sector-Specific Corporate Methodology 2025-09-26数字基础设施章建立历史调整桥和条件路径；方法代理、实际现金和分析估计分列。
... A28: 限制 | B28: 来源 SSEC, SFASB, S_SP_XBRL 未列单一正式公布日期；各报告期间的公开日、快照取得日或尚待核准事项见来源记录。历史时点结论须逐项依据实际公开时间。

Sheet Facts
A1: ID | B1: 原始科目 | C1: 证据 | D1: 原始数值 | E1: 倍数 | F1: 基础单位数值 | G1: 量纲 | H1: 币种 | I1: 实体 | J1: 范围 | K1: 开始 | L1: 结束 | M1: 统计类型 | N1: 状态 | O1: 准则 | P1: 说明 | Q1: 概念 | R1: 实物单位
A2: cash2025 | B2: 2025 持续经营非受限现金 | C2: E25BS | D2: 99 | E2: 1000000 | F2: =IF(COUNT(D2,E2)=2,D2*E2,NA()) -> 99000000 | G2: money | H2: USD | I2: Crown Castle Inc. and subsidiaries | J2: consolidated | L2: 2025-12-31 | M2: instant | N2: reported | O2: US GAAP | Q2: cash
A3: cash2024 | B3: 2024 持续经营非受限现金 | C3: E25BS | D3: 100 | E3: 1000000 | F3: =IF(COUNT(D3,E3)=2,D3*E3,NA()) -> 100000000 | G3: money | H3: USD | I3: Crown Castle Inc. and subsidiaries | J3: consolidated | L3: 2024-12-31 | M3: instant | N3: restated | O3: US GAAP | P3: 2024 列是终止经营展示重列，不表示会计差错更正。 | Q3: cash
A4: restrict2025 | B4: 2025 持续经营流动受限现金 | C4: E25BS | D4: 170 | E4: 1000000 | F4: =IF(COUNT(D4,E4)=2,D4*E4,NA()) -> 170000000 | G4: money | H4: USD | I4: Crown Castle Inc. and subsidiaries | J4: consolidated | L4: 2025-12-31 | M4: instant | N4: reported | O4: US GAAP | Q4: restrict
A5: restrict2024 | B5: 2024 持续经营流动受限现金 | C5: E25BS | D5: 170 | E5: 1000000 | F5: =IF(COUNT(D5,E5)=2,D5*E5,NA()) -> 170000000 | G5: money | H5: USD | I5: Crown Castle Inc. and subsidiaries | J5: consolidated | L5: 2024-12-31 | M5: instant | N5: restated | O5: US GAAP | P5: 2024 列是终止经营展示重列，不表示会计差错更正。 | Q5: restrict
A6: recv2025 | B6: 2025 持续经营净应收款 | C6: E25BS | D6: 172 | E6: 1000000 | F6: =IF(COUNT(D6,E6)=2,D6*E6,NA()) -> 172000000 | G6: money | H6: USD | I6: Crown Castle Inc. and subsidiaries | J6: consolidated | L6: 2025-12-31 | M6: instant | N6: reported | O6: US GAAP | Q6: recv
A7: recv2024 | B7: 2024 持续经营净应收款 | C7: E25BS | D7: 129 | E7: 1000000 | F7: =IF(COUNT(D7,E7)=2,D7*E7,NA()) -> 129000000 | G7: money | H7: USD | I7: Crown Castle Inc. and subsidiaries | J7: consolidated | L7: 2024-12-31 | M7: instant | N7: restated | O7: US GAAP | P7: 2024 列是终止经营展示重列，不表示会计差错更正。 | Q7: recv
A8: prepaid2025 | B8: 2025 预付款 | C8: E25BS | D8: 79 | E8: 1000000 | F8: =IF(COUNT(D8,E8)=2,D8*E8,NA()) -> 79000000 | G8: money | H8: USD | I8: Crown Castle Inc. and subsidiaries | J8: consolidated | L8: 2025-12-31 | M8: instant | N8: reported | O8: US GAAP | Q8: prepaid
A9: prepaid2024 | B9: 2024 预付款 | C9: E25BS | D9: 74 | E9: 1000000 | F9: =IF(COUNT(D9,E9)=2,D9*E9,NA()) -> 74000000 | G9: money | H9: USD | I9: Crown Castle Inc. and subsidiaries | J9: consolidated | L9: 2024-12-31 | M9: instant | N9: restated | O9: US GAAP | P9: 2024 列是终止经营展示重列，不表示会计差错更正。 | Q9: prepaid
A10: rentcur2025 | B10: 2025 流动递延站点租金应收 | C10: E25BS | D10: 167 | E10: 1000000 | F10: =IF(COUNT(D10,E10)=2,D10*E10,NA()) -> 167000000 | G10: money | H10: USD | I10: Crown Castle Inc. and subsidiaries | J10: consolidated | L10: 2025-12-31 | M10: instant | N10: reported | O10: US GAAP | Q10: rentcur
A11: rentcur2024 | B11: 2024 流动递延站点租金应收 | C11: E25BS | D11: 164 | E11: 1000000 | F11: =IF(COUNT(D11,E11)=2,D11*E11,NA()) -> 164000000 | G11: money | H11: USD | I11: Crown Castle Inc. and subsidiaries | J11: consolidated | L11: 2024-12-31 | M11: instant | N11: restated | O11: US GAAP | P11: 2024 列是终止经营展示重列，不表示会计差错更正。 | Q11: rentcur
A12: otherca2025 | B12: 2025 其他流动资产 | C12: E25BS | D12: 23 | E12: 1000000 | F12: =IF(COUNT(D12,E12)=2,D12*E12,NA()) -> 23000000 | G12: money | H12: USD | I12: Crown Castle Inc. and subsidiaries | J12: consolidated | L12: 2025-12-31 | M12: instant | N12: reported | O12: US GAAP | Q12: otherca
A13: otherca2024 | B13: 2024 其他流动资产 | C13: E25BS | D13: 24 | E13: 1000000 | F13: =IF(COUNT(D13,E13)=2,D13*E13,NA()) -> 24000000 | G13: money | H13: USD | I13: Crown Castle Inc. and subsidiaries | J13: consolidated | L13: 2024-12-31 | M13: instant | N13: restated | O13: US GAAP | P13: 2024 列是终止经营展示重列，不表示会计差错更正。 | Q13: otherca
A14: disc_ca2025 | B14: 2025 终止经营流动资产 | C14: E25BS | D14: 434 | E14: 1000000 | F14: =IF(COUNT(D14,E14)=2,D14*E14,NA()) -> 434000000 | G14: money | H14: USD | I14: Crown Castle Inc. and subsidiaries | J14: consolidated | L14: 2025-12-31 | M14: instant | N14: reported | O14: US GAAP | Q14: disc_ca
A15: disc_ca2024 | B15: 2024 终止经营流动资产 | C15: E25BS | D15: 429 | E15: 1000000 | F15: =IF(COUNT(D15,E15)=2,D15*E15,NA()) -> 429000000 | G15: money | H15: USD | I15: Crown Castle Inc. and subsidiaries | J15: consolidated | L15: 2024-12-31 | M15: instant | N15: restated | O15: US GAAP | P15: 2024 列是终止经营展示重列，不表示会计差错更正。 | Q15: disc_ca
A16: ca2025 | B16: 2025 流动资产 | C16: E25BS | D16: 1144 | E16: 1000000 | F16: =IF(COUNT(D16,E16)=2,D16*E16,NA()) -> 1144000000 | G16: money | H16: USD | I16: Crown Castle Inc. and subsidiaries | J16: consolidated | L16: 2025-12-31 | M16: instant | N16: reported | O16: US GAAP | Q16: ca
A17: ca2024 | B17: 2024 流动资产 | C17: E25BS | D17: 1090 | E17: 1000000 | F17: =IF(COUNT(D17,E17)=2,D17*E17,NA()) -> 1090000000 | G17: money | H17: USD | I17: Crown Castle Inc. and subsidiaries | J17: consolidated | L17: 2024-12-31 | M17: instant | N17: restated | O17: US GAAP | P17: 2024 列是终止经营展示重列，不表示会计差错更正。 | Q17: ca
A18: rentnoncur2025 | B18: 2025 非流动递延站点租金应收 | C18: E25BS | D18: 2288 | E18: 1000000 | F18: =IF(COUNT(D18,E18)=2,D18*E18,NA()) -> 2288000000 | G18: money | H18: USD | I18: Crown Castle Inc. and subsidiaries | J18: consolidated | L18: 2025-12-31 | M18: instant | N18: reported | O18: US GAAP | Q18: rentnoncur
A19: rentnoncur2024 | B19: 2024 非流动递延站点租金应收 | C19: E25BS | D19: 2279 | E19: 1000000 | F19: =IF(COUNT(D19,E19)=2,D19*E19,NA()) -> 2279000000 | G19: money | H19: USD | I19: Crown Castle Inc. and subsidiaries | J19: consolidated | L19: 2024-12-31 | M19: instant | N19: restated | O19: US GAAP | P19: 2024 列是终止经营展示重列，不表示会计差错更正。 | Q19: rentnoncur
A20: ppe2025 | B20: 2025 持续经营净 PPE | C20: E25BS | D20: 6273 | E20: 1000000 | F20: =IF(COUNT(D20,E20)=2,D20*E20,NA()) -> 6273000000 | G20: money | H20: USD | I20: Crown Castle Inc. and subsidiaries | J20: consolidated | L20: 2025-12-31 | M20: instant | N20: reported | O20: US GAAP | Q20: ppe
A21: ppe2024 | B21: 2024 持续经营净 PPE | C21: E25BS | D21: 6577 | E21: 1000000 | F21: =IF(COUNT(D21,E21)=2,D21*E21,NA()) -> 6577000000 | G21: money | H21: USD | I21: Crown Castle Inc. and subsidiaries | J21: consolidated | L21: 2024-12-31 | M21: instant | N21: restated | O21: US GAAP | P21: 2024 列是终止经营展示重列，不表示会计差错更正。 | Q21: ppe
A22: rou2025 | B22: 2025 持续经营经营租赁 ROU | C22: E25BS | D22: 5473 | E22: 1000000 | F22: =IF(COUNT(D22,E22)=2,D22*E22,NA()) -> 5473000000 | G22: money | H22: USD | I22: Crown Castle Inc. and subsidiaries | J22: consolidated | L22: 2025-12-31 | M22: instant | N22: reported | O22: US GAAP | Q22: rou
A23: rou2024 | B23: 2024 持续经营经营租赁 ROU | C23: E25BS | D23: 5600 | E23: 1000000 | F23: =IF(COUNT(D23,E23)=2,D23*E23,NA()) -> 5600000000 | G23: money | H23: USD | I23: Crown Castle Inc. and subsidiaries | J23: consolidated | L23: 2024-12-31 | M23: instant | N23: restated | O23: US GAAP | P23: 2024 列是终止经营展示重列，不表示会计差错更正。 | Q23: rou
A24: gw2025 | B24: 2025 持续经营商誉 | C24: E25BS | D24: 5127 | E24: 1000000 | F24: =IF(COUNT(D24,E24)=2,D24*E24,NA()) -> 5127000000 | G24: money | H24: USD | I24: Crown Castle Inc. and subsidiaries | J24: consolidated | L24: 2025-12-31 | M24: instant | N24: reported | O24: US GAAP | Q24: gw
A25: gw2024 | B25: 2024 持续经营商誉 | C25: E25BS | D25: 5127 | E25: 1000000 | F25: =IF(COUNT(D25,E25)=2,D25*E25,NA()) -> 5127000000 | G25: money | H25: USD | I25: Crown Castle Inc. and subsidiaries | J25: consolidated | L25: 2024-12-31 | M25: instant | N25: restated | O25: US GAAP | P25: 2024 列是终止经营展示重列，不表示会计差错更正。 | Q25: gw
A26: siteint2025 | B26: 2025 租约及租户关系净无形资产 | C26: E25BS | D26: 834 | E26: 1000000 | F26: =IF(COUNT(D26,E26)=2,D26*E26,NA()) -> 834000000 | G26: money | H26: USD | I26: Crown Castle Inc. and subsidiaries | J26: consolidated | L26: 2025-12-31 | M26: instant | N26: reported | O26: US GAAP | Q26: siteint
A27: siteint2024 | B27: 2024 租约及租户关系净无形资产 | C27: E25BS | D27: 1009 | E27: 1000000 | F27: =IF(COUNT(D27,E27)=2,D27*E27,NA()) -> 1009000000 | G27: money | H27: USD | I27: Crown Castle Inc. and subsidiaries | J27: consolidated | L27: 2024-12-31 | M27: instant | N27: restated | O27: US GAAP | P27: 2024 列是终止经营展示重列，不表示会计差错更正。 | Q27: siteint
A28: otherint2025 | B28: 2025 其他净无形资产 | C28: E25BS | D28: 27 | E28: 1000000 | F28: =IF(COUNT(D28,E28)=2,D28*E28,NA()) -> 27000000 | G28: money | H28: USD | I28: Crown Castle Inc. and subsidiaries | J28: consolidated | L28: 2025-12-31 | M28: instant | N28: reported | O28: US GAAP | Q28: otherint
A29: otherint2024 | B29: 2024 其他净无形资产 | C29: E25BS | D29: 28 | E29: 1000000 | F29: =IF(COUNT(D29,E29)=2,D29*E29,NA()) -> 28000000 | G29: money | H29: USD | I29: Crown Castle Inc. and subsidiaries | J29: consolidated | L29: 2024-12-31 | M29: instant | N29: restated | O29: US GAAP | P29: 2024 列是终止经营展示重列，不表示会计差错更正。 | Q29: otherint
A30: othera2025 | B30: 2025 其他净资产 | C30: E25BS | D30: 61 | E30: 1000000 | F30: =IF(COUNT(D30,E30)=2,D30*E30,NA()) -> 61000000 | G30: money | H30: USD | I30: Crown Castle Inc. and subsidiaries | J30: consolidated | L30: 2025-12-31 | M30: instant | N30: reported | O30: US GAAP | Q30: othera
A31: othera2024 | B31: 2024 其他净资产 | C31: E25BS | D31: 58 | E31: 1000000 | F31: =IF(COUNT(D31,E31)=2,D31*E31,NA()) -> 58000000 | G31: money | H31: USD | I31: Crown Castle Inc. and subsidiaries | J31: consolidated | L31: 2024-12-31 | M31: instant | N31: restated | O31: US GAAP | P31: 2024 列是终止经营展示重列，不表示会计差错更正。 | Q31: othera
A32: disc_nca2025 | B32: 2025 终止经营非流动资产 | C32: E25BS | D32: 10291 | E32: 1000000 | F32: =IF(COUNT(D32,E32)=2,D32*E32,NA()) -> 10291000000 | G32: money | H32: USD | I32: Crown Castle Inc. and subsidiaries | J32: consolidated | L32: 2025-12-31 | M32: instant | N32: reported | O32: US GAAP | Q32: disc_nca
A33: disc_nca2024 | B33: 2024 终止经营非流动资产 | C33: E25BS | D33: 10968 | E33: 1000000 | F33: =IF(COUNT(D33,E33)=2,D33*E33,NA()) -> 10968000000 | G33: money | H33: USD | I33: Crown Castle Inc. and subsidiaries | J33: consolidated | L33: 2024-12-31 | M33: instant | N33: restated | O33: US GAAP | P33: 2024 列是终止经营展示重列，不表示会计差错更正。 | Q33: disc_nca
A34: assets2025 | B34: 2025 合并总资产 | C34: E25BS | D34: 31518 | E34: 1000000 | F34: =IF(COUNT(D34,E34)=2,D34*E34,NA()) -> 31518000000 | G34: money | H34: USD | I34: Crown Castle Inc. and subsidiaries | J34: consolidated | L34: 2025-12-31 | M34: instant | N34: reported | O34: US GAAP | Q34: assets
A35: assets2024 | B35: 2024 合并总资产 | C35: E25BS | D35: 32736 | E35: 1000000 | F35: =IF(COUNT(D35,E35)=2,D35*E35,NA()) -> 32736000000 | G35: money | H35: USD | I35: Crown Castle Inc. and subsidiaries | J35: consolidated | L35: 2024-12-31 | M35: instant | N35: restated | O35: US GAAP | P35: 2024 列是终止经营展示重列，不表示会计差错更正。 | Q35: assets
A36: ap2025 | B36: 2025 持续经营应付款 | C36: E25BS | D36: 71 | E36: 1000000 | F36: =IF(COUNT(D36,E36)=2,D36*E36,NA()) -> 71000000 | G36: money | H36: USD | I36: Crown Castle Inc. and subsidiaries | J36: consolidated | L36: 2025-12-31 | M36: instant | N36: reported | O36: US GAAP | Q36: ap
A37: ap2024 | B37: 2024 持续经营应付款 | C37: E25BS | D37: 48 | E37: 1000000 | F37: =IF(COUNT(D37,E37)=2,D37*E37,NA()) -> 48000000 | G37: money | H37: USD | I37: Crown Castle Inc. and subsidiaries | J37: consolidated | L37: 2024-12-31 | M37: instant | N37: restated | O37: US GAAP | P37: 2024 列是终止经营展示重列，不表示会计差错更正。 | Q37: ap
A38: intaccr2025 | B38: 2025 应计利息 | C38: E25BS | D38: 235 | E38: 1000000 | F38: =IF(COUNT(D38,E38)=2,D38*E38,NA()) -> 235000000 | G38: money | H38: USD | I38: Crown Castle Inc. and subsidiaries | J38: consolidated | L38: 2025-12-31 | M38: instant | N38: reported | O38: US GAAP | Q38: intaccr
A39: intaccr2024 | B39: 2024 应计利息 | C39: E25BS | D39: 244 | E39: 1000000 | F39: =IF(COUNT(D39,E39)=2,D39*E39,NA()) -> 244000000 | G39: money | H39: USD | I39: Crown Castle Inc. and subsidiaries | J39: consolidated | L39: 2024-12-31 | M39: instant | N39: restated | O39: US GAAP | P39: 2024 列是终止经营展示重列，不表示会计差错更正。 | Q39: intaccr
A40: defrev2025 | B40: 2025 流动递延收入 | C40: E25BS | D40: 192 | E40: 1000000 | F40: =IF(COUNT(D40,E40)=2,D40*E40,NA()) -> 192000000 | G40: money | H40: USD | I40: Crown Castle Inc. and subsidiaries | J40: consolidated | L40: 2025-12-31 | M40: instant | N40: reported | O40: US GAAP | Q40: defrev
...

Sheet Calculations
A1: ID | B1: 指标或桥 | C1: 基础单位公式 | D1: 基础单位结果 | E1: 展示结果 | F1: 状态 | G1: 不计算原因 | H1: 定义 | I1: 解释边界 | J1: 展示单位 | K1: 倍数 | L1: 实体 | M1: 范围 | N1: 开始 | O1: 结束
A2: C_ca_2025 | B2: 2025 流动资产分项合计 | C2: =(('Facts'!F2*1)+('Facts'!F4*1)+('Facts'!F6*1)+('Facts'!F8*1)+('Facts'!F10*1)+('Facts'!F12*1)+('Facts'!F14*1))*1 | D2: =(('Facts'!F2*1)+('Facts'!F4*1)+('Facts'!F6*1)+('Facts'!F8*1)+('Facts'!F10*1)+('Facts'!F12*1)+('Facts'!F14*1))*1 -> 1144000000 | E2: =D2/K2 -> 1144 | F2: =IF(ISNUMBER(D2),"calculated","not_calculated") -> calculated | G2: =IF(ISNUMBER(D2),"","检查缺失值、分母与输入；口径变更须重跑Python") | H2: (1 × cash2025) + (1 × restrict2025) + (1 × recv2025) + (1 × prepaid2025) + (1 × rentcur2025) + (1 × otherca2025) + (1 × disc_ca2025) | I2: 在披露精度内复算；不是新增管理层披露或审计保证。 | J2: 百万USD | K2: 1000000 | L2: Crown Castle Inc. and subsidiaries | M2: consolidated | O2: 2025-12-31
A3: C_assets_2025 | B3: 2025 总资产分项合计 | C3: =(('Facts'!F16*1)+('Facts'!F18*1)+('Facts'!F20*1)+('Facts'!F22*1)+('Facts'!F24*1)+('Facts'!F26*1)+('Facts'!F28*1)+('Facts'!F30*1)+('Facts'!F32*1))*1 | D3: =(('Facts'!F16*1)+('Facts'!F18*1)+('Facts'!F20*1)+('Facts'!F22*1)+('Facts'!F24*1)+('Facts'!F26*1)+('Facts'!F28*1)+('Facts'!F30*1)+('Facts'!F32*1))*1 -> 31518000000 | E3: =D3/K3 -> 31518 | F3: =IF(ISNUMBER(D3),"calculated","not_calculated") -> calculated | G3: =IF(ISNUMBER(D3),"","检查缺失值、分母与输入；口径变更须重跑Python") | H3: (1 × ca2025) + (1 × rentnoncur2025) + (1 × ppe2025) + (1 × rou2025) + (1 × gw2025) + (1 × siteint2025) + (1 × otherint2025) + (1 × othera2025) + (1 × disc_nca2025) | I3: 在披露精度内复算；不是新增管理层披露或审计保证。 | J3: 百万USD | K3: 1000000 | L3: Crown Castle Inc. and subsidiaries | M3: consolidated | O3: 2025-12-31
A4: C_cl_2025 | B4: 2025 流动负债分项合计 | C4: =(('Facts'!F36*1)+('Facts'!F38*1)+('Facts'!F40*1)+('Facts'!F42*1)+('Facts'!F44*1)+('Facts'!F46*1)+('Facts'!F48*1))*1 | D4: =(('Facts'!F36*1)+('Facts'!F38*1)+('Facts'!F40*1)+('Facts'!F42*1)+('Facts'!F44*1)+('Facts'!F46*1)+('Facts'!F48*1))*1 -> 4479000000 | E4: =D4/K4 -> 4479 | F4: =IF(ISNUMBER(D4),"calculated","not_calculated") -> calculated | G4: =IF(ISNUMBER(D4),"","检查缺失值、分母与输入；口径变更须重跑Python") | H4: (1 × ap2025) + (1 × intaccr2025) + (1 × defrev2025) + (1 × accr2025) + (1 × debtcur2025) + (1 × leasecur2025) + (1 × disc_cl2025) | I4: 在披露精度内复算；不是新增管理层披露或审计保证。 | J4: 百万USD | K4: 1000000 | L4: Crown Castle Inc. and subsidiaries | M4: consolidated | O4: 2025-12-31
A5: C_liab_2025 | B5: 2025 总负债分项合计 | C5: =(('Facts'!F50*1)+('Facts'!F52*1)+('Facts'!F54*1)+('Facts'!F56*1)+('Facts'!F58*1))*1 | D5: =(('Facts'!F50*1)+('Facts'!F52*1)+('Facts'!F54*1)+('Facts'!F56*1)+('Facts'!F58*1))*1 -> 33153000000 | E5: =D5/K5 -> 33153 | F5: =IF(ISNUMBER(D5),"calculated","not_calculated") -> calculated | G5: =IF(ISNUMBER(D5),"","检查缺失值、分母与输入；口径变更须重跑Python") | H5: (1 × cl2025) + (1 × debtlong2025) + (1 × leaselong2025) + (1 × otherl2025) + (1 × disc_ncl2025) | I5: 在披露精度内复算；不是新增管理层披露或审计保证。 | J5: 百万USD | K5: 1000000 | L5: Crown Castle Inc. and subsidiaries | M5: consolidated | O5: 2025-12-31
A6: C_eqparts_2025 | B6: 2025 权益组成 | C6: =(('Facts'!F62*1)+('Facts'!F64*1)+('Facts'!F66*1)+('Facts'!F68*1))*1 | D6: =(('Facts'!F62*1)+('Facts'!F64*1)+('Facts'!F66*1)+('Facts'!F68*1))*1 -> -1635000000 | E6: =D6/K6 -> -1635 | F6: =IF(ISNUMBER(D6),"calculated","not_calculated") -> calculated | G6: =IF(ISNUMBER(D6),"","检查缺失值、分母与输入；口径变更须重跑Python") | H6: (1 × common2025) + (1 × apic2025) + (1 × aoci2025) + (1 × deficit2025) | I6: 在披露精度内复算；不是新增管理层披露或审计保证。 | J6: 百万USD | K6: 1000000 | L6: Crown Castle Inc. and subsidiaries | M6: consolidated | O6: 2025-12-31
A7: C_bs_2025 | B7: 2025 资产负债恒等式 | C7: =(('Facts'!F60*1)+('Facts'!F70*1))*1 | D7: =(('Facts'!F60*1)+('Facts'!F70*1))*1 -> 31518000000 | E7: =D7/K7 -> 31518 | F7: =IF(ISNUMBER(D7),"calculated","not_calculated") -> calculated | G7: =IF(ISNUMBER(D7),"","检查缺失值、分母与输入；口径变更须重跑Python") | H7: (1 × liabilities2025) + (1 × equity2025) | I7: 在披露精度内复算；不是新增管理层披露或审计保证。 | J7: 百万USD | K7: 1000000 | L7: Crown Castle Inc. and subsidiaries | M7: consolidated | O7: 2025-12-31
A8: C_rev_2025 | B8: 2025 持续收入组成 | C8: =(('Facts'!F72*1)+('Facts'!F74*1))*1 | D8: =(('Facts'!F72*1)+('Facts'!F74*1))*1 -> 4264000000 | E8: =D8/K8 -> 4264 | F8: =IF(ISNUMBER(D8),"calculated","not_calculated") -> calculated | G8: =IF(ISNUMBER(D8),"","检查缺失值、分母与输入；口径变更须重跑Python") | H8: (1 × siterent2025) + (1 × services2025) | I8: 在披露精度内复算；不是新增管理层披露或审计保证。 | J8: 百万USD | K8: 1000000 | L8: Crown Castle Inc. and subsidiaries | M8: consolidated | N8: 2025-01-01 | O8: 2025-12-31
A9: C_opex_2025 | B9: 2025 持续费用组成 | C9: =(('Facts'!F78*1)+('Facts'!F80*1)+('Facts'!F82*1)+('Facts'!F84*1)+('Facts'!F86*1)+('Facts'!F88*1)+('Facts'!F90*1))*1 | D9: =(('Facts'!F78*1)+('Facts'!F80*1)+('Facts'!F82*1)+('Facts'!F84*1)+('Facts'!F86*1)+('Facts'!F88*1)+('Facts'!F90*1))*1 -> 2189000000 | E9: =D9/K9 -> 2189 | F9: =IF(ISNUMBER(D9),"calculated","not_calculated") -> calculated | G9: =IF(ISNUMBER(D9),"","检查缺失值、分母与输入；口径变更须重跑Python") | H9: (1 × costrent2025) + (1 × costservice2025) + (1 × sga2025) + (1 × writedown2025) + (1 × acqexpense2025) + (1 × daa2025) + (1 × restruct2025) | I9: 在披露精度内复算；不是新增管理层披露或审计保证。 | J9: 百万USD | K9: 1000000 | L9: Crown Castle Inc. and subsidiaries | M9: consolidated | N9: 2025-01-01 | O9: 2025-12-31
A10: C_pbt_2025 | B10: 2025 持续税前利润桥 | C10: =(('Facts'!F94*1)+('Facts'!F96*1)+('Facts'!F98*1)+('Facts'!F100*1))*1 | D10: =(('Facts'!F94*1)+('Facts'!F96*1)+('Facts'!F98*1)+('Facts'!F100*1))*1 -> 1119000000 | E10: =D10/K10 -> 1119 | F10: =IF(ISNUMBER(D10),"calculated","not_calculated") -> calculated | G10: =IF(ISNUMBER(D10),"","检查缺失值、分母与输入；口径变更须重跑Python") | H10: (1 × opincome2025) + (1 × interest2025) + (1 × intincome2025) + (1 × otherincome2025) | I10: 在披露精度内复算；不是新增管理层披露或审计保证。 | J10: 百万USD | K10: 1000000 | L10: Crown Castle Inc. and subsidiaries | M10: consolidated | N10: 2025-01-01 | O10: 2025-12-31
A11: C_contni_2025 | B11: 2025 持续净利润桥 | C11: =(('Facts'!F102*1)+('Facts'!F104*1))*1 | D11: =(('Facts'!F102*1)+('Facts'!F104*1))*1 -> 1103000000 | E11: =D11/K11 -> 1103 | F11: =IF(ISNUMBER(D11),"calculated","not_calculated") -> calculated | G11: =IF(ISNUMBER(D11),"","检查缺失值、分母与输入；口径变更须重跑Python") | H11: (1 × contpbt2025) + (1 × conttax2025) | I11: 在披露精度内复算；不是新增管理层披露或审计保证。 | J11: 百万USD | K11: 1000000 | L11: Crown Castle Inc. and subsidiaries | M11: consolidated | N11: 2025-01-01 | O11: 2025-12-31
A12: C_net_2025 | B12: 2025 持续加终止净利润 | C12: =(('Facts'!F106*1)+('Facts'!F112*1))*1 | D12: =(('Facts'!F106*1)+('Facts'!F112*1))*1 -> 444000000 | E12: =D12/K12 -> 444 | F12: =IF(ISNUMBER(D12),"calculated","not_calculated") -> calculated | G12: =IF(ISNUMBER(D12),"","检查缺失值、分母与输入；口径变更须重跑Python") | H12: (1 × contni2025) + (1 × discni2025) | I12: 在披露精度内复算；不是新增管理层披露或审计保证。 | J12: 百万USD | K12: 1000000 | L12: Crown Castle Inc. and subsidiaries | M12: consolidated | N12: 2025-01-01 | O12: 2025-12-31
A13: C_comp_2025 | B13: 2025 综合收益桥 | C13: =(('Facts'!F114*1)+('Facts'!F116*1))*1 | D13: =(('Facts'!F114*1)+('Facts'!F116*1))*1 -> 444000000 | E13: =D13/K13 -> 444 | F13: =IF(ISNUMBER(D13),"calculated","not_calculated") -> calculated | G13: =IF(ISNUMBER(D13),"","检查缺失值、分母与输入；口径变更须重跑Python") | H13: (1 × netincome2025) + (1 × oci2025) | I13: 在披露精度内复算；不是新增管理层披露或审计保证。 | J13: 百万USD | K13: 1000000 | L13: Crown Castle Inc. and subsidiaries | M13: consolidated | N13: 2025-01-01 | O13: 2025-12-31
A14: C_cfi_2025 | B14: 2025 投资现金流组成 | C14: =(('Facts'!F144*1)+('Facts'!F146*1)+('Facts'!F148*1)+('Facts'!F150*1))*1 | D14: =(('Facts'!F144*1)+('Facts'!F146*1)+('Facts'!F148*1)+('Facts'!F150*1))*1 -> -1158000000 | E14: =D14/K14 -> -1158 | F14: =IF(ISNUMBER(D14),"calculated","not_calculated") -> calculated | G14: =IF(ISNUMBER(D14),"","检查缺失值、分母与输入；口径变更须重跑Python") | H14: (1 × capex2025) + (1 × acqcf2025) + (1 × othercfi2025) + (1 × disccfi2025) | I14: 在披露精度内复算；不是新增管理层披露或审计保证。 | J14: 百万USD | K14: 1000000 | L14: Crown Castle Inc. and subsidiaries | M14: consolidated | N14: 2025-01-01 | O14: 2025-12-31
A15: C_cff_2025 | B15: 2025 融资现金流组成 | C15: =(('Facts'!F154*1)+('Facts'!F156*1)+('Facts'!F158*1)+('Facts'!F160*1)+('Facts'!F162*1)+('Facts'!F164*1)+('Facts'!F166*1)+('Facts'!F168*1)+('Facts'!F170*1))*1 | D15: =(('Facts'!F154*1)+('Facts'!F156*1)+('Facts'!F158*1)+('Facts'!F160*1)+('Facts'!F162*1)+('Facts'!F164*1)+('Facts'!F166*1)+('Facts'!F168*1)+('Facts'!F170*1))*1 -> -1886000000 | E15: =D15/K15 -> -1886 | F15: =IF(ISNUMBER(D15),"calculated","not_calculated") -> calculated | G15: =IF(ISNUMBER(D15),"","检查缺失值、分母与输入；口径变更须重跑Python") | H15: (1 × issuecf2025) + (1 × principalcf2025) + (1 × redeemcf2025) + (1 × drawcf2025) + (1 × repaycf2025) + (1 × cpcf2025) + (1 × feecf2025) + (1 × buycf2025) + (1 × divcf2025) | I15: 在披露精度内复算；不是新增管理层披露或审计保证。 | J15: 百万USD | K15: 1000000 | L15: Crown Castle Inc. and subsidiaries | M15: consolidated | N15: 2025-01-01 | O15: 2025-12-31
A16: C_cashdelta_2025 | B16: 2025 三类现金流合计 | C16: =(('Facts'!F142*1)+('Facts'!F152*1)+('Facts'!F172*1))*1 | D16: =(('Facts'!F142*1)+('Facts'!F152*1)+('Facts'!F172*1))*1 -> 13000000 | E16: =D16/K16 -> 13 | F16: =IF(ISNUMBER(D16),"calculated","not_calculated") -> calculated | G16: =IF(ISNUMBER(D16),"","检查缺失值、分母与输入；口径变更须重跑Python") | H16: (1 × cfo2025) + (1 × cfi2025) + (1 × cff2025) | I16: 在披露精度内复算；不是新增管理层披露或审计保证。 | J16: 百万USD | K16: 1000000 | L16: Crown Castle Inc. and subsidiaries | M16: consolidated | N16: 2025-01-01 | O16: 2025-12-31
A17: C_discassets_2025 | B17: 2025 终止资产分项 | C17: =(('Facts'!F14*1)+('Facts'!F204*1)+('Facts'!F206*1)+('Facts'!F208*1)+('Facts'!F210*-1))*1 | D17: =(('Facts'!F14*1)+('Facts'!F204*1)+('Facts'!F206*1)+('Facts'!F208*1)+('Facts'!F210*-1))*1 -> 10725000000 | E17: =D17/K17 -> 10725 | F17: =IF(ISNUMBER(D17),"calculated","not_calculated") -> calculated | G17: =IF(ISNUMBER(D17),"","检查缺失值、分母与输入；口径变更须重跑Python") | H17: (1 × disc_ca2025) + (1 × discppe2025) + (1 × discint2025) + (1 × discothernca2025) + (-1 × hfsallow2025) | I17: 在披露精度内复算；不是新增管理层披露或审计保证。 | J17: 百万USD | K17: 1000000 | L17: Crown Castle Inc. and subsidiaries | M17: consolidated | O17: 2025-12-31
A18: C_discliab_2025 | B18: 2025 终止负债分项 | C18: =(('Facts'!F48*1)+('Facts'!F222*1)+('Facts'!F224*1)+('Facts'!F226*1))*1 | D18: =(('Facts'!F48*1)+('Facts'!F222*1)+('Facts'!F224*1)+('Facts'!F226*1))*1 -> 2314000000 | E18: =D18/K18 -> 2314 | F18: =IF(ISNUMBER(D18),"calculated","not_calculated") -> calculated | G18: =IF(ISNUMBER(D18),"","检查缺失值、分母与输入；口径变更须重跑Python") | H18: (1 × disc_cl2025) + (1 × discdebtlong2025) + (1 × discleaselong2025) + (1 × discotherl2025) | I18: 在披露精度内复算；不是新增管理层披露或审计保证。 | J18: 百万USD | K18: 1000000 | L18: Crown Castle Inc. and subsidiaries | M18: consolidated | O18: 2025-12-31
A19: C_discpbt_2025 | B19: 2025 终止税前利润桥 | C19: =(('Facts'!F190*1)+('Facts'!F192*-1)+('Facts'!F194*-1))*1 | D19: =(('Facts'!F190*1)+('Facts'!F192*-1)+('Facts'!F194*-1))*1 -> 923000000 | E19: =D19/K19 -> 923 | F19: =IF(ISNUMBER(D19),"calculated","not_calculated") -> calculated | G19: =IF(ISNUMBER(D19),"","检查缺失值、分母与输入；口径变更须重跑Python") | H19: (1 × discrevenue2025) + (-1 × discopex2025) + (-1 × discgw2025) | I19: 在披露精度内复算；不是新增管理层披露或审计保证。 | J19: 百万USD | K19: 1000000 | L19: Crown Castle Inc. and subsidiaries | M19: consolidated | N19: 2025-01-01 | O19: 2025-12-31
A20: C_discpre_2025 | B20: 2025 终止处置前净利润桥 | C20: =(('Facts'!F196*1)+('Facts'!F198*1))*1 | D20: =(('Facts'!F196*1)+('Facts'!F198*1))*1 -> 916000000 | E20: =D20/K20 -> 916 | F20: =IF(ISNUMBER(D20),"calculated","not_calculated") -> calculated | G20: =IF(ISNUMBER(D20),"","检查缺失值、分母与输入；口径变更须重跑Python") | H20: (1 × discpbt2025) + (1 × disctax2025) | I20: 在披露精度内复算；不是新增管理层披露或审计保证。 | J20: 百万USD | K20: 1000000 | L20: Crown Castle Inc. and subsidiaries | M20: consolidated | N20: 2025-01-01 | O20: 2025-12-31
A21: C_tax_2025 | B21: 2025 持续税额调节 | C21: =(('Facts'!F240*1)+('Facts'!F242*1)+('Facts'!F244*1)+('Facts'!F246*1)+('Facts'!F248*1))*1 | D21: =(('Facts'!F240*1)+('Facts'!F242*1)+('Facts'!F244*1)+('Facts'!F246*1)+('Facts'!F248*1))*1 -> -16000000 | E21: =D21/K21 -> -16 | F21: =IF(ISNUMBER(D21),"calculated","not_calculated") -> calculated | G21: =IF(ISNUMBER(D21),"","检查缺失值、分母与输入；口径变更须重跑Python") | H21: (1 × statutorytax2025) + (1 × reittax2025) + (1 × vatax2025) + (1 × statetax2025) + (1 × foreigntax2025) | I21: 在披露精度内复算；不是新增管理层披露或审计保证。 | J21: 百万USD | K21: 1000000 | L21: Crown Castle Inc. and subsidiaries | M21: consolidated | N21: 2025-01-01 | O21: 2025-12-31
A22: C_contcash_2025 | B22: 2025 持续现金分层 | C22: =(('Facts'!F2*1)+('Facts'!F4*1)+('Facts'!F250*1))*1 | D22: =(('Facts'!F2*1)+('Facts'!F4*1)+('Facts'!F250*1))*1 -> 274000000 | E22: =D22/K22 -> 274 | F22: =IF(ISNUMBER(D22),"calculated","not_calculated") -> calculated | G22: =IF(ISNUMBER(D22),"","检查缺失值、分母与输入；口径变更须重跑Python") | H22: (1 × cash2025) + (1 × restrict2025) + (1 × restrictnoncur2025) | I22: 在披露精度内复算；不是新增管理层披露或审计保证。 | J22: 百万USD | K22: 1000000 | L22: Crown Castle Inc. and subsidiaries | M22: consolidated | O22: 2025-12-31
A23: C_disccash_2025 | B23: 2025 终止现金分层 | C23: =(('Facts'!F252*1)+('Facts'!F254*1))*1 | D23: =(('Facts'!F252*1)+('Facts'!F254*1))*1 -> 34000000 | E23: =D23/K23 -> 34 | F23: =IF(ISNUMBER(D23),"calculated","not_calculated") -> calculated | G23: =IF(ISNUMBER(D23),"","检查缺失值、分母与输入；口径变更须重跑Python") | H23: (1 × disccash2025) + (1 × discrestrict2025) | I23: 在披露精度内复算；不是新增管理层披露或审计保证。 | J23: 百万USD | K23: 1000000 | L23: Crown Castle Inc. and subsidiaries | M23: consolidated | O23: 2025-12-31
A24: C_cashall_2025 | B24: 2025 全部现金分层 | C24: =(('Facts'!F256*1)+('Facts'!F258*1))*1 | D24: =(('Facts'!F256*1)+('Facts'!F258*1))*1 -> 308000000 | E24: =D24/K24 -> 308 | F24: =IF(ISNUMBER(D24),"calculated","not_calculated") -> calculated | G24: =IF(ISNUMBER(D24),"","检查缺失值、分母与输入；口径变更须重跑Python") | H24: (1 × contcashall2025) + (1 × disccashall2025) | I24: 在披露精度内复算；不是新增管理层披露或审计保证。 | J24: 百万USD | K24: 1000000 | L24: Crown Castle Inc. and subsidiaries | M24: consolidated | O24: 2025-12-31
A25: C_op_2025 | B25: 2025 持续营业利润 | C25: =(('Facts'!F76*1)+('Facts'!F92*-1))*1 | D25: =(('Facts'!F76*1)+('Facts'!F92*-1))*1 -> 2075000000 | E25: =D25/K25 -> 2075 | F25: =IF(ISNUMBER(D25),"calculated","not_calculated") -> calculated | G25: =IF(ISNUMBER(D25),"","检查缺失值、分母与输入；口径变更须重跑Python") | H25: (1 × revenue2025) + (-1 × opex2025) | I25: 在披露精度内复算；不是新增管理层披露或审计保证。 | J25: 百万USD | K25: 1000000 | L25: Crown Castle Inc. and subsidiaries | M25: consolidated | N25: 2025-01-01 | O25: 2025-12-31
A26: C_discni_2025 | B26: 2025 终止净损益 | C26: =(('Facts'!F108*1)+('Facts'!F110*-1))*1 | D26: =(('Facts'!F108*1)+('Facts'!F110*-1))*1 -> -659000000 | E26: =D26/K26 -> -659 | F26: =IF(ISNUMBER(D26),"calculated","not_calculated") -> calculated | G26: =IF(ISNUMBER(D26),"","检查缺失值、分母与输入；口径变更须重跑Python") | H26: (1 × discpre2025) + (-1 × saleloss2025) | I26: 在披露精度内复算；不是新增管理层披露或审计保证。 | J26: 百万USD | K26: 1000000 | L26: Crown Castle Inc. and subsidiaries | M26: consolidated | N26: 2025-01-01 | O26: 2025-12-31
A27: C_cfo_2025 | B27: 2025 从合并净利润到 CFO | C27: =(('Facts'!F114*1)+('Facts'!F108*-1)+('Facts'!F110*1)+('Facts'!F88*1)+('Facts'!F120*1)+('Facts'!F122*1)+('Facts'!F84*1)+('Facts'!F124*1)+('Facts'!F126*1)+('Facts'!F128*1)+('Facts'!F130*1)+('Facts'!F132*1)+('Facts'!F134*1)+('Facts'!F136*1)+('Facts'!F138*1)+('Facts'!F140*1))*1 | D27: =(('Facts'!F114*1)+('Facts'!F108*-1)+('Facts'!F110*1)+('Facts'!F88*1)+('Facts'!F120*1)+('Facts'!F122*1)+('Facts'!F84*1)+('Facts'!F124*1)+('Facts'!F126*1)+('Facts'!F128*1)+('Facts'!F130*1)+('Facts'!F132*1)+('Facts'!F134*1)+('Facts'!F136*1)+('Facts'!F138*1)+('Facts'!F140*1))*1 -> 3057000000 | E27: =D27/K27 -> 3057 | F27: =IF(ISNUMBER(D27),"calculated","not_calculated") -> calculated | G27: =IF(ISNUMBER(D27),"","检查缺失值、分母与输入；口径变更须重跑Python") | H27: (1 × netincome2025) + (-1 × discpre2025) + (1 × saleloss2025) + (1 × daa2025) + (1 × finamort2025) + (1 × sbc2025) + (1 × writedown2025) + (1 × deftaxcf2025) + (1 × noncashrestruct2025) + (1 × othernoncash2025) + (1 × disccfo2025) + (1 × wcint2025) + (1 × wcap2025) + (1 × wcl2025) + (1 × wcrecv2025) + (1 × wca2025) | I27: 在披露精度内复算；不是新增管理层披露或审计保证。 | J27: 百万USD | K27: 1000000 | L27: Crown Castle Inc. and subsidiaries | M27: consolidated | N27: 2025-01-01 | O27: 2025-12-31
A28: C_cashroll_2025 | B28: 2025 现金期初至期末 | C28: =(('Facts'!F182*1)+('Facts'!F174*1)+('Facts'!F176*1))*1 | D28: =(('Facts'!F182*1)+('Facts'!F174*1)+('Facts'!F176*1))*1 -> 308000000 | E28: =D28/K28 -> 308 | F28: =IF(ISNUMBER(D28),"calculated","not_calculated") -> calculated | G28: =IF(ISNUMBER(D28),"","检查缺失值、分母与输入；口径变更须重跑Python") | H28: (1 × cashopen2025) + (1 × cashdelta2025) + (1 × fxcash2025) | I28: 在披露精度内复算；不是新增管理层披露或审计保证。 | J28: 百万USD | K28: 1000000 | L28: Crown Castle Inc. and subsidiaries | M28: consolidated | N28: 2025-01-01 | O28: 2025-12-31
A29: C_eqroll_2025 | B29: 2025 权益期初至期末 | C29: =(('Facts'!F180*1)+('Facts'!F184*1)+('Facts'!F186*1)+('Facts'!F188*1)+('Facts'!F114*1)+('Facts'!F116*1))*1 | D29: =(('Facts'!F180*1)+('Facts'!F184*1)+('Facts'!F186*1)+('Facts'!F188*1)+('Facts'!F114*1)+('Facts'!F116*1))*1 -> -1635000000 | E29: =D29/K29 -> -1635 | F29: =IF(ISNUMBER(D29),"calculated","not_calculated") -> calculated | G29: =IF(ISNUMBER(D29),"","检查缺失值、分母与输入；口径变更须重跑Python") | H29: (1 × eqopen2025) + (1 × eqstock2025) + (1 × eqbuy2025) + (1 × eqdiv2025) + (1 × netincome2025) + (1 × oci2025) | I29: 在披露精度内复算；不是新增管理层披露或审计保证。 | J29: 百万USD | K29: 1000000 | L29: Crown Castle Inc. and subsidiaries | M29: consolidated | N29: 2025-01-01 | O29: 2025-12-31
A30: C_contcfo_2025 | B30: 2025 持续经营 CFO | C30: =(('Facts'!F142*1)+('Facts'!F130*-1))*1 | D30: =(('Facts'!F142*1)+('Facts'!F130*-1))*1 -> 1872000000 | E30: =D30/K30 -> 1872 | F30: =IF(ISNUMBER(D30),"calculated","not_calculated") -> calculated | G30: =IF(ISNUMBER(D30),"","检查缺失值、分母与输入；口径变更须重跑Python") | H30: (1 × cfo2025) + (-1 × disccfo2025) | I30: 在披露精度内复算；不是新增管理层披露或审计保证。 | J30: 百万USD | K30: 1000000 | L30: Crown Castle Inc. and subsidiaries | M30: consolidated | N30: 2025-01-01 | O30: 2025-12-31
A31: C_cashcapex_2025 | B31: 2025 持续 CFO 减持续资本支出 | C31: =(('Calculations'!D30*1)+('Facts'!F144*1))*1 | D31: =(('Calculations'!D30*1)+('Facts'!F144*1))*1 -> 1690000000 | E31: =D31/K31 -> 1690 | F31: =IF(ISNUMBER(D31),"calculated","not_calculated") -> calculated | G31: =IF(ISNUMBER(D31),"","检查缺失值、分母与输入；口径变更须重跑Python") | H31: (1 × C_contcfo_2025) + (1 × capex2025) | I31: 简单现金覆盖观察，未称 AFFO、FCF 或契约 EBITDA。 | J31: 百万USD | K31: 1000000 | L31: Crown Castle Inc. and subsidiaries | M31: consolidated | N31: 2025-01-01 | O31: 2025-12-31
A32: C_cashdiv_2025 | B32: 2025 持续 CFO 减持续资本支出及集团已付分配 | C32: =(('Calculations'!D31*1)+('Facts'!F170*1))*1 | D32: =(('Calculations'!D31*1)+('Facts'!F170*1))*1 -> -390000000 | E32: =D32/K32 -> -390 | F32: =IF(ISNUMBER(D32),"calculated","not_calculated") -> calculated | G32: =IF(ISNUMBER(D32),"","检查缺失值、分母与输入；口径变更须重跑Python") | H32: (1 × C_cashcapex_2025) + (1 × divcf2025) | I32: 反事实覆盖观察：持续业务内部生成现金相对集团分配的缺口；并非母公司现金流或已归属的持续业务股利。 | J32: 百万USD | K32: 1000000 | L32: Crown Castle Inc. and subsidiaries | M32: consolidated | N32: 2025-01-01 | O32: 2025-12-31
A33: C_disccashflow_2025 | B33: 2025 终止 CFO 加 CFI | C33: =(('Facts'!F130*1)+('Facts'!F150*1))*1 | D33: =(('Facts'!F130*1)+('Facts'!F150*1))*1 -> 205000000 | E33: =D33/K33 -> 205 | F33: =IF(ISNUMBER(D33),"calculated","not_calculated") -> calculated | G33: =IF(ISNUMBER(D33),"","检查缺失值、分母与输入；口径变更须重跑Python") | H33: (1 × disccfo2025) + (1 × disccfi2025) | I33: 只含终止经营披露的经营与投资净现金，不假定终止融资现金为零。 | J33: 百万USD | K33: 1000000 | L33: Crown Castle Inc. and subsidiaries | M33: consolidated | N33: 2025-01-01 | O33: 2025-12-31
A34: C_ca_2024 | B34: 2024 流动资产分项合计 | C34: =(('Facts'!F3*1)+('Facts'!F5*1)+('Facts'!F7*1)+('Facts'!F9*1)+('Facts'!F11*1)+('Facts'!F13*1)+('Facts'!F15*1))*1 | D34: =(('Facts'!F3*1)+('Facts'!F5*1)+('Facts'!F7*1)+('Facts'!F9*1)+('Facts'!F11*1)+('Facts'!F13*1)+('Facts'!F15*1))*1 -> 1090000000 | E34: =D34/K34 -> 1090 | F34: =IF(ISNUMBER(D34),"calculated","not_calculated") -> calculated | G34: =IF(ISNUMBER(D34),"","检查缺失值、分母与输入；口径变更须重跑Python") | H34: (1 × cash2024) + (1 × restrict2024) + (1 × recv2024) + (1 × prepaid2024) + (1 × rentcur2024) + (1 × otherca2024) + (1 × disc_ca2024) | I34: 在披露精度内复算；不是新增管理层披露或审计保证。 | J34: 百万USD | K34: 1000000 | L34: Crown Castle Inc. and subsidiaries | M34: consolidated | O34: 2024-12-31
A35: C_assets_2024 | B35: 2024 总资产分项合计 | C35: =(('Facts'!F17*1)+('Facts'!F19*1)+('Facts'!F21*1)+('Facts'!F23*1)+('Facts'!F25*1)+('Facts'!F27*1)+('Facts'!F29*1)+('Facts'!F31*1)+('Facts'!F33*1))*1 | D35: =(('Facts'!F17*1)+('Facts'!F19*1)+('Facts'!F21*1)+('Facts'!F23*1)+('Facts'!F25*1)+('Facts'!F27*1)+('Facts'!F29*1)+('Facts'!F31*1)+('Facts'!F33*1))*1 -> 32736000000 | E35: =D35/K35 -> 32736 | F35: =IF(ISNUMBER(D35),"calculated","not_calculated") -> calculated | G35: =IF(ISNUMBER(D35),"","检查缺失值、分母与输入；口径变更须重跑Python") | H35: (1 × ca2024) + (1 × rentnoncur2024) + (1 × ppe2024) + (1 × rou2024) + (1 × gw2024) + (1 × siteint2024) + (1 × otherint2024) + (1 × othera2024) + (1 × disc_nca2024) | I35: 在披露精度内复算；不是新增管理层披露或审计保证。 | J35: 百万USD | K35: 1000000 | L35: Crown Castle Inc. and subsidiaries | M35: consolidated | O35: 2024-12-31
A36: C_cl_2024 | B36: 2024 流动负债分项合计 | C36: =(('Facts'!F37*1)+('Facts'!F39*1)+('Facts'!F41*1)+('Facts'!F43*1)+('Facts'!F45*1)+('Facts'!F47*1)+('Facts'!F49*1))*1 | D36: =(('Facts'!F37*1)+('Facts'!F39*1)+('Facts'!F41*1)+('Facts'!F43*1)+('Facts'!F45*1)+('Facts'!F47*1)+('Facts'!F49*1))*1 -> 2177000000 | E36: =D36/K36 -> 2177 | F36: =IF(ISNUMBER(D36),"calculated","not_calculated") -> calculated | G36: =IF(ISNUMBER(D36),"","检查缺失值、分母与输入；口径变更须重跑Python") | H36: (1 × ap2024) + (1 × intaccr2024) + (1 × defrev2024) + (1 × accr2024) + (1 × debtcur2024) + (1 × leasecur2024) + (1 × disc_cl2024) | I36: 在披露精度内复算；不是新增管理层披露或审计保证。 | J36: 百万USD | K36: 1000000 | L36: Crown Castle Inc. and subsidiaries | M36: consolidated | O36: 2024-12-31
A37: C_liab_2024 | B37: 2024 总负债分项合计 | C37: =(('Facts'!F51*1)+('Facts'!F53*1)+('Facts'!F55*1)+('Facts'!F57*1)+('Facts'!F59*1))*1 | D37: =(('Facts'!F51*1)+('Facts'!F53*1)+('Facts'!F55*1)+('Facts'!F57*1)+('Facts'!F59*1))*1 -> 32869000000 | E37: =D37/K37 -> 32869 | F37: =IF(ISNUMBER(D37),"calculated","not_calculated") -> calculated | G37: =IF(ISNUMBER(D37),"","检查缺失值、分母与输入；口径变更须重跑Python") | H37: (1 × cl2024) + (1 × debtlong2024) + (1 × leaselong2024) + (1 × otherl2024) + (1 × disc_ncl2024) | I37: 在披露精度内复算；不是新增管理层披露或审计保证。 | J37: 百万USD | K37: 1000000 | L37: Crown Castle Inc. and subsidiaries | M37: consolidated | O37: 2024-12-31
A38: C_eqparts_2024 | B38: 2024 权益组成 | C38: =(('Facts'!F63*1)+('Facts'!F65*1)+('Facts'!F67*1)+('Facts'!F69*1))*1 | D38: =(('Facts'!F63*1)+('Facts'!F65*1)+('Facts'!F67*1)+('Facts'!F69*1))*1 -> -133000000 | E38: =D38/K38 -> -133 | F38: =IF(ISNUMBER(D38),"calculated","not_calculated") -> calculated | G38: =IF(ISNUMBER(D38),"","检查缺失值、分母与输入；口径变更须重跑Python") | H38: (1 × common2024) + (1 × apic2024) + (1 × aoci2024) + (1 × deficit2024) | I38: 在披露精度内复算；不是新增管理层披露或审计保证。 | J38: 百万USD | K38: 1000000 | L38: Crown Castle Inc. and subsidiaries | M38: consolidated | O38: 2024-12-31
A39: C_bs_2024 | B39: 2024 资产负债恒等式 | C39: =(('Facts'!F61*1)+('Facts'!F71*1))*1 | D39: =(('Facts'!F61*1)+('Facts'!F71*1))*1 -> 32736000000 | E39: =D39/K39 -> 32736 | F39: =IF(ISNUMBER(D39),"calculated","not_calculated") -> calculated | G39: =IF(ISNUMBER(D39),"","检查缺失值、分母与输入；口径变更须重跑Python") | H39: (1 × liabilities2024) + (1 × equity2024) | I39: 在披露精度内复算；不是新增管理层披露或审计保证。 | J39: 百万USD | K39: 1000000 | L39: Crown Castle Inc. and subsidiaries | M39: consolidated | O39: 2024-12-31
A40: C_rev_2024 | B40: 2024 持续收入组成 | C40: =(('Facts'!F73*1)+('Facts'!F75*1))*1 | D40: =(('Facts'!F73*1)+('Facts'!F75*1))*1 -> 4460000000 | E40: =D40/K40 -> 4460 | F40: =IF(ISNUMBER(D40),"calculated","not_calculated") -> calculated | G40: =IF(ISNUMBER(D40),"","检查缺失值、分母与输入；口径变更须重跑Python") | H40: (1 × siterent2024) + (1 × services2024) | I40: 在披露精度内复算；不是新增管理层披露或审计保证。 | J40: 百万USD | K40: 1000000 | L40: Crown Castle Inc. and subsidiaries | M40: consolidated | N40: 2024-01-01 | O40: 2024-12-31
...

Sheet Reconciliations
A1: ID | B1: 勾稽 | C1: 实际 | D1: 目标 | E1: 残差 基础单位 | F1: 容差 基础单位 | G1: 状态 | H1: 容差依据 | I1: 未测试原因 | J1: 金额残差小数位
A2: R_ca_2025 | B2: 2025 流动资产分项合计 | C2: ca2025 | D2: C_ca_2025 | E2: =ROUND('Facts'!F16-'Calculations'!D2,J2) -> 0 | F2: 0 | G2: =IF(COUNT(E2,F2)<2,"not_tested",IF(ABS(E2)<=F2,"within_input_tolerance","unexplained_difference")) -> within_input_tolerance | H2: 原表百万美元列示精度，检验可直接复算桥；阈值以美元计。 | I2: =IF(ISNUMBER(E2),"","missing or unavailable input") | J2: 0
A3: R_assets_2025 | B3: 2025 总资产分项合计 | C3: assets2025 | D3: C_assets_2025 | E3: =ROUND('Facts'!F34-'Calculations'!D3,J3) -> 0 | F3: 0 | G3: =IF(COUNT(E3,F3)<2,"not_tested",IF(ABS(E3)<=F3,"within_input_tolerance","unexplained_difference")) -> within_input_tolerance | H3: 原表百万美元列示精度，检验可直接复算桥；阈值以美元计。 | I3: =IF(ISNUMBER(E3),"","missing or unavailable input") | J3: 0
A4: R_cl_2025 | B4: 2025 流动负债分项合计 | C4: cl2025 | D4: C_cl_2025 | E4: =ROUND('Facts'!F50-'Calculations'!D4,J4) -> 0 | F4: 0 | G4: =IF(COUNT(E4,F4)<2,"not_tested",IF(ABS(E4)<=F4,"within_input_tolerance","unexplained_difference")) -> within_input_tolerance | H4: 原表百万美元列示精度，检验可直接复算桥；阈值以美元计。 | I4: =IF(ISNUMBER(E4),"","missing or unavailable input") | J4: 0
A5: R_liab_2025 | B5: 2025 总负债分项合计 | C5: liabilities2025 | D5: C_liab_2025 | E5: =ROUND('Facts'!F60-'Calculations'!D5,J5) -> 0 | F5: 0 | G5: =IF(COUNT(E5,F5)<2,"not_tested",IF(ABS(E5)<=F5,"within_input_tolerance","unexplained_difference")) -> within_input_tolerance | H5: 原表百万美元列示精度，检验可直接复算桥；阈值以美元计。 | I5: =IF(ISNUMBER(E5),"","missing or unavailable input") | J5: 0
A6: R_eqparts_2025 | B6: 2025 权益组成 | C6: equity2025 | D6: C_eqparts_2025 | E6: =ROUND('Facts'!F70-'Calculations'!D6,J6) -> 0 | F6: 0 | G6: =IF(COUNT(E6,F6)<2,"not_tested",IF(ABS(E6)<=F6,"within_input_tolerance","unexplained_difference")) -> within_input_tolerance | H6: 原表百万美元列示精度，检验可直接复算桥；阈值以美元计。 | I6: =IF(ISNUMBER(E6),"","missing or unavailable input") | J6: 0
A7: R_bs_2025 | B7: 2025 资产负债恒等式 | C7: assets2025 | D7: C_bs_2025 | E7: =ROUND('Facts'!F34-'Calculations'!D7,J7) -> 0 | F7: 0 | G7: =IF(COUNT(E7,F7)<2,"not_tested",IF(ABS(E7)<=F7,"within_input_tolerance","unexplained_difference")) -> within_input_tolerance | H7: 原表百万美元列示精度，检验可直接复算桥；阈值以美元计。 | I7: =IF(ISNUMBER(E7),"","missing or unavailable input") | J7: 0
A8: R_rev_2025 | B8: 2025 持续收入组成 | C8: revenue2025 | D8: C_rev_2025 | E8: =ROUND('Facts'!F76-'Calculations'!D8,J8) -> 0 | F8: 0 | G8: =IF(COUNT(E8,F8)<2,"not_tested",IF(ABS(E8)<=F8,"within_input_tolerance","unexplained_difference")) -> within_input_tolerance | H8: 原表百万美元列示精度，检验可直接复算桥；阈值以美元计。 | I8: =IF(ISNUMBER(E8),"","missing or unavailable input") | J8: 0
A9: R_opex_2025 | B9: 2025 持续费用组成 | C9: opex2025 | D9: C_opex_2025 | E9: =ROUND('Facts'!F92-'Calculations'!D9,J9) -> 0 | F9: 0 | G9: =IF(COUNT(E9,F9)<2,"not_tested",IF(ABS(E9)<=F9,"within_input_tolerance","unexplained_difference")) -> within_input_tolerance | H9: 原表百万美元列示精度，检验可直接复算桥；阈值以美元计。 | I9: =IF(ISNUMBER(E9),"","missing or unavailable input") | J9: 0
A10: R_pbt_2025 | B10: 2025 持续税前利润桥 | C10: contpbt2025 | D10: C_pbt_2025 | E10: =ROUND('Facts'!F102-'Calculations'!D10,J10) -> 0 | F10: 0 | G10: =IF(COUNT(E10,F10)<2,"not_tested",IF(ABS(E10)<=F10,"within_input_tolerance","unexplained_difference")) -> within_input_tolerance | H10: 原表百万美元列示精度，检验可直接复算桥；阈值以美元计。 | I10: =IF(ISNUMBER(E10),"","missing or unavailable input") | J10: 0
A11: R_contni_2025 | B11: 2025 持续净利润桥 | C11: contni2025 | D11: C_contni_2025 | E11: =ROUND('Facts'!F106-'Calculations'!D11,J11) -> 0 | F11: 0 | G11: =IF(COUNT(E11,F11)<2,"not_tested",IF(ABS(E11)<=F11,"within_input_tolerance","unexplained_difference")) -> within_input_tolerance | H11: 原表百万美元列示精度，检验可直接复算桥；阈值以美元计。 | I11: =IF(ISNUMBER(E11),"","missing or unavailable input") | J11: 0
A12: R_net_2025 | B12: 2025 持续加终止净利润 | C12: netincome2025 | D12: C_net_2025 | E12: =ROUND('Facts'!F114-'Calculations'!D12,J12) -> 0 | F12: 0 | G12: =IF(COUNT(E12,F12)<2,"not_tested",IF(ABS(E12)<=F12,"within_input_tolerance","unexplained_difference")) -> within_input_tolerance | H12: 原表百万美元列示精度，检验可直接复算桥；阈值以美元计。 | I12: =IF(ISNUMBER(E12),"","missing or unavailable input") | J12: 0
A13: R_comp_2025 | B13: 2025 综合收益桥 | C13: comprehensive2025 | D13: C_comp_2025 | E13: =ROUND('Facts'!F118-'Calculations'!D13,J13) -> 0 | F13: 0 | G13: =IF(COUNT(E13,F13)<2,"not_tested",IF(ABS(E13)<=F13,"within_input_tolerance","unexplained_difference")) -> within_input_tolerance | H13: 原表百万美元列示精度，检验可直接复算桥；阈值以美元计。 | I13: =IF(ISNUMBER(E13),"","missing or unavailable input") | J13: 0
A14: R_cfi_2025 | B14: 2025 投资现金流组成 | C14: cfi2025 | D14: C_cfi_2025 | E14: =ROUND('Facts'!F152-'Calculations'!D14,J14) -> 0 | F14: 0 | G14: =IF(COUNT(E14,F14)<2,"not_tested",IF(ABS(E14)<=F14,"within_input_tolerance","unexplained_difference")) -> within_input_tolerance | H14: 原表百万美元列示精度，检验可直接复算桥；阈值以美元计。 | I14: =IF(ISNUMBER(E14),"","missing or unavailable input") | J14: 0
A15: R_cff_2025 | B15: 2025 融资现金流组成 | C15: cff2025 | D15: C_cff_2025 | E15: =ROUND('Facts'!F172-'Calculations'!D15,J15) -> 0 | F15: 0 | G15: =IF(COUNT(E15,F15)<2,"not_tested",IF(ABS(E15)<=F15,"within_input_tolerance","unexplained_difference")) -> within_input_tolerance | H15: 原表百万美元列示精度，检验可直接复算桥；阈值以美元计。 | I15: =IF(ISNUMBER(E15),"","missing or unavailable input") | J15: 0
A16: R_cashdelta_2025 | B16: 2025 三类现金流合计 | C16: cashdelta2025 | D16: C_cashdelta_2025 | E16: =ROUND('Facts'!F174-'Calculations'!D16,J16) -> 0 | F16: 0 | G16: =IF(COUNT(E16,F16)<2,"not_tested",IF(ABS(E16)<=F16,"within_input_tolerance","unexplained_difference")) -> within_input_tolerance | H16: 原表百万美元列示精度，检验可直接复算桥；阈值以美元计。 | I16: =IF(ISNUMBER(E16),"","missing or unavailable input") | J16: 0
A17: R_discassets_2025 | B17: 2025 终止资产分项 | C17: discassets2025 | D17: C_discassets_2025 | E17: =ROUND('Facts'!F212-'Calculations'!D17,J17) -> 0 | F17: 0 | G17: =IF(COUNT(E17,F17)<2,"not_tested",IF(ABS(E17)<=F17,"within_input_tolerance","unexplained_difference")) -> within_input_tolerance | H17: 原表百万美元列示精度，检验可直接复算桥；阈值以美元计。 | I17: =IF(ISNUMBER(E17),"","missing or unavailable input") | J17: 0
A18: R_discliab_2025 | B18: 2025 终止负债分项 | C18: discliab2025 | D18: C_discliab_2025 | E18: =ROUND('Facts'!F228-'Calculations'!D18,J18) -> 0 | F18: 0 | G18: =IF(COUNT(E18,F18)<2,"not_tested",IF(ABS(E18)<=F18,"within_input_tolerance","unexplained_difference")) -> within_input_tolerance | H18: 原表百万美元列示精度，检验可直接复算桥；阈值以美元计。 | I18: =IF(ISNUMBER(E18),"","missing or unavailable input") | J18: 0
A19: R_discpbt_2025 | B19: 2025 终止税前利润桥 | C19: discpbt2025 | D19: C_discpbt_2025 | E19: =ROUND('Facts'!F196-'Calculations'!D19,J19) -> 0 | F19: 0 | G19: =IF(COUNT(E19,F19)<2,"not_tested",IF(ABS(E19)<=F19,"within_input_tolerance","unexplained_difference")) -> within_input_tolerance | H19: 原表百万美元列示精度，检验可直接复算桥；阈值以美元计。 | I19: =IF(ISNUMBER(E19),"","missing or unavailable input") | J19: 0
A20: R_discpre_2025 | B20: 2025 终止处置前净利润桥 | C20: discpre2025 | D20: C_discpre_2025 | E20: =ROUND('Facts'!F108-'Calculations'!D20,J20) -> 0 | F20: 0 | G20: =IF(COUNT(E20,F20)<2,"not_tested",IF(ABS(E20)<=F20,"within_input_tolerance","unexplained_difference")) -> within_input_tolerance | H20: 原表百万美元列示精度，检验可直接复算桥；阈值以美元计。 | I20: =IF(ISNUMBER(E20),"","missing or unavailable input") | J20: 0
A21: R_tax_2025 | B21: 2025 持续税额调节 | C21: conttax2025 | D21: C_tax_2025 | E21: =ROUND('Facts'!F104-'Calculations'!D21,J21) -> 0 | F21: 0 | G21: =IF(COUNT(E21,F21)<2,"not_tested",IF(ABS(E21)<=F21,"within_input_tolerance","unexplained_difference")) -> within_input_tolerance | H21: 原表百万美元列示精度，检验可直接复算桥；阈值以美元计。 | I21: =IF(ISNUMBER(E21),"","missing or unavailable input") | J21: 0
A22: R_contcash_2025 | B22: 2025 持续现金分层 | C22: contcashall2025 | D22: C_contcash_2025 | E22: =ROUND('Facts'!F256-'Calculations'!D22,J22) -> 0 | F22: 0 | G22: =IF(COUNT(E22,F22)<2,"not_tested",IF(ABS(E22)<=F22,"within_input_tolerance","unexplained_difference")) -> within_input_tolerance | H22: 原表百万美元列示精度，检验可直接复算桥；阈值以美元计。 | I22: =IF(ISNUMBER(E22),"","missing or unavailable input") | J22: 0
A23: R_disccash_2025 | B23: 2025 终止现金分层 | C23: disccashall2025 | D23: C_disccash_2025 | E23: =ROUND('Facts'!F258-'Calculations'!D23,J23) -> 0 | F23: 0 | G23: =IF(COUNT(E23,F23)<2,"not_tested",IF(ABS(E23)<=F23,"within_input_tolerance","unexplained_difference")) -> within_input_tolerance | H23: 原表百万美元列示精度，检验可直接复算桥；阈值以美元计。 | I23: =IF(ISNUMBER(E23),"","missing or unavailable input") | J23: 0
A24: R_cashall_2025 | B24: 2025 全部现金分层 | C24: cashend2025 | D24: C_cashall_2025 | E24: =ROUND('Facts'!F178-'Calculations'!D24,J24) -> 0 | F24: 0 | G24: =IF(COUNT(E24,F24)<2,"not_tested",IF(ABS(E24)<=F24,"within_input_tolerance","unexplained_difference")) -> within_input_tolerance | H24: 原表百万美元列示精度，检验可直接复算桥；阈值以美元计。 | I24: =IF(ISNUMBER(E24),"","missing or unavailable input") | J24: 0
A25: R_op_2025 | B25: 2025 持续营业利润 | C25: opincome2025 | D25: C_op_2025 | E25: =ROUND('Facts'!F94-'Calculations'!D25,J25) -> 0 | F25: 0 | G25: =IF(COUNT(E25,F25)<2,"not_tested",IF(ABS(E25)<=F25,"within_input_tolerance","unexplained_difference")) -> within_input_tolerance | H25: 原表百万美元列示精度，检验可直接复算桥；阈值以美元计。 | I25: =IF(ISNUMBER(E25),"","missing or unavailable input") | J25: 0
A26: R_discni_2025 | B26: 2025 终止净损益 | C26: discni2025 | D26: C_discni_2025 | E26: =ROUND('Facts'!F112-'Calculations'!D26,J26) -> 0 | F26: 0 | G26: =IF(COUNT(E26,F26)<2,"not_tested",IF(ABS(E26)<=F26,"within_input_tolerance","unexplained_difference")) -> within_input_tolerance | H26: 原表百万美元列示精度，检验可直接复算桥；阈值以美元计。 | I26: =IF(ISNUMBER(E26),"","missing or unavailable input") | J26: 0
A27: R_cfo_2025 | B27: 2025 CFO 全桥 | C27: cfo2025 | D27: C_cfo_2025 | E27: =ROUND('Facts'!F142-'Calculations'!D27,J27) -> 0 | F27: 0 | G27: =IF(COUNT(E27,F27)<2,"not_tested",IF(ABS(E27)<=F27,"within_input_tolerance","unexplained_difference")) -> within_input_tolerance | H27: 原表百万美元列示精度，检验可直接复算桥；阈值以美元计。 | I27: =IF(ISNUMBER(E27),"","missing or unavailable input") | J27: 0
A28: R_cashroll_2025 | B28: 2025 现金滚动 | C28: cashend2025 | D28: C_cashroll_2025 | E28: =ROUND('Facts'!F178-'Calculations'!D28,J28) -> 0 | F28: 0 | G28: =IF(COUNT(E28,F28)<2,"not_tested",IF(ABS(E28)<=F28,"within_input_tolerance","unexplained_difference")) -> within_input_tolerance | H28: 原表百万美元列示精度，检验可直接复算桥；阈值以美元计。 | I28: =IF(ISNUMBER(E28),"","missing or unavailable input") | J28: 0
A29: R_eqroll_2025 | B29: 2025 权益滚动 | C29: equity2025 | D29: C_eqroll_2025 | E29: =ROUND('Facts'!F70-'Calculations'!D29,J29) -> 0 | F29: 0 | G29: =IF(COUNT(E29,F29)<2,"not_tested",IF(ABS(E29)<=F29,"within_input_tolerance","unexplained_difference")) -> within_input_tolerance | H29: 原表百万美元列示精度，检验可直接复算桥；阈值以美元计。 | I29: =IF(ISNUMBER(E29),"","missing or unavailable input") | J29: 0
A30: R_ca_2024 | B30: 2024 流动资产分项合计 | C30: ca2024 | D30: C_ca_2024 | E30: =ROUND('Facts'!F17-'Calculations'!D34,J30) -> 0 | F30: 0 | G30: =IF(COUNT(E30,F30)<2,"not_tested",IF(ABS(E30)<=F30,"within_input_tolerance","unexplained_difference")) -> within_input_tolerance | H30: 原表百万美元列示精度，检验可直接复算桥；阈值以美元计。 | I30: =IF(ISNUMBER(E30),"","missing or unavailable input") | J30: 0
A31: R_assets_2024 | B31: 2024 总资产分项合计 | C31: assets2024 | D31: C_assets_2024 | E31: =ROUND('Facts'!F35-'Calculations'!D35,J31) -> 0 | F31: 0 | G31: =IF(COUNT(E31,F31)<2,"not_tested",IF(ABS(E31)<=F31,"within_input_tolerance","unexplained_difference")) -> within_input_tolerance | H31: 原表百万美元列示精度，检验可直接复算桥；阈值以美元计。 | I31: =IF(ISNUMBER(E31),"","missing or unavailable input") | J31: 0
A32: R_cl_2024 | B32: 2024 流动负债分项合计 | C32: cl2024 | D32: C_cl_2024 | E32: =ROUND('Facts'!F51-'Calculations'!D36,J32) -> 0 | F32: 0 | G32: =IF(COUNT(E32,F32)<2,"not_tested",IF(ABS(E32)<=F32,"within_input_tolerance","unexplained_difference")) -> within_input_tolerance | H32: 原表百万美元列示精度，检验可直接复算桥；阈值以美元计。 | I32: =IF(ISNUMBER(E32),"","missing or unavailable input") | J32: 0
A33: R_liab_2024 | B33: 2024 总负债分项合计 | C33: liabilities2024 | D33: C_liab_2024 | E33: =ROUND('Facts'!F61-'Calculations'!D37,J33) -> 0 | F33: 0 | G33: =IF(COUNT(E33,F33)<2,"not_tested",IF(ABS(E33)<=F33,"within_input_tolerance","unexplained_difference")) -> within_input_tolerance | H33: 原表百万美元列示精度，检验可直接复算桥；阈值以美元计。 | I33: =IF(ISNUMBER(E33),"","missing or unavailable input") | J33: 0
A34: R_eqparts_2024 | B34: 2024 权益组成 | C34: equity2024 | D34: C_eqparts_2024 | E34: =ROUND('Facts'!F71-'Calculations'!D38,J34) -> 0 | F34: 0 | G34: =IF(COUNT(E34,F34)<2,"not_tested",IF(ABS(E34)<=F34,"within_input_tolerance","unexplained_difference")) -> within_input_tolerance | H34: 原表百万美元列示精度，检验可直接复算桥；阈值以美元计。 | I34: =IF(ISNUMBER(E34),"","missing or unavailable input") | J34: 0
A35: R_bs_2024 | B35: 2024 资产负债恒等式 | C35: assets2024 | D35: C_bs_2024 | E35: =ROUND('Facts'!F35-'Calculations'!D39,J35) -> 0 | F35: 0 | G35: =IF(COUNT(E35,F35)<2,"not_tested",IF(ABS(E35)<=F35,"within_input_tolerance","unexplained_difference")) -> within_input_tolerance | H35: 原表百万美元列示精度，检验可直接复算桥；阈值以美元计。 | I35: =IF(ISNUMBER(E35),"","missing or unavailable input") | J35: 0
A36: R_rev_2024 | B36: 2024 持续收入组成 | C36: revenue2024 | D36: C_rev_2024 | E36: =ROUND('Facts'!F77-'Calculations'!D40,J36) -> 0 | F36: 0 | G36: =IF(COUNT(E36,F36)<2,"not_tested",IF(ABS(E36)<=F36,"within_input_tolerance","unexplained_difference")) -> within_input_tolerance | H36: 原表百万美元列示精度，检验可直接复算桥；阈值以美元计。 | I36: =IF(ISNUMBER(E36),"","missing or unavailable input") | J36: 0
A37: R_opex_2024 | B37: 2024 持续费用组成 | C37: opex2024 | D37: C_opex_2024 | E37: =ROUND('Facts'!F93-'Calculations'!D41,J37) -> 0 | F37: 0 | G37: =IF(COUNT(E37,F37)<2,"not_tested",IF(ABS(E37)<=F37,"within_input_tolerance","unexplained_difference")) -> within_input_tolerance | H37: 原表百万美元列示精度，检验可直接复算桥；阈值以美元计。 | I37: =IF(ISNUMBER(E37),"","missing or unavailable input") | J37: 0
A38: R_pbt_2024 | B38: 2024 持续税前利润桥 | C38: contpbt2024 | D38: C_pbt_2024 | E38: =ROUND('Facts'!F103-'Calculations'!D42,J38) -> 0 | F38: 0 | G38: =IF(COUNT(E38,F38)<2,"not_tested",IF(ABS(E38)<=F38,"within_input_tolerance","unexplained_difference")) -> within_input_tolerance | H38: 原表百万美元列示精度，检验可直接复算桥；阈值以美元计。 | I38: =IF(ISNUMBER(E38),"","missing or unavailable input") | J38: 0
A39: R_contni_2024 | B39: 2024 持续净利润桥 | C39: contni2024 | D39: C_contni_2024 | E39: =ROUND('Facts'!F107-'Calculations'!D43,J39) -> 0 | F39: 0 | G39: =IF(COUNT(E39,F39)<2,"not_tested",IF(ABS(E39)<=F39,"within_input_tolerance","unexplained_difference")) -> within_input_tolerance | H39: 原表百万美元列示精度，检验可直接复算桥；阈值以美元计。 | I39: =IF(ISNUMBER(E39),"","missing or unavailable input") | J39: 0
A40: R_net_2024 | B40: 2024 持续加终止净利润 | C40: netincome2024 | D40: C_net_2024 | E40: =ROUND('Facts'!F115-'Calculations'!D44,J40) -> 0 | F40: 0 | G40: =IF(COUNT(E40,F40)<2,"not_tested",IF(ABS(E40)<=F40,"within_input_tolerance","unexplained_difference")) -> within_input_tolerance | H40: 原表百万美元列示精度，检验可直接复算桥；阈值以美元计。 | I40: =IF(ISNUMBER(E40),"","missing or unavailable input") | J40: 0
...

Sheet Sources
A1: ID | B1: 文件 | C1: 链接 | D1: 公布日期 | E1: SHA256 | F1: 时间证据与限制
A2: S25 | B2: Crown Castle 2025 Form 10-K | C2: https://investor.crowncastle.com/static-files/68fb84e1-1dac-440d-96b4-55b9603e10dd | D2: 2026-02-23 | E2: 56243c10e5fe5d02b60178eb88aff4ad5f4de6e3220b3060c2b1b3a9f70eb803 | F2: 官方 IR 原件；SEC accession 0001051470-26-000016。重点实际读印刷/物理页 40、45、56–61、65–72、75–81、87–90；数字表 p45/58/59/60/61/72/88 视觉复核。其余只用于检索定位，不称全页审阅。 核对note8/p75–79、note18/p89及Exhibit Index p101–102。
A3: S24 | B3: Crown Castle 2024 Form 10-K（原报） | C3: https://investor.crowncastle.com/static-files/baed4489-6578-4e32-81e6-a084eea66a02 | D3: 2025-03-14 | E3: 2c228ec3bcecba25d66882f47bd38f6016b3932981e716b70c88b8fd2223993d | F3: 官方IR原件；accession 0001051470-25-000089。承接原读p39、48–50、61、89；实际读取note5/p75和note14/p88–89，p75图像核对Fiber/Towers/合并商誉三列。
A4: SSEC | B4: Crown Castle 2025-06-04 SEC comment-response letter | C4: https://www.sec.gov/Archives/edgar/data/1051470/000105147025000154/filename1.htm | D4: 未列单一日期 | F4: 实际在线阅读完整公司回复；信函日期 2025-06-04、accession 为 2025 年；首次公开日期未独立核准，故 published=null。用于事后理解截至截止日已公开的会计解释，不是当时市场首次获悉日研究。 在线核对comments1–2；ASC360实际引用35-17，税及830/819差额均在comment2。
A5: SQ125 | B5: Crown Castle Q1 2025 Form 10-Q 原报 | C5: https://www.sec.gov/Archives/edgar/data/1051470/000105147025000141/cci-20250331.htm | D5: 2025-05-09 | F5: 实际在线读 note 3 待售资产负债及准备；未本地保存全文。日期经公司 IR filing index 核对。
A6: SQ126 | B6: Crown Castle Q1 2026 Form 10-Q | C6: https://investor.crowncastle.com/static-files/de60fca2-89d5-499d-899b-8e0a23030617 | D6: 2026-05-07 | E6: f00ac5617bb5713a00240c46c0bf1915f161b658c26e815bb6a78984219c8f5b | F6: accession 0001051470-26-000059；印刷页比物理 PDF 页少 1。实际读四表相关行、note 3/p9、债务 p12、现金 p18、期后 p19–20、流动性 p28；物理 p10/19/20/21 视觉复核。未经审计中期报表。 另读Item6 Exhibit Index印刷p38/PDF p39，用于公开协议版本核查。
A7: SSALE | B7: Crown Castle announces completion of fiber and small cell sale | C7: https://investor.crowncastle.com/node/29086 | D7: 2026-05-01 | E7: 3fa9331057186a54cd18bdc580ed723fe6164a9f7de14980a769bf3918e31fff | F7: 实际阅读公司 2026-05-01 09:19 EDT 新闻稿；区分已完成交割与预计未来偿债/回购。
A8: SCREDIT | B8: Crown Castle May 1 2026 Form 8-K and Exhibit 10.1 credit agreement | C8: https://investor.crowncastle.com/static-files/dd7712df-51aa-4a29-b6a5-67becf7b2234 | D8: 2026-05-01 | E8: 50bc26bcb8f671d133d1c36756a99d769d3780fcf2fdcdd4c598fc53a22d5d68 | F8: accession 0001051470-26-000055；已读 8-K 概要、协议 §1.01 EBITDA/债务/现金定义、§1.04、§1.05、§4.02、§6.10；协议印刷页 43/44/93/108 对应 PDF 物理页 53/54/103/118。未声称检查所有附件。 核对8-K Item1.02及新协议Net Income印刷p12–13/PDF p22–23，与旧协议分别比较，不追溯使用新本金/租赁文字。
A9: SFASB | B9: FASB ASU 2017-04 — Simplifying the Test for Goodwill Impairment | C9: https://storage.fasb.org/ASU2017-04.pdf | D9: 未列单一日期 | E9: e2ee3d7f5672615190b8e14719576e110e4ad77f40fec4043b03fe387177f648 | F9: 封面 January 2017，未核定日级发表日期。实际读封面权威性说明、摘要、印刷 p8/PDF p14 与印刷 p12/PDF p18，后两页图像复核下划线新增和删除线。ASU 说明 Codification 变更，本身并非权威 Codification；未称已核对所有后续修订。
A10: SPROFORMA | B10: 2026-05-01 出售8-K及Exhibit99.2公开未经审计备考 | C10: https://investor.crowncastle.com/static-files/f4ff727f-0f13-4f18-affa-1ff461698ccf | D10: 2026-05-01 | E10: 8027c9c3885a4c41f6b2a30687dedee25f084b96d06d8d8275ea1736f107c6c3 | F10: 官方21页PDF；实际读物理p2–3正文/索引、p5/p10公告及p18–21 Exhibit99.2，特别Note2(A)–(E)。完整下载和提取不等于全文审阅；BS假设2025-12-31、利润表假设2025-01-01完成。
A11: SSPA | B11: 2025-03-13签署出售协议（2025-03-17提交8-K Exhibit2.1） | C11: https://investor.crowncastle.com/static-files/3b910737-4f3d-4197-a8b4-893f83855c9f | D11: 2025-03-17 | E11: 47073f1af131b85356eb749a4ed8703ee22f5593fbd1cb01f06bbf75b6667c69 | F11: 官方169页PDF；SEC对应原件https://www.sec.gov/Archives/edgar/data/1051470/000095014225000762/eh250603725_ex0201.htm亦在线读。实际读§2.2–2.7（协议p35–44/PDF p45–54）、§1.1相关定义PDF p16/20/23/34–37/40和§12.9 PDF p160。附表/部分内容按Reg S-K省略；未把最初协议称作完整最终修订版。
A12: SOLDCREDIT | B12: 2022-07-08 Amendment No.7及附后旧信用协议 | C12: https://investor.crowncastle.com/static-files/d735da3e-9136-43ce-ad76-3a96bcb686cf | D12: 2022-07-08 | E12: 8fcc0400dc2335a91feed8c83e4eb821b9750fa8fe86fca14b93918d23766333 | F12: 官方196页PDF，SEC对应https://www.sec.gov/Archives/edgar/data/1051470/000119312522190527/d536644dex101.htm。实际读指定定义PDF p42–43/45–46/56–57/69/73/79–81、§1.04/1.05 PDF p84–85（印刷p55–56）、§6.09/6.10 PDF p158（印刷p129）；SEC在线区分删除线。未全读所有附件。
A13: S_SP_Q4 | B13: Crown Castle Q4 2025 Supplemental Information | C13: https://investor.crowncastle.com/static-files/bea23792-6649-4b95-9395-aa837e68396c | D13: 2026-02-04 | E13: 9f02eedff49239618fc0454339d80c8b8edbfc13f3e0a166e93fad313b86854b | F13: 官方原件；S&P日期为当前所用重发版，原发日期与阅读范围见对应证据；公司补充资料页码为PDF物理页。
A14: S_SP_Q1 | B14: Crown Castle Q1 2026 Supplemental Information | C14: https://investor.crowncastle.com/static-files/38f6a584-60a8-452d-bfd2-a44103aeec82 | D14: 2026-04-22 | E14: cb5cd5c2bc971628c318e0d4c63014e036364c1044381af9885bfcc808684572 | F14: 官方原件；S&P日期为当前所用重发版，原发日期与阅读范围见对应证据；公司补充资料页码为PDF物理页。
A15: S_SP_RATIOS | B15: S&P Corporate Methodology: Ratios And Adjustments | C15: https://www.maalot.co.il/Publications/MT20251223092257.pdf | D15: 2025-12-17 | E15: 0e97e341f6cc5f5662c76b021da898c243f10d32a89d13d3b233613d2b7619f3 | F15: 官方原件；S&P日期为当前所用重发版，原发日期与阅读范围见对应证据；公司补充资料页码为PDF物理页。
A16: S_SP_SECTORS | B16: S&P Sector-Specific Corporate Methodology — Digital Infrastructure | C16: https://www.maalot.co.il/Publications/MT20251012123218.pdf | D16: 2025-09-26 | E16: 31a53f0162f26153a279644fe954a064efdb35dfc549accfe2e4b601e0be5474 | F16: 官方原件；S&P日期为当前所用重发版，原发日期与阅读范围见对应证据；公司补充资料页码为PDF物理页。
A17: S_SP_XBRL | B17: SEC Companyfacts：Crown Castle 2025年度及2026Q1原申报事实 | C17: https://data.sec.gov/api/xbrl/companyfacts/CIK0001051470.json | D17: 未列单一日期 | E17: 26332892a4dcd974308249d90b2fd21a8a0a454f86190fc157c66b1699b57196 | F17: API响应取得于2026-10-04；动态合并响应没有单一公开日，published留空。年度事实选accession 0001051470-26-000016、filed 2026-02-23、2025-01-01至2025-12-31及该申报比较期间；季度事实选accession 0001051470-26-000059、filed 2026-05-07、2026-01-01至2026-03-31及该申报比较期间。只使用信息截止日前原申报选择；申报公开日与API快照取得日分开。InterestPaidNet标签原定义排除资本化利息，不能仅凭10-Q表中cash paid for interest行标题推定此属性。
... A23: S_DEV_SUB | B23: Reflecting Subordination Risk In Corporate Issue Ratings | C23: https://spratings.spglobal.com/ratings/en/regulatory/article/-/view/sourceId/10486915 | D23: 2026-03-31 | E23: fd48104a99b711ae867fd13e69a5e218aefaf3fb54a939d301eceeb40cd01ba4 | F23: 完整官方HTML内嵌2026-03-31非重大重发文章；核scope、六步及债务定义。2024本地PDF不替代当前版本；特殊行业附录未全面审阅。

Sheet Evidence
A1: ID | B1: 来源 | C1: 定位 | D1: 观察 | E1: 可靠性与限制
A2: E25BS | B2: S25 | C2: 印刷及 PDF p58，Consolidated Balance Sheet，2025/2024 两列 | D2: 资产、负债及权益四表组成行；比较列已按终止经营重列。 | E2: 官方原件披露；阅读与复算不构成审计保证
A3: E25PL | B3: S25 | C3: 印刷及 PDF p59，Consolidated Statement of Operations and Comprehensive Income | D3: 持续、终止、处置损失及合并损益分别列示。 | E3: 官方原件披露；阅读与复算不构成审计保证
A4: E25CF | B4: S25 | C4: 印刷及 PDF p60，Consolidated Statement of Cash Flows | D4: 现金流始于合并净利润，先去除终止经营损益及处置损失，再并入终止经营 CFO；期末现金含受限及终止经营。 | E4: 官方原件披露；阅读与复算不构成审计保证
A5: E25EQ | B5: S25 | C5: 印刷及 PDF p61，Consolidated Statement of Equity (Deficit) | D5: 权益年初、股份支付相关净额、库存股/回购、综合收益和宣告分配桥。 | E5: 官方原件披露；阅读与复算不构成审计保证
A6: E25HFS | B6: S25 | C6: note 3，印刷及 PDF p71–72，尤其 p72 资产负债、损益及脚注 (b)(c) | D6: Fiber Business 出售构成重大策略转变；持有待售后停止折旧摊销；处置损失包括准备与已发生售出费用，REIT 未确认对应税益。 | E6: 官方原件披露；阅读与复算不构成审计保证
A7: E24IMPAIR | B7: S24 | C7: p48–50 Critical Accounting Policies；note 5，印刷/PDF p75 goodwill rollforward | D7: 长期资产用未折现现金流先测试可收回性；Fiber 商誉估值受 small cells 需求、扩张计划、长期现金流及估值假设影响；年末尚未满足持有待售。 p75分部表：Fiber商誉4,958全额减值至0；Towers5,127未变；集团合并10,085减至5,127，剩余全属Towers。 | E7: 官方原件披露；阅读与复算不构成审计保证
A8: E24WRITE | B8: S24 | C8: MD&A p39，Asset write-down charges | D8: 当年取消约七千 greenfield nodes 有独立资产核销；不能把未触发 ASC360 资产组减值泛化为没有任何资产核销。 | E8: 官方原件披露；阅读与复算不构成审计保证
A9: ESECSEQ | B9: SSEC | C9: 公司回复 Staff comment 1；引用 ASC350-20-35-31 和 ASC360-10-35-17 | D9: 公司明确先测长期资产再测商誉。Fiber segment 同时是最低独立现金流资产组及商誉报告单元；同一预算模型以未折现和折现两个计量基础形成不同结论。CBSA 分析为辅助，非主要测试单元。 | E9: SEC 托管公司正式回复；非 SEC 接受结论或审计程序执行证据
A10: ESECSALE | B10: SSEC | C10: 公司回复 comment 2；ASC205-20-45-3A、税项及830损失/819准备/11售出费用 | D10: 公司区分当季处置损失与持有待售准备，差额系已支付或应计售出成本；终止业务税额与处置税额不是同一事项。 | E10: 公司回复；未把其承诺的披露修订等同会计差错更正
A11: E24ORIG | B11: S24 | C11: 原报 p61 合并损益；note 14/p88–89 segment results，分部表p89 | D11: 保留原报合并收入及原 Tower/Fiber 分部收入，与次年重列版本独立比较。 | E11: 官方原件披露；阅读与复算不构成审计保证
A12: E25TAX | B12: S25 | C12: note 10，印刷及 PDF p80，所得税组成及法定税率金额调节 | D12: 持续经营税项以法定金额、REIT、州及外国税因素调节；REIT 不代表全部业务免税。 | E12: 官方原件披露；阅读与复算不构成审计保证
